Workbook

Sheet padi sawah
A2: DATA LUAS TANAM PADI (SAWAH) PER BULAN
A3: KOTA CILEGON TAHUN 2017
O5: (Ha)
A6: No | B6: Kecamatan | C6: Bulan | O6: Jumlah
C7: Jan | D7: Feb | E7: Maret | F7: Apr | G7: Mei | H7: Juni | I7: Juli | J7: Agst | K7: Sept | L7: Okt | M7: Nov | N7: Des
A8: 1 | B8: 2 | C8: 3 | D8: 4 | E8: 5 | F8: 6 | G8: 7 | H8: 8 | I8: 9 | J8: 10 | K8: 11 | L8: 12 | M8: 13 | N8: 14 | O8: 15
A9: 1 | B9: CIWANDAN | C9: 177 | D9: 45 | E9: 0 | F9: 0 | G9: 35 | H9: 29 | I9: 0 | J9: 0 | K9: 0 | L9: 1 | M9: 1 | N9: 5 | O9: =SUM(C9:N9) -> 293 | Q9: =SUM(I9:K9) -> 0
A10: 2 | B10: CITANGKIL | C10: 24 | D10: 9 | E10: 0 | F10: 0 | G10: 100 | H10: 49 | I10: 0 | J10: 4 | K10: 0 | L10: 14 | M10: 0 | N10: 35 | O10: =SUM(C10:N10) -> 235 | Q10: =SUM(I10:K10) -> 4
A11: 3 | B11: PULOMERAK | C11: 10 | D11: 5 | E11: 0 | F11: 0 | G11: 10 | H11: 0 | I11: 0 | J11: 0 | K11: 1 | L11: 0 | M11: 0 | N11: 0 | O11: =SUM(C11:N11) -> 26 | Q11: =SUM(I11:K11) -> 1
A12: 4 | B12: PURWAKARTA | C12: 129 | D12: 20 | E12: 5 | F12: 0 | G12: 3 | H12: 10 | I12: 0 | J12: 1 | K12: 0 | L12: 0 | M12: 0 | N12: 15 | O12: =SUM(C12:N12) -> 183 | Q12: =SUM(I12:K12) -> 1
A13: 5 | B13: GROGOL | C13: 166 | D13: 0 | E13: 0 | F13: 8 | G13: 13 | H13: 0 | I13: 0 | J13: 0 | K13: 0 | L13: 0 | M13: 0 | N13: 0 | O13: =SUM(C13:N13) -> 187 | Q13: =SUM(I13:K13) -> 0
A14: 6 | B14: CILEGON | C14: 0 | D14: 1 | E14: 9 | F14: 17 | G14: 25 | H14: 0 | I14: 0 | J14: 7 | K14: 0 | L14: 8 | M14: 4 | N14: 6 | O14: =SUM(C14:N14) -> 77 | Q14: =SUM(I14:K14) -> 7 | S14: =(8+19)/1782*100 -> 1.5151515
A15: 7 | B15: JOMBANG | C15: 178 | D15: 3 | E15: 0 | F15: 12 | G15: 169 | H15: 58 | I15: 25 | J15: 0 | K15: 0 | L15: 0 | M15: 5 | N15: 41 | O15: =SUM(C15:N15) -> 491 | Q15: =SUM(I15:K15) -> 25
A16: 8 | B16: CIBEBER | C16: 7 | D16: 33 | E16: 0 | F16: 53 | G16: 89 | H16: 16 | I16: 25 | J16: 21 | K16: 3 | L16: 0 | M16: 13 | N16: 115 | O16: =SUM(C16:N16) -> 375 | Q16: =SUM(I16:K16) -> 49
A17: JUMLAH | C17: =SUM(C9:C16) -> 691 | D17: =SUM(D9:D16) -> 116 | E17: =SUM(E9:E16) -> 14 | F17: =SUM(F9:F16) -> 90 | G17: =SUM(G9:G16) -> 444 | H17: =SUM(H9:H16) -> 162 | I17: =SUM(I9:I16) -> 50 | J17: =SUM(J9:J16) -> 33 | ... O17: =SUM(O9:O16) -> 1867 | Q17: =SUM(Q9:Q16) -> 87 | T17: 23 | U17: 23 | V17: 217 | W17: 40
Q19: =SUM(L17:N17) -> 263 | T19: =SUM(T17:W17) -> 303 | U19: =T19/1782*100 -> 17.003367
U20: =T19/2860*100 -> 10.594406
A35: DATA LUAS PANEN PADI (SAWAH) PER BULAN
A36: KOTA CILEGON TAHUN 2017
O38: (Ha)
A39: No | B39: Kecamatan | C39: Bulan | O39: Jumlah
C40: Jan | D40: Feb | E40: Maret | F40: Apr | G40: Mei | H40: Juni | I40: Juli | J40: Agst | K40: Sept | L40: Okt | M40: Nov | N40: Des
A41: 1 | B41: 2 | C41: 3 | D41: 4 | E41: 5 | F41: 6 | G41: 7 | H41: 8 | I41: 9 | J41: 10 | K41: 11 | L41: 12 | M41: 13 | N41: 14 | O41: 15
A42: 1 | B42: CIWANDAN | C42: 2 | D42: 0 | E42: 45 | F42: 177 | G42: 45 | H42: 0 | I42: 0 | J42: 35 | K42: 29 | L42: 0 | M42: 0 | N42: 0 | O42: =SUM(C42:N42) -> 333
A43: 2 | B43: CITANGKIL | C43: 6 | D43: 17 | E43: 133 | F43: 57 | G43: 5 | H43: 0 | I43: 8 | J43: 133 | K43: 8 | L43: 3 | M43: 1 | N43: 0 | O43: =SUM(C43:N43) -> 371
A44: 3 | B44: PULOMERAK | C44: 0 | D44: 5 | E44: 5 | F44: 20 | G44: 0 | H44: 0 | I44: 0 | J44: 10 | K44: 0 | L44: 0 | M44: 0 | N44: 1 | O44: =SUM(C44:N44) -> 41
A45: 4 | B45: PURWAKARTA | C45: 5 | D45: 0 | E45: 10 | F45: 161 | G45: 25 | H45: 0 | I45: 3 | J45: 10 | K45: 0 | L45: 1 | M45: 0 | N45: 0 | O45: =SUM(C45:N45) -> 215
A46: 5 | B46: GROGOL | C46: 0 | D46: 5 | E46: 10 | F46: 166 | G46: 0 | H46: 0 | I46: 8 | J46: 13 | K46: 0 | L46: 0 | M46: 0 | N46: 0 | O46: =SUM(C46:N46) -> 202
A47: 6 | B47: CILEGON | C47: 7 | D47: 43 | E47: 0 | F47: 0 | G47: 1 | H47: 15 | I47: 11 | J47: 25 | K47: 0 | L47: 0 | M47: 0 | N47: 7 | O47: =SUM(C47:N47) -> 109
A48: 7 | B48: JOMBANG | C48: 15 | D48: 5 | E48: 162 | F48: 158 | G48: 2 | H48: 15 | I48: 12 | J48: 165 | K48: 48 | L48: 24 | M48: 0 | N48: 0 | O48: =SUM(C48:N48) -> 606
A49: 8 | B49: CIBEBER | C49: 26 | D49: 113 | E49: 134 | F49: 0 | G49: 40 | H49: 30 | I49: 112 | J49: 16 | K49: 25 | L49: 21 | M49: 3 | N49: 0 | O49: =SUM(C49:N49) -> 520
A50: JUMLAH | C50: =SUM(C42:C49) -> 61 | D50: =SUM(D42:D49) -> 188 | E50: =SUM(E42:E49) -> 499 | F50: =SUM(F42:F49) -> 739 | G50: =SUM(G42:G49) -> 118 | H50: =SUM(H42:H49) -> 60 | I50: =SUM(I42:I49) -> 154 | J50: =SUM(J42:J49) -> 407 | ... O50: =SUM(O42:O49) -> 2397
J52: =SUM(C50:J50) -> 2226
L56: =J50*5.8 -> 2360.6
A68: DATA PRODUKSI PADI (SAWAH) PER BULAN
A69: KOTA CILEGON TAHUN 2017
O71: (Ton)
A72: No | B72: Kecamatan | C72: Bulan | O72: Jumlah
C73: Jan | D73: Feb | E73: Maret | F73: Apr | G73: Mei | H73: Juni | I73: Juli | J73: Agst | K73: Sept | L73: Okt | M73: Nov | N73: Des
A74: 1 | B74: 2 | C74: 3 | D74: 4 | E74: 5 | F74: 6 | G74: 7 | H74: 8 | I74: 9 | J74: 10 | K74: 11 | L74: 12 | M74: 13 | N74: 14 | O74: 15
...

Sheet puso
A1: DATA LUAS PUSO PADI (SAWAH) PER BULAN
A2: KOTA CILEGON TAHUN 2017
O3: (Ha)
A4: No | B4: Kecamatan | C4: Bulan | O4: Jumlah
C5: Jan | D5: Feb | E5: Maret | F5: Apr | G5: Mei | H5: Juni | I5: Juli | J5: Agst | K5: Sept | L5: Okt | M5: Nov | N5: Des
A6: 1 | B6: 2 | C6: 3 | D6: 4 | E6: 5 | F6: 6 | G6: 7 | H6: 8 | I6: 9 | J6: 10 | K6: 11 | L6: 12 | M6: 13 | N6: 14 | O6: 15
A7: 1 | B7: CIWANDAN | C7: 0 | D7: 0 | E7: 0 | F7: 0 | G7: 0 | H7: 0 | I7: 0 | J7: 0 | K7: 0 | L7: 0 | M7: 0 | N7: 0 | O7: =SUM(C7:N7) -> 0
A8: 2 | B8: CITANGKIL | C8: 0 | D8: 0 | E8: 0 | F8: 0 | G8: 0 | H8: 0 | I8: 0 | J8: 0 | K8: 0 | L8: 0 | M8: 0 | N8: 0 | O8: =SUM(C8:N8) -> 0
A9: 3 | B9: PULOMERAK | C9: 0 | D9: 0 | E9: 0 | F9: 0 | G9: 0 | H9: 0 | I9: 0 | J9: 0 | K9: 0 | L9: 0 | M9: 0 | N9: 0 | O9: =SUM(C9:N9) -> 0
A10: 4 | B10: PURWAKARTA | C10: 0 | D10: 0 | E10: 0 | F10: 0 | G10: 0 | H10: 0 | I10: 0 | J10: 0 | K10: 0 | L10: 0 | M10: 0 | N10: 0 | O10: =SUM(C10:N10) -> 0
A11: 5 | B11: GROGOL | C11: 0 | D11: 0 | E11: 0 | F11: 0 | G11: 0 | H11: 0 | I11: 0 | J11: 0 | K11: 0 | L11: 0 | M11: 0 | N11: 0 | O11: =SUM(C11:N11) -> 0
A12: 6 | B12: CILEGON | C12: 0 | D12: 0 | E12: 0 | F12: 0 | G12: 0 | H12: 0 | I12: 0 | J12: 0 | K12: 0 | L12: 0 | M12: 0 | N12: 0 | O12: =SUM(C12:N12) -> 0
A13: 7 | B13: JOMBANG | C13: 0 | D13: 0 | E13: 0 | F13: 0 | G13: 0 | H13: 0 | I13: 0 | J13: 0 | K13: 1 | L13: 0 | M13: 0 | N13: 0 | O13: =SUM(C13:N13) -> 1
A14: 8 | B14: CIBEBER | C14: 0 | D14: 0 | E14: 0 | F14: 0 | G14: 0 | H14: 0 | I14: 0 | J14: 0 | K14: 0 | L14: 0 | M14: 0 | N14: 0 | O14: =SUM(C14:N14) -> 0
A15: JUMLAH | C15: =SUM(C7:C14) -> 0 | D15: =SUM(D7:D14) -> 0 | E15: =SUM(E7:E14) -> 0 | F15: =SUM(F7:F14) -> 0 | G15: =SUM(G7:G14) -> 0 | H15: =SUM(H7:H14) -> 0 | I15: =SUM(I7:I14) -> 0 | J15: =SUM(J7:J14) -> 0 | ... O15: =SUM(O7:O14) -> 1
A17: DATA LUAS PUSO KEDELAI PER BULAN
A18: KOTA CILEGON TAHUN 2017
O19: (Ha)
A20: No | B20: Kecamatan | C20: Bulan | O20: Jumlah
C21: Jan | D21: Feb | E21: Maret | F21: Apr | G21: Mei | H21: Juni | I21: Juli | J21: Agst | K21: Sept | L21: Okt | M21: Nov | N21: Des
A22: 1 | B22: 2 | C22: 3 | D22: 4 | E22: 5 | F22: 6 | G22: 7 | H22: 8 | I22: 9 | J22: 10 | K22: 11 | L22: 12 | M22: 13 | N22: 14 | O22: 15
A23: 1 | B23: CIWANDAN | C23: 0 | D23: 0 | E23: 0 | F23: 0 | G23: 0 | H23: 0 | I23: 0 | J23: 0 | K23: 0 | L23: 0 | M23: 0 | N23: 0 | O23: =SUM(C23:N23) -> 0
A24: 2 | B24: CITANGKIL | C24: 0 | D24: 0 | E24: 0 | F24: 0 | G24: 0 | H24: 0 | I24: 0 | J24: 0 | K24: 0 | L24: 0 | M24: 0 | N24: 0 | O24: =SUM(C24:N24) -> 0
A25: 3 | B25: PULOMERAK | C25: 0 | D25: 0 | E25: 0 | F25: 0 | G25: 0 | H25: 0 | I25: 0 | J25: 0 | K25: 0 | L25: 0 | M25: 0 | N25: 0 | O25: =SUM(C25:N25) -> 0
A26: 4 | B26: PURWAKARTA | C26: 0 | D26: 0 | E26: 0 | F26: 0 | G26: 0 | H26: 0 | I26: 0 | J26: 0 | K26: 0 | L26: 0 | M26: 0 | N26: 0 | O26: =SUM(C26:N26) -> 0
A27: 5 | B27: GROGOL | C27: 0 | D27: 0 | E27: 0 | F27: 0 | G27: 0 | H27: 0 | I27: 0 | J27: 0 | K27: 0 | L27: 0 | M27: 0 | N27: 0 | O27: =SUM(C27:N27) -> 0
A28: 6 | B28: CILEGON | C28: 0 | D28: 0 | E28: 0 | F28: 0 | G28: 0 | H28: 0 | I28: 0 | J28: 0 | K28: 0 | L28: 0 | M28: 0 | N28: 0 | O28: =SUM(C28:N28) -> 0
A29: 7 | B29: JOMBANG | C29: 0 | D29: 0 | E29: 0 | F29: 0 | G29: 0 | H29: 0 | I29: 0 | J29: 0 | K29: 0 | L29: 0 | M29: 0 | N29: 0 | O29: =SUM(C29:N29) -> 0
A30: 8 | B30: CIBEBER | C30: 0 | D30: 0 | E30: 0 | F30: 0 | G30: 0 | H30: 0 | I30: 0 | J30: 0 | K30: 0 | L30: 0 | M30: 0 | N30: 0 | O30: =SUM(C30:N30) -> 0
A31: JUMLAH | C31: =SUM(C23:C30) -> 0 | D31: =SUM(D23:D30) -> 0 | E31: =SUM(E23:E30) -> 0 | F31: =SUM(F23:F30) -> 0 | G31: =SUM(G23:G30) -> 0 | H31: =SUM(H23:H30) -> 0 | I31: =SUM(I23:I30) -> 0 | J31: =SUM(J23:J30) -> 0 | ... O31: =SUM(O23:O30) -> 0
K34: Kepala Dinas Ketahanan Pangan dan Pertanian
K35: Kota Cilegon
K39: Ir. Wawan Hermawan, MM
K40: NIP. 19600110 198603 1 012

Sheet padi ladang
A2: DATA LUAS TANAM PADI (DARAT) PER BULAN
A3: KOTA CILEGON TAHUN 2017
O5: (Ha)
A6: No | B6: Kecamatan | C6: Bulan | O6: Jumlah
C7: Jan | D7: Feb | E7: Maret | F7: Apr | G7: Mei | H7: Juni | I7: Juli | J7: Agst | K7: Sept | L7: Okt | M7: Nov | N7: Des
A8: 1 | B8: 2 | C8: 3 | D8: 4 | E8: 5 | F8: 6 | G8: 7 | H8: 8 | I8: 9 | J8: 10 | K8: 11 | L8: 12 | M8: 13 | N8: 14 | O8: 15
A9: 1 | B9: CIWANDAN | C9: 0 | D9: 0 | E9: 0 | F9: 0 | G9: 0 | H9: 0 | I9: 0 | J9: 0 | K9: 0 | L9: 0 | M9: 0 | N9: 0 | O9: =SUM(C9:N9) -> 0
A10: 2 | B10: CITANGKIL | C10: 0 | D10: 0 | E10: 0 | F10: 0 | G10: 0 | H10: 0 | I10: 0 | J10: 0 | K10: 0 | L10: 0 | M10: 0 | N10: 0 | O10: =SUM(C10:N10) -> 0
A11: 3 | B11: PULOMERAK | C11: 18 | D11: 0 | E11: 0 | F11: 0 | G11: 0 | H11: 0 | I11: 0 | J11: 0 | K11: 0 | L11: 0 | M11: 0 | N11: 0 | O11: =SUM(C11:N11) -> 18
A12: 4 | B12: PURWAKARTA | C12: 0 | D12: 0 | E12: 0 | F12: 0 | G12: 0 | H12: 0 | I12: 0 | J12: 0 | K12: 0 | L12: 0 | M12: 0 | N12: 0 | O12: =SUM(C12:N12) -> 0
A13: 5 | B13: GROGOL | C13: 0 | D13: 0 | E13: 0 | F13: 0 | G13: 0 | H13: 0 | I13: 0 | J13: 0 | K13: 0 | L13: 0 | M13: 0 | N13: 0 | O13: =SUM(C13:N13) -> 0
A14: 6 | B14: CILEGON | C14: 0 | D14: 0 | E14: 0 | F14: 0 | G14: 0 | H14: 0 | I14: 0 | J14: 0 | K14: 0 | L14: 0 | M14: 0 | N14: 0 | O14: =SUM(C14:N14) -> 0
A15: 7 | B15: JOMBANG | C15: 0 | D15: 0 | E15: 0 | F15: 0 | G15: 0 | H15: 0 | I15: 0 | J15: 0 | K15: 0 | L15: 0 | M15: 0 | N15: 0 | O15: =SUM(C15:N15) -> 0
A16: 8 | B16: CIBEBER | C16: 0 | D16: 0 | E16: 0 | F16: 0 | G16: 0 | H16: 0 | I16: 0 | J16: 0 | K16: 0 | L16: 0 | M16: 0 | N16: 0 | O16: =SUM(C16:N16) -> 0
A17: JUMLAH | C17: =SUM(C9:C16) -> 18 | D17: =SUM(D9:D16) -> 0 | E17: =SUM(E9:E16) -> 0 | F17: =SUM(F9:F16) -> 0 | G17: =SUM(G9:G16) -> 0 | H17: =SUM(H9:H16) -> 0 | I17: =SUM(I9:I16) -> 0 | J17: =SUM(J9:J16) -> 0 | ... O17: =SUM(O9:O16) -> 18
A35: DATA LUAS PANEN PADI (DARAT) PER BULAN
A36: KOTA CILEGON TAHUN 2017
O38: (Ha)
A39: No | B39: Kecamatan | C39: Bulan | O39: Jumlah
C40: Jan | D40: Feb | E40: Maret | F40: Apr | G40: Mei | H40: Juni | I40: Juli | J40: Agst | K40: Sept | L40: Okt | M40: Nov | N40: Des
A41: 1 | B41: 2 | C41: 3 | D41: 4 | E41: 5 | F41: 6 | G41: 7 | H41: 8 | I41: 9 | J41: 10 | K41: 11 | L41: 12 | M41: 13 | N41: 14 | O41: 15
A42: 1 | B42: CIWANDAN | C42: 0 | D42: 0 | E42: 0 | F42: 0 | G42: 0 | H42: 0 | I42: 0 | J42: 0 | K42: 0 | L42: 0 | M42: 0 | N42: 0 | O42: =SUM(C42:N42) -> 0
A43: 2 | B43: CITANGKIL | C43: 0 | D43: 0 | E43: 0 | F43: 0 | G43: 0 | H43: 0 | I43: 0 | J43: 0 | K43: 0 | L43: 0 | M43: 0 | N43: 0 | O43: =SUM(C43:N43) -> 0
A44: 3 | B44: PULOMERAK | C44: 0 | D44: 35 | E44: 29 | F44: 18 | G44: 0 | H44: 0 | I44: 0 | J44: 0 | K44: 0 | L44: 0 | M44: 0 | N44: 0 | O44: =SUM(C44:N44) -> 82
A45: 4 | B45: PURWAKARTA | C45: 0 | D45: 0 | E45: 0 | F45: 0 | G45: 0 | H45: 0 | I45: 0 | J45: 0 | K45: 0 | L45: 0 | M45: 0 | N45: 0 | O45: =SUM(C45:N45) -> 0
A46: 5 | B46: GROGOL | C46: 0 | D46: 0 | E46: 0 | F46: 0 | G46: 0 | H46: 0 | I46: 0 | J46: 0 | K46: 0 | L46: 0 | M46: 0 | N46: 0 | O46: =SUM(C46:N46) -> 0
A47: 6 | B47: CILEGON | C47: 0 | D47: 0 | E47: 0 | F47: 0 | G47: 0 | H47: 0 | I47: 0 | J47: 0 | K47: 0 | L47: 0 | M47: 0 | N47: 0 | O47: =SUM(C47:N47) -> 0
A48: 7 | B48: JOMBANG | C48: 0 | D48: 0 | E48: 0 | F48: 0 | G48: 0 | H48: 0 | I48: 0 | J48: 0 | K48: 0 | L48: 0 | M48: 0 | N48: 0 | O48: =SUM(C48:N48) -> 0
A49: 8 | B49: CIBEBER | C49: 0 | D49: 0 | E49: 0 | F49: 0 | G49: 0 | H49: 0 | I49: 0 | J49: 0 | K49: 0 | L49: 0 | M49: 0 | N49: 0 | O49: =SUM(C49:N49) -> 0
A50: JUMLAH | C50: =SUM(C42:C49) -> 0 | D50: =SUM(D42:D49) -> 35 | E50: =SUM(E42:E49) -> 29 | F50: =SUM(F42:F49) -> 18 | G50: =SUM(G42:G49) -> 0 | H50: =SUM(H42:H49) -> 0 | I50: =SUM(I42:I49) -> 0 | J50: =SUM(J42:J49) -> 0 | ... O50: =SUM(O42:O49) -> 82
A68: DATA PRODUKSI PADI (DARAT) PER BULAN
A69: KOTA CILEGON TAHUN 2017
O71: (Ton)
A72: No | B72: Kecamatan | C72: Bulan | O72: Jumlah
C73: Jan | D73: Feb | E73: Maret | F73: Apr | G73: Mei | H73: Juni | I73: Juli | J73: Agst | K73: Sept | L73: Okt | M73: Nov | N73: Des
A74: 1 | B74: 2 | C74: 3 | D74: 4 | E74: 5 | F74: 6 | G74: 7 | H74: 8 | I74: 9 | J74: 10 | K74: 11 | L74: 12 | M74: 13 | N74: 14 | O74: 15
A75: 1 | B75: CIWANDAN | C75: 0 | D75: 0 | E75: 0 | F75: 0 | G75: 0 | H75: 0 | I75: 0 | J75: 0 | K75: 0 | L75: 0 | M75: 0 | N75: 0 | O75: =SUM(C75:N75) -> 0
A76: 2 | B76: CITANGKIL | C76: 0 | D76: 0 | E76: 0 | F76: 0 | G76: 0 | H76: 0 | I76: 0 | J76: 0 | K76: 0 | L76: 0 | M76: 0 | N76: 0 | O76: =SUM(C76:N76) -> 0
A77: 3 | B77: PULOMERAK | C77: 0 | D77: 123 | E77: 116 | F77: 72 | G77: 0 | H77: 0 | I77: 0 | J77: 0 | K77: 0 | L77: 0 | M77: 0 | N77: 0 | O77: =SUM(C77:N77) -> 311
A78: 4 | B78: PURWAKARTA | C78: 0 | D78: 0 | E78: 0 | F78: 0 | G78: 0 | H78: 0 | I78: 0 | J78: 0 | K78: 0 | L78: 0 | M78: 0 | N78: 0 | O78: =SUM(C78:N78) -> 0
...

Sheet jagung
A2: DATA LUAS TANAM JAGUNG PER BULAN
A3: KOTA CILEGON TAHUN 2017
O5: (Ha)
A6: No | B6: Kecamatan | C6: Bulan | O6: Jumlah
C7: Jan | D7: Feb | E7: Maret | F7: Apr | G7: Mei | H7: Juni | I7: Juli | J7: Agst | K7: Sept | L7: Okt | M7: Nov | N7: Des
A8: 1 | B8: 2 | C8: 3 | D8: 4 | E8: 5 | F8: 6 | G8: 7 | H8: 8 | I8: 9 | J8: 10 | K8: 11 | L8: 12 | M8: 13 | N8: 14 | O8: 15
A9: 1 | B9: CIWANDAN | C9: 0 | D9: 0 | E9: 0 | F9: 0 | G9: 0 | H9: 0 | I9: 0 | J9: 0 | K9: 0 | L9: 1 | M9: 6 | N9: 40 | O9: =SUM(C9:N9) -> 47 | P9: =SUM(I9:K9) -> 0
A10: 2 | B10: CITANGKIL | C10: 0 | D10: 0 | E10: 0 | F10: 0 | G10: 0 | H10: 0 | I10: 0 | J10: 1 | K10: 0 | L10: 0 | M10: 2 | N10: 24 | O10: =SUM(C10:N10) -> 27 | P10: =SUM(I10:K10) -> 1
A11: 3 | B11: PULOMERAK | C11: 0 | D11: 0 | E11: 0 | F11: 0 | G11: 0 | H11: 0 | I11: 0 | J11: 0 | K11: 0 | L11: 20 | M11: 0 | N11: 50 | O11: =SUM(C11:N11) -> 70 | P11: =SUM(I11:K11) -> 0
A12: 4 | B12: PURWAKARTA | C12: 0 | D12: 0 | E12: 0 | F12: 0 | G12: 0 | H12: 0 | I12: 0 | J12: 0 | K12: 2 | L12: 1 | M12: 1 | N12: 2 | O12: =SUM(C12:N12) -> 6 | P12: =SUM(I12:K12) -> 2
A13: 5 | B13: GROGOL | C13: 0 | D13: 0 | E13: 0 | F13: 0 | G13: 2 | H13: 0 | I13: 6 | J13: 2 | K13: 0 | L13: 0 | M13: 2 | N13: 25 | O13: =SUM(C13:N13) -> 37 | P13: =SUM(I13:K13) -> 8
A14: 6 | B14: CILEGON | C14: 0 | D14: 0 | E14: 0 | F14: 0 | G14: 0 | H14: 0 | I14: 0 | J14: 0 | K14: 0 | L14: 5 | M14: 2 | N14: 8 | O14: =SUM(C14:N14) -> 15 | P14: =SUM(I14:K14) -> 0
A15: 7 | B15: JOMBANG | C15: 0 | D15: 0 | E15: 0 | F15: 0 | G15: 0 | H15: 0 | I15: 0 | J15: 0 | K15: 0 | L15: 0 | M15: 3 | N15: 0 | O15: =SUM(C15:N15) -> 3 | P15: =SUM(I15:K15) -> 0
A16: 8 | B16: CIBEBER | C16: 1 | D16: 1 | E16: 0 | F16: 0 | G16: 1 | H16: 0 | I16: 0 | J16: 0 | K16: 0 | L16: 0 | M16: 5 | N16: 16 | O16: =SUM(C16:N16) -> 24 | P16: =SUM(I16:K16) -> 0
A17: JUMLAH | C17: =SUM(C9:C16) -> 1 | D17: =SUM(D9:D16) -> 1 | E17: =SUM(E9:E16) -> 0 | F17: =SUM(F9:F16) -> 0 | G17: =SUM(G9:G16) -> 3 | H17: =SUM(H9:H16) -> 0 | I17: =SUM(I9:I16) -> 6 | J17: =SUM(J9:J16) -> 3 | ... P17: =SUM(P9:P16) -> 11
N19: =SUM(L17:N17) -> 213
A35: DATA LUAS PANEN JAGUNG PER BULAN
A36: KOTA CILEGON TAHUN 2017
O38: (Ha)
A39: No | B39: Kecamatan | C39: Bulan | O39: Jumlah
C40: Jan | D40: Feb | E40: Maret | F40: Apr | G40: Mei | H40: Juni | I40: Juli | J40: Agst | K40: Sept | L40: Okt | M40: Nov | N40: Des
A41: 1 | B41: 2 | C41: 3 | D41: 4 | E41: 5 | F41: 6 | G41: 7 | H41: 8 | I41: 9 | J41: 10 | K41: 11 | L41: 12 | M41: 13 | N41: 14 | O41: 15
A42: 1 | B42: CIWANDAN | C42: 1* | D42: 0 | E42: 0 | F42: 0 | G42: 0 | H42: 0 | I42: 0 | J42: 0 | K42: 0 | L42: 0 | M42: 0 | N42: 0 | O42: 1 | P42: 1
A43: 2 | B43: CITANGKIL | C43: 1* | D43: 0 | E43: 0 | F43: 0 | G43: 0 | H43: 0 | I43: 0 | J43: 0 | K43: 0 | L43: 1* | M43: 0 | N43: 0 | O43: 2 | P43: 1
A44: 3 | B44: PULOMERAK | C44: 0 | D44: 45* | E44: 5 | F44: 0 | G44: 0 | H44: 0 | I44: 0 | J44: 0 | K44: 0 | L44: 0 | M44: 0 | N44: 0 | O44: 50 | P44: 50
A45: 4 | B45: PURWAKARTA | C45: 0 | D45: 1 | E45: 0 | F45: 0 | G45: 0 | H45: 0 | I45: 0 | J45: 0 | K45: 0 | L45: 0 | M45: 0 | N45: 1 | O45: =SUM(C45:N45) -> 2 | P45: 2
A46: 5 | B46: GROGOL | C46: 0 | D46: 0 | E46: 0 | F46: 0 | G46: 0 | H46: 0 | I46: 0 | J46: 2 | K46: 0 | L46: 8 | M46: 0 | N46: 0 | O46: =SUM(C46:N46) -> 10 | P46: 0
A47: 6 | B47: CILEGON | C47: 0 | D47: 0 | E47: 0 | F47: 0 | G47: 0 | H47: 0 | I47: 0 | J47: 0 | K47: 0 | L47: 0 | M47: 0 | N47: 0 | O47: =SUM(C47:N47) -> 0 | P47: 0
A48: 7 | B48: JOMBANG | C48: 0 | D48: 0 | E48: 0 | F48: 0 | G48: 0 | H48: 0 | I48: 0 | J48: 0 | K48: 0 | L48: 0 | M48: 0 | N48: 0 | O48: =SUM(C48:N48) -> 0 | P48: 0
A49: 8 | B49: CIBEBER | C49: 0 | D49: 1* | E49: 0 | F49: 1 | G49: 0 | H49: 1* | I49: 0 | J49: 0 | K49: 0 | L49: 0 | M49: 0 | N49: 0 | O49: 3 | P49: 2
A50: JUMLAH | C50: 2 | D50: 47 | E50: =SUM(E42:E49) -> 5 | F50: =SUM(F42:F49) -> 1 | G50: =SUM(G42:G49) -> 0 | H50: 1* | I50: =SUM(I42:I49) -> 0 | J50: =SUM(J42:J49) -> 2 | K50: =SUM(K42:K49) -> 0 | L50: 9 | M50: =SUM(M42:M49) -> 0 | N50: =SUM(N42:N49) -> 1 | O50: =SUM(O42:O49) -> 68 | P50: =SUM(P42:P49) -> 56
C51: =SUM(C42:C49) -> 0 | D51: =SUM(D42:D49) -> 1 | E51: =SUM(E42:E49) -> 5 | F51: =SUM(F42:F49) -> 1 | G51: =SUM(G42:G49) -> 0 | H51: =SUM(H42:H49) -> 0 | I51: =SUM(I42:I49) -> 0 | J51: =SUM(J42:J49) -> 2 | ... N51: =SUM(N42:N49) -> 1 | O51: =SUM(C51:N51) -> 18
A52: Ket : * : Panen Muda
A68: DATA PRODUKSI JAGUNG PER BULAN
A69: KOTA CILEGON TAHUN 2017
O71: (Ton)
A72: No | B72: Kecamatan | C72: Bulan | O72: Jumlah
C73: Jan | D73: Feb | E73: Maret | F73: Apr | G73: Mei | H73: Juni | I73: Juli | J73: Agst | K73: Sept | L73: Okt | M73: Nov | N73: Des
A74: 1 | B74: 2 | C74: 3 | D74: 4 | E74: 5 | F74: 6 | G74: 7 | H74: 8 | I74: 9 | J74: 10 | K74: 11 | L74: 12 | M74: 13 | N74: 14 | O74: 15
A75: 1 | B75: CIWANDAN | C75: 0 | D75: 0 | E75: 0 | F75: 0 | G75: 0 | H75: 0 | I75: 0 | J75: 0 | K75: 0 | L75: 0 | M75: 0 | N75: 0 | O75: =SUM(C75:N75) -> 0 | Q75: =O75*3000 -> 0
...

Sheet kedelai
A2: DATA LUAS TANAM KEDELAI PER BULAN
A3: KOTA CILEGON TAHUN 2017
O5: (Ha)
A6: No | B6: Kecamatan | C6: Bulan | O6: Jumlah
C7: Jan | D7: Feb | E7: Maret | F7: Apr | G7: Mei | H7: Juni | I7: Juli | J7: Agst | K7: Sept | L7: Okt | M7: Nov | N7: Des
A8: 1 | B8: 2 | C8: 3 | D8: 4 | E8: 5 | F8: 6 | G8: 7 | H8: 8 | I8: 9 | J8: 10 | K8: 11 | L8: 12 | M8: 13 | N8: 14 | O8: 15 | Q8: ok-nop
A9: 1 | B9: CIWANDAN | C9: 0 | D9: 0 | E9: 0 | F9: 0 | G9: 0 | H9: 0 | I9: 0 | J9: 0 | K9: 0 | L9: 0 | M9: 0 | N9: 0 | O9: =SUM(C9:N9) -> 0 | Q9: =SUM(L9:M9) -> 0
A10: 2 | B10: CITANGKIL | C10: 0 | D10: 0 | E10: 0 | F10: 0 | G10: 0 | H10: 0 | I10: 0 | J10: 0 | K10: 0 | L10: 0 | M10: 0 | N10: 0 | O10: =SUM(C10:N10) -> 0 | Q10: =SUM(L10:M10) -> 0
A11: 3 | B11: PULOMERAK | C11: 0 | D11: 0 | E11: 0 | F11: 0 | G11: 0 | H11: 0 | I11: 0 | J11: 0 | K11: 0 | L11: 0 | M11: 0 | N11: 0 | O11: =SUM(C11:N11) -> 0 | Q11: =SUM(L11:M11) -> 0
A12: 4 | B12: PURWAKARTA | C12: 0 | D12: 0 | E12: 0 | F12: 0 | G12: 0 | H12: 0 | I12: 0 | J12: 0 | K12: 0 | L12: 0 | M12: 0 | N12: 0 | O12: =SUM(C12:N12) -> 0 | Q12: =SUM(L12:M12) -> 0
A13: 5 | B13: GROGOL | C13: 0 | D13: 0 | E13: 0 | F13: 0 | G13: 0 | H13: 0 | I13: 0 | J13: 0 | K13: 0 | L13: 0 | M13: 0 | N13: 0 | O13: =SUM(C13:N13) -> 0 | Q13: =SUM(L13:M13) -> 0
A14: 6 | B14: CILEGON | C14: 0 | D14: 0 | E14: 0 | F14: 0 | G14: 0 | H14: 0 | I14: 0 | J14: 0 | K14: 0 | L14: 0 | M14: 0 | N14: 0 | O14: =SUM(C14:N14) -> 0 | Q14: =SUM(L14:M14) -> 0
A15: 7 | B15: JOMBANG | C15: 0 | D15: 0 | E15: 0 | F15: 0 | G15: 0 | H15: 0 | I15: 0 | J15: 0 | K15: 0 | L15: 0 | M15: 0 | N15: 0 | O15: =SUM(C15:N15) -> 0 | Q15: =SUM(L15:M15) -> 0
A16: 8 | B16: CIBEBER | C16: 0 | D16: 0 | E16: 0 | F16: 0 | G16: 0 | H16: 0 | I16: 0 | J16: 0 | K16: 0 | L16: 0 | M16: 0 | N16: 0 | O16: =SUM(C16:N16) -> 0 | Q16: =SUM(L16:M16) -> 0
A17: JUMLAH | C17: =SUM(C9:C16) -> 0 | D17: =SUM(D9:D16) -> 0 | E17: =SUM(E9:E16) -> 0 | F17: =SUM(F9:F16) -> 0 | G17: =SUM(G9:G16) -> 0 | H17: =SUM(H9:H16) -> 0 | I17: =SUM(I9:I16) -> 0 | J17: =SUM(J9:J16) -> 0 | ... O17: =SUM(O9:O16) -> 0
A35: DATA LUAS PANEN KEDELAI PER BULAN
A36: KOTA CILEGON TAHUN 2017
O38: (Ha)
A39: No | B39: Kecamatan | C39: Bulan | O39: Jumlah
C40: Jan | D40: Feb | E40: Maret | F40: Apr | G40: Mei | H40: Juni | I40: Juli | J40: Agst | K40: Sept | L40: Okt | M40: Nov | N40: Des
A41: 1 | B41: 2 | C41: 3 | D41: 4 | E41: 5 | F41: 6 | G41: 7 | H41: 8 | I41: 9 | J41: 10 | K41: 11 | L41: 12 | M41: 13 | N41: 14 | O41: 15
A42: 1 | B42: CIWANDAN | C42: 0 | D42: 0 | E42: 0 | F42: 0 | G42: 0 | H42: 0 | I42: 0 | J42: 0 | K42: 0 | L42: 0 | M42: 0 | N42: 0 | O42: =SUM(C42:N42) -> 0 | Q42: =SUM(C42:E42) -> 0
A43: 2 | B43: CITANGKIL | C43: 0 | D43: 0 | E43: 0 | F43: 0 | G43: 0 | H43: 0 | I43: 0 | J43: 0 | K43: 0 | L43: 0 | M43: 0 | N43: 0 | O43: =SUM(C43:N43) -> 0 | Q43: =SUM(C43:E43) -> 0
A44: 3 | B44: PULOMERAK | C44: 0 | D44: 0 | E44: 0 | F44: 0 | G44: 0 | H44: 0 | I44: 0 | J44: 0 | K44: 0 | L44: 0 | M44: 0 | N44: 0 | O44: =SUM(C44:N44) -> 0 | Q44: =SUM(C44:E44) -> 0
A45: 4 | B45: PURWAKARTA | C45: 0 | D45: 0 | E45: 0 | F45: 0 | G45: 0 | H45: 0 | I45: 0 | J45: 0 | K45: 0 | L45: 0 | M45: 0 | N45: 0 | O45: =SUM(C45:N45) -> 0 | Q45: =SUM(C45:E45) -> 0
A46: 5 | B46: GROGOL | C46: 0 | D46: 0 | E46: 0 | F46: 0 | G46: 0 | H46: 0 | I46: 0 | J46: 0 | K46: 0 | L46: 0 | M46: 0 | N46: 0 | O46: =SUM(C46:N46) -> 0 | Q46: =SUM(C46:E46) -> 0
A47: 6 | B47: CILEGON | C47: 0 | D47: 0 | E47: 0 | F47: 0 | G47: 0 | H47: 0 | I47: 0 | J47: 0 | K47: 0 | L47: 0 | M47: 0 | N47: 0 | O47: =SUM(C47:N47) -> 0 | Q47: =SUM(C47:E47) -> 0
A48: 7 | B48: JOMBANG | C48: 0 | D48: 0 | E48: 0 | F48: 0 | G48: 0 | H48: 0 | I48: 0 | J48: 0 | K48: 0 | L48: 0 | M48: 0 | N48: 0 | O48: =SUM(C48:N48) -> 0 | Q48: =SUM(C48:E48) -> 0
A49: 8 | B49: CIBEBER | C49: 0 | D49: 0 | E49: 0 | F49: 0 | G49: 0 | H49: 0 | I49: 0 | J49: 0 | K49: 0 | L49: 0 | M49: 0 | N49: 0 | O49: =SUM(C49:N49) -> 0 | P49: 15 | Q49: =SUM(C49:E49) -> 0
A50: JUMLAH | C50: =SUM(C42:C49) -> 0 | D50: =SUM(D42:D49) -> 0 | E50: =SUM(E42:E49) -> 0 | F50: =SUM(F42:F49) -> 0 | G50: =SUM(G42:G49) -> 0 | H50: =SUM(H42:H49) -> 0 | I50: =SUM(I42:I49) -> 0 | J50: =SUM(J42:J49) -> 0 | ... P50: =SUM(P42:P49) -> 15
A68: DATA PRODUKSI KEDELAI PER BULAN
A69: KOTA CILEGON TAHUN 2017
O71: (Ton)
A72: No | B72: Kecamatan | C72: Bulan | O72: Jumlah
C73: Jan | D73: Feb | E73: Maret | F73: Apr | G73: Mei | H73: Juni | I73: Juli | J73: Agst | K73: Sept | L73: Okt | M73: Nov | N73: Des
A74: 1 | B74: 2 | C74: 3 | D74: 4 | E74: 5 | F74: 6 | G74: 7 | H74: 8 | I74: 9 | J74: 10 | K74: 11 | L74: 12 | M74: 13 | N74: 14 | O74: 15
A75: 1 | B75: CIWANDAN | C75: 0 | D75: 0 | E75: 0 | F75: 0 | G75: 0 | H75: 0 | I75: 0 | J75: 0 | K75: 0 | L75: 0 | M75: 0 | N75: 0 | O75: =SUM(C75:N75) -> 0 | Q75: =SUM(C75:E75) -> 0
A76: 2 | B76: CITANGKIL | C76: 0 | D76: 0 | E76: 0 | F76: 0 | G76: 0 | H76: 0 | I76: 0 | J76: 0 | K76: 0 | L76: 0 | M76: 0 | N76: 0 | O76: =SUM(C76:N76) -> 0 | Q76: =SUM(C76:E76) -> 0
A77: 3 | B77: PULOMERAK | C77: 0 | D77: 0 | E77: 0 | F77: 0 | G77: 0 | H77: 0 | I77: 0 | J77: 0 | K77: 0 | L77: 0 | M77: 0 | N77: 0 | O77: =SUM(C77:N77) -> 0 | Q77: =SUM(C77:E77) -> 0
A78: 4 | B78: PURWAKARTA | C78: 0 | D78: 0 | E78: 0 | F78: 0 | G78: 0 | H78: 0 | I78: 0 | J78: 0 | K78: 0 | L78: 0 | M78: 0 | N78: 0 | O78: =SUM(C78:N78) -> 0 | Q78: =SUM(C78:E78) -> 0
...

Sheet kc tanah
A2: DATA LUAS TANAM KACANG TANAH PER BULAN
A3: KOTA CILEGON TAHUN 2017
O5: (Ha)
A6: No | B6: Kecamatan | C6: Bulan | O6: Jumlah
C7: Jan | D7: Feb | E7: Maret | F7: Apr | G7: Mei | H7: Juni | I7: Juli | J7: Agst | K7: Sept | L7: Okt | M7: Nov | N7: Des
A8: 1 | B8: 2 | C8: 3 | D8: 4 | E8: 5 | F8: 6 | G8: 7 | H8: 8 | I8: 9 | J8: 10 | K8: 11 | L8: 12 | M8: 13 | N8: 14 | O8: 15
A9: 1 | B9: CIWANDAN | C9: 0 | D9: 185 | E9: 0 | F9: 0 | H9: 0 | I9: 0 | J9: 0 | K9: 0 | L9: 0 | M9: 50 | N9: 0 | O9: =SUM(C9:N9) -> 235 | P9: =SUM(I9:K9) -> 0 | Q9: =SUM(F9:K9) -> 0
A10: 2 | B10: CITANGKIL | C10: 25 | D10: 85 | E10: 0 | F10: 0 | G10: 0 | H10: 0 | I10: 0 | J10: 0 | K10: 0 | L10: 2 | M10: 3 | N10: 181 | O10: =SUM(C10:N10) -> 296 | P10: =SUM(I10:K10) -> 0 | Q10: =SUM(F10:K10) -> 0
A11: 3 | B11: PULOMERAK | C11: 0 | D11: 257 | E11: 0.5 | F11: 6 | G11: 3 | H11: 6 | I11: 0 | J11: 0 | K11: 5 | L11: 0 | M11: 0 | N11: 250 | O11: =SUM(C11:N11) -> 527.5 | P11: =SUM(I11:K11) -> 5 | Q11: =SUM(F11:K11) -> 20
A12: 4 | B12: PURWAKARTA | C12: 167 | D12: 0 | E12: 5 | F12: 0 | G12: 10 | H12: 5 | I12: 10 | J12: 0 | K12: 5 | L12: 0 | M12: 25 | N12: 18 | O12: =SUM(C12:N12) -> 245 | P12: =SUM(I12:K12) -> 15 | Q12: =SUM(F12:K12) -> 30
A13: 5 | B13: GROGOL | C13: 0 | D13: 83 | E13: 25 | F13: 0 | G13: 0 | H13: 0 | I13: 0 | J13: 0 | K13: 2 | L13: 0 | M13: 2 | N13: 278 | O13: =SUM(C13:N13) -> 390 | P13: =SUM(I13:K13) -> 2 | Q13: =SUM(F13:K13) -> 2
A14: 6 | B14: CILEGON | C14: 0 | D14: 0 | E14: 50 | F14: 0 | G14: 0 | H14: 40 | I14: 0 | J14: 0 | K14: 0 | L14: 5 | M14: 30 | N14: 45 | O14: =SUM(C14:N14) -> 170 | P14: =SUM(I14:K14) -> 0 | Q14: =SUM(F14:K14) -> 40
A15: 7 | B15: JOMBANG | C15: 1 | D15: 1 | E15: 0 | F15: 0 | G15: 0 | H15: 0 | I15: 0 | J15: 0 | K15: 0 | L15: 0 | M15: 0 | N15: 0 | O15: =SUM(C15:N15) -> 2 | P15: =SUM(I15:K15) -> 0 | Q15: =SUM(F15:K15) -> 0
A16: 8 | B16: CIBEBER | C16: 235 | D16: 45 | E16: 0 | F16: 25 | G16: 114 | H16: 0 | I16: 42 | J16: 0 | K16: 4 | L16: 5 | M16: 16 | N16: 10 | O16: =SUM(C16:N16) -> 496 | P16: =SUM(I16:K16) -> 46 | Q16: =SUM(F16:K16) -> 185
A17: JUMLAH | C17: =SUM(C9:C16) -> 428 | D17: =SUM(D9:D16) -> 656 | E17: =SUM(E9:E16) -> 80.5 | F17: =SUM(F9:F16) -> 31 | G17: =SUM(G9:G16) -> 127 | H17: =SUM(H9:H16) -> 51 | I17: =SUM(I9:I16) -> 52 | J17: =SUM(J9:J16) -> 0 | ... P17: =SUM(P9:P16) -> 68 | Q17: =SUM(I9:K9) -> 0
J19: =SUM(C17:J17) -> 1425.5 | K19: =SUM(C17:K17) -> 1441.5
A35: DATA LUAS PANEN KACANG TANAH PER BULAN
A36: KOTA CILEGON TAHUN 2017
O38: (Ha)
A39: No | B39: Kecamatan | C39: Bulan | O39: Jumlah
C40: Jan | D40: Feb | E40: Maret | F40: Apr | G40: Mei | H40: Juni | I40: Juli | J40: Agst | K40: Sept | L40: Okt | M40: Nov | N40: Des
A41: 1 | B41: 2 | C41: 3 | D41: 4 | E41: 5 | F41: 6 | G41: 7 | H41: 8 | I41: 9 | J41: 10 | K41: 11 | L41: 12 | M41: 13 | N41: 14 | O41: 15
A42: 1 | B42: CIWANDAN | C42: 126 | D42: 35 | F42: 185 | G42: 0 | H42: 0 | I42: 0 | J42: 0 | K42: 0 | L42: 0 | M42: 0 | N42: 0 | O42: =SUM(C42:N42) -> 346 | Q42: =SUM(F42:K42) -> 185
A43: 2 | B43: CITANGKIL | C43: 122 | D43: 64 | E43: 0 | F43: 25 | G43: 85 | H43: 0 | I43: 0 | J43: 0 | K43: 0 | L43: 0 | M43: 0 | N43: 0 | O43: =SUM(C43:N43) -> 296 | Q43: =SUM(F43:K43) -> 110
A44: 3 | B44: PULOMERAK | C44: 0 | D44: 305 | E44: 200 | F44: 57 | G44: 0.5 | H44: 0 | I44: 0 | J44: 15 | K44: 0 | L44: 0 | M44: 0 | N44: 0 | O44: =SUM(C44:N44) -> 577.5 | Q44: =SUM(F44:K44) -> 72.5
A45: 4 | B45: PURWAKARTA | C45: 0 | D45: 21 | E45: 0 | F45: 167 | G45: 5 | H45: 0 | I45: 5 | J45: 10 | K45: 0 | L45: 0 | M45: 10 | N45: 10 | O45: =SUM(C45:N45) -> 228 | Q45: =SUM(F45:K45) -> 187
A46: 5 | B46: GROGOL | C46: 178 | D46: 52 | E46: 48 | F46: 70 | G46: 38 | H46: 0 | I46: 0 | J46: 0 | K46: 0 | L46: 0 | M46: 0 | N46: 0 | O46: =SUM(C46:N46) -> 386 | Q46: =SUM(F46:K46) -> 108
A47: 6 | B47: CILEGON | C47: 0 | D47: 15 | E47: 0 | F47: 0 | G47: 5 | H47: 45 | I47: 0 | J47: 40 | K47: 0 | L47: 0 | M47: 0 | N47: 0 | O47: =SUM(C47:N47) -> 105 | Q47: =SUM(F47:K47) -> 90
A48: 7 | B48: JOMBANG | C48: 0 | D48: 0 | E48: 1 | F48: 1 | G48: 0 | H48: 0 | I48: 0 | J48: 0 | K48: 0 | L48: 0 | M48: 0 | N48: 0 | O48: =SUM(C48:N48) -> 2 | Q48: =SUM(F48:K48) -> 1
A49: 8 | B49: CIBEBER | C49: 35 | D49: 85 | E49: 0 | F49: 200 | G49: 45 | H49: 0 | I49: 139 | J49: 0 | K49: 0 | L49: 0 | M49: 42 | N49: 42 | O49: =SUM(C49:N49) -> 588 | Q49: =SUM(F49:K49) -> 384
A50: JUMLAH | C50: =SUM(C42:C49) -> 461 | D50: =SUM(D42:D49) -> 577 | E50: =SUM(E42:E49) -> 249 | F50: =SUM(F42:F49) -> 705 | G50: =SUM(G42:G49) -> 178.5 | H50: =SUM(H42:H49) -> 45 | I50: =SUM(I42:I49) -> 144 | J50: =SUM(J42:J49) -> 65 | ... O50: =SUM(O42:O49) -> 2528.5 | Q50: =SUM(F50:K50) -> 1137.5
A68: DATA PRODUKSI KACANG TANAH PER BULAN
A69: KOTA CILEGON TAHUN 2017
O71: (Ton)
A72: No | B72: Kecamatan | C72: Bulan | O72: Jumlah
C73: Jan | D73: Feb | E73: Maret | F73: Apr | G73: Mei | H73: Juni | I73: Juli | J73: Agst | K73: Sept | L73: Okt | M73: Nov | N73: Des
A74: 1 | B74: 2 | C74: 3 | D74: 4 | E74: 5 | F74: 6 | G74: 7 | H74: 8 | I74: 9 | J74: 10 | K74: 11 | L74: 12 | M74: 13 | N74: 14 | O74: 15
A75: 1 | B75: CIWANDAN | C75: 83 | D75: 28 | F75: 160 | G75: 0 | H75: 0 | I75: 0 | J75: 0 | K75: 0 | L75: 0 | M75: 0 | N75: 0 | O75: =SUM(C75:N75) -> 271 | Q75: =SUM(F75:K75) -> 160 | R75: =O75*20000 -> 5420000 | S75: 20000 | T75: =SUM(R75:S75) -> 5440000
A76: 2 | B76: CITANGKIL | C76: 86 | D76: 43 | E76: 0 | F76: 17 | G76: 49 | H76: 0 | I76: 0 | J76: 0 | K76: 0 | L76: 0 | M76: 0 | N76: 0 | O76: =SUM(C76:N76) -> 195 | Q76: =SUM(F76:K76) -> 66 | R76: =O76*20000 -> 3900000 | S76: 0 | T76: =SUM(R76:S76) -> 3900000
A77: 3 | B77: PULOMERAK | C77: 0 | D77: 312 | E77: 305 | F77: 56 | G77: 0.4 | H77: 0 | I77: 0 | J77: 11 | K77: 0 | L77: 0 | M77: 0 | N77: 0 | O77: =SUM(C77:N77) -> 684.4 | Q77: =SUM(F77:K77) -> 67.4 | R77: =O77*20000 -> 13688000 | S77: 0 | T77: =SUM(R77:S77) -> 13688000
...

Sheet ubi kayu
A2: DATA LUAS TANAM UBI KAYU PER BULAN
A3: KOTA CILEGON TAHUN 2017
O5: (Ha)
A6: No | B6: Kecamatan | C6: Bulan | O6: Jumlah
C7: Jan | D7: Feb | E7: Maret | F7: Apr | G7: Mei | H7: Juni | I7: Juli | J7: Agst | K7: Sept | L7: Okt | M7: Nov | N7: Des
A8: 1 | B8: 2 | C8: 3 | D8: 4 | E8: 5 | F8: 6 | G8: 7 | H8: 8 | I8: 9 | J8: 10 | K8: 11 | L8: 12 | M8: 13 | N8: 14 | O8: 15 | Q8: APR-SEP
A9: 1 | B9: CIWANDAN | C9: 0 | D9: 0 | E9: 0 | F9: 0 | H9: 0 | I9: 1 | J9: 0 | K9: 0 | L9: 0 | M9: 0 | N9: 2 | O9: =SUM(C9:N9) -> 3 | P9: =SUM(E9:K9) -> 1 | Q9: =SUM(F9:K9) -> 1
A10: 2 | B10: CITANGKIL | C10: 0 | D10: 1 | E10: 0 | F10: 0 | G10: 1 | H10: 0 | I10: 0 | J10: 0 | K10: 0 | L10: 0 | M10: 1 | N10: 1 | O10: =SUM(C10:N10) -> 4 | P10: =SUM(E10:K10) -> 1 | Q10: =SUM(F10:K10) -> 1
A11: 3 | B11: PULOMERAK | C11: 0 | D11: 0 | E11: 0 | F11: 0 | G11: 0 | H11: 0 | I11: 0 | J11: 0 | K11: 3 | L11: 3 | M11: 0 | N11: 0 | O11: =SUM(C11:N11) -> 6 | P11: =SUM(E11:K11) -> 3 | Q11: =SUM(F11:K11) -> 3
A12: 4 | B12: PURWAKARTA | C12: 0 | D12: 0 | E12: 0 | F12: 1 | G12: 1 | H12: 0 | I12: 0 | J12: 0 | K12: 0 | L12: 0 | M12: 0 | N12: 0 | O12: =SUM(C12:N12) -> 2 | P12: =SUM(E12:K12) -> 2 | Q12: =SUM(F12:K12) -> 2
A13: 5 | B13: GROGOL | C13: 0 | D13: 1 | E13: 0 | F13: 1 | G13: 0 | H13: 1 | I13: 0 | J13: 0 | K13: 0 | L13: 0 | M13: 0 | N13: 12 | O13: =SUM(C13:N13) -> 15 | P13: =SUM(E13:K13) -> 2 | Q13: =SUM(F13:K13) -> 2
A14: 6 | B14: CILEGON | C14: 0 | D14: 0 | E14: 0 | F14: 1 | G14: 0 | H14: 0 | I14: 0 | J14: 1 | K14: 0 | L14: 1 | M14: 1 | N14: 1 | O14: =SUM(C14:N14) -> 5 | P14: =SUM(E14:K14) -> 2 | Q14: =SUM(F14:K14) -> 2
A15: 7 | B15: JOMBANG | C15: 1 | D15: 0 | E15: 0 | F15: 0 | G15: 0 | H15: 0 | I15: 0 | J15: 0 | K15: 1 | L15: 0 | M15: 0 | N15: 0 | O15: =SUM(C15:N15) -> 2 | P15: =SUM(E15:K15) -> 1 | Q15: =SUM(F15:K15) -> 1
A16: 8 | B16: CIBEBER | C16: 0 | D16: 0 | E16: 0 | F16: 0 | G16: 0 | H16: 0 | I16: 1 | J16: 0 | K16: 1 | L16: 0 | M16: 1 | N16: 1 | O16: =SUM(C16:N16) -> 4 | P16: =SUM(E16:K16) -> 2 | Q16: =SUM(F16:K16) -> 2
A17: JUMLAH | C17: =SUM(C9:C16) -> 1 | D17: =SUM(D9:D16) -> 2 | E17: =SUM(E9:E16) -> 0 | F17: =SUM(F9:F16) -> 3 | G17: =SUM(G9:G16) -> 2 | H17: =SUM(H9:H16) -> 1 | I17: =SUM(I9:I16) -> 2 | J17: =SUM(J9:J16) -> 1 | ... P17: =SUM(P9:P16) -> 14 | Q17: =SUM(F17:K17) -> 14
A34: DATA LUAS PANEN UBI KAYU PER BULAN
A35: KOTA CILEGON TAHUN 2017
O37: (Ha)
A38: No | B38: Kecamatan | C38: Bulan | O38: Jumlah
C39: Jan | D39: Feb | E39: Maret | F39: Apr | G39: Mei | H39: Juni | I39: Juli | J39: Agst | K39: Sept | L39: Okt | M39: Nov | N39: Des
A40: 1 | B40: 2 | C40: 3 | D40: 4 | E40: 5 | F40: 6 | G40: 7 | H40: 8 | I40: 9 | J40: 10 | K40: 11 | L40: 12 | M40: 13 | N40: 14 | O40: 15
A41: 1 | B41: CIWANDAN | C41: 0 | D41: 0 | E41: 0 | F41: 0 | G41: 0 | H41: 6 | I41: 0 | J41: 0 | K41: 0 | L41: 0 | M41: 0 | N41: 1 | O41: =SUM(C41:N41) -> 7 | Q41: =SUM(F41:K41) -> 6
A42: 2 | B42: CITANGKIL | C42: 1 | D42: 0 | E42: 0 | F42: 1 | G42: 0 | H42: 0 | I42: 0 | J42: 1 | K42: 0 | L42: 1 | M42: 0 | N42: 0 | O42: =SUM(C42:N42) -> 4 | Q42: =SUM(F42:K42) -> 2
A43: 3 | B43: PULOMERAK | C43: 0 | D43: 0 | E43: 0 | F43: 0 | G43: 0 | H43: 0 | I43: 0 | J43: 0 | K43: 8 | L43: 1 | M43: 0 | N43: 0 | O43: =SUM(C43:N43) -> 9 | Q43: =SUM(F43:K43) -> 8
A44: 4 | B44: PURWAKARTA | C44: 0 | D44: 0 | E44: 4 | F44: 0 | G44: 0 | H44: 0 | I44: 0 | J44: 0 | K44: 0 | L44: 0 | M44: 0 | N44: 0 | O44: =SUM(C44:N44) -> 4 | Q44: =SUM(F44:K44) -> 0
A45: 5 | B45: GROGOL | C45: 0 | D45: 3 | E45: 1 | F45: 1 | G45: 0 | H45: 0 | I45: 0 | J45: 1 | K45: 0 | L45: 0 | M45: 0 | N45: 2 | O45: =SUM(C45:N45) -> 8 | Q45: =SUM(F45:K45) -> 2
A46: 6 | B46: CILEGON | C46: 0 | D46: 0 | E46: 0 | F46: 0 | G46: 0 | H46: 2 | I46: 1 | J46: 1 | K46: 0 | L46: 1 | M46: 0 | N46: 0 | O46: =SUM(C46:N46) -> 5 | Q46: =SUM(F46:K46) -> 4
A47: 7 | B47: JOMBANG | C47: 0 | D47: 0 | E47: 0 | F47: 0 | G47: 0 | H47: 0 | I47: 0 | J47: 0 | K47: 1 | L47: 0 | M47: 0 | N47: 0 | O47: =SUM(C47:N47) -> 1 | Q47: =SUM(F47:K47) -> 1
A48: 8 | B48: CIBEBER | C48: 1 | D48: 0 | E48: 0 | F48: 1 | G48: 0 | H48: 0 | I48: 4 | J48: 0 | K48: 0 | L48: 0 | M48: 1 | N48: 0 | O48: =SUM(C48:N48) -> 7 | Q48: =SUM(F48:K48) -> 5
A49: JUMLAH | C49: =SUM(C41:C48) -> 2 | D49: =SUM(D41:D48) -> 3 | E49: =SUM(E41:E48) -> 5 | F49: =SUM(F41:F48) -> 3 | G49: =SUM(G41:G48) -> 0 | H49: =SUM(H41:H48) -> 8 | I49: =SUM(I41:I48) -> 5 | J49: =SUM(J41:J48) -> 3 | ... O49: =SUM(O41:O48) -> 45 | Q49: =SUM(F49:K49) -> 28
A68: DATA PRODUKSI UBI KAYU PER BULAN
A69: KOTA CILEGON TAHUN 2017
O71: (Ton)
A72: No | B72: Kecamatan | C72: Bulan | O72: Jumlah
C73: Jan | D73: Feb | E73: Maret | F73: Apr | G73: Mei | H73: Juni | I73: Juli | J73: Agst | K73: Sept | L73: Okt | M73: Nov | N73: Des
A74: 1 | B74: 2 | C74: 3 | D74: 4 | E74: 5 | F74: 6 | G74: 7 | H74: 8 | I74: 9 | J74: 10 | K74: 11 | L74: 12 | M74: 13 | N74: 14 | O74: 15
A75: 1 | B75: CIWANDAN | C75: 0 | D75: 0 | E75: 0 | F75: 0 | G75: 0 | H75: 54 | I75: 0 | J75: 0 | K75: 0 | L75: 0 | M75: 0 | N75: 9 | O75: =SUM(C75:N75) -> 63 | Q75: =SUM(F75:K75) -> 54 | R75: =O75*2000 -> 126000
A76: 2 | B76: CITANGKIL | C76: 25 | D76: 0 | E76: 0 | F76: 9 | G76: 0 | H76: 0 | I76: 0 | J76: 11 | K76: 0 | L76: 12 | M76: 0 | N76: 0 | O76: =SUM(C76:N76) -> 57 | Q76: =SUM(F76:K76) -> 20 | R76: =O76*2000 -> 114000
A77: 3 | B77: PULOMERAK | C77: 0 | D77: 0 | E77: 0 | F77: 0 | G77: 0 | H77: 0 | I77: 0 | J77: 0 | K77: 94 | L77: 12 | M77: 0 | N77: 0 | O77: =SUM(C77:N77) -> 106 | Q77: =SUM(F77:K77) -> 94 | R77: =O77*2000 -> 212000
A78: 4 | B78: PURWAKARTA | C78: 0 | D78: 0 | E78: 30 | F78: 0 | G78: 0 | H78: 0 | I78: 0 | J78: 0 | K78: 0 | L78: 0 | M78: 0 | N78: 0 | O78: =SUM(C78:N78) -> 30 | Q78: =SUM(F78:K78) -> 0 | R78: =O78*2000 -> 60000
...

Sheet ubi jalar
A2: DATA LUAS TANAM UBI JALAR PER BULAN
A3: KOTA CILEGON TAHUN 2017
O5: (Ha)
A6: No | B6: Kecamatan | C6: Bulan | O6: Jumlah
C7: Jan | D7: Feb | E7: Maret | F7: Apr | G7: Mei | H7: Juni | I7: Juli | J7: Agst | K7: Sept | L7: Okt | M7: Nov | N7: Des
A8: 1 | B8: 2 | C8: 3 | D8: 4 | E8: 5 | F8: 6 | G8: 7 | H8: 8 | I8: 9 | J8: 10 | K8: 11 | L8: 12 | M8: 13 | N8: 14 | O8: 15 | Q8: APR-SEP
A9: 1 | B9: CIWANDAN | C9: 0 | D9: 0 | E9: 0 | F9: 0 | H9: 0 | I9: 2 | J9: 0 | K9: 0 | L9: 0 | M9: 0 | N9: 1 | O9: =SUM(C9:N9) -> 3 | P9: =SUM(H9:K9) -> 2 | Q9: =SUM(F9:K9) -> 2
A10: 2 | B10: CITANGKIL | C10: 0 | D10: 1 | E10: 0 | F10: 0 | G10: 1 | H10: 0 | I10: 1 | J10: 0 | K10: 0 | L10: 0 | M10: 1 | N10: 0 | O10: =SUM(C10:N10) -> 4 | P10: =SUM(H10:K10) -> 1 | Q10: =SUM(F10:K10) -> 2
A11: 3 | B11: PULOMERAK | C11: 0 | D11: 0 | E11: 0 | F11: 0 | G11: 0 | H11: 0 | I11: 0 | J11: 0 | K11: 0 | L11: 0 | M11: 0 | N11: 0 | O11: =SUM(C11:N11) -> 0 | P11: =SUM(H11:K11) -> 0 | Q11: =SUM(F11:K11) -> 0
A12: 4 | B12: PURWAKARTA | C12: 0 | D12: 0 | E12: 0 | F12: 0 | G12: 0 | H12: 0 | I12: 0 | J12: 0 | K12: 0 | L12: 3 | M12: 0 | N12: 0 | O12: =SUM(C12:N12) -> 3 | P12: =SUM(H12:K12) -> 0 | Q12: =SUM(F12:K12) -> 0
A13: 5 | B13: GROGOL | C13: 0 | D13: 1 | E13: 0 | F13: 1 | G13: 0 | H13: 1 | I13: 0 | J13: 0 | K13: 0 | L13: 0 | M13: 0 | N13: 0 | O13: =SUM(C13:N13) -> 3 | P13: =SUM(H13:K13) -> 1 | Q13: =SUM(F13:K13) -> 2
A14: 6 | B14: CILEGON | C14: 0 | D14: 1 | E14: 0 | F14: 0 | G14: 0 | H14: 1 | I14: 0 | J14: 0 | K14: 1 | L14: 0 | M14: 0 | N14: 1 | O14: =SUM(C14:N14) -> 4 | P14: =SUM(H14:K14) -> 2 | Q14: =SUM(F14:K14) -> 2
A15: 7 | B15: JOMBANG | C15: 0 | D15: 1 | E15: 1 | F15: 0 | G15: 0 | H15: 0 | I15: 0 | J15: 0 | K15: 0 | L15: 0 | M15: 0 | N15: 0 | O15: =SUM(C15:N15) -> 2 | P15: =SUM(H15:K15) -> 0 | Q15: =SUM(F15:K15) -> 0
A16: 8 | B16: CIBEBER | C16: 0 | D16: 0 | E16: 0 | F16: 0 | G16: 1 | H16: 0 | I16: 0 | J16: 0 | K16: 0 | L16: 0 | M16: 0 | N16: 0 | O16: =SUM(C16:N16) -> 1 | P16: =SUM(H16:K16) -> 0 | Q16: =SUM(F16:K16) -> 1
A17: JUMLAH | C17: =SUM(C9:C16) -> 0 | D17: =SUM(D9:D16) -> 4 | E17: =SUM(E9:E16) -> 1 | F17: =SUM(F9:F16) -> 1 | G17: =SUM(G9:G16) -> 2 | H17: =SUM(H9:H16) -> 2 | I17: =SUM(I9:I16) -> 3 | J17: =SUM(J9:J16) -> 0 | ... P17: =SUM(P9:P16) -> 6 | Q17: =SUM(F17:K17) -> 9
A35: DATA LUAS PANEN UBI JALAR PER BULAN
A36: KOTA CILEGON TAHUN 2017
O38: (Ha)
A39: No | B39: Kecamatan | C39: Bulan | O39: Jumlah
C40: Jan | D40: Feb | E40: Maret | F40: Apr | G40: Mei | H40: Juni | I40: Juli | J40: Agst | K40: Sept | L40: Okt | M40: Nov | N40: Des
A41: 1 | B41: 2 | C41: 3 | D41: 4 | E41: 5 | F41: 6 | G41: 7 | H41: 8 | I41: 9 | J41: 10 | K41: 11 | L41: 12 | M41: 13 | N41: 14 | O41: 15
A42: 1 | B42: CIWANDAN | C42: 1 | D42: 0 | E42: 2 | F42: 0 | G42: 0 | H42: 0 | I42: 0 | J42: 0 | K42: 0 | L42: 0 | M42: 0 | N42: 2 | O42: =SUM(C42:N42) -> 5 | Q42: =SUM(F42:K42) -> 0
A43: 2 | B43: CITANGKIL | C43: 1 | D43: 0 | E43: 0 | F43: 0 | G43: 0 | H43: 0 | I43: 0 | J43: 1 | K43: 0 | L43: 0 | M43: 1 | N43: 0 | O43: =SUM(C43:N43) -> 3 | Q43: =SUM(F43:K43) -> 1
A44: 3 | B44: PULOMERAK | C44: 0 | D44: 0 | E44: 0 | F44: 0 | G44: 0 | H44: 0 | I44: 0 | J44: 0 | K44: 0 | L44: 0 | M44: 0 | N44: 0 | O44: =SUM(C44:N44) -> 0 | Q44: =SUM(F44:K44) -> 0
A45: 4 | B45: PURWAKARTA | C45: 0 | D45: 0 | E45: 3 | F45: 0 | G45: 0 | H45: 0 | I45: 0 | J45: 0 | K45: 0 | L45: 0 | M45: 0 | N45: 0 | O45: =SUM(C45:N45) -> 3 | Q45: =SUM(F45:K45) -> 0
A46: 5 | B46: GROGOL | C46: 2 | D46: 0 | E46: 0 | F46: 0 | G46: 0 | H46: 0 | I46: 0 | J46: 0 | K46: 0 | L46: 0 | M46: 0 | N46: 1 | O46: =SUM(C46:N46) -> 3 | Q46: =SUM(F46:K46) -> 0
A47: 6 | B47: CILEGON | C47: 0 | D47: 0 | E47: 0 | F47: 0 | G47: 0 | H47: 1 | I47: 0 | J47: 0 | K47: 0 | L47: 1 | M47: 0 | N47: 0 | O47: =SUM(C47:N47) -> 2 | Q47: =SUM(F47:K47) -> 1
A48: 7 | B48: JOMBANG | C48: 0 | D48: 0 | E48: 0 | F48: 0 | G48: 0 | H48: 1 | I48: 0 | J48: 0 | K48: 0 | L48: 0 | M48: 0 | N48: 0 | O48: =SUM(C48:N48) -> 1 | Q48: =SUM(F48:K48) -> 1
A49: 8 | B49: CIBEBER | C49: 0 | D49: 0 | E49: 0 | F49: 1 | G49: 0 | H49: 0 | I49: 1 | J49: 0 | K49: 0 | L49: 0 | M49: 0 | N49: 0 | O49: =SUM(C49:N49) -> 2 | Q49: =SUM(F49:K49) -> 2
A50: JUMLAH | C50: =SUM(C42:C49) -> 4 | D50: =SUM(D42:D49) -> 0 | E50: =SUM(E42:E49) -> 5 | F50: =SUM(F42:F49) -> 1 | G50: =SUM(G42:G49) -> 0 | H50: =SUM(H42:H49) -> 2 | I50: =SUM(I42:I49) -> 1 | J50: =SUM(J42:J49) -> 1 | ... O50: =SUM(O42:O49) -> 19 | Q50: =SUM(F50:K50) -> 5
A68: DATA PRODUKSI UBI JALAR PER BULAN
A69: KOTA CILEGON TAHUN 2017
O71: (Ton)
A72: No | B72: Kecamatan | C72: Bulan | O72: Jumlah
C73: Jan | D73: Feb | E73: Maret | F73: Apr | G73: Mei | H73: Juni | I73: Juli | J73: Agst | K73: Sept | L73: Okt | M73: Nov | N73: Des
A74: 1 | B74: 2 | C74: 3 | D74: 4 | E74: 5 | F74: 6 | G74: 7 | H74: 8 | I74: 9 | J74: 10 | K74: 11 | L74: 12 | M74: 13 | N74: 14 | O74: 15
A75: 1 | B75: CIWANDAN | C75: 9 | D75: 0 | E75: 17 | F75: 0 | G75: 0 | H75: 0 | I75: 0 | J75: 0 | K75: 0 | L75: 0 | M75: 0 | N75: 19 | O75: =SUM(C75:N75) -> 45 | Q75: =SUM(F75:K75) -> 0 | R75: =O75*2500 -> 112500 | S75: 126000 | T75: =SUM(R75:S75) -> 238500
A76: 2 | B76: CITANGKIL | C76: 12 | D76: 0 | E76: 0 | F76: 0 | G76: 0 | H76: 0 | I76: 0 | J76: 10 | K76: 0 | L76: 0 | M76: 9 | N76: 0 | O76: =SUM(C76:N76) -> 31 | Q76: =SUM(F76:K76) -> 10 | R76: =O76*2500 -> 77500 | S76: 114000 | T76: =SUM(R76:S76) -> 191500
A77: 3 | B77: PULOMERAK | C77: 0 | D77: 0 | E77: 0 | F77: 0 | G77: 0 | H77: 0 | I77: 0 | J77: 0 | K77: 0 | L77: 0 | M77: 0 | N77: 0 | O77: =SUM(C77:N77) -> 0 | Q77: =SUM(F77:K77) -> 0 | R77: =O77*2500 -> 0 | S77: 212000 | T77: =SUM(R77:S77) -> 212000
A78: 4 | B78: PURWAKARTA | C78: 0 | D78: 0 | E78: 19 | F78: 0 | G78: 0 | H78: 0 | I78: 0 | J78: 0 | K78: 0 | L78: 0 | M78: 0 | N78: 0 | O78: =SUM(C78:N78) -> 19 | Q78: =SUM(F78:K78) -> 0 | R78: =O78*2500 -> 47500 | S78: 60000 | T78: =SUM(R78:S78) -> 107500
...

Sheet kc ijo
A2: DATA LUAS TANAM KACANG HIJAU PER BULAN
A3: KOTA CILEGON TAHUN 2017
O5: (Ha)
A6: No | B6: Kecamatan | C6: Bulan | O6: Jumlah
C7: Jan | D7: Feb | E7: Maret | F7: Apr | G7: Mei | H7: Juni | I7: Juli | J7: Agst | K7: Sept | L7: Okt | M7: Nov | N7: Des
A8: 1 | B8: 2 | C8: 3 | D8: 4 | E8: 5 | F8: 6 | G8: 7 | H8: 8 | I8: 9 | J8: 10 | K8: 11 | L8: 12 | M8: 13 | N8: 14 | O8: 15 | Q8: APR-SEP
A9: 1 | B9: CIWANDAN | C9: 0 | D9: 0 | E9: 0 | F9: 0 | H9: 0 | I9: 0 | J9: 0 | K9: 0 | L9: 0 | M9: 0 | N9: 1 | O9: =SUM(C9:N9) -> 1 | P9: =SUM(I9:K9) -> 0 | Q9: =SUM(F9:K9) -> 0
A10: 2 | B10: CITANGKIL | C10: 0 | D10: 0 | E10: 0 | F10: 0 | G10: 0 | H10: 0 | I10: 0 | J10: 0 | K10: 0 | L10: 0 | M10: 0 | N10: 1 | O10: =SUM(C10:N10) -> 1 | P10: =SUM(I10:K10) -> 0 | Q10: =SUM(F10:K10) -> 0
A11: 3 | B11: PULOMERAK | C11: 0 | D11: 0 | E11: 0 | F11: 0 | G11: 0 | H11: 0 | I11: 0 | J11: 0 | K11: 0 | L11: 0 | M11: 0 | N11: 0 | O11: =SUM(C11:N11) -> 0 | P11: =SUM(I11:K11) -> 0 | Q11: =SUM(F11:K11) -> 0
A12: 4 | B12: PURWAKARTA | C12: 0 | D12: 0 | E12: 4 | F12: 0 | G12: 15 | H12: 0 | I12: 0 | J12: 0 | K12: 10 | L12: 0 | M12: 5 | N12: 0 | O12: =SUM(C12:N12) -> 34 | P12: =SUM(I12:K12) -> 10 | Q12: =SUM(F12:K12) -> 25
A13: 5 | B13: GROGOL | C13: 0 | D13: 0 | E13: 0 | F13: 0 | G13: 2 | H13: 1 | I13: 0 | J13: 0 | K13: 0 | L13: 0 | M13: 0 | N13: 0 | O13: =SUM(C13:N13) -> 3 | P13: =SUM(I13:K13) -> 0 | Q13: =SUM(F13:K13) -> 3
A14: 6 | B14: CILEGON | C14: 0 | D14: 0 | E14: 0 | F14: 0 | G14: 0 | H14: 0 | I14: 0 | J14: 0 | K14: 0 | L14: 0 | M14: 1 | N14: 0 | O14: =SUM(C14:N14) -> 1 | P14: =SUM(I14:K14) -> 0 | Q14: =SUM(F14:K14) -> 0
A15: 7 | B15: JOMBANG | C15: 1 | D15: 0 | E15: 0 | F15: 0 | G15: 0 | H15: 0 | I15: 0 | J15: 0 | K15: 0 | L15: 0 | M15: 0 | N15: 0 | O15: =SUM(C15:N15) -> 1 | P15: =SUM(I15:K15) -> 0 | Q15: =SUM(F15:K15) -> 0
A16: 8 | B16: CIBEBER | C16: 0 | D16: 0 | E16: 0 | F16: 0 | G16: 0 | H16: 0 | I16: 0.5 | J16: 0 | K16: 0 | L16: 0 | M16: 0 | N16: 0 | O16: =SUM(C16:N16) -> 0.5 | P16: =SUM(I16:K16) -> 0.5 | Q16: =SUM(F16:K16) -> 0.5
A17: JUMLAH | C17: =SUM(C9:C16) -> 1 | D17: =SUM(D9:D16) -> 0 | E17: =SUM(E9:E16) -> 4 | F17: =SUM(F9:F16) -> 0 | G17: =SUM(G9:G16) -> 17 | H17: =SUM(H9:H16) -> 1 | I17: =SUM(I9:I16) -> 0.5 | J17: =SUM(J9:J16) -> 0 | ... P17: =SUM(P9:P16) -> 10.5 | Q17: =SUM(F17:K17) -> 28.5
A35: DATA LUAS PANEN KACANG HIJAU PER BULAN
A36: KOTA CILEGON TAHUN 2017
O38: (Ha)
A39: No | B39: Kecamatan | C39: Bulan | O39: Jumlah
C40: Jan | D40: Feb | E40: Maret | F40: Apr | G40: Mei | H40: Juni | I40: Juli | J40: Agst | K40: Sept | L40: Okt | M40: Nov | N40: Des
A41: 1 | B41: 2 | C41: 3 | D41: 4 | E41: 5 | F41: 6 | G41: 7 | H41: 8 | I41: 9 | J41: 10 | K41: 11 | L41: 12 | M41: 13 | N41: 14 | O41: 15
A42: 1 | B42: CIWANDAN | C42: 0 | D42: 2 | E42: 0 | F42: 0 | G42: 0 | H42: 0 | I42: 0 | J42: 0 | K42: 0 | L42: 0 | M42: 0 | N42: 0 | O42: =SUM(C42:N42) -> 2 | Q42: =SUM(F42:K42) -> 0
A43: 2 | B43: CITANGKIL | C43: 0 | D43: 0 | E43: 0 | F43: 0 | G43: 0 | H43: 0 | I43: 0 | J43: 0 | K43: 0 | L43: 0 | M43: 0 | N43: 0 | O43: =SUM(C43:N43) -> 0 | Q43: =SUM(F43:K43) -> 0
A44: 3 | B44: PULOMERAK | C44: 0 | D44: 0 | E44: 0 | F44: 0 | G44: 0 | H44: 0 | I44: 0 | J44: 0 | K44: 0 | L44: 0 | M44: 0 | N44: 0 | O44: =SUM(C44:N44) -> 0 | Q44: =SUM(F44:K44) -> 0
A45: 4 | B45: PURWAKARTA | C45: 0 | D45: 2 | E45: 0 | F45: 0 | G45: 0 | H45: 0 | I45: 9 | J45: 10 | K45: 0 | L45: 0 | M45: 0 | N45: 5 | O45: =SUM(C45:N45) -> 26 | Q45: =SUM(F45:K45) -> 19
A46: 5 | B46: GROGOL | C46: 0 | D46: 0 | E46: 0 | F46: 0 | G46: 0 | H46: 0 | I46: 2 | J46: 1 | K46: 0 | L46: 0 | M46: 0 | N46: 0 | O46: =SUM(C46:N46) -> 3 | Q46: =SUM(F46:K46) -> 3
A47: 6 | B47: CILEGON | C47: 0 | D47: 0 | E47: 0 | F47: 0 | G47: 0 | H47: 0 | I47: 0 | J47: 0 | K47: 0 | L47: 0 | M47: 0 | N47: 0 | O47: =SUM(C47:N47) -> 0 | Q47: =SUM(F47:K47) -> 0
A48: 7 | B48: JOMBANG | C48: 0 | D48: 0 | E48: 0 | F48: 0 | G48: 1 | H48: 0 | I48: 0 | J48: 0 | K48: 0 | L48: 0 | M48: 0 | N48: 0 | O48: =SUM(C48:N48) -> 1 | Q48: =SUM(F48:K48) -> 1
A49: 8 | B49: CIBEBER | C49: 0 | D49: 0 | E49: 0 | F49: 0 | G49: 0 | H49: 0 | I49: 0 | J49: 0 | K49: 0 | L49: 0.5 | M49: 0 | N49: 0 | O49: =SUM(C49:N49) -> 0.5 | Q49: =SUM(F49:K49) -> 0
A50: JUMLAH | C50: =SUM(C42:C49) -> 0 | D50: =SUM(D42:D49) -> 4 | E50: =SUM(E42:E49) -> 0 | F50: =SUM(F42:F49) -> 0 | G50: =SUM(G42:G49) -> 1 | H50: =SUM(H42:H49) -> 0 | I50: =SUM(I42:I49) -> 11 | J50: =SUM(J42:J49) -> 11 | ... O50: =SUM(O42:O49) -> 32.5 | Q50: =SUM(F50:K50) -> 23
A68: DATA PRODUKSI KACANG HIJAU PER BULAN
A69: KOTA CILEGON TAHUN 2017
O71: (Ton)
A72: No | B72: Kecamatan | C72: Bulan | O72: Jumlah
C73: Jan | D73: Feb | E73: Maret | F73: Apr | G73: Mei | H73: Juni | I73: Juli | J73: Agst | K73: Sept | L73: Okt | M73: Nov | N73: Des
A74: 1 | B74: 2 | C74: 3 | D74: 4 | E74: 5 | F74: 6 | G74: 7 | H74: 8 | I74: 9 | J74: 10 | K74: 11 | L74: 12 | M74: 13 | N74: 14 | O74: 15
A75: 1 | B75: CIWANDAN | C75: 0 | D75: 1 | E75: 0 | F75: 0 | G75: 0 | H75: 0 | I75: 0 | J75: 0 | K75: 0 | L75: 0 | M75: 0 | N75: 0 | O75: =SUM(C75:N75) -> 1 | Q75: =SUM(F75:K75) -> 0 | R75: =O75*20000 -> 20000
A76: 2 | B76: CITANGKIL | C76: 0 | D76: 0 | E76: 0 | F76: 0 | G76: 0 | H76: 0 | I76: 0 | J76: 0 | K76: 0 | L76: 0 | M76: 0 | N76: 0 | O76: =SUM(C76:N76) -> 0 | Q76: =SUM(F76:K76) -> 0 | R76: =O76*20000 -> 0
A77: 3 | B77: PULOMERAK | C77: 0 | D77: 0 | E77: 0 | F77: 0 | G77: 0 | H77: 0 | I77: 0 | J77: 0 | K77: 0 | L77: 0 | M77: 0 | N77: 0 | O77: =SUM(C77:N77) -> 0 | Q77: =SUM(F77:K77) -> 0 | R77: =O77*20000 -> 0
A78: 4 | B78: PURWAKARTA | C78: 0 | D78: 1 | E78: 0 | F78: 0 | G78: 0 | H78: 0 | I78: 5.76 | J78: 6 | K78: 0 | L78: 0 | M78: 0 | N78: 4 | O78: =SUM(C78:N78) -> 16.76 | Q78: =SUM(F78:K78) -> 11.76 | R78: =O78*20000 -> 335200
...

Sheet talas
A2: DATA LUAS TANAM TALAS PER BULAN
A3: KOTA CILEGON TAHUN 2017
O5: (Ha)
A6: No | B6: Kecamatan | C6: Bulan | O6: Jumlah
C7: Jan | D7: Feb | E7: Maret | F7: Apr | G7: Mei | H7: Juni | I7: Juli | J7: Agst | K7: Sept | L7: Okt | M7: Nov | N7: Des
A8: 1 | B8: 2 | C8: 3 | D8: 4 | E8: 5 | F8: 6 | G8: 7 | H8: 8 | I8: 9 | J8: 10 | K8: 11 | L8: 12 | M8: 13 | N8: 14 | O8: 15 | Q8: ok-nop
A9: 1 | B9: CIWANDAN | C9: 0 | D9: 0 | E9: 0 | F9: 0 | G9: 0 | H9: 0 | I9: 0 | J9: 0 | K9: 0 | L9: 0 | M9: 0 | N9: 0 | O9: =SUM(C9:N9) -> 0 | Q9: =SUM(L9:M9) -> 0
A10: 2 | B10: CITANGKIL | C10: 0 | D10: 0 | E10: 0 | F10: 0 | G10: 1 | H10: 0 | I10: 0 | J10: 0 | K10: 0 | L10: 0 | M10: 1 | N10: 0 | O10: =SUM(C10:N10) -> 2 | Q10: =SUM(L10:M10) -> 1
A11: 3 | B11: PULOMERAK | C11: 0 | D11: 0 | E11: 0 | F11: 0 | G11: 0 | H11: 0 | I11: 0 | J11: 0 | K11: 0 | L11: 0 | M11: 0 | N11: 0 | O11: =SUM(C11:N11) -> 0 | Q11: =SUM(L11:M11) -> 0
A12: 4 | B12: PURWAKARTA | C12: 0 | D12: 0 | E12: 0 | F12: 0 | G12: 0 | H12: 0 | I12: 0 | J12: 0 | K12: 0 | L12: 0 | M12: 0 | N12: 0 | O12: =SUM(C12:N12) -> 0 | Q12: =SUM(L12:M12) -> 0
A13: 5 | B13: GROGOL | C13: 0 | D13: 0 | E13: 0 | F13: 0 | G13: 0 | H13: 0 | I13: 0 | J13: 0 | K13: 0 | L13: 0 | M13: 0 | N13: 0 | O13: =SUM(C13:N13) -> 0 | Q13: =SUM(L13:M13) -> 0
A14: 6 | B14: CILEGON | C14: 0 | D14: 0 | E14: 0 | F14: 0 | G14: 0 | H14: 0 | I14: 0 | J14: 0 | K14: 0 | L14: 0 | M14: 0 | N14: 0 | O14: =SUM(C14:N14) -> 0 | Q14: =SUM(L14:M14) -> 0
A15: 7 | B15: JOMBANG | C15: 0 | D15: 0 | E15: 0 | F15: 0 | G15: 0 | H15: 0 | I15: 0 | J15: 0 | K15: 0 | L15: 0 | M15: 0 | N15: 0 | O15: =SUM(C15:N15) -> 0 | Q15: =SUM(L15:M15) -> 0
A16: 8 | B16: CIBEBER | C16: 0 | D16: 0 | E16: 0 | F16: 0 | G16: 0 | H16: 0 | I16: 0 | J16: 0 | K16: 0 | L16: 0 | M16: 0 | N16: 0 | O16: =SUM(C16:N16) -> 0 | Q16: =SUM(L16:M16) -> 0
A17: JUMLAH | C17: =SUM(C9:C16) -> 0 | D17: =SUM(D9:D16) -> 0 | E17: =SUM(E9:E16) -> 0 | F17: =SUM(F9:F16) -> 0 | G17: =SUM(G9:G16) -> 1 | H17: =SUM(H9:H16) -> 0 | I17: =SUM(I9:I16) -> 0 | J17: =SUM(J9:J16) -> 0 | ... O17: =SUM(O9:O16) -> 2
A35: DATA LUAS PANEN TALAS PER BULAN
A36: KOTA CILEGON TAHUN 2017
O38: (Ha)
A39: No | B39: Kecamatan | C39: Bulan | O39: Jumlah
C40: Jan | D40: Feb | E40: Maret | F40: Apr | G40: Mei | H40: Juni | I40: Juli | J40: Agst | K40: Sept | L40: Okt | M40: Nov | N40: Des
A41: 1 | B41: 2 | C41: 3 | D41: 4 | E41: 5 | F41: 6 | G41: 7 | H41: 8 | I41: 9 | J41: 10 | K41: 11 | L41: 12 | M41: 13 | N41: 14 | O41: 15
A42: 1 | B42: CIWANDAN | C42: 0 | D42: 0 | E42: 0 | F42: 0 | G42: 0 | H42: 0 | I42: 0 | J42: 0 | K42: 0 | L42: 0 | M42: 0 | N42: 0 | O42: =SUM(C42:N42) -> 0 | Q42: =SUM(C42:E42) -> 0
A43: 2 | B43: CITANGKIL | C43: 0 | D43: 0 | E43: 0 | F43: 0 | G43: 0 | H43: 0 | I43: 0 | J43: 0 | K43: 0 | L43: 0 | M43: 1 | N43: 0 | O43: =SUM(C43:N43) -> 1 | Q43: =SUM(C43:E43) -> 0
A44: 3 | B44: PULOMERAK | C44: 0 | D44: 0 | E44: 0 | F44: 0 | G44: 0 | H44: 0 | I44: 0 | J44: 0 | K44: 0 | L44: 0 | M44: 0 | N44: 0 | O44: =SUM(C44:N44) -> 0 | Q44: =SUM(C44:E44) -> 0
A45: 4 | B45: PURWAKARTA | C45: 0 | D45: 0 | E45: 0 | F45: 0 | G45: 0 | H45: 0 | I45: 0 | J45: 0 | K45: 0 | L45: 0 | M45: 0 | N45: 0 | O45: =SUM(C45:N45) -> 0 | Q45: =SUM(C45:E45) -> 0
A46: 5 | B46: GROGOL | C46: 0 | D46: 0 | E46: 0 | F46: 0 | G46: 0 | H46: 0 | I46: 0 | J46: 0 | K46: 0 | L46: 0 | M46: 0 | N46: 0 | O46: =SUM(C46:N46) -> 0 | Q46: =SUM(C46:E46) -> 0
A47: 6 | B47: CILEGON | C47: 0 | D47: 0 | E47: 0 | F47: 0 | G47: 0 | H47: 0 | I47: 0 | J47: 0 | K47: 0 | L47: 0 | M47: 0 | N47: 0 | O47: =SUM(C47:N47) -> 0 | Q47: =SUM(C47:E47) -> 0
A48: 7 | B48: JOMBANG | C48: 0 | D48: 0 | E48: 0 | F48: 0 | G48: 0 | H48: 0 | I48: 0 | J48: 0 | K48: 0 | L48: 0 | M48: 0 | N48: 0 | O48: =SUM(C48:N48) -> 0 | Q48: =SUM(C48:E48) -> 0
A49: 8 | B49: CIBEBER | C49: 0 | D49: 0 | E49: 0 | F49: 0 | G49: 0 | H49: 0 | I49: 0 | J49: 0 | K49: 0 | L49: 0 | M49: 0 | N49: 0 | O49: =SUM(C49:N49) -> 0 | P49: 15 | Q49: =SUM(C49:E49) -> 0
A50: JUMLAH | C50: =SUM(C42:C49) -> 0 | D50: =SUM(D42:D49) -> 0 | E50: 0 | F50: =SUM(F42:F49) -> 0 | G50: =SUM(G42:G49) -> 0 | H50: =SUM(H42:H49) -> 0 | I50: =SUM(I42:I49) -> 0 | J50: =SUM(J42:J49) -> 0 | K50: =SUM(K42:K49) -> 0 | L50: =SUM(L42:L49) -> 0 | M50: =SUM(M42:M49) -> 1 | ... P50: =SUM(P42:P49) -> 15
A68: DATA PRODUKSI TALAS PER BULAN
A69: KOTA CILEGON TAHUN 2017
O71: (Ton)
A72: No | B72: Kecamatan | C72: Bulan | O72: Jumlah
C73: Jan | D73: Feb | E73: Maret | F73: Apr | G73: Mei | H73: Juni | I73: Juli | J73: Agst | K73: Sept | L73: Okt | M73: Nov | N73: Des
A74: 1 | B74: 2 | C74: 3 | D74: 4 | E74: 5 | F74: 6 | G74: 7 | H74: 8 | I74: 9 | J74: 10 | K74: 11 | L74: 12 | M74: 13 | N74: 14 | O74: 15
A75: 1 | B75: CIWANDAN | C75: 0 | D75: 0 | E75: 0 | F75: 0 | G75: 0 | H75: 0 | I75: 0 | J75: 0 | K75: 0 | L75: 0 | M75: 0 | N75: 0 | O75: =SUM(C75:N75) -> 0 | Q75: =SUM(C75:E75) -> 0
A76: 2 | B76: CITANGKIL | C76: 0 | D76: 0 | E76: 0 | F76: 0 | G76: 0 | H76: 0 | I76: 0 | J76: 0 | K76: 0 | L76: 0 | M76: 9.6 | N76: 0 | O76: =SUM(C76:N76) -> 9.6 | Q76: =SUM(C76:E76) -> 0
A77: 3 | B77: PULOMERAK | C77: 0 | D77: 0 | E77: 0 | F77: 0 | G77: 0 | H77: 0 | I77: 0 | J77: 0 | K77: 0 | L77: 0 | M77: 0 | N77: 0 | O77: =SUM(C77:N77) -> 0 | Q77: =SUM(C77:E77) -> 0
A78: 4 | B78: PURWAKARTA | C78: 0 | D78: 0 | E78: 0 | F78: 0 | G78: 0 | H78: 0 | I78: 0 | J78: 0 | K78: 0 | L78: 0 | M78: 0 | N78: 0 | O78: =SUM(C78:N78) -> 0 | Q78: =SUM(C78:E78) -> 0
...

Sheet sorgum
A2: DATA LUAS TANAM SORGUM PER BULAN
A3: KOTA CILEGON TAHUN 2017
O5: (Ha)
A6: No | B6: Kecamatan | C6: Bulan | O6: Jumlah
C7: Jan | D7: Feb | E7: Maret | F7: Apr | G7: Mei | H7: Juni | I7: Juli | J7: Agst | K7: Sept | L7: Okt | M7: Nov | N7: Des
A8: 1 | B8: 2 | C8: 3 | D8: 4 | E8: 5 | F8: 6 | G8: 7 | H8: 8 | I8: 9 | J8: 10 | K8: 11 | L8: 12 | M8: 13 | N8: 14 | O8: 15 | Q8: ok-nop
A9: 1 | B9: CIWANDAN | C9: 0 | D9: 0 | E9: 0 | F9: 0 | G9: 0 | H9: 0 | I9: 0 | J9: 0 | K9: 0 | L9: 0 | M9: 0 | N9: 0 | O9: =SUM(C9:N9) -> 0 | Q9: =SUM(L9:M9) -> 0
A10: 2 | B10: CITANGKIL | C10: 0 | D10: 0 | E10: 0 | F10: 0 | G10: 0 | H10: 0 | I10: 0 | J10: 0 | K10: 0 | L10: 0 | M10: 0 | N10: 0 | O10: =SUM(C10:N10) -> 0 | Q10: =SUM(L10:M10) -> 0
A11: 3 | B11: PULOMERAK | C11: 0 | D11: 0 | E11: 0 | F11: 0 | G11: 0 | H11: 0 | I11: 0 | J11: 0 | K11: 0 | L11: 0 | M11: 0 | N11: 0 | O11: =SUM(C11:N11) -> 0 | Q11: =SUM(L11:M11) -> 0
A12: 4 | B12: PURWAKARTA | C12: 0 | D12: 0 | E12: 0 | F12: 0 | G12: 0 | H12: 0 | I12: 0 | J12: 0 | K12: 0 | L12: 0 | M12: 0 | N12: 0 | O12: =SUM(C12:N12) -> 0 | Q12: =SUM(L12:M12) -> 0
A13: 5 | B13: GROGOL | C13: 0 | D13: 0 | E13: 0 | F13: 0 | G13: 0 | H13: 0 | I13: 0 | J13: 0 | K13: 0 | L13: 0 | M13: 0 | N13: 0 | O13: =SUM(C13:N13) -> 0 | Q13: =SUM(L13:M13) -> 0
A14: 6 | B14: CILEGON | C14: 0 | D14: 0 | E14: 0 | F14: 0 | G14: 0 | H14: 0 | I14: 0 | J14: 0 | K14: 0 | L14: 0 | M14: 0 | N14: 0 | O14: =SUM(C14:N14) -> 0 | Q14: =SUM(L14:M14) -> 0
A15: 7 | B15: JOMBANG | C15: 0 | D15: 0 | E15: 0 | F15: 0 | G15: 0 | H15: 0 | I15: 0 | J15: 0 | K15: 0 | L15: 0 | M15: 0 | N15: 0 | O15: =SUM(C15:N15) -> 0 | Q15: =SUM(L15:M15) -> 0
A16: 8 | B16: CIBEBER | C16: 0 | D16: 0 | E16: 0 | F16: 0 | G16: 0 | H16: 0 | I16: 0.5 | J16: 0 | K16: 0 | L16: 0 | M16: 0 | N16: 0 | O16: =SUM(C16:N16) -> 0.5 | Q16: =SUM(L16:M16) -> 0
A17: JUMLAH | C17: =SUM(C9:C16) -> 0 | D17: =SUM(D9:D16) -> 0 | E17: =SUM(E9:E16) -> 0 | F17: =SUM(F9:F16) -> 0 | G17: =SUM(G9:G16) -> 0 | H17: =SUM(H9:H16) -> 0 | I17: =SUM(I9:I16) -> 0.5 | J17: =SUM(J9:J16) -> 0 | ... O17: =SUM(O9:O16) -> 0.5
A35: DATA LUAS PANEN SORGUM PER BULAN
A36: KOTA CILEGON TAHUN 2017
O38: (Ha)
A39: No | B39: Kecamatan | C39: Bulan | O39: Jumlah
C40: Jan | D40: Feb | E40: Maret | F40: Apr | G40: Mei | H40: Juni | I40: Juli | J40: Agst | K40: Sept | L40: Okt | M40: Nov | N40: Des
A41: 1 | B41: 2 | C41: 3 | D41: 4 | E41: 5 | F41: 6 | G41: 7 | H41: 8 | I41: 9 | J41: 10 | K41: 11 | L41: 12 | M41: 13 | N41: 14 | O41: 15
A42: 1 | B42: CIWANDAN | C42: 0 | D42: 0 | E42: 0 | F42: 0 | G42: 0 | H42: 0 | I42: 0 | J42: 0 | K42: 0 | L42: 0 | M42: 0 | N42: 0 | O42: =SUM(C42:N42) -> 0 | Q42: =SUM(C42:E42) -> 0
A43: 2 | B43: CITANGKIL | C43: 0 | D43: 0 | E43: 0 | F43: 0 | G43: 0 | H43: 0 | I43: 0 | J43: 0 | K43: 0 | L43: 0 | M43: 0 | N43: 0 | O43: =SUM(C43:N43) -> 0 | Q43: =SUM(C43:E43) -> 0
A44: 3 | B44: PULOMERAK | C44: 0 | D44: 0 | E44: 0 | F44: 0 | G44: 0 | H44: 0 | I44: 0 | J44: 0 | K44: 0 | L44: 0 | M44: 0 | N44: 0 | O44: =SUM(C44:N44) -> 0 | Q44: =SUM(C44:E44) -> 0
A45: 4 | B45: PURWAKARTA | C45: 0 | D45: 0 | E45: 0 | F45: 0 | G45: 0 | H45: 0 | I45: 0 | J45: 0 | K45: 0 | L45: 0 | M45: 0 | N45: 0 | O45: =SUM(C45:N45) -> 0 | Q45: =SUM(C45:E45) -> 0
A46: 5 | B46: GROGOL | C46: 0 | D46: 0 | E46: 0 | F46: 0 | G46: 0 | H46: 0 | I46: 0 | J46: 0 | K46: 0 | L46: 0 | M46: 0 | N46: 0 | O46: =SUM(C46:N46) -> 0 | Q46: =SUM(C46:E46) -> 0
A47: 6 | B47: CILEGON | C47: 0 | D47: 0 | E47: 0 | F47: 0 | G47: 0 | H47: 0 | I47: 0 | J47: 0 | K47: 0 | L47: 0 | M47: 0 | N47: 0 | O47: =SUM(C47:N47) -> 0 | Q47: =SUM(C47:E47) -> 0
A48: 7 | B48: JOMBANG | C48: 0 | D48: 0 | E48: 0 | F48: 0 | G48: 0 | H48: 0 | I48: 0 | J48: 0 | K48: 0 | L48: 0 | M48: 0 | N48: 0 | O48: =SUM(C48:N48) -> 0 | Q48: =SUM(C48:E48) -> 0
A49: 8 | B49: CIBEBER | C49: 0 | D49: 0 | E49: 0 | F49: 0 | G49: 0 | H49: 0 | I49: 0 | J49: 0 | K49: 0 | L49: 0 | M49: 0 | N49: 0 | O49: =SUM(C49:N49) -> 0 | P49: 15 | Q49: =SUM(C49:E49) -> 0
A50: JUMLAH | C50: =SUM(C42:C49) -> 0 | D50: =SUM(D42:D49) -> 0 | E50: 0 | F50: =SUM(F42:F49) -> 0 | G50: =SUM(G42:G49) -> 0 | H50: =SUM(H42:H49) -> 0 | I50: =SUM(I42:I49) -> 0 | J50: =SUM(J42:J49) -> 0 | K50: =SUM(K42:K49) -> 0 | L50: =SUM(L42:L49) -> 0 | M50: =SUM(M42:M49) -> 0 | ... P50: =SUM(P42:P49) -> 15
A68: DATA PRODUKSI SORGUM PER BULAN
A69: KOTA CILEGON TAHUN 2017
O71: (Ton)
A72: No | B72: Kecamatan | C72: Bulan | O72: Jumlah
C73: Jan | D73: Feb | E73: Maret | F73: Apr | G73: Mei | H73: Juni | I73: Juli | J73: Agst | K73: Sept | L73: Okt | M73: Nov | N73: Des
A74: 1 | B74: 2 | C74: 3 | D74: 4 | E74: 5 | F74: 6 | G74: 7 | H74: 8 | I74: 9 | J74: 10 | K74: 11 | L74: 12 | M74: 13 | N74: 14 | O74: 15
A75: 1 | B75: CIWANDAN | C75: 0 | D75: 0 | E75: 0 | F75: 0 | G75: 0 | H75: 0 | I75: 0 | J75: 0 | K75: 0 | L75: 0 | M75: 0 | N75: 0 | O75: =SUM(C75:N75) -> 0 | Q75: =SUM(C75:E75) -> 0
A76: 2 | B76: CITANGKIL | C76: 0 | D76: 0 | E76: 0 | F76: 0 | G76: 0 | H76: 0 | I76: 0 | J76: 0 | K76: 0 | L76: 0 | M76: 0 | N76: 0 | O76: =SUM(C76:N76) -> 0 | Q76: =SUM(C76:E76) -> 0
A77: 3 | B77: PULOMERAK | C77: 0 | D77: 0 | E77: 0 | F77: 0 | G77: 0 | H77: 0 | I77: 0 | J77: 0 | K77: 0 | L77: 0 | M77: 0 | N77: 0 | O77: =SUM(C77:N77) -> 0 | Q77: =SUM(C77:E77) -> 0
A78: 4 | B78: PURWAKARTA | C78: 0 | D78: 0 | E78: 0 | F78: 0 | G78: 0 | H78: 0 | I78: 0 | J78: 0 | K78: 0 | L78: 0 | M78: 0 | N78: 0 | O78: =SUM(C78:N78) -> 0 | Q78: =SUM(C78:E78) -> 0
...

Sheet rekap
A1: REALISASI TANAM, PANEN, PRODUKSI DAN PRODUKTIVITAS PADI DAN PALAWIJA
A2: KOTA CILEGON 2017
A4: 1. PADI SAWAH
A5: No | B5: Kecamatan | C5: TANAM | D5: PANEN | E5: PRODUKSI | F5: PRODUKTIVITAS
C6: (Ha) | D6: (Ha) | E6: (Ton) | F6: (Ku/Ha)
A7: 1 | B7: 2 | C7: 3 | D7: 4 | E7: 5 | F7: 6
A8: 1 | B8: CIWANDAN | C8: ='padi sawah'!O9 -> 293 | D8: ='padi sawah'!O42 -> 333 | E8: ='padi sawah'!O75 -> 1861 | F8: ='padi sawah'!O108 -> 55.885886
A9: 2 | B9: CITANGKIL | C9: ='padi sawah'!O10 -> 235 | D9: ='padi sawah'!O43 -> 371 | E9: ='padi sawah'!O76 -> 3076 | F9: ='padi sawah'!O109 -> 82.911051
A10: 3 | B10: PULOMERAK | C10: ='padi sawah'!O11 -> 26 | D10: ='padi sawah'!O44 -> 41 | E10: ='padi sawah'!O77 -> 228 | F10: ='padi sawah'!O110 -> 55.609756
A11: 4 | B11: PURWAKARTA | C11: ='padi sawah'!O12 -> 183 | D11: ='padi sawah'!O45 -> 215 | E11: ='padi sawah'!O78 -> 1443 | F11: ='padi sawah'!O111 -> 67.116279
A12: 5 | B12: GROGOL | C12: ='padi sawah'!O13 -> 187 | D12: ='padi sawah'!O46 -> 202 | E12: ='padi sawah'!O79 -> 1307 | F12: ='padi sawah'!O112 -> 64.70297
A13: 6 | B13: CILEGON | C13: ='padi sawah'!O14 -> 77 | D13: ='padi sawah'!O47 -> 109 | E13: ='padi sawah'!O80 -> 738 | F13: ='padi sawah'!O113 -> 67.706422
A14: 7 | B14: JOMBANG | C14: ='padi sawah'!O15 -> 491 | D14: ='padi sawah'!O48 -> 606 | E14: ='padi sawah'!O81 -> 3358 | F14: ='padi sawah'!O114 -> 55.412541
A15: 8 | B15: CIBEBER | C15: ='padi sawah'!O16 -> 375 | D15: ='padi sawah'!O49 -> 520 | E15: ='padi sawah'!O82 -> 3179 | F15: ='padi sawah'!O115 -> 61.134615
A16: JUMLAH | C16: =SUM(C8:C15) -> 1867 | D16: =SUM(D8:D15) -> 2397 | E16: =SUM(E8:E15) -> 15190 | F16: =E16/D16*10 -> 63.37088
A18: 2. PADI LADANG
A19: No | B19: Kecamatan | C19: TANAM | D19: PANEN | E19: PRODUKSI | F19: PRODUKTIVITAS
C20: (Ha) | D20: (Ha) | E20: (Ton) | F20: (Ku/Ha)
A21: 1 | B21: 2 | C21: 3 | D21: 4 | E21: 5 | F21: 6
