Workbook

Sheet padi sawah
A2: DATA LUAS TANAM PADI (SAWAH) PER BULAN
A3: KOTA CILEGON TAHUN 2025
O5: (Ha)
A6: No | B6: Kecamatan | C6: Bulan | O6: Jumlah | S6: mei | T6: 130
C7: Jan | D7: Feb | E7: Maret | F7: Apr | G7: Mei | H7: Juni | I7: Juli | J7: Agst | K7: Sept | L7: Okt | M7: Nov | N7: Des | Q7: apr - juni | S7: jun | T7: 108
A8: 1 | B8: 2 | C8: 3 | D8: 4 | E8: 5 | F8: 6 | G8: 7 | H8: 8 | I8: 9 | J8: 10 | K8: 11 | L8: 12 | M8: 13 | N8: 14 | O8: 15 | S8: jul | T8: 35
A9: 1 | B9: CIWANDAN | C9: 145 | D9: 25 | E9: 0 | F9: 0 | G9: 20 | H9: 208 | I9: 40 | J9: 1 | K9: 2 | L9: 2 | M9: 1 | N9: 88 | O9: =SUM(C9:N9) -> 532 | Q9: =SUM(F9:H9) -> 228 | R9: 9000 | S9: agst
A10: 2 | B10: CITANGKIL | C10: 45 | D10: 10 | E10: 1 | F10: 1 | G10: 23 | H10: 91 | I10: 0 | J10: 2 | K10: 5 | L10: 2 | M10: 10 | N10: 35 | O10: =SUM(C10:N10) -> 225 | Q10: =SUM(F10:H10) -> 115 | R10: 8500 | S10: sep
A11: 3 | B11: PULOMERAK | C11: 11 | D11: 0 | E11: 0 | F11: 3 | G11: 7 | H11: 1 | I11: 0 | J11: 0 | K11: 0 | L11: 0 | M11: 0 | N11: 0 | O11: =SUM(C11:N11) -> 22 | Q11: =SUM(F11:H11) -> 11 | S11: okt
A12: 4 | B12: PURWAKARTA | C12: 97 | D12: 50 | E12: 0 | F12: 0 | G12: 17 | H12: 98 | I12: 0 | J12: 0 | K12: 0 | L12: 5 | M12: 3.5 | N12: 104 | O12: =SUM(C12:N12) -> 374.5 | Q12: =SUM(F12:H12) -> 115 | S12: nov
A13: 5 | B13: GROGOL | C13: 78 | D13: 0 | E13: 0 | F13: 11 | G13: 5 | H13: 0 | I13: 0 | J13: 0 | K13: 0 | L13: 1 | M13: 2 | N13: 91 | O13: =SUM(C13:N13) -> 188 | Q13: =SUM(F13:H13) -> 16 | S13: des
A14: 6 | B14: CILEGON | C14: 10 | D14: 3 | E14: 0 | F14: 2 | G14: 21 | H14: 9 | I14: 3 | J14: 0 | K14: 8 | L14: 11.5 | M14: 3 | N14: 5 | O14: =SUM(C14:N14) -> 75.5 | Q14: =SUM(F14:H14) -> 32
A15: 7 | B15: JOMBANG | C15: 185 | D15: 31 | E15: 4 | F15: 81 | G15: 65 | H15: 78 | I15: 0 | J15: 59 | K15: 0 | L15: 8 | M15: 101 | N15: 120 | O15: =SUM(C15:N15) -> 732 | Q15: =SUM(F15:H15) -> 224
A16: 8 | B16: CIBEBER | C16: 65 | D16: 23 | E16: 0 | F16: 7 | G16: 63 | H16: 98 | I16: 11 | J16: 31 | K16: 16 | L16: 16 | M16: 40 | N16: 114 | O16: =SUM(C16:N16) -> 484 | Q16: =SUM(F16:H16) -> 168
A17: JUMLAH | C17: =SUM(C9:C16) -> 636 | D17: =SUM(D9:D16) -> 142 | E17: =SUM(E9:E16) -> 5 | F17: =SUM(F9:F16) -> 105 | G17: =SUM(G9:G16) -> 221 | H17: =SUM(H9:H16) -> 583 | I17: =SUM(I9:I16) -> 54 | J17: =SUM(J9:J16) -> 93 | ... O17: =SUM(O9:O16) -> 2633 | Q17: =SUM(Q9:Q16) -> 909
A35: DATA LUAS PANEN PADI (SAWAH) PER BULAN
A36: KOTA CILEGON TAHUN 2025
O38: (Ha)
A39: No | B39: Kecamatan | C39: Bulan | O39: Jumlah
C40: Jan | D40: Feb | E40: Maret | F40: Apr | G40: Mei | H40: Juni | I40: Juli | J40: Agst | K40: Sept | L40: Okt | M40: Nov | N40: Des
A41: 1 | B41: 2 | C41: 3 | D41: 4 | E41: 5 | F41: 6 | G41: 7 | H41: 8 | I41: 9 | J41: 10 | K41: 11 | L41: 12 | M41: 13 | N41: 14 | O41: 15
A42: 1 | B42: CIWANDAN | C42: 0 | D42: 0 | E42: 3 | F42: 245 | G42: 20 | H42: 0 | I42: 40 | J42: 20 | K42: 116 | L42: 135 | M42: 1 | N42: 0 | O42: =SUM(C42:N42) -> 580
A43: 2 | B43: CITANGKIL | C43: 0 | D43: 0 | E43: 51 | F43: 54 | G43: 10 | H43: 1 | I43: 0 | J43: 23 | K43: 81 | L43: 10 | M43: 0 | N43: 5 | O43: =SUM(C43:N43) -> 235
A44: 3 | B44: PULOMERAK | C44: 0 | D44: 0 | E44: 0 | F44: 11 | G44: - | H44: 0 | I44: - | J44: 3 | K44: 5 | L44: 0 | M44: 0 | N44: 0 | O44: =SUM(C44:N44) -> 19
A45: 4 | B45: PURWAKARTA | C45: 0 | D45: 0 | E45: 0 | F45: 164 | G45: 2 | H45: 0 | I45: 0 | J45: 25 | K45: 90 | L45: 0 | M45: 0 | N45: 0 | O45: =SUM(C45:N45) -> 281
A46: 5 | B46: GROGOL | C46: 0 | D46: 0 | E46: 30 | F46: 78.32 | G46: - | H46: 0 | I46: - | J46: 5 | K46: 0 | L46: 0 | M46: 0 | N46: 0 | O46: =SUM(C46:N46) -> 113.32
A47: 6 | B47: CILEGON | C47: 5 | D47: 3 | E47: 18 | F47: 10 | G47: 0 | H47: 0 | I47: 5 | J47: 21 | K47: 7 | L47: 5 | M47: 5 | N47: 8 | O47: =SUM(C47:N47) -> 87
A48: 7 | B48: JOMBANG | C48: 45 | D48: 39 | E48: 110 | F48: 210 | G48: 118 | H48: 4 | I48: - | J48: 57 | K48: 100 | L48: 0 | M48: 59 | N48: 0 | O48: =SUM(C48:N48) -> 742
A49: 8 | B49: CIBEBER | C49: 10 | D49: 5 | E49: 35 | F49: 131 | G49: 0 | H49: 0 | I49: 3 | J49: 115 | K49: 55 | L49: 0 | M49: 1 | N49: 16 | O49: =SUM(C49:N49) -> 371
A50: JUMLAH | C50: =SUM(C42:C49) -> 60 | D50: =SUM(D42:D49) -> 47 | E50: =SUM(E42:E49) -> 247 | F50: =SUM(F42:F49) -> 903.32 | G50: =SUM(G42:G49) -> 150 | H50: =SUM(H42:H49) -> 5 | I50: =SUM(I42:I49) -> 48 | J50: =SUM(J42:J49) -> 269 | ... O50: =SUM(O42:O49) -> 2428.32 | Q50: =O50*5% -> 121.416 | R50: =O50-Q50 -> 2306.904 | S50: =O50*95% -> 2306.904
A68: DATA PRODUKSI PADI (SAWAH) PER BULAN
A69: KOTA CILEGON TAHUN 2025
O71: (Ton GKG)
A72: No | B72: Kecamatan | C72: Bulan | O72: Jumlah
C73: Jan | D73: Feb | E73: Maret | F73: Apr | G73: Mei | H73: Juni | I73: Juli | J73: Agst | K73: Sept | L73: Okt | M73: Nov | N73: Des
A74: 1 | B74: 2 | C74: 3 | D74: 4 | E74: 5 | F74: 6 | G74: 7 | H74: 8 | I74: 9 | J74: 10 | K74: 11 | L74: 12 | M74: 13 | N74: 14 | O74: 15
A75: 1 | B75: CIWANDAN | C75: 0 | D75: 0 | E75: 17.1 | F75: 1421 | G75: 116 | H75: 0 | I75: - | J75: 116 | K75: 672.8 | L75: 769.5 | M75: 5.7 | O75: =SUM(C75:N75) -> 3118.1
A76: 2 | B76: CITANGKIL | C76: 0 | D76: 0 | E76: 290 | F76: 313.2 | G76: 58 | H76: 5.8 | I76: 5.8 | J76: 133.4 | K76: 469.8 | L76: 58 | M76: 0 | N76: 29 | O76: =SUM(C76:N76) -> 1363
A77: 3 | B77: PULOMERAK | C77: 0 | D77: 0 | E77: 0 | F77: 63.8 | G77: 0 | H77: 0 | I77: - | J77: 17.4 | K77: 29 | L77: 0 | M77: 0 | O77: =SUM(C77:N77) -> 110.2
A78: 4 | B78: PURWAKARTA | C78: 0 | D78: 0 | E78: 0 | F78: 951.2 | G78: 11.6 | H78: 0 | I78: 0 | J78: 145 | K78: 522 | L78: 0 | M78: 0 | O78: =SUM(C78:N78) -> 1629.8
...

Sheet puso
A1: DATA LUAS PUSO PADI (SAWAH) PER BULAN
A2: KOTA CILEGON TAHUN 2025
O3: (Ha)
A4: No | B4: Kecamatan | C4: Bulan | O4: Jumlah
C5: Jan | D5: Feb | E5: Maret | F5: Apr | G5: Mei | H5: Juni | I5: Juli | J5: Agst | K5: Sept | L5: Okt | M5: Nov | N5: Des
A6: 1 | B6: 2 | C6: 3 | D6: 4 | E6: 5 | F6: 6 | G6: 7 | H6: 8 | I6: 9 | J6: 10 | K6: 11 | L6: 12 | M6: 13 | N6: 14 | O6: 15
A7: 1 | B7: CIWANDAN | C7: 0 | D7: 0 | E7: 0 | F7: 0 | G7: 0 | H7: 0 | I7: 0 | J7: 0 | K7: 0 | L7: 0 | M7: 0 | N7: 0 | O7: =SUM(C7:N7) -> 0
A8: 2 | B8: CITANGKIL | C8: 0 | D8: 0 | E8: 0 | F8: 0 | G8: 0 | H8: 0 | I8: 0 | J8: 0 | K8: 0 | L8: 0 | M8: 0 | N8: 0 | O8: =SUM(C8:N8) -> 0
A9: 3 | B9: PULOMERAK | C9: 0 | D9: 0 | E9: 0 | F9: 0 | G9: 0 | H9: 0 | I9: 0 | J9: 0 | K9: 0 | L9: 0 | M9: 0 | N9: 0 | O9: =SUM(C9:N9) -> 0
A10: 4 | B10: PURWAKARTA | C10: 0 | D10: 0 | E10: 0 | F10: 0 | G10: 0 | H10: 0 | I10: 0 | J10: 0 | K10: 0 | L10: 0 | M10: 0 | N10: 0 | O10: =SUM(C10:N10) -> 0
A11: 5 | B11: GROGOL | C11: 0 | D11: 0 | E11: 0 | F11: 0 | G11: 0 | H11: 0 | I11: 0 | J11: 0 | K11: 0 | L11: 0 | M11: 0 | N11: 0 | O11: =SUM(C11:N11) -> 0
A12: 6 | B12: CILEGON | C12: 0 | D12: 0 | E12: 0 | F12: 0 | G12: 0 | H12: 0 | I12: 0 | J12: 0 | K12: 0 | L12: 0 | M12: 0 | N12: 0 | O12: =SUM(C12:N12) -> 0
A13: 7 | B13: JOMBANG | C13: 0 | D13: 0 | E13: 0 | F13: 0 | G13: 0 | H13: 0 | I13: 0 | J13: 0 | K13: 0 | L13: 0 | M13: 0 | N13: 0 | O13: =SUM(C13:N13) -> 0
A14: 8 | B14: CIBEBER | C14: 0 | D14: 0 | E14: 0 | F14: 0 | G14: 0 | H14: 0 | I14: 0 | J14: 0 | K14: 0 | L14: 0 | M14: 0 | N14: 0 | O14: =SUM(C14:N14) -> 0
A15: JUMLAH | C15: =SUM(C7:C14) -> 0 | D15: =SUM(D7:D14) -> 0 | E15: =SUM(E7:E14) -> 0 | F15: =SUM(F7:F14) -> 0 | G15: =SUM(G7:G14) -> 0 | H15: =SUM(H7:H14) -> 0 | I15: =SUM(I7:I14) -> 0 | J15: =SUM(J7:J14) -> 0 | ... O15: =SUM(O7:O14) -> 0
A34: DATA LUAS PUSO KEDELAI PER BULAN
A35: KOTA CILEGON TAHUN 2025
O36: (Ha)
A37: No | B37: Kecamatan | C37: Bulan | O37: Jumlah
C38: Jan | D38: Feb | E38: Maret | F38: Apr | G38: Mei | H38: Juni | I38: Juli | J38: Agst | K38: Sept | L38: Okt | M38: Nov | N38: Des
A39: 1 | B39: 2 | C39: 3 | D39: 4 | E39: 5 | F39: 6 | G39: 7 | H39: 8 | I39: 9 | J39: 10 | K39: 11 | L39: 12 | M39: 13 | N39: 14 | O39: 15
A40: 1 | B40: CIWANDAN | C40: 0 | D40: 0 | E40: 0 | F40: 0 | G40: 0 | H40: 0 | I40: 0 | J40: 0 | K40: 0 | L40: 0 | M40: 0 | N40: 0 | O40: =SUM(C40:N40) -> 0
A41: 2 | B41: CITANGKIL | C41: 0 | D41: 0 | E41: 0 | F41: 0 | G41: 0 | H41: 0 | I41: 0 | J41: 0 | K41: 0 | L41: 0 | M41: 0 | N41: 0 | O41: =SUM(C41:N41) -> 0
A42: 3 | B42: PULOMERAK | C42: 0 | D42: 0 | E42: 0 | F42: 0 | G42: 0 | H42: 0 | I42: 0 | J42: 0 | K42: 0 | L42: 0 | M42: 0 | N42: 0 | O42: =SUM(C42:N42) -> 0
A43: 4 | B43: PURWAKARTA | C43: 0 | D43: 0 | E43: 0 | F43: 0 | G43: 0 | H43: 0 | I43: 0 | J43: 0 | K43: 0 | L43: 0 | M43: 0 | N43: 0 | O43: =SUM(C43:N43) -> 0
A44: 5 | B44: GROGOL | C44: 0 | D44: 0 | E44: 0 | F44: 0 | G44: 0 | H44: 0 | I44: 0 | J44: 0 | K44: 0 | L44: 0 | M44: 0 | N44: 0 | O44: =SUM(C44:N44) -> 0
A45: 6 | B45: CILEGON | C45: 0 | D45: 0 | E45: 0 | F45: 0 | G45: 0 | H45: 0 | I45: 0 | J45: 0 | K45: 0 | L45: 0 | M45: 0 | N45: 0 | O45: =SUM(C45:N45) -> 0
A46: 7 | B46: JOMBANG | C46: 0 | D46: 0 | E46: 0 | F46: 0 | G46: 0 | H46: 0 | I46: 0 | J46: 0 | K46: 0 | L46: 0 | M46: 0 | N46: 0 | O46: =SUM(C46:N46) -> 0
A47: 8 | B47: CIBEBER | C47: 0 | D47: 0 | E47: 0 | F47: 0 | G47: 0 | H47: 0 | I47: 0 | J47: 0 | K47: 0 | L47: 0 | M47: 0 | N47: 0 | O47: =SUM(C47:N47) -> 0
A48: JUMLAH | C48: =SUM(C40:C47) -> 0 | D48: =SUM(D40:D47) -> 0 | E48: =SUM(E40:E47) -> 0 | F48: =SUM(F40:F47) -> 0 | G48: =SUM(G40:G47) -> 0 | H48: =SUM(H40:H47) -> 0 | I48: =SUM(I40:I47) -> 0 | J48: =SUM(J40:J47) -> 0 | ... O48: =SUM(O40:O47) -> 0

Sheet padi ladang
A2: DATA LUAS TANAM PADI (DARAT) PER BULAN
A3: KOTA CILEGON TAHUN 2025
O5: (Ha)
A6: No | B6: Kecamatan | C6: Bulan | O6: Jumlah
C7: Jan | D7: Feb | E7: Maret | F7: Apr | G7: Mei | H7: Juni | I7: Juli | J7: Agst | K7: Sept | L7: Okt | M7: Nov | N7: Des
A8: 1 | B8: 2 | C8: 3 | D8: 4 | E8: 5 | F8: 6 | G8: 7 | H8: 8 | I8: 9 | J8: 10 | K8: 11 | L8: 12 | M8: 13 | N8: 14 | O8: 15
A9: 1 | B9: CIWANDAN | C9: 0 | D9: 0 | E9: 0 | F9: 0 | G9: 0 | H9: 0 | I9: 0 | J9: 0 | K9: 0 | L9: 0 | M9: 0 | N9: 0 | O9: =SUM(C9:N9) -> 0
A10: 2 | B10: CITANGKIL | C10: 0 | D10: 0 | E10: 0 | F10: 0 | G10: 0 | H10: 0 | I10: 0 | J10: 0 | K10: 0 | L10: 0 | M10: 0 | N10: 0 | O10: =SUM(C10:N10) -> 0
A11: 3 | B11: PULOMERAK | C11: 0 | D11: 0 | E11: 0 | F11: 0 | G11: 0 | H11: 0 | I11: 0 | J11: 0 | K11: 0 | L11: 0 | M11: 0 | N11: 0 | O11: =SUM(C11:N11) -> 0
A12: 4 | B12: PURWAKARTA | C12: 0 | D12: 0 | E12: 0 | F12: 0 | G12: 0 | H12: 0 | I12: 0 | J12: 0 | K12: 0 | L12: 0 | M12: 0 | N12: 0 | O12: =SUM(C12:N12) -> 0
A13: 5 | B13: GROGOL | C13: 0 | D13: 0 | E13: 0 | F13: 0 | G13: 0 | H13: 0 | I13: 0 | J13: 0 | K13: 0 | L13: 0 | M13: 0 | N13: 0 | O13: =SUM(C13:N13) -> 0
A14: 6 | B14: CILEGON | C14: 0 | D14: 0 | E14: 0 | F14: 0 | G14: 0 | H14: 0 | I14: 0 | J14: 0 | K14: 0 | L14: 0 | M14: 0 | N14: 0 | O14: =SUM(C14:N14) -> 0
A15: 7 | B15: JOMBANG | C15: 0 | D15: 0 | E15: 0 | F15: 0 | G15: 0 | H15: 0 | I15: 0 | J15: 0 | K15: 0 | L15: 0 | M15: 0 | N15: 0 | O15: =SUM(C15:N15) -> 0
A16: 8 | B16: CIBEBER | C16: 0 | D16: 0 | E16: 0 | F16: 0 | G16: 0 | H16: - | I16: 0 | J16: 0 | K16: 0 | L16: 0 | M16: 0 | N16: 0 | O16: =SUM(C16:N16) -> 0
A17: JUMLAH | C17: =SUM(C9:C16) -> 0 | D17: =SUM(D9:D16) -> 0 | E17: =SUM(E9:E16) -> 0 | F17: =SUM(F9:F16) -> 0 | G17: =SUM(G9:G16) -> 0 | H17: =SUM(H9:H16) -> 0 | I17: =SUM(I9:I16) -> 0 | J17: =SUM(J9:J16) -> 0 | ... O17: =SUM(O9:O16) -> 0
A35: DATA LUAS PANEN PADI (DARAT) PER BULAN
A36: KOTA CILEGON TAHUN 2025
O38: (Ha)
A39: No | B39: Kecamatan | C39: Bulan | O39: Jumlah
C40: Jan | D40: Feb | E40: Maret | F40: Apr | G40: Mei | H40: Juni | I40: Juli | J40: Agst | K40: Sept | L40: Okt | M40: Nov | N40: Des
A41: 1 | B41: 2 | C41: 3 | D41: 4 | E41: 5 | F41: 6 | G41: 7 | H41: 8 | I41: 9 | J41: 10 | K41: 11 | L41: 12 | M41: 13 | N41: 14 | O41: 15
A42: 1 | B42: CIWANDAN | C42: 0 | D42: 0 | E42: 0 | F42: 0 | G42: 0 | H42: 0 | I42: 0 | J42: 0 | K42: 0 | L42: 0 | M42: 0 | N42: 0 | O42: =SUM(C42:N42) -> 0
A43: 2 | B43: CITANGKIL | C43: 0 | D43: 0 | E43: 0 | F43: 0 | G43: 0 | H43: 0 | I43: 0 | J43: 0 | K43: 0 | L43: 0 | M43: 0 | N43: 0 | O43: =SUM(C43:N43) -> 0
A44: 3 | B44: PULOMERAK | C44: 0 | D44: 0 | E44: 0 | F44: 0 | G44: 0 | H44: 0 | I44: 0 | J44: 0 | K44: 0 | L44: 0 | M44: 0 | N44: 0 | O44: =SUM(C44:N44) -> 0
A45: 4 | B45: PURWAKARTA | C45: 0 | D45: 0 | E45: 0 | F45: 0 | G45: 0 | H45: 0 | I45: 0 | J45: 0 | K45: 0 | L45: 0 | M45: 0 | N45: 0 | O45: =SUM(C45:N45) -> 0
A46: 5 | B46: GROGOL | C46: 0 | D46: 0 | E46: 0 | F46: 0 | G46: 0 | H46: 0 | I46: 0 | J46: 0 | K46: 0 | L46: 0 | M46: 0 | N46: 0 | O46: =SUM(C46:N46) -> 0
A47: 6 | B47: CILEGON | C47: 0 | D47: 0 | E47: 0 | F47: 0 | G47: 0 | H47: 0 | I47: 0 | J47: 0 | K47: 0 | L47: 0 | M47: 0 | N47: 0 | O47: =SUM(C47:N47) -> 0
A48: 7 | B48: JOMBANG | C48: 0 | D48: 0 | E48: 0 | F48: 0 | G48: 0 | H48: 0 | I48: 0 | J48: 0 | K48: 0 | L48: 0 | M48: 0 | N48: 0 | O48: =SUM(C48:N48) -> 0
A49: 8 | B49: CIBEBER | C49: 0 | D49: 0 | E49: 0 | F49: 0 | G49: 0 | H49: 0 | I49: 0 | J49: 0 | K49: - | L49: 0 | M49: 0 | N49: 0 | O49: =SUM(C49:N49) -> 0
A50: JUMLAH | C50: =SUM(C42:C49) -> 0 | D50: =SUM(D42:D49) -> 0 | E50: =SUM(E42:E49) -> 0 | F50: =SUM(F42:F49) -> 0 | G50: =SUM(G42:G49) -> 0 | H50: =SUM(H42:H49) -> 0 | I50: =SUM(I42:I49) -> 0 | J50: =SUM(J42:J49) -> 0 | ... O50: =SUM(O42:O49) -> 0
A68: DATA PRODUKSI PADI (DARAT) PER BULAN
A69: KOTA CILEGON TAHUN 2025
O71: (Ton)
A72: No | B72: Kecamatan | C72: Bulan | O72: Jumlah
C73: Jan | D73: Feb | E73: Maret | F73: Apr | G73: Mei | H73: Juni | I73: Juli | J73: Agst | K73: Sept | L73: Okt | M73: Nov | N73: Des
A74: 1 | B74: 2 | C74: 3 | D74: 4 | E74: 5 | F74: 6 | G74: 7 | H74: 8 | I74: 9 | J74: 10 | K74: 11 | L74: 12 | M74: 13 | N74: 14 | O74: 15
A75: 1 | B75: CIWANDAN | C75: 0 | D75: 0 | E75: 0 | F75: 0 | G75: 0 | H75: 0 | I75: 0 | J75: 0 | K75: 0 | L75: 0 | M75: 0 | N75: 0 | O75: =SUM(C75:N75) -> 0
A76: 2 | B76: CITANGKIL | C76: 0 | D76: 0 | E76: 0 | F76: 0 | G76: 0 | H76: 0 | I76: 0 | J76: 0 | K76: 0 | L76: 0 | M76: 0 | N76: 0 | O76: =SUM(C76:N76) -> 0
A77: 3 | B77: PULOMERAK | C77: 0 | D77: 0 | E77: 0 | F77: 0 | G77: 0 | H77: 0 | I77: 0 | J77: 0 | K77: 0 | L77: 0 | M77: 0 | N77: 0 | O77: =SUM(C77:N77) -> 0
A78: 4 | B78: PURWAKARTA | C78: 0 | D78: 0 | E78: 0 | F78: 0 | G78: 0 | H78: 0 | I78: 0 | J78: 0 | K78: 0 | L78: 0 | M78: 0 | N78: 0 | O78: =SUM(C78:N78) -> 0
...

Sheet jagung
A2: DATA LUAS TANAM JAGUNG PER BULAN
A3: KOTA CILEGON TAHUN 2025
O5: (Ha)
A6: No | B6: Kecamatan | C6: Bulan | O6: Jumlah
C7: Jan | D7: Feb | E7: Maret | F7: Apr | G7: Mei | H7: Juni | I7: Juli | J7: Agst | K7: Sept | L7: Okt | M7: Nov | N7: Des
A8: 1 | B8: 2 | C8: 3 | D8: 4 | E8: 5 | F8: 6 | G8: 7 | H8: 8 | I8: 9 | J8: 10 | K8: 11 | L8: 12 | M8: 13 | N8: 14 | O8: 15
A9: 1 | B9: CIWANDAN | C9: 0 | D9: 0 | E9: 0 | F9: 0 | G9: 0 | H9: 0.2 | I9: 0 | J9: 4.15 | K9: 0.4 | L9: 0 | M9: 3.15 | O9: =SUM(C9:N9) -> 7.9
A10: 2 | B10: CITANGKIL | C10: 0.2 | D10: 0.25 | E10: 0 | F10: 0.2 | G10: 0.3 | H10: 0.1 | I10: 0 | J10: 0.6 | K10: 0.1 | L10: 0.3 | M10: 0.1 | N10: 0.1 | O10: =SUM(C10:N10) -> 1.95
A11: 3 | B11: PULOMERAK | C11: 2 | D11: 0 | E11: 0 | F11: 3 | G11: 0 | H11: 0 | I11: 0 | J11: 0 | K11: 0 | L11: 0.5 | M11: 0.5 | N11: 0 | O11: =SUM(C11:N11) -> 6
A12: 4 | B12: PURWAKARTA | C12: 0.15 | D12: 0 | E12: 0 | F12: 0 | G12: 0 | H12: 0 | I12: - | J12: 0 | K12: 0 | L12: 0 | M12: 1 | N12: 0 | O12: =SUM(C12:N12) -> 1.15
A13: 5 | B13: GROGOL | C13: 0 | D13: 0 | E13: 1 | F13: 0 | G13: 0 | H13: 1 | I13: - | J13: 0.2 | K13: 1 | L13: 0 | M13: 0.1 | O13: =SUM(C13:N13) -> 3.3
A14: 6 | B14: CILEGON | C14: 0.2 | D14: 0.1 | E14: 0 | F14: 0.2 | G14: 0.1 | H14: 0 | I14: 0 | J14: 4 | K14: 0 | L14: 0.3 | M14: 0.5 | N14: 0.2 | O14: =SUM(C14:N14) -> 5.6
A15: 7 | B15: JOMBANG | C15: 0.5 | D15: 0 | E15: 0 | F15: 0.5 | G15: 0.5 | H15: 0 | I15: - | J15: 1 | K15: 0 | L15: 1 | M15: 1 | N15: 1 | O15: =SUM(C15:N15) -> 5.5
A16: 8 | B16: CIBEBER | C16: 0 | D16: 1 | E16: 0 | F16: 1 | G16: 0 | H16: 1 | I16: 0 | J16: 1 | K16: 1 | L16: 2 | M16: 1 | N16: 0 | O16: =SUM(C16:N16) -> 8
A17: JUMLAH | C17: =SUM(C9:C16) -> 3.05 | D17: =SUM(D9:D16) -> 1.35 | E17: =SUM(E9:E16) -> 1 | F17: =SUM(F9:F16) -> 4.9 | G17: =SUM(G9:G16) -> 0.6 | H17: =SUM(H9:H16) -> 2.3 | I17: =SUM(I9:I16) -> 0 | J17: =SUM(J9:J16) -> 10.95 | ... O17: =SUM(O9:O16) -> 39.4
A35: DATA LUAS PANEN JAGUNG PER BULAN
A36: KOTA CILEGON TAHUN 2025
O38: (Ha)
A39: No | B39: Kecamatan | C39: Bulan | O39: Jumlah
C40: Jan | D40: Feb | E40: Maret | F40: Apr | G40: Mei | H40: Juni | I40: Juli | J40: Agst | K40: Sept | L40: Okt | M40: Nov | N40: Des
A41: 1 | B41: 2 | C41: 3 | D41: 4 | E41: 5 | F41: 6 | G41: 7 | H41: 8 | I41: 9 | J41: 10 | K41: 11 | L41: 12 | M41: 13 | N41: 14 | O41: 15
A42: 1 | B42: CIWANDAN | C42: 0 | D42: 0 | E42: 0 | F42: 0 | G42: 0 | H42: - | I42: - | J42: 0 | K42: 0 | L42: 0 | M42: 0 | O42: =SUM(C42:N42) -> 0
A43: 2 | B43: CITANGKIL | C43: 0 | D43: 0 | E43: 0 | F43: 0 | G43: 0 | H43: 0 | I43: 0 | J43: - | K43: 0 | L43: 0 | M43: 0 | O43: =SUM(C43:N43) -> 0
A44: 3 | B44: PULOMERAK | C44: 0 | D44: 0 | E44: 0 | F44: 0 | G44: - | H44: - | I44: - | J44: - | K44: 0 | L44: 0 | M44: 0 | O44: =SUM(C44:N44) -> 0
A45: 4 | B45: PURWAKARTA | C45: 0 | D45: 0 | E45: 0 | F45: - | G45: - | H45: 0 | I45: 0 | J45: - | K45: 0 | L45: 0.2 | M45: 0 | N45: 0 | O45: =SUM(C45:N45) -> 0.2
A46: 5 | B46: GROGOL | C46: 0 | D46: 0 | E46: 0 | F46: 0 | G46: - | H46: - | I46: - | J46: - | K46: 0 | L46: 0 | M46: 0 | O46: =SUM(C46:N46) -> 0
A47: 6 | B47: CILEGON | C47: 0 | D47: 0 | E47: 0 | F47: - | G47: 0 | H47: 0 | I47: - | J47: - | K47: 0 | L47: 0 | M47: 0 | N47: 0 | O47: =SUM(C47:N47) -> 0
A48: 7 | B48: JOMBANG | C48: 0 | D48: 0 | E48: 0 | F48: - | G48: - | H48: - | I48: 0 | J48: - | K48: 0 | L48: 0 | M48: 0 | O48: =SUM(C48:N48) -> 0
A49: 8 | B49: CIBEBER | C49: 0 | D49: 0 | E49: 0 | F49: 0 | G49: 0 | H49: - | I49: 0 | J49: - | K49: 0 | L49: 0 | M49: 0 | N49: 1 | O49: =SUM(C49:N49) -> 1
A50: JUMLAH | C50: =SUM(C42:C49) -> 0 | D50: =SUM(D42:D49) -> 0 | E50: =SUM(E42:E49) -> 0 | F50: =SUM(F42:F49) -> 0 | G50: =SUM(G42:G49) -> 0 | H50: =SUM(H42:H49) -> 0 | I50: =SUM(I42:I49) -> 0 | J50: =SUM(J42:J49) -> 0 | ... O50: =SUM(O42:O49) -> 1.2 | Q50: =SUM(C50:N50) -> 1.2
N52: (Ha Panen Muda)
A53: No | B53: Kecamatan | C53: Bulan | O53: Jumlah
C54: Jan | D54: Feb | E54: Maret | F54: Apr | G54: Mei | H54: Juni | I54: Juli | J54: Agst | K54: Sept | L54: Okt | M54: Nov | N54: Des
A55: 1 | B55: 2 | C55: 3 | D55: 4 | E55: 5 | F55: 6 | G55: 7 | H55: 8 | I55: 9 | J55: 10 | K55: 11 | L55: 12 | M55: 13 | N55: 14 | O55: 15
A56: 1 | B56: CIWANDAN | C56: 0 | D56: 0 | E56: 0 | F56: 0 | G56: 0 | H56: - | I56: - | J56: 0.2 | K56: 0 | L56: 0 | M56: 0 | N56: 1.15 | O56: =SUM(C56:N56) -> 1.35
A57: 2 | B57: CITANGKIL | C57: 0.2 | D57: 0.2 | E57: 0 | F57: 0.25 | G57: 0 | H57: 0.2 | I57: 0 | J57: 0.1 | K57: 0.79 | L57: 0.6 | M57: 0.1 | N57: 0.3 | O57: =SUM(C57:N57) -> 2.74
A58: 3 | B58: PULOMERAK | C58: 0 | D58: 0 | E58: 0 | F58: 0 | G58: 4 | H58: 4 | I58: 0 | J58: 1 | K58: 0 | L58: 0 | M58: 0 | N58: 0 | O58: =SUM(C58:N58) -> 9
A59: 4 | B59: PURWAKARTA | C59: 0 | D59: 0 | E59: 0 | G59: 1 | H59: - | I59: - | J59: - | K59: 0 | L59: 0 | M59: 0 | N59: 0 | O59: =SUM(C59:N59) -> 1
A60: 5 | B60: GROGOL | C60: 0 | D60: 0 | E60: 0 | G60: 0 | H60: - | I60: 0 | J60: 0 | K60: 4.9 | L60: 0 | M60: 0 | O60: =SUM(C60:N60) -> 4.9
A61: 6 | B61: CILEGON | C61: 0.2 | D61: 0 | E61: 0 | F61: 0.3 | G61: 0 | H61: 0 | I61: - | J61: - | K61: 0 | L61: 0 | M61: 0.4 | N61: 0.3 | O61: =SUM(C61:N61) -> 1.2
...

Sheet kedelai
A2: DATA LUAS TANAM KEDELAI PER BULAN
A3: KOTA CILEGON TAHUN 2025
O5: (Ha)
A6: No | B6: Kecamatan | C6: Bulan | O6: Jumlah
C7: Jan | D7: Feb | E7: Maret | F7: Apr | G7: Mei | H7: Juni | I7: Juli | J7: Agst | K7: Sept | L7: Okt | M7: Nov | N7: Des
A8: 1 | B8: 2 | C8: 3 | D8: 4 | E8: 5 | F8: 6 | G8: 7 | H8: 8 | I8: 9 | J8: 10 | K8: 11 | L8: 12 | M8: 13 | N8: 14 | O8: 15 | Q8: ok-nop
A9: 1 | B9: CIWANDAN | C9: 0 | D9: 0 | E9: 0 | F9: 0 | G9: 0 | H9: 0 | I9: 0 | J9: 0 | K9: 0 | L9: 0 | M9: 0 | N9: 0 | O9: =SUM(C9:N9) -> 0 | Q9: =SUM(L9:M9) -> 0
A10: 2 | B10: CITANGKIL | C10: 0 | D10: 0 | E10: 0 | F10: 0 | G10: 0 | H10: 0 | I10: 0 | J10: 0 | K10: 0 | L10: 0 | M10: 0 | N10: 0 | O10: =SUM(C10:N10) -> 0 | Q10: =SUM(L10:M10) -> 0
A11: 3 | B11: PULOMERAK | C11: 0 | D11: 0 | E11: 0 | F11: 0 | G11: 0 | H11: 0 | I11: 0 | J11: 0 | K11: 0 | L11: 0 | M11: 0 | N11: 0 | O11: =SUM(C11:N11) -> 0 | Q11: =SUM(L11:M11) -> 0
A12: 4 | B12: PURWAKARTA | C12: 0 | D12: 0 | E12: 0 | F12: 0 | G12: 0 | H12: 0 | I12: 0 | J12: 0 | K12: 0 | L12: 0 | M12: 0 | N12: 0 | O12: =SUM(C12:N12) -> 0 | Q12: =SUM(L12:M12) -> 0
A13: 5 | B13: GROGOL | C13: 0 | D13: 0 | E13: 0 | F13: 0 | G13: 0 | H13: 0 | I13: 0 | J13: 0 | K13: 0 | L13: 0 | M13: 0 | N13: 0 | O13: =SUM(C13:N13) -> 0 | Q13: =SUM(L13:M13) -> 0
A14: 6 | B14: CILEGON | C14: 0 | D14: 0 | E14: 0 | F14: 0 | G14: 0 | H14: 0 | I14: 0 | J14: 0 | K14: 0 | L14: 0 | M14: 0 | N14: 0 | O14: =SUM(C14:N14) -> 0 | Q14: =SUM(L14:M14) -> 0
A15: 7 | B15: JOMBANG | C15: 0 | D15: 0 | E15: 0 | F15: 0 | G15: 0 | H15: 0 | I15: 0 | J15: 0 | K15: 0 | L15: 0 | M15: 0 | N15: 0 | O15: =SUM(C15:N15) -> 0 | Q15: =SUM(L15:M15) -> 0
A16: 8 | B16: CIBEBER | C16: 0 | D16: 0 | E16: 0 | F16: 0 | G16: 0 | H16: 0 | I16: 0 | J16: 0 | K16: 0 | L16: 0 | M16: 0 | N16: 0 | O16: =SUM(C16:N16) -> 0 | Q16: =SUM(L16:M16) -> 0
A17: JUMLAH | C17: =SUM(C9:C16) -> 0 | D17: =SUM(D9:D16) -> 0 | E17: =SUM(E9:E16) -> 0 | F17: =SUM(F9:F16) -> 0 | G17: =SUM(G9:G16) -> 0 | H17: =SUM(H9:H16) -> 0 | I17: =SUM(I9:I16) -> 0 | J17: =SUM(J9:J16) -> 0 | ... O17: =SUM(O9:O16) -> 0
A35: DATA LUAS PANEN KEDELAI PER BULAN
A36: KOTA CILEGON TAHUN 2025
O38: (Ha)
A39: No | B39: Kecamatan | C39: Bulan | O39: Jumlah
C40: Jan | D40: Feb | E40: Maret | F40: Apr | G40: Mei | H40: Juni | I40: Juli | J40: Agst | K40: Sept | L40: Okt | M40: Nov | N40: Des
A41: 1 | B41: 2 | C41: 3 | D41: 4 | E41: 5 | F41: 6 | G41: 7 | H41: 8 | I41: 9 | J41: 10 | K41: 11 | L41: 12 | M41: 13 | N41: 14 | O41: 15
A42: 1 | B42: CIWANDAN | C42: 0 | D42: 0 | E42: 0 | F42: 0 | G42: 0 | H42: 0 | I42: 0 | J42: 0 | K42: 0 | L42: 0 | M42: 0 | N42: 0 | O42: =SUM(C42:N42) -> 0 | Q42: =SUM(C42:E42) -> 0
A43: 2 | B43: CITANGKIL | C43: 0 | D43: 0 | E43: 0 | F43: 0 | G43: 0 | H43: 0 | I43: 0 | J43: 0 | K43: 0 | L43: 0 | M43: 0 | N43: 0 | O43: =SUM(C43:N43) -> 0 | Q43: =SUM(C43:E43) -> 0
A44: 3 | B44: PULOMERAK | C44: 0 | D44: 0 | E44: 0 | F44: 0 | G44: 0 | H44: 0 | I44: 0 | J44: 0 | K44: 0 | L44: 0 | M44: 0 | N44: 0 | O44: =SUM(C44:N44) -> 0 | Q44: =SUM(C44:E44) -> 0
A45: 4 | B45: PURWAKARTA | C45: 0 | D45: 0 | E45: 0 | F45: 0 | G45: 0 | H45: 0 | I45: 0 | J45: 0 | K45: 0 | L45: 0 | M45: 0 | N45: 0 | O45: =SUM(C45:N45) -> 0 | Q45: =SUM(C45:E45) -> 0
A46: 5 | B46: GROGOL | C46: 0 | D46: 0 | E46: 0 | F46: 0 | G46: 0 | H46: 0 | I46: 0 | J46: 0 | K46: 0 | L46: 0 | M46: 0 | N46: 0 | O46: =SUM(C46:N46) -> 0 | Q46: =SUM(C46:E46) -> 0
A47: 6 | B47: CILEGON | C47: 0 | D47: 0 | E47: 0 | F47: 0 | G47: 0 | H47: 0 | I47: 0 | J47: 0 | K47: 0 | L47: 0 | M47: 0 | N47: 0 | O47: =SUM(C47:N47) -> 0 | Q47: =SUM(C47:E47) -> 0
A48: 7 | B48: JOMBANG | C48: 0 | D48: 0 | E48: 0 | F48: 0 | G48: 0 | H48: 0 | I48: 0 | J48: 0 | K48: 0 | L48: 0 | M48: 0 | N48: 0 | O48: =SUM(C48:N48) -> 0 | Q48: =SUM(C48:E48) -> 0
A49: 8 | B49: CIBEBER | C49: 0 | D49: 0 | E49: 0 | F49: 0 | G49: 0 | H49: 0 | I49: 0 | J49: 0 | K49: 0 | L49: 0 | M49: 0 | N49: 0 | O49: =SUM(C49:N49) -> 0 | P49: 15 | Q49: =SUM(C49:E49) -> 0
A50: JUMLAH | C50: =SUM(C42:C49) -> 0 | D50: =SUM(D42:D49) -> 0 | E50: =SUM(E42:E49) -> 0 | F50: =SUM(F42:F49) -> 0 | G50: =SUM(G42:G49) -> 0 | H50: =SUM(H42:H49) -> 0 | I50: =SUM(I42:I49) -> 0 | J50: =SUM(J42:J49) -> 0 | ... P50: =SUM(P42:P49) -> 15
A68: DATA PRODUKSI KEDELAI PER BULAN
A69: KOTA CILEGON TAHUN 2025
O71: (Ton)
A72: No | B72: Kecamatan | C72: Bulan | O72: Jumlah
C73: Jan | D73: Feb | E73: Maret | F73: Apr | G73: Mei | H73: Juni | I73: Juli | J73: Agst | K73: Sept | L73: Okt | M73: Nov | N73: Des
A74: 1 | B74: 2 | C74: 3 | D74: 4 | E74: 5 | F74: 6 | G74: 7 | H74: 8 | I74: 9 | J74: 10 | K74: 11 | L74: 12 | M74: 13 | N74: 14 | O74: 15
A75: 1 | B75: CIWANDAN | C75: 0 | D75: 0 | E75: 0 | F75: 0 | G75: 0 | H75: 0 | I75: 0 | J75: 0 | K75: 0 | L75: 0 | M75: 0 | N75: 0 | O75: =SUM(C75:N75) -> 0 | Q75: =SUM(C75:E75) -> 0
A76: 2 | B76: CITANGKIL | C76: 0 | D76: 0 | E76: 0 | F76: 0 | G76: 0 | H76: 0 | I76: 0 | J76: 0 | K76: 0 | L76: 0 | M76: 0 | N76: 0 | O76: =SUM(C76:N76) -> 0 | Q76: =SUM(C76:E76) -> 0
A77: 3 | B77: PULOMERAK | C77: 0 | D77: 0 | E77: 0 | F77: 0 | G77: 0 | H77: 0 | I77: 0 | J77: 0 | K77: 0 | L77: 0 | M77: 0 | N77: 0 | O77: =SUM(C77:N77) -> 0 | Q77: =SUM(C77:E77) -> 0
A78: 4 | B78: PURWAKARTA | C78: 0 | D78: 0 | E78: 0 | F78: 0 | G78: 0 | H78: 0 | I78: 0 | J78: 0 | K78: 0 | L78: 0 | M78: 0 | N78: 0 | O78: =SUM(C78:N78) -> 0 | Q78: =SUM(C78:E78) -> 0
...

Sheet kc tanah
A2: DATA LUAS TANAM KACANG TANAH PER BULAN
A3: KOTA CILEGON TAHUN 2025
O5: (Ha)
A6: No | B6: Kecamatan | C6: Bulan | O6: Jumlah
C7: Jan | D7: Feb | E7: Maret | F7: Apr | G7: Mei | H7: Juni | I7: Juli | J7: Agst | K7: Sept | L7: Okt | M7: Nov | N7: Des
A8: 1 | B8: 2 | C8: 3 | D8: 4 | E8: 5 | F8: 6 | G8: 7 | H8: 8 | I8: 9 | J8: 10 | K8: 11 | L8: 12 | M8: 13 | N8: 14 | O8: 15
A9: 1 | B9: CIWANDAN | C9: 0 | D9: 0 | E9: 0 | F9: 10 | G9: - | H9: - | I9: - | J9: 0 | K9: 0 | L9: 0 | M9: 0 | N9: 0 | O9: =SUM(C9:N9) -> 10 | P9: =SUM(I9:K9) -> 0 | Q9: =SUM(F9:K9) -> 10
A10: 2 | B10: CITANGKIL | C10: 0 | D10: 25 | E10: 125 | F10: 0 | G10: 0 | H10: 10 | I10: 0 | J10: 1 | K10: 0 | L10: 30 | M10: 70 | N10: 25 | O10: =SUM(C10:N10) -> 286 | P10: =SUM(I10:K10) -> 1 | Q10: =SUM(F10:K10) -> 11
A11: 3 | B11: PULOMERAK | C11: 0 | D11: 0 | E11: 0 | F11: 4 | G11: - | H11: - | I11: 0 | K11: 0 | L11: 50 | M11: 0 | N11: 0 | O11: =SUM(C11:N11) -> 54 | P11: =SUM(I11:K11) -> 0 | Q11: =SUM(F11:K11) -> 4
A12: 4 | B12: PURWAKARTA | C12: 0 | D12: 0 | E12: 0 | F12: 10 | G12: 10 | H12: 0 | I12: 0 | J12: - | K12: 0 | L12: 0 | M12: 0 | N12: 1 | O12: =SUM(C12:N12) -> 21 | P12: =SUM(I12:K12) -> 0 | Q12: =SUM(F12:K12) -> 20
A13: 5 | B13: GROGOL | C13: 0 | D13: 0 | E13: 0 | F13: 15 | G13: 0 | H13: 5 | I13: 0 | J13: - | K13: 0 | L13: 0 | M13: 0 | N13: 235 | O13: =SUM(C13:N13) -> 255 | P13: =SUM(I13:K13) -> 0 | Q13: =SUM(F13:K13) -> 20
A14: 6 | B14: CILEGON | C14: 0 | D14: 0 | E14: 0 | F14: 0 | G14: 14 | H14: 5 | I14: 0 | J14: 4 | K14: 0 | L14: 0 | M14: 5 | N14: 0 | O14: =SUM(C14:N14) -> 28 | P14: =SUM(I14:K14) -> 4 | Q14: =SUM(F14:K14) -> 23
A15: 7 | B15: JOMBANG | C15: 0 | D15: 0 | E15: 0 | F15: 0 | G15: - | H15: - | I15: 0 | J15: - | K15: 0 | L15: 0 | M15: 2 | N15: 0 | O15: =SUM(C15:N15) -> 2 | P15: =SUM(I15:K15) -> 0 | Q15: =SUM(F15:K15) -> 0
A16: 8 | B16: CIBEBER | C16: 0 | D16: 15 | E16: 0 | F16: 10 | G16: 0 | H16: 25 | I16: 0 | J16: 30 | K16: 1 | L16: 45 | M16: 15 | N16: 0 | O16: =SUM(C16:N16) -> 141 | P16: =SUM(I16:K16) -> 31 | Q16: =SUM(F16:K16) -> 66
A17: JUMLAH | C17: =SUM(C9:C16) -> 0 | D17: =SUM(D9:D16) -> 40 | E17: =SUM(E9:E16) -> 125 | F17: =SUM(F9:F16) -> 49 | G17: =SUM(G9:G16) -> 24 | H17: =SUM(H9:H16) -> 45 | I17: =SUM(I9:I16) -> 0 | J17: =SUM(J9:J16) -> 35 | ... P17: =SUM(P9:P16) -> 36 | Q17: =SUM(I9:K9) -> 0
A34: DATA LUAS PANEN KACANG TANAH PER BULAN
A35: KOTA CILEGON TAHUN 2025
O37: (Ha)
A38: No | B38: Kecamatan | C38: Bulan | O38: Jumlah
C39: Jan | D39: Feb | E39: Maret | F39: Apr | G39: Mei | H39: Juni | I39: Juli | J39: Agst | K39: Sept | L39: Okt | M39: Nov | N39: Des
A40: 1 | B40: 2 | C40: 3 | D40: 4 | E40: 5 | F40: 6 | G40: 7 | H40: 8 | I40: 9 | J40: 10 | K40: 11 | L40: 12 | M40: 13 | N40: 14 | O40: 15
A41: 1 | B41: CIWANDAN | C41: 0 | D41: 10 | E41: 0 | F41: 0 | G41: 0 | H41: - | I41: - | J41: - | K41: 0 | L41: 0 | M41: 0 | O41: =SUM(C41:N41) -> 10 | Q41: =SUM(F41:K41) -> 0
A42: 2 | B42: CITANGKIL | C42: 6 | D42: 164 | E42: 0 | F42: 0 | G42: 25 | H42: 125 | I42: 0 | J42: 0 | K42: 10 | L42: 0 | M42: 1 | N42: 1 | O42: =SUM(C42:N42) -> 332 | Q42: =SUM(F42:K42) -> 160
A43: 3 | B43: PULOMERAK | C43: 15 | D43: 0 | E43: 0 | F43: 0 | G43: 0 | H43: 0 | I43: 0 | J43: 4 | K43: 0 | L43: 0 | M43: 0 | O43: =SUM(C43:N43) -> 19 | Q43: =SUM(F43:K43) -> 4
A44: 4 | B44: PURWAKARTA | C44: 10 | D44: 15 | E44: 0 | F44: 15 | G44: 0 | H44: 10 | I44: - | J44: - | K44: 10 | L44: 0 | M44: 0 | O44: =SUM(C44:N44) -> 60 | Q44: =SUM(F44:K44) -> 35
A45: 5 | B45: GROGOL | C45: 0 | D45: 0 | E45: 0 | F45: 0 | G45: 0 | H45: 0 | I45: 0 | J45: 0 | K45: 5 | L45: 0 | M45: 0 | O45: =SUM(C45:N45) -> 5 | Q45: =SUM(F45:K45) -> 5
A46: 6 | B46: CILEGON | C46: 0 | D46: 23 | E46: 0 | F46: 0 | G46: 0 | H46: 0 | I46: 0 | J46: 0 | K46: 5 | L46: 0 | M46: 4 | O46: =SUM(C46:N46) -> 32 | Q46: =SUM(F46:K46) -> 5
A47: 7 | B47: JOMBANG | C47: 0 | D47: 0 | E47: 0 | F47: 0 | G47: 0 | H47: - | I47: - | J47: - | K47: 0 | L47: 0 | M47: 0 | O47: =SUM(C47:N47) -> 0 | Q47: =SUM(F47:K47) -> 0
A48: 8 | B48: CIBEBER | C48: 49 | D48: 25 | E48: 0 | F48: 0 | G48: 15 | H48: 0 | I48: 0 | J48: 25 | K48: 0 | L48: 25 | M48: 30 | N48: 45 | O48: =SUM(C48:N48) -> 214 | Q48: =SUM(F48:K48) -> 40
A49: JUMLAH | C49: =SUM(C41:C48) -> 80 | D49: =SUM(D41:D48) -> 237 | E49: =SUM(E41:E48) -> 0 | F49: =SUM(F41:F48) -> 15 | G49: =SUM(G41:G48) -> 40 | H49: =SUM(H41:H48) -> 135 | I49: =SUM(I41:I48) -> 0 | J49: =SUM(J41:J48) -> 29 | ... O49: =SUM(O41:O48) -> 672 | Q49: =SUM(F49:K49) -> 249
A67: DATA PRODUKSI KACANG TANAH PER BULAN
A68: KOTA CILEGON TAHUN 2025
O70: (Ton)
A71: No | B71: Kecamatan | C71: Bulan | O71: Jumlah
C72: Jan | D72: Feb | E72: Maret | F72: Apr | G72: Mei | H72: Juni | I72: Juli | J72: Agst | K72: Sept | L72: Okt | M72: Nov | N72: Des
A73: 1 | B73: 2 | C73: 3 | D73: 4 | E73: 5 | F73: 6 | G73: 7 | H73: 8 | I73: 9 | J73: 10 | K73: 11 | L73: 12 | M73: 13 | N73: 14 | O73: 15
A74: 1 | B74: CIWANDAN | C74: 0 | D74: 12 | E74: 0 | F74: 0 | G74: 0 | H74: - | I74: - | J74: - | K74: 0 | L74: 0 | M74: 0 | O74: =SUM(C74:N74) -> 12 | Q74: =SUM(F74:K74) -> 0
A75: 2 | B75: CITANGKIL | C75: 7.2 | D75: 196.8 | E75: 0 | F75: 0 | G75: 30 | H75: 150 | I75: 0 | J75: 0 | K75: 120 | L75: 0 | M75: 12 | N75: 12 | O75: =SUM(C75:N75) -> 528 | Q75: =SUM(F75:K75) -> 300
A76: 3 | B76: PULOMERAK | C76: 18 | D76: 0 | E76: 0 | F76: 0 | G76: 0 | H76: 0 | I76: 0 | J76: 4.8 | K76: 0 | L76: 0 | M76: 0 | O76: =SUM(C76:N76) -> 22.8 | Q76: =SUM(F76:K76) -> 4.8
A77: 4 | B77: PURWAKARTA | C77: 12 | D77: 18 | E77: 0 | F77: 18 | G77: 0 | H77: 12 | I77: - | J77: 0 | K77: 12 | L77: 0 | M77: 2 | O77: =SUM(C77:N77) -> 74 | Q77: =SUM(F77:K77) -> 42
...

Sheet ubi kayu
A2: DATA LUAS TANAM UBI KAYU/SINGKONG
A3: KOTA CILEGON TAHUN 2025
O5: (Ha)
A6: No | B6: Kecamatan | C6: Bulan | O6: Jumlah
C7: Jan | D7: Feb | E7: Maret | F7: Apr | G7: Mei | H7: Juni | I7: Juli | J7: Agst | K7: Sept | L7: Okt | M7: Nov | N7: Des
A8: 1 | B8: 2 | C8: 3 | D8: 4 | E8: 5 | F8: 6 | G8: 7 | H8: 8 | I8: 9 | J8: 10 | K8: 11 | L8: 12 | M8: 13 | N8: 14 | O8: 15
A9: 1 | B9: CIWANDAN | C9: 1 | D9: 0 | E9: 0 | F9: 0 | G9: 1 | H9: 0 | I9: 0 | J9: - | K9: 1 | L9: 0 | M9: 0 | O9: =SUM(C9:N9) -> 3
A10: 2 | B10: CITANGKIL | C10: 0 | D10: 2 | E10: 0 | F10: 0 | G10: 1 | H10: 0 | I10: 0 | J10: 0 | K10: 1 | L10: 0 | M10: 0.2 | N10: 0 | O10: =SUM(C10:N10) -> 4.2
A11: 3 | B11: PULOMERAK | C11: 0 | D11: 0 | E11: 0 | F11: 4 | G11: 0 | H11: - | I11: 0 | J11: 0 | K11: 0 | L11: 0 | M11: 0 | N11: 0 | O11: =SUM(C11:N11) -> 4
A12: 4 | B12: PURWAKARTA | C12: 2 | D12: 0 | E12: 0 | F12: 0 | G12: 0 | H12: - | I12: - | J12: - | K12: 0 | L12: 0 | M12: 3 | N12: 3 | O12: =SUM(C12:N12) -> 8
A13: 5 | B13: GROGOL | C13: 0 | D13: 0 | E13: 0 | F13: 0 | G13: - | H13: - | I13: - | J13: - | K13: 0 | L13: 0 | M13: 0.1 | N13: 2 | O13: =SUM(C13:N13) -> 2.1
A14: 6 | B14: CILEGON | C14: 0 | D14: 0.3 | E14: 0 | F14: - | G14: 0.1 | H14: - | I14: 0 | J14: - | K14: 0 | L14: 0.2 | M14: 0 | N14: 0 | O14: =SUM(C14:N14) -> 0.5
A15: 7 | B15: JOMBANG | C15: 0 | D15: 0 | E15: 0 | F15: - | G15: - | H15: - | I15: - | J15: - | K15: 1 | L15: 0 | M15: 0 | N15: 0 | O15: =SUM(C15:N15) -> 1
A16: 8 | B16: CIBEBER | C16: 0 | D16: 0 | E16: 0 | F16: 0 | G16: 0 | H16: 1 | I16: 0 | J16: 1 | K16: 1 | L16: 2 | M16: 2 | N16: 0 | O16: =SUM(C16:N16) -> 7
A17: JUMLAH | C17: =SUM(C9:C16) -> 3 | D17: =SUM(D9:D16) -> 2.3 | E17: =SUM(E9:E16) -> 0 | F17: =SUM(F9:F16) -> 4 | G17: =SUM(G9:G16) -> 2 | H17: =SUM(H9:H16) -> 1 | I17: =SUM(I9:I16) -> 0 | J17: =SUM(J9:J16) -> 1 | ... O17: =SUM(O9:O16) -> 29.8
A34: DATA LUAS PANEN UBI KAYU PER BULAN
A35: KOTA CILEGON TAHUN 2025
O37: (Ha)
A38: No | B38: Kecamatan | C38: Bulan | O38: Jumlah
C39: Jan | D39: Feb | E39: Maret | F39: Apr | G39: Mei | H39: Juni | I39: Juli | J39: Agst | K39: Sept | L39: Okt | M39: Nov | N39: Des
A40: 1 | B40: 2 | C40: 3 | D40: 4 | E40: 5 | F40: 6 | G40: 7 | H40: 8 | I40: 9 | J40: 10 | K40: 11 | L40: 12 | M40: 13 | N40: 14 | O40: 15
A41: 1 | B41: CIWANDAN | C41: 1 | D41: 0 | E41: 0 | F41: 0 | G41: 0 | H41: - | I41: 0 | J41: 0 | K41: 0 | L41: 0 | M41: 0 | N41: 0 | O41: =SUM(C41:N41) -> 1
A42: 2 | B42: CITANGKIL | C42: 0 | D42: 1 | E42: 0 | F42: 1 | G42: 1 | H42: 0 | I42: - | J42: 0 | K42: 0 | L42: 0 | M42: 0 | N42: 1 | O42: =SUM(C42:N42) -> 4
A43: 3 | B43: PULOMERAK | C43: 0 | D43: 0 | E43: 0 | F43: 0 | G43: 3 | H43: 3 | I43: 0 | J43: 2 | K43: 0 | L43: 0 | M43: 0 | O43: =SUM(C43:N43) -> 8
A44: 4 | B44: PURWAKARTA | C44: 1 | D44: 0 | E44: 0 | F44: 0 | G44: 0 | H44: - | I44: 0 | J44: - | K44: 0 | L44: 0 | M44: 0 | O44: =SUM(C44:N44) -> 1
A45: 5 | B45: GROGOL | C45: 0 | D45: 0 | E45: 0 | F45: 0 | G45: - | H45: 0 | I45: 0 | J45: 4 | K45: 0 | L45: 0 | M45: 0 | N45: 0 | O45: =SUM(C45:N45) -> 4
A46: 6 | B46: CILEGON | C46: 0 | D46: 0 | E46: 0 | F46: 0.2 | G46: - | H46: - | I46: 0 | J46: 0 | K46: 0 | L46: 0.1 | M46: 0 | O46: =SUM(C46:N46) -> 0.3
A47: 7 | B47: JOMBANG | C47: 0 | D47: 0 | E47: 0 | F47: - | G47: - | H47: - | I47: - | J47: - | K47: 0 | L47: 0 | M47: 0 | O47: =SUM(C47:N47) -> 0
A48: 8 | B48: CIBEBER | C48: 85 | D48: 22 | E48: 0 | F48: 12 | G48: 8 | H48: 5 | I48: 0 | J48: 10 | K48: 2 | L48: 1 | M48: 3 | N48: 1 | O48: =SUM(C48:N48) -> 149
A49: JUMLAH | C49: =SUM(C41:C48) -> 87 | D49: =SUM(D41:D48) -> 23 | E49: =SUM(E41:E48) -> 0 | F49: =SUM(F41:F48) -> 13.2 | G49: =SUM(G41:G48) -> 12 | H49: =SUM(H41:H48) -> 8 | I49: =SUM(I41:I48) -> 0 | J49: =SUM(J41:J48) -> 16 | ... O49: =SUM(O41:O48) -> 167.3
A68: DATA PRODUKSI UBI KAYU PER BULAN
A69: KOTA CILEGON TAHUN 2025
O71: (Ton)
A72: No | B72: Kecamatan | C72: Bulan | O72: Jumlah
C73: Jan | D73: Feb | E73: Maret | F73: Apr | G73: Mei | H73: Juni | I73: Juli | J73: Agst | K73: Sept | L73: Okt | M73: Nov | N73: Des
A74: 1 | B74: 2 | C74: 3 | D74: 4 | E74: 5 | F74: 6 | G74: 7 | H74: 8 | I74: 9 | J74: 10 | K74: 11 | L74: 12 | M74: 13 | N74: 14 | O74: 15
A75: 1 | B75: CIWANDAN | C75: 12 | D75: 0 | E75: 0 | F75: 0 | G75: 0 | H75: 0 | I75: 0 | J75: 0 | K75: 0 | L75: 0 | M75: 0 | N75: 0 | O75: =SUM(C75:N75) -> 12
A76: 2 | B76: CITANGKIL | C76: 0 | D76: 12 | E76: 0 | F76: 12 | G76: 12 | H76: 0 | I76: 0 | J76: 0 | K76: 0 | L76: 0 | M76: 0 | N76: 12 | O76: =SUM(C76:N76) -> 48
A77: 3 | B77: PULOMERAK | C77: 0 | D77: 0 | E77: 0 | F77: 0 | G77: 36 | H77: 36 | I77: 0 | J77: 24 | K77: 0 | L77: 0 | M77: 0 | O77: =SUM(C77:N77) -> 96
A78: 4 | B78: PURWAKARTA | C78: 12 | D78: 0 | E78: 0 | F78: 0 | G78: 0 | H78: 0 | I78: 0 | J78: - | K78: 0 | L78: 0 | M78: 0 | O78: =SUM(C78:N78) -> 12
...

Sheet ubi jalar
A2: DATA LUAS TANAM UBI JALAR PER BULAN
A3: KOTA CILEGON TAHUN 2025
O5: (Ha)
A6: No | B6: Kecamatan | C6: Bulan | O6: Jumlah
C7: Jan | D7: Feb | E7: Maret | F7: Apr | G7: Mei | H7: Juni | I7: Juli | J7: Agst | K7: Sept | L7: Okt | M7: Nov | N7: Des
A8: 1 | B8: 2 | C8: 3 | D8: 4 | E8: 5 | F8: 6 | G8: 7 | H8: 8 | I8: 9 | J8: 10 | K8: 11 | L8: 12 | M8: 13 | N8: 14 | O8: 15
A9: 1 | B9: CIWANDAN | C9: 0 | D9: 0 | E9: 0 | F9: 0 | G9: 0 | H9: 0 | I9: 0 | J9: - | K9: 0 | L9: 0 | M9: 0 | O9: =SUM(C9:N9) -> 0
A10: 2 | B10: CITANGKIL | C10: 0 | D10: 0.1 | E10: 0 | F10: 0 | G10: 0.15 | H10: - | I10: 0 | J10: 0.2 | K10: 0 | L10: 0 | M10: 0 | N10: 0.1 | O10: =SUM(C10:N10) -> 0.4
A11: 3 | B11: PULOMERAK | C11: 0 | D11: 0 | E11: 0 | F11: 0 | G11: 0 | H11: - | I11: 0 | J11: 0 | K11: 0 | L11: 0 | M11: 0 | N11: 0 | O11: =SUM(C11:N11) -> 0
A12: 4 | B12: PURWAKARTA | C12: 0 | D12: 0.5 | E12: 0 | F12: 0 | G12: - | H12: 0 | I12: - | J12: 0 | K12: 0 | L12: 0 | M12: 0 | N12: 0.5 | O12: =SUM(C12:N12) -> 1
A13: 5 | B13: GROGOL | C13: 0 | D13: 0 | E13: 0 | F13: 0 | G13: - | H13: 1 | I13: - | J13: - | K13: 0 | L13: 0 | M13: 0 | N13: 2 | O13: =SUM(C13:N13) -> 3
A14: 6 | B14: CILEGON | C14: 0 | D14: 0.1 | E14: 0 | F14: 0.2 | G14: 0.3 | H14: 0.1 | I14: 0 | J14: - | K14: 0 | L14: 0.3 | M14: 0 | N14: 0.2 | O14: =SUM(C14:N14) -> 1.2
A15: 7 | B15: JOMBANG | C15: 0 | D15: 0 | E15: 0 | F15: 0 | G15: - | H15: - | I15: - | J15: - | K15: 1 | L15: 0 | M15: 1 | N15: 1 | O15: =SUM(C15:N15) -> 3
A16: 8 | B16: CIBEBER | C16: 0 | D16: 0 | E16: 0 | F16: 1 | G16: 0 | H16: 0 | I16: 0 | J16: 1 | K16: 0 | L16: 1 | M16: 0 | N16: 0 | O16: =SUM(C16:N16) -> 3
A17: JUMLAH | C17: =SUM(C9:C16) -> 0 | D17: =SUM(D9:D16) -> 0.7 | E17: =SUM(E9:E16) -> 0 | F17: =SUM(F9:F16) -> 1.2 | G17: =SUM(G9:G16) -> 0.3 | H17: =SUM(H9:H16) -> 1.1 | I17: =SUM(I9:I16) -> 0 | J17: =SUM(J9:J16) -> 1.2 | ... O17: =SUM(O9:O16) -> 11.6
A35: DATA LUAS PANEN UBI JALAR PER BULAN
A36: KOTA CILEGON TAHUN 2025
O38: (Ha)
A39: No | B39: Kecamatan | C39: Bulan | O39: Jumlah
C40: Jan | D40: Feb | E40: Maret | F40: Apr | G40: Mei | H40: Juni | I40: Juli | J40: Agst | K40: Sept | L40: Okt | M40: Nov | N40: Des
A41: 1 | B41: 2 | C41: 3 | D41: 4 | E41: 5 | F41: 6 | G41: 7 | H41: 8 | I41: 9 | J41: 10 | K41: 11 | L41: 12 | M41: 13 | N41: 14 | O41: 15
A42: 1 | B42: CIWANDAN | C42: 0 | D42: 0 | E42: 0 | G42: - | H42: 0 | I42: 0 | J42: 0 | K42: 0 | L42: 0 | M42: 0 | O42: =SUM(C42:N42) -> 0
A43: 2 | B43: CITANGKIL | C43: 0 | D43: 0 | E43: 0 | F43: 0.15 | G43: 0.1 | H43: - | I43: 0 | J43: 0.1 | K43: 0.15 | L43: 0 | M43: 0 | N43: 0.2 | O43: =SUM(C43:N43) -> 0.6
A44: 3 | B44: PULOMERAK | C44: 0 | D44: 0 | E44: 0 | F44: 0 | G44: - | H44: - | I44: 0 | J44: 0 | K44: 0 | L44: 0 | M44: 0 | O44: =SUM(C44:N44) -> 0
A45: 4 | B45: PURWAKARTA | C45: 1 | D45: 0 | E45: 0 | G45: 0 | H45: 0 | I45: - | J45: 0 | K45: 0 | L45: 0 | M45: 0 | O45: =SUM(C45:N45) -> 1
A46: 5 | B46: GROGOL | C46: 0 | D46: 0 | E46: 441 | G46: - | H46: - | I46: 0 | J46: 0 | K46: 0 | L46: 0 | M46: 0 | O46: =SUM(C46:N46) -> 441
A47: 6 | B47: CILEGON | C47: 0 | D47: 0.2 | E47: 0 | F47: 0.3 | G47: 0.1 | H47: 0 | I47: 0 | J47: 0.2 | K47: 0 | L47: 0.2 | M47: 0 | N47: 0.2 | O47: =SUM(C47:N47) -> 1.2
A48: 7 | B48: JOMBANG | C48: 0 | D48: 0 | E48: 0 | G48: - | H48: - | I48: - | J48: - | K48: 0 | L48: 0 | M48: 0 | O48: =SUM(C48:N48) -> 0
A49: 8 | B49: CIBEBER | C49: 0 | D49: 0 | E49: 0 | F49: 0 | G49: 0 | H49: 0 | I49: 0 | J49: 1 | K49: 0 | L49: 0 | M49: 1 | O49: =SUM(C49:N49) -> 2
A50: JUMLAH | C50: =SUM(C42:C49) -> 1 | D50: =SUM(D42:D49) -> 0.2 | E50: =SUM(E42:E49) -> 441 | F50: =SUM(F42:F49) -> 0.45 | G50: =SUM(G42:G49) -> 0.1 | H50: =SUM(H42:H49) -> 0 | I50: =SUM(I42:I49) -> 0 | J50: =SUM(J42:J49) -> 1.3 | ... O50: =SUM(O42:O49) -> 445.8
A68: DATA PRODUKSI UBI JALAR PER BULAN
A69: KOTA CILEGON TAHUN 2025
O71: (Ton)
A72: No | B72: Kecamatan | C72: Bulan | O72: Jumlah
C73: Jan | D73: Feb | E73: Maret | F73: Apr | G73: Mei | H73: Juni | I73: Juli | J73: Agst | K73: Sept | L73: Okt | M73: Nov | N73: Des
A74: 1 | B74: 2 | C74: 3 | D74: 4 | E74: 5 | F74: 6 | G74: 7 | H74: 8 | I74: 9 | J74: 10 | K74: 11 | L74: 12 | M74: 13 | N74: 14 | O74: 15
A75: 1 | B75: CIWANDAN | C75: 0 | D75: 0 | E75: 0 | F75: 0 | G75: - | H75: 0 | I75: 0 | J75: 0 | K75: 0 | L75: 0 | M75: 0 | O75: =SUM(C75:N75) -> 0
A76: 2 | B76: CITANGKIL | C76: 0 | D76: 0 | E76: 0 | F76: 1.5 | G76: 1.05 | H76: - | I76: 0 | J76: 1.5 | K76: 2.1 | L76: 0 | M76: 0 | N76: 2.1 | O76: =SUM(C76:N76) -> 8.25
A77: 3 | B77: PULOMERAK | C77: 0 | D77: 0 | E77: 0 | F77: 0 | G77: - | H77: - | I77: 0 | J77: 0 | K77: 0 | L77: 0 | M77: 0 | O77: =SUM(C77:N77) -> 0
A78: 4 | B78: PURWAKARTA | C78: 10.5 | D78: 0 | E78: 0 | F78: - | G78: 0 | H78: - | I78: - | J78: 0 | K78: 0 | L78: 0 | M78: 2 | O78: =SUM(C78:N78) -> 12.5
...

Sheet kc ijo
A2: DATA LUAS TANAM KACANG HIJAU PER BULAN
A3: KOTA CILEGON TAHUN 2025
O5: (Ha)
A6: No | B6: Kecamatan | C6: Bulan | O6: Jumlah
C7: Jan | D7: Feb | E7: Maret | F7: Apr | G7: Mei | H7: Juni | I7: Juli | J7: Agst | K7: Sept | L7: Okt | M7: Nov | N7: Des
A8: 1 | B8: 2 | C8: 3 | D8: 4 | E8: 5 | F8: 6 | G8: 7 | H8: 8 | I8: 9 | J8: 10 | K8: 11 | L8: 12 | M8: 13 | N8: 14 | O8: 15
A9: 1 | B9: CIWANDAN | C9: 0 | D9: 0 | E9: 0 | F9: - | G9: - | H9: - | I9: - | J9: - | K9: 0 | L9: 0 | M9: 0 | O9: =SUM(C9:N9) -> 0
A10: 2 | B10: CITANGKIL | C10: 0 | D10: 0 | E10: 0 | F10: - | G10: - | H10: - | I10: - | J10: - | K10: 0 | L10: 0 | M10: 0 | O10: =SUM(C10:N10) -> 0
A11: 3 | B11: PULOMERAK | C11: 0 | D11: 0 | E11: 0 | F11: - | G11: - | H11: - | I11: - | J11: - | K11: 0 | L11: 0 | M11: 0 | O11: =SUM(C11:N11) -> 0
A12: 4 | B12: PURWAKARTA | C12: 0 | D12: 0 | E12: 0 | F12: 0 | G12: - | H12: 0 | I12: - | J12: 0 | K12: 0 | L12: 0 | M12: 0 | O12: =SUM(C12:N12) -> 0
A13: 5 | B13: GROGOL | C13: 0 | D13: 0 | E13: 0 | F13: 0 | G13: 0 | H13: - | I13: - | J13: - | K13: 0 | L13: 0 | M13: 0 | O13: =SUM(C13:N13) -> 0
A14: 6 | B14: CILEGON | C14: 0 | D14: 0 | E14: 0 | F14: - | G14: - | H14: - | I14: - | J14: - | K14: 0 | L14: 0 | M14: 0 | O14: =SUM(C14:N14) -> 0
A15: 7 | B15: JOMBANG | C15: 0 | D15: 0 | E15: 0 | F15: - | G15: - | H15: - | I15: - | J15: - | K15: 0 | L15: 0 | M15: 0 | O15: =SUM(C15:N15) -> 0
A16: 8 | B16: CIBEBER | C16: 0 | D16: 0 | E16: 0 | F16: 1 | G16: 0 | H16: 0 | I16: - | J16: 1 | K16: 0 | L16: 1 | M16: 0 | O16: =SUM(C16:N16) -> 3
A17: JUMLAH | C17: =SUM(C9:C16) -> 0 | D17: =SUM(D9:D16) -> 0 | E17: =SUM(E9:E16) -> 0 | F17: =SUM(F9:F16) -> 1 | G17: =SUM(G9:G16) -> 0 | H17: =SUM(H9:H16) -> 0 | I17: =SUM(I9:I16) -> 0 | J17: =SUM(J9:J16) -> 1 | ... O17: =SUM(O9:O16) -> 3
A35: DATA LUAS PANEN KACANG HIJAU PER BULAN
A36: KOTA CILEGON TAHUN 2025
O38: (Ha)
A39: No | B39: Kecamatan | C39: Bulan | O39: Jumlah
C40: Jan | D40: Feb | E40: Maret | F40: Apr | G40: Mei | H40: Juni | I40: Juli | J40: Agst | K40: Sept | L40: Okt | M40: Nov | N40: Des
A41: 1 | B41: 2 | C41: 3 | D41: 4 | E41: 5 | F41: 6 | G41: 7 | H41: 8 | I41: 9 | J41: 10 | K41: 11 | L41: 12 | M41: 13 | N41: 14 | O41: 15
A42: 1 | B42: CIWANDAN | C42: 0 | D42: 0 | E42: 0 | F42: 0 | G42: - | H42: - | I42: 0 | J42: - | K42: 0 | L42: 0 | M42: 0 | O42: =SUM(C42:N42) -> 0
A43: 2 | B43: CITANGKIL | C43: 0 | D43: 0 | E43: 0 | F43: - | G43: - | H43: - | I43: - | J43: - | K43: 0 | L43: 0 | M43: 0 | O43: =SUM(C43:N43) -> 0
A44: 3 | B44: PULOMERAK | C44: 0 | D44: 0 | E44: 0 | F44: - | G44: - | H44: - | I44: - | J44: - | K44: 0 | L44: 0 | M44: 0 | O44: =SUM(C44:N44) -> 0
A45: 4 | B45: PURWAKARTA | C45: 0 | D45: 0 | E45: 0 | F45: 0 | G45: 0 | H45: 0 | I45: 0 | J45: 0 | K45: 0 | L45: 0 | M45: 0 | O45: =SUM(C45:N45) -> 0
A46: 5 | B46: GROGOL | C46: 0 | D46: 0 | E46: 0 | F46: - | G46: - | H46: - | I46: 0 | J46: - | K46: 0 | L46: 0 | M46: 0 | O46: =SUM(C46:N46) -> 0
A47: 6 | B47: CILEGON | C47: 0 | D47: 0 | E47: 0 | F47: - | G47: - | H47: - | I47: - | J47: - | K47: 0 | L47: 0 | M47: 0 | N47: 0 | O47: =SUM(C47:N47) -> 0
A48: 7 | B48: JOMBANG | C48: 0 | D48: 0 | E48: 0 | F48: - | G48: - | H48: - | I48: - | J48: - | K48: 0 | L48: 0 | M48: 0 | O48: =SUM(C48:N48) -> 0
A49: 8 | B49: CIBEBER | C49: 0 | D49: 0 | E49: 0 | F49: 0 | G49: 0 | H49: 0 | I49: - | J49: 1 | K49: 0 | L49: 0 | M49: 1 | O49: =SUM(C49:N49) -> 2
A50: JUMLAH | C50: =SUM(C42:C49) -> 0 | D50: =SUM(D42:D49) -> 0 | E50: =SUM(E42:E49) -> 0 | F50: =SUM(F42:F49) -> 0 | G50: =SUM(G42:G49) -> 0 | H50: =SUM(H42:H49) -> 0 | I50: =SUM(I42:I49) -> 0 | J50: =SUM(J42:J49) -> 1 | ... O50: =SUM(O42:O49) -> 2
A68: DATA PRODUKSI KACANG HIJAU PER BULAN
A69: KOTA CILEGON TAHUN 2025
O71: (Ton)
A72: No | B72: Kecamatan | C72: Bulan | O72: Jumlah
C73: Jan | D73: Feb | E73: Maret | F73: Apr | G73: Mei | H73: Juni | I73: Juli | J73: Agst | K73: Sept | L73: Okt | M73: Nov | N73: Des
A74: 1 | B74: 2 | C74: 3 | D74: 4 | E74: 5 | F74: 6 | G74: 7 | H74: 8 | I74: 9 | J74: 10 | K74: 11 | L74: 12 | M74: 13 | N74: 14 | O74: 15
A75: 1 | B75: CIWANDAN | C75: 0 | D75: 0 | E75: 0 | F75: 0 | G75: - | H75: - | I75: 0 | J75: - | K75: 0 | L75: 0 | M75: 0 | O75: =SUM(C75:N75) -> 0
A76: 2 | B76: CITANGKIL | C76: 0 | D76: 0 | E76: 0 | F76: - | G76: - | H76: - | I76: - | J76: - | K76: 0 | L76: 0 | M76: 0 | O76: =SUM(C76:N76) -> 0
A77: 3 | B77: PULOMERAK | C77: 0 | D77: 0 | E77: 0 | F77: - | G77: - | H77: - | I77: - | J77: - | K77: 0 | L77: 0 | M77: 0 | O77: =SUM(C77:N77) -> 0
A78: 4 | B78: PURWAKARTA | C78: 0 | D78: 0 | E78: 0 | F78: 0 | G78: 0 | H78: 0 | I78: 0 | J78: 0 | K78: 0 | L78: 0 | M78: 0 | O78: =SUM(C78:N78) -> 0
...

Sheet talas
A2: DATA LUAS TANAM TALAS PER BULAN
A3: KOTA CILEGON TAHUN 2025
O5: (Ha)
A6: No | B6: Kecamatan | C6: Bulan | O6: Jumlah
C7: Jan | D7: Feb | E7: Maret | F7: Apr | G7: Mei | H7: Juni | I7: Juli | J7: Agst | K7: Sept | L7: Okt | M7: Nov | N7: Des
A8: 1 | B8: 2 | C8: 3 | D8: 4 | E8: 5 | F8: 6 | G8: 7 | H8: 8 | I8: 9 | J8: 10 | K8: 11 | L8: 12 | M8: 13 | N8: 14 | O8: 15 | Q8: ok-nop
A9: 1 | B9: CIWANDAN | C9: 0 | D9: 0 | E9: 0 | F9: - | G9: - | H9: - | I9: - | J9: - | K9: 0 | L9: 0 | M9: 0 | O9: =SUM(C9:N9) -> 0 | Q9: =SUM(L9:M9) -> 0
A10: 2 | B10: CITANGKIL | C10: 0 | D10: 0 | E10: 0 | F10: - | G10: - | H10: - | I10: - | J10: - | K10: 0 | L10: 0 | M10: 0 | O10: =SUM(C10:N10) -> 0 | Q10: =SUM(L10:M10) -> 0
A11: 3 | B11: PULOMERAK | C11: 0 | D11: 0 | E11: 0 | F11: - | G11: - | H11: - | I11: - | J11: - | K11: 0 | L11: 0 | M11: 0 | O11: =SUM(C11:N11) -> 0 | Q11: =SUM(L11:M11) -> 0
A12: 4 | B12: PURWAKARTA | C12: 0 | D12: 0 | E12: 0 | F12: - | G12: - | H12: - | I12: - | J12: - | K12: 0 | L12: 0 | M12: 0 | O12: =SUM(C12:N12) -> 0 | Q12: =SUM(L12:M12) -> 0
A13: 5 | B13: GROGOL | C13: 0 | D13: 0 | E13: 0 | F13: - | G13: - | H13: - | I13: - | J13: - | K13: 0 | L13: 0 | M13: 0 | O13: =SUM(C13:N13) -> 0 | Q13: =SUM(L13:M13) -> 0
A14: 6 | B14: CILEGON | C14: 0 | D14: 0 | E14: 0 | F14: - | G14: - | H14: - | I14: - | J14: - | K14: 0 | L14: 0 | M14: 0 | O14: =SUM(C14:N14) -> 0 | Q14: =SUM(L14:M14) -> 0
A15: 7 | B15: JOMBANG | C15: 0 | D15: 0 | E15: 0 | F15: - | G15: - | H15: - | I15: - | J15: - | K15: 0 | L15: 0 | M15: 0 | O15: =SUM(C15:N15) -> 0 | Q15: =SUM(L15:M15) -> 0
A16: 8 | B16: CIBEBER | C16: 0 | D16: 0 | E16: 0 | F16: - | G16: - | H16: - | I16: - | J16: - | K16: 0 | L16: 0 | M16: 0 | O16: =SUM(C16:N16) -> 0 | Q16: =SUM(L16:M16) -> 0
A17: JUMLAH | C17: =SUM(C9:C16) -> 0 | D17: =SUM(D9:D16) -> 0 | E17: =SUM(E9:E16) -> 0 | F17: - | G17: =SUM(G9:G16) -> 0 | H17: =SUM(H9:H16) -> 0 | I17: =SUM(I9:I16) -> 0 | J17: =SUM(J9:J16) -> 0 | K17: =SUM(K9:K16) -> 0 | L17: =SUM(L9:L16) -> 0 | M17: =SUM(M9:M16) -> 0 | N17: =SUM(N9:N16) -> 0 | O17: =SUM(O9:O16) -> 0
A35: DATA LUAS PANEN TALAS PER BULAN
A36: KOTA CILEGON TAHUN 2025
O38: (Ha)
A39: No | B39: Kecamatan | C39: Bulan | O39: Jumlah
C40: Jan | D40: Feb | E40: Maret | F40: Apr | G40: Mei | H40: Juni | I40: Juli | J40: Agst | K40: Sept | L40: Okt | M40: Nov | N40: Des
A41: 1 | B41: 2 | C41: 3 | D41: 4 | E41: 5 | F41: 6 | G41: 7 | H41: 8 | I41: 9 | J41: 10 | K41: 11 | L41: 12 | M41: 13 | N41: 14 | O41: 15
A42: 1 | B42: CIWANDAN | C42: 0 | D42: 0 | E42: 0 | F42: - | G42: - | H42: - | I42: - | J42: - | K42: 0 | L42: 0 | M42: 0 | O42: =SUM(C42:N42) -> 0 | Q42: =SUM(C42:E42) -> 0
A43: 2 | B43: CITANGKIL | C43: 0 | D43: 0 | E43: 0 | F43: - | G43: - | H43: - | I43: - | J43: - | K43: 0 | L43: 0 | M43: 0 | O43: =SUM(C43:N43) -> 0 | Q43: =SUM(C43:E43) -> 0
A44: 3 | B44: PULOMERAK | C44: 0 | D44: 0 | E44: 0 | F44: - | G44: - | H44: - | I44: - | J44: - | K44: 0 | L44: 0 | M44: 0 | O44: =SUM(C44:N44) -> 0 | Q44: =SUM(C44:E44) -> 0
A45: 4 | B45: PURWAKARTA | C45: 0 | D45: 0 | E45: 0 | F45: - | G45: - | H45: - | I45: - | J45: - | K45: 0 | L45: 0 | M45: 0 | O45: =SUM(C45:N45) -> 0 | Q45: =SUM(C45:E45) -> 0
A46: 5 | B46: GROGOL | C46: 0 | D46: 0 | E46: 0 | F46: - | G46: - | H46: - | I46: - | J46: - | K46: 0 | L46: 0 | M46: 0 | O46: =SUM(C46:N46) -> 0 | Q46: =SUM(C46:E46) -> 0
A47: 6 | B47: CILEGON | C47: 0 | D47: 0 | E47: 0 | F47: - | G47: - | H47: - | I47: - | J47: - | K47: 0 | L47: 0 | M47: 0 | O47: =SUM(C47:N47) -> 0 | Q47: =SUM(C47:E47) -> 0
A48: 7 | B48: JOMBANG | C48: 0 | D48: 0 | E48: 0 | F48: - | G48: - | H48: - | I48: - | J48: - | K48: 0 | L48: 0 | M48: 0 | O48: =SUM(C48:N48) -> 0 | Q48: =SUM(C48:E48) -> 0
A49: 8 | B49: CIBEBER | C49: 0 | D49: 0 | E49: 0 | F49: - | G49: - | H49: - | I49: - | J49: - | K49: 0 | L49: 0 | M49: 0 | O49: =SUM(C49:N49) -> 0 | P49: 15 | Q49: =SUM(C49:E49) -> 0
A50: JUMLAH | C50: =SUM(C42:C49) -> 0 | D50: =SUM(D42:D49) -> 0 | E50: =SUM(E42:E49) -> 0 | F50: =SUM(F42:F49) -> 0 | G50: =SUM(G42:G49) -> 0 | H50: =SUM(H42:H49) -> 0 | I50: =SUM(I42:I49) -> 0 | J50: =SUM(J42:J49) -> 0 | ... P50: =SUM(P42:P49) -> 15
A68: DATA PRODUKSI TALAS PER BULAN
A69: KOTA CILEGON TAHUN 2025
O71: (Ton)
A72: No | B72: Kecamatan | C72: Bulan | O72: Jumlah
C73: Jan | D73: Feb | E73: Maret | F73: Apr | G73: Mei | H73: Juni | I73: Juli | J73: Agst | K73: Sept | L73: Okt | M73: Nov | N73: Des
A74: 1 | B74: 2 | C74: 3 | D74: 4 | E74: 5 | F74: 6 | G74: 7 | H74: 8 | I74: 9 | J74: 10 | K74: 11 | L74: 12 | M74: 13 | N74: 14 | O74: 15
A75: 1 | B75: CIWANDAN | C75: 0 | D75: 0 | E75: 0 | F75: - | G75: - | H75: - | I75: - | J75: - | K75: 0 | L75: 0 | M75: 0 | O75: =SUM(C75:N75) -> 0 | Q75: =SUM(C75:E75) -> 0
A76: 2 | B76: CITANGKIL | C76: 0 | D76: 0 | E76: 0 | F76: - | G76: - | H76: - | I76: - | J76: - | K76: 0 | L76: 0 | M76: 0 | O76: =SUM(C76:N76) -> 0 | Q76: =SUM(C76:E76) -> 0
A77: 3 | B77: PULOMERAK | C77: 0 | D77: 0 | E77: 0 | F77: - | G77: - | H77: - | I77: - | J77: - | K77: 0 | L77: 0 | M77: 0 | O77: =SUM(C77:N77) -> 0 | Q77: =SUM(C77:E77) -> 0
A78: 4 | B78: PURWAKARTA | C78: 0 | D78: 0 | E78: 0 | F78: - | G78: - | H78: - | I78: - | J78: - | K78: 0 | L78: 0 | M78: 0 | O78: =SUM(C78:N78) -> 0 | Q78: =SUM(C78:E78) -> 0
...

Sheet sorgum
A2: DATA LUAS TANAM SORGUM PER BULAN
A3: KOTA CILEGON TAHUN 2025
O5: (Ha)
A6: No | B6: Kecamatan | C6: Bulan | O6: Jumlah
C7: Jan | D7: Feb | E7: Maret | F7: Apr | G7: Mei | H7: Juni | I7: Juli | J7: Agst | K7: Sept | L7: Okt | M7: Nov | N7: Des
A8: 1 | B8: 2 | C8: 3 | D8: 4 | E8: 5 | F8: 6 | G8: 7 | H8: 8 | I8: 9 | J8: 10 | K8: 11 | L8: 12 | M8: 13 | N8: 14 | O8: 15 | Q8: ok-nop
A9: 1 | B9: CIWANDAN | C9: 0 | D9: 0 | E9: 0 | F9: 0 | G9: 0 | H9: 0 | I9: 0 | J9: 0 | K9: 0 | L9: 0 | M9: 0 | N9: 0 | O9: =SUM(C9:N9) -> 0 | Q9: =SUM(L9:M9) -> 0
A10: 2 | B10: CITANGKIL | C10: 0 | D10: 0 | E10: 0 | F10: 0 | G10: 0 | H10: 0 | I10: 0 | J10: 0 | K10: 0 | L10: 0 | M10: 0 | N10: 0 | O10: =SUM(C10:N10) -> 0 | Q10: =SUM(L10:M10) -> 0
A11: 3 | B11: PULOMERAK | C11: 0 | D11: 0 | E11: 0 | F11: 0 | G11: 0 | H11: 0 | I11: 0 | J11: 0 | K11: 0 | L11: 0 | M11: 0 | N11: 0 | O11: =SUM(C11:N11) -> 0 | Q11: =SUM(L11:M11) -> 0
A12: 4 | B12: PURWAKARTA | C12: 0 | D12: 0 | E12: 0 | F12: 0 | G12: 0 | H12: 0 | I12: 0 | J12: 0 | K12: 0 | L12: 0 | M12: 0 | N12: 0 | O12: =SUM(C12:N12) -> 0 | Q12: =SUM(L12:M12) -> 0
A13: 5 | B13: GROGOL | C13: 0 | D13: 0 | E13: 0 | F13: 0 | G13: 0 | H13: 0 | I13: 0 | J13: 0 | K13: 0 | L13: 0 | M13: 0 | N13: 0 | O13: =SUM(C13:N13) -> 0 | Q13: =SUM(L13:M13) -> 0
A14: 6 | B14: CILEGON | C14: 0 | D14: 0 | E14: 0 | F14: 0 | G14: 0 | H14: 0 | I14: 0 | J14: 0 | K14: 0 | L14: 0 | M14: 0 | N14: 0 | O14: =SUM(C14:N14) -> 0 | Q14: =SUM(L14:M14) -> 0
A15: 7 | B15: JOMBANG | C15: 0 | D15: 0 | E15: 0 | F15: 0 | G15: 0 | H15: 0 | I15: 0 | J15: 0 | K15: 0 | L15: 0 | M15: 0 | N15: 0 | O15: =SUM(C15:N15) -> 0 | Q15: =SUM(L15:M15) -> 0
A16: 8 | B16: CIBEBER | C16: 0 | D16: 0 | E16: 0 | F16: 0 | G16: 0 | H16: 0 | I16: 0 | J16: 0 | K16: 0 | L16: 0 | M16: 0 | N16: 0 | O16: =SUM(C16:N16) -> 0 | Q16: =SUM(L16:M16) -> 0
A17: JUMLAH | C17: =SUM(C9:C16) -> 0 | D17: =SUM(D9:D16) -> 0 | E17: =SUM(E9:E16) -> 0 | F17: =SUM(F9:F16) -> 0 | G17: =SUM(G9:G16) -> 0 | H17: =SUM(H9:H16) -> 0 | I17: =SUM(I9:I16) -> 0 | J17: =SUM(J9:J16) -> 0 | ... O17: =SUM(O9:O16) -> 0
A35: DATA LUAS PANEN SORGUM PER BULAN
A36: KOTA CILEGON TAHUN 2025
O38: (Ha)
A39: No | B39: Kecamatan | C39: Bulan | O39: Jumlah
C40: Jan | D40: Feb | E40: Maret | F40: Apr | G40: Mei | H40: Juni | I40: Juli | J40: Agst | K40: Sept | L40: Okt | M40: Nov | N40: Des
A41: 1 | B41: 2 | C41: 3 | D41: 4 | E41: 5 | F41: 6 | G41: 7 | H41: 8 | I41: 9 | J41: 10 | K41: 11 | L41: 12 | M41: 13 | N41: 14 | O41: 15
A42: 1 | B42: CIWANDAN | C42: 0 | D42: 0 | E42: 0 | F42: 0 | G42: 0 | H42: 0 | I42: 0 | J42: 0 | K42: 0 | L42: 0 | M42: 0 | N42: 0 | O42: =SUM(C42:N42) -> 0 | Q42: =SUM(C42:E42) -> 0
A43: 2 | B43: CITANGKIL | C43: 0 | D43: 0 | E43: 0 | F43: 0 | G43: 0 | H43: 0 | I43: 0 | J43: 0 | K43: 0 | L43: 0 | M43: 0 | N43: 0 | O43: =SUM(C43:N43) -> 0 | Q43: =SUM(C43:E43) -> 0
A44: 3 | B44: PULOMERAK | C44: 0 | D44: 0 | E44: 0 | F44: 0 | G44: 0 | H44: 0 | I44: 0 | J44: 0 | K44: 0 | L44: 0 | M44: 0 | N44: 0 | O44: =SUM(C44:N44) -> 0 | Q44: =SUM(C44:E44) -> 0
A45: 4 | B45: PURWAKARTA | C45: 0 | D45: 0 | E45: 0 | F45: 0 | G45: 0 | H45: 0 | I45: 0 | J45: 0 | K45: 0 | L45: 0 | M45: 0 | N45: 0 | O45: =SUM(C45:N45) -> 0 | Q45: =SUM(C45:E45) -> 0
A46: 5 | B46: GROGOL | C46: 0 | D46: 0 | E46: 0 | F46: 0 | G46: 0 | H46: 0 | I46: 0 | J46: 0 | K46: 0 | L46: 0 | M46: 0 | N46: 0 | O46: =SUM(C46:N46) -> 0 | Q46: =SUM(C46:E46) -> 0
A47: 6 | B47: CILEGON | C47: 0 | D47: 0 | E47: 0 | F47: 0 | G47: 0 | H47: 0 | I47: 0 | J47: 0 | K47: 0 | L47: 0 | M47: 0 | N47: 0 | O47: =SUM(C47:N47) -> 0 | Q47: =SUM(C47:E47) -> 0
A48: 7 | B48: JOMBANG | C48: 0 | D48: 0 | E48: 0 | F48: 0 | G48: 0 | H48: 0 | I48: 0 | J48: 0 | K48: 0 | L48: 0 | M48: 0 | N48: 0 | O48: =SUM(C48:N48) -> 0 | Q48: =SUM(C48:E48) -> 0
A49: 8 | B49: CIBEBER | C49: 0 | D49: 0 | E49: 0 | F49: 0 | G49: 0 | H49: 0 | I49: 0 | J49: 0 | K49: 0 | L49: 0 | M49: 0 | N49: 0 | O49: =SUM(C49:N49) -> 0 | P49: 15 | Q49: =SUM(C49:E49) -> 0
A50: JUMLAH | C50: =SUM(C42:C49) -> 0 | D50: =SUM(D42:D49) -> 0 | E50: =SUM(E42:E49) -> 0 | F50: =SUM(F42:F49) -> 0 | G50: =SUM(G42:G49) -> 0 | H50: =SUM(H42:H49) -> 0 | I50: =SUM(I42:I49) -> 0 | J50: =SUM(J42:J49) -> 0 | ... P50: =SUM(P42:P49) -> 15
A68: DATA PRODUKSI SORGUM PER BULAN
A69: KOTA CILEGON TAHUN 2025
O71: (Ton)
A72: No | B72: Kecamatan | C72: Bulan | O72: Jumlah
C73: Jan | D73: Feb | E73: Maret | F73: Apr | G73: Mei | H73: Juni | I73: Juli | J73: Agst | K73: Sept | L73: Okt | M73: Nov | N73: Des
A74: 1 | B74: 2 | C74: 3 | D74: 4 | E74: 5 | F74: 6 | G74: 7 | H74: 8 | I74: 9 | J74: 10 | K74: 11 | L74: 12 | M74: 13 | N74: 14 | O74: 15
A75: 1 | B75: CIWANDAN | C75: 0 | D75: 0 | E75: 0 | F75: 0 | G75: 0 | H75: 0 | I75: 0 | J75: 0 | K75: 0 | L75: 0 | M75: 0 | N75: 0 | O75: =SUM(C75:N75) -> 0 | Q75: =SUM(C75:E75) -> 0
A76: 2 | B76: CITANGKIL | C76: 0 | D76: 0 | E76: 0 | F76: 0 | G76: 0 | H76: 0 | I76: 0 | J76: 0 | K76: 0 | L76: 0 | M76: 0 | N76: 0 | O76: =SUM(C76:N76) -> 0 | Q76: =SUM(C76:E76) -> 0
A77: 3 | B77: PULOMERAK | C77: 0 | D77: 0 | E77: 0 | F77: 0 | G77: 0 | H77: 0 | I77: 0 | J77: 0 | K77: 0 | L77: 0 | M77: 0 | N77: 0 | O77: =SUM(C77:N77) -> 0 | Q77: =SUM(C77:E77) -> 0
A78: 4 | B78: PURWAKARTA | C78: 0 | D78: 0 | E78: 0 | F78: 0 | G78: 0 | H78: 0 | I78: 0 | J78: 0 | K78: 0 | L78: 0 | M78: 0 | N78: 0 | O78: =SUM(C78:N78) -> 0 | Q78: =SUM(C78:E78) -> 0
...

Sheet porang
A2: DATA LUAS TANAM PORANG PER BULAN
A3: KOTA CILEGON TAHUN 2025
O5: (Ha)
A6: No | B6: Kecamatan | C6: Bulan | O6: Jumlah
C7: Jan | D7: Feb | E7: Maret | F7: Apr | G7: Mei | H7: Juni | I7: Juli | J7: Agst | K7: Sept | L7: Okt | M7: Nov | N7: Des
A8: 1 | B8: 2 | C8: 3 | D8: 4 | E8: 5 | F8: 6 | G8: 7 | H8: 8 | I8: 9 | J8: 10 | K8: 11 | L8: 12 | M8: 13 | N8: 14 | O8: 15 | Q8: ok-nop
A9: 1 | B9: CIWANDAN | C9: 0 | D9: 0 | E9: 0 | F9: 0 | G9: 0 | H9: 0 | I9: 0 | J9: 0 | K9: 0 | L9: 0 | M9: 0 | N9: 0 | O9: =SUM(C9:N9) -> 0 | Q9: =SUM(L9:M9) -> 0
A10: 2 | B10: CITANGKIL | C10: 0 | D10: 0 | E10: 0 | F10: 0 | G10: 0 | H10: 0 | I10: 0 | J10: 0 | K10: 0 | L10: 0 | M10: 0 | N10: 0 | O10: =SUM(C10:N10) -> 0 | Q10: =SUM(L10:M10) -> 0
A11: 3 | B11: PULOMERAK | C11: 0 | D11: 0 | E11: 0 | F11: 0 | G11: 0 | H11: 0 | I11: 0 | J11: 0 | K11: 0 | L11: 0 | M11: 0 | N11: 0 | O11: =SUM(C11:N11) -> 0 | Q11: =SUM(L11:M11) -> 0
A12: 4 | B12: PURWAKARTA | C12: 0 | D12: 0 | E12: 0 | F12: 0 | G12: 0 | H12: 0 | I12: 0 | J12: 0 | K12: 0 | L12: 0 | M12: 0 | N12: 0 | O12: =SUM(C12:N12) -> 0 | Q12: =SUM(L12:M12) -> 0
A13: 5 | B13: GROGOL | C13: 0 | D13: 0 | E13: 0 | F13: 0 | G13: 0 | H13: 0 | I13: 0 | J13: 0 | K13: 0 | L13: 0 | M13: 0 | N13: 0 | O13: =SUM(C13:N13) -> 0 | Q13: =SUM(L13:M13) -> 0
A14: 6 | B14: CILEGON | C14: 0 | D14: 0 | E14: 0 | F14: 0 | G14: 0 | H14: 0 | I14: 0 | J14: 0 | K14: 0 | L14: 0 | M14: 0 | N14: 0 | O14: =SUM(C14:N14) -> 0 | Q14: =SUM(L14:M14) -> 0
A15: 7 | B15: JOMBANG | C15: 0 | D15: 0 | E15: 0 | F15: 0 | G15: 0 | H15: 0 | I15: 0 | J15: 0 | K15: 0 | L15: 0 | M15: 0 | N15: 0 | O15: =SUM(C15:N15) -> 0 | Q15: =SUM(L15:M15) -> 0
A16: 8 | B16: CIBEBER | C16: 0 | D16: 0 | E16: 0 | F16: 0 | G16: 0 | H16: 0 | I16: 0 | J16: 0 | K16: 0 | L16: 0 | M16: 0 | N16: 0 | O16: =SUM(C16:N16) -> 0 | Q16: =SUM(L16:M16) -> 0
A17: JUMLAH | C17: =SUM(C9:C16) -> 0 | D17: =SUM(D9:D16) -> 0 | E17: =SUM(E9:E16) -> 0 | F17: =SUM(F9:F16) -> 0 | G17: =SUM(G9:G16) -> 0 | H17: =SUM(H9:H16) -> 0 | I17: =SUM(I9:I16) -> 0 | J17: =SUM(J9:J16) -> 0 | ... O17: =SUM(O9:O16) -> 0
A35: DATA LUAS PANEN PORANG PER BULAN
A36: KOTA CILEGON TAHUN 2025
O38: (Ha)
A39: No | B39: Kecamatan | C39: Bulan | O39: Jumlah
C40: Jan | D40: Feb | E40: Maret | F40: Apr | G40: Mei | H40: Juni | I40: Juli | J40: Agst | K40: Sept | L40: Okt | M40: Nov | N40: Des
A41: 1 | B41: 2 | C41: 3 | D41: 4 | E41: 5 | F41: 6 | G41: 7 | H41: 8 | I41: 9 | J41: 10 | K41: 11 | L41: 12 | M41: 13 | N41: 14 | O41: 15
A42: 1 | B42: CIWANDAN | C42: 0 | D42: 0 | E42: 0 | F42: 0 | G42: 0 | H42: 0 | I42: 0 | J42: 0 | K42: 0 | L42: 0 | M42: 0 | N42: 0 | O42: =SUM(C42:N42) -> 0 | Q42: =SUM(C42:E42) -> 0
A43: 2 | B43: CITANGKIL | C43: 0 | D43: 0 | E43: 0 | F43: 0 | G43: 0 | H43: 0 | I43: 0 | J43: 0 | K43: 0 | L43: 0 | M43: 0 | N43: 0 | O43: =SUM(C43:N43) -> 0 | Q43: =SUM(C43:E43) -> 0
A44: 3 | B44: PULOMERAK | C44: 0 | D44: 0 | E44: 0 | F44: 0 | G44: 0 | H44: 0 | I44: 0 | J44: 0 | K44: 0 | L44: 0 | M44: 0 | N44: 0 | O44: =SUM(C44:N44) -> 0 | Q44: =SUM(C44:E44) -> 0
A45: 4 | B45: PURWAKARTA | C45: 0 | D45: 0 | E45: 0 | F45: 0 | G45: 0 | H45: 0 | I45: 0 | J45: 0 | K45: 0 | L45: 0 | M45: 0 | N45: 0 | O45: =SUM(C45:N45) -> 0 | Q45: =SUM(C45:E45) -> 0
A46: 5 | B46: GROGOL | C46: 0 | D46: 0 | E46: 0 | F46: 0 | G46: 0 | H46: 0 | I46: 0 | J46: 0 | K46: 0 | L46: 0 | M46: 0 | N46: 0 | O46: =SUM(C46:N46) -> 0 | Q46: =SUM(C46:E46) -> 0
A47: 6 | B47: CILEGON | C47: 0 | D47: 0 | E47: 0 | F47: 0 | G47: 0 | H47: 0 | I47: 0 | J47: 0 | K47: 0 | L47: 0 | M47: 0 | N47: 0 | O47: =SUM(C47:N47) -> 0 | Q47: =SUM(C47:E47) -> 0
A48: 7 | B48: JOMBANG | C48: 0 | D48: 0 | E48: 0 | F48: 0 | G48: 0 | H48: 0 | I48: 0 | J48: 0 | K48: 0 | L48: 0 | M48: 0 | N48: 0 | O48: =SUM(C48:N48) -> 0 | Q48: =SUM(C48:E48) -> 0
A49: 8 | B49: CIBEBER | C49: 0 | D49: 0 | E49: 0 | F49: 0 | G49: 0 | H49: 0 | I49: 0 | J49: 0 | K49: 0 | L49: 0 | M49: 0 | N49: 0 | O49: =SUM(C49:N49) -> 0 | P49: 15 | Q49: =SUM(C49:E49) -> 0
A50: JUMLAH | C50: =SUM(C42:C49) -> 0 | D50: =SUM(D42:D49) -> 0 | E50: =SUM(E42:E49) -> 0 | F50: =SUM(F42:F49) -> 0 | G50: =SUM(G42:G49) -> 0 | H50: =SUM(H42:H49) -> 0 | I50: =SUM(I42:I49) -> 0 | J50: =SUM(J42:J49) -> 0 | ... P50: =SUM(P42:P49) -> 15
A68: DATA PRODUKSI PORANG PER BULAN
A69: KOTA CILEGON TAHUN 2025
O71: (Ton)
A72: No | B72: Kecamatan | C72: Bulan | O72: Jumlah
C73: Jan | D73: Feb | E73: Maret | F73: Apr | G73: Mei | H73: Juni | I73: Juli | J73: Agst | K73: Sept | L73: Okt | M73: Nov | N73: Des
A74: 1 | B74: 2 | C74: 3 | D74: 4 | E74: 5 | F74: 6 | G74: 7 | H74: 8 | I74: 9 | J74: 10 | K74: 11 | L74: 12 | M74: 13 | N74: 14 | O74: 15
A75: 1 | B75: CIWANDAN | C75: 0 | D75: 0 | E75: 0 | F75: 0 | G75: 0 | H75: 0 | I75: 0 | J75: 0 | K75: 0 | L75: 0 | M75: 0 | N75: 0 | O75: =SUM(C75:N75) -> 0 | Q75: =SUM(C75:E75) -> 0
