Workbook

Sheet padi sawah
A2: DATA LUAS TANAM PADI (SAWAH) PER BULAN
A3: KOTA CILEGON TAHUN 2016
O5: (Ha)
A6: No | B6: Kecamatan | C6: Bulan | O6: Jumlah
C7: Jan | D7: Feb | E7: Maret | F7: Apr | G7: Mei | H7: Juni | I7: Juli | J7: Agst | K7: Sept | L7: Okt | M7: Nov | N7: Des | S7: JAN-APR | T7: MEI-AGST
A8: 1 | B8: 2 | C8: 3 | D8: 4 | E8: 5 | F8: 6 | G8: 7 | H8: 8 | I8: 9 | J8: 10 | K8: 11 | L8: 12 | M8: 13 | N8: 14 | O8: 15 | Q8: ok-nop
A9: 1 | B9: CIWANDAN | C9: 7 | D9: 248 | E9: 0 | F9: 0 | G9: 3 | H9: 37 | I9: 27 | J9: 8 | K9: 0 | L9: 0 | M9: 2 | N9: 45 | O9: =SUM(C9:N9) -> 377 | Q9: =SUM(L9:M9) -> 2 | S9: =SUM(C9:F9) -> 255 | T9: =SUM(G9:J9) -> 75 | U9: =SUM(L9:N9) -> 47 | W9: =SUM(U9:V9) -> 47
A10: 2 | B10: CITANGKIL | C10: 49 | D10: 128 | E10: 4 | F10: 5 | G10: 13 | H10: 38 | I10: 37 | J10: 31 | K10: 11 | L10: 5 | M10: 27 | N10: 143 | O10: =SUM(C10:N10) -> 491 | P10: =SUM(L10:N10) -> 175 | Q10: =SUM(L10:M10) -> 32 | S10: =SUM(C10:F10) -> 186 | T10: =SUM(G10:J10) -> 119 | U10: =SUM(L10:N10) -> 175 | W10: =SUM(U10:V10) -> 175
A11: 3 | B11: PULOMERAK | C11: 10 | D11: 15 | E11: 0 | F11: 0 | G11: 10 | H11: 5 | I11: 0 | J11: 0 | K11: 5 | L11: 5 | M11: 5 | N11: 0 | O11: =SUM(C11:N11) -> 55 | Q11: =SUM(L11:M11) -> 10 | S11: =SUM(C11:F11) -> 25 | T11: =SUM(G11:J11) -> 15 | U11: =SUM(L11:N11) -> 10 | V11: 29 | W11: =SUM(U11:V11) -> 39
A12: 4 | B12: PURWAKARTA | C12: 182 | D12: 1 | E12: 1 | F12: 0 | G12: 21 | H12: 11 | I12: 2 | J12: 1 | K12: 5 | L12: 9 | M12: 1 | N12: 36 | O12: =SUM(C12:N12) -> 270 | Q12: =SUM(L12:M12) -> 10 | S12: =SUM(C12:F12) -> 184 | T12: =SUM(G12:J12) -> 35 | U12: =SUM(L12:N12) -> 46 | W12: =SUM(U12:V12) -> 46
A13: 5 | B13: GROGOL | C13: 45 | D13: 119 | E13: 0 | F13: 0 | G13: 20 | H13: 0 | I13: 0 | J13: 0 | K13: 10 | L13: 0 | M13: 0 | N13: 15 | O13: =SUM(C13:N13) -> 209 | Q13: =SUM(L13:M13) -> 0 | S13: =SUM(C13:F13) -> 164 | T13: =SUM(G13:J13) -> 20 | U13: =SUM(L13:N13) -> 15 | W13: =SUM(U13:V13) -> 15
A14: 6 | B14: CILEGON | C14: 29 | D14: 18 | E14: 0 | F14: 0 | G14: 10 | H14: 25 | I14: 6 | J14: 0 | K14: 0 | L14: 7 | M14: 43 | N14: 0 | O14: =SUM(C14:N14) -> 138 | Q14: =SUM(L14:M14) -> 50 | S14: =SUM(C14:F14) -> 47 | T14: =SUM(G14:J14) -> 41 | U14: =SUM(L14:N14) -> 50 | W14: =SUM(U14:V14) -> 50
A15: 7 | B15: JOMBANG | C15: 104 | D15: 59 | E15: 1 | F15: 1 | G15: 48 | H15: 189 | I15: 27 | J15: 3 | K15: 1 | L15: 15 | M15: 14 | N15: 136 | O15: =SUM(C15:N15) -> 598 | Q15: =SUM(L15:M15) -> 29 | S15: =SUM(C15:F15) -> 165 | T15: =SUM(G15:J15) -> 267 | U15: =SUM(L15:N15) -> 165 | W15: =SUM(U15:V15) -> 165
A16: 8 | B16: CIBEBER | C16: 64 | D16: 145 | E16: 6 | F16: 26 | G16: 66 | H16: 101 | I16: 0 | J16: 48 | K16: 27 | L16: 26 | M16: 125 | N16: 122 | O16: =SUM(C16:N16) -> 756 | Q16: =SUM(L16:M16) -> 151 | S16: =SUM(C16:F16) -> 241 | T16: =SUM(G16:J16) -> 215 | U16: =SUM(L16:N16) -> 273 | W16: =SUM(U16:V16) -> 273
A17: JUMLAH | C17: =SUM(C9:C16) -> 490 | D17: =SUM(D9:D16) -> 733 | E17: =SUM(E9:E16) -> 12 | F17: =SUM(F9:F16) -> 32 | G17: =SUM(G9:G16) -> 191 | H17: =SUM(H9:H16) -> 406 | I17: =SUM(I9:I16) -> 99 | J17: =SUM(J9:J16) -> 91 | ... O17: =SUM(O9:O16) -> 2894 | Q17: =SUM(L17:M17) -> 284 | U17: =SUM(U9:U16) -> 781 | V17: =SUM(V9:V16) -> 29 | W17: =SUM(W9:W16) -> 810
H19: =SUM(F16:H16) -> 193 | J19: =SUM(C17:J17) -> 2054 | K19: =SUM(F17:K17) -> 878 | N19: =SUM(L17:N17) -> 781
K20: =SUM(K17:M17) -> 343
A35: DATA LUAS PANEN PADI (SAWAH) PER BULAN
A36: KOTA CILEGON TAHUN 2016
O38: (Ha)
A39: No | B39: Kecamatan | C39: Bulan | O39: Jumlah
C40: Jan | D40: Feb | E40: Maret | F40: Apr | G40: Mei | H40: Juni | I40: Juli | J40: Agst | K40: Sept | L40: Okt | M40: Nov | N40: Des
A41: 1 | B41: 2 | C41: 3 | D41: 4 | E41: 5 | F41: 6 | G41: 7 | H41: 8 | I41: 9 | J41: 10 | K41: 11 | L41: 12 | M41: 13 | N41: 14 | O41: 15
A42: 1 | B42: CIWANDAN | C42: 0 | D42: 0 | E42: 0 | F42: 7 | G42: 248 | H42: 0 | I42: 1 | J42: 3 | K42: 62 | L42: 0 | M42: 9 | N42: 0 | O42: =SUM(C42:N42) -> 330 | Q42: =SUM(C42:E42) -> 0
A43: 2 | B43: CITANGKIL | C43: 0 | D43: 4 | E43: 14 | F43: 92 | G43: 101 | H43: 4 | I43: 13 | J43: 21 | K43: 27 | L43: 60 | M43: 1 | N43: 4 | O43: =SUM(C43:N43) -> 341 | Q43: =SUM(C43:E43) -> 18
A44: 3 | B44: PULOMERAK | C44: 0 | D44: 0 | E44: 0 | F44: 10 | G44: 15 | H44: 0 | I44: 5 | J44: 10 | K44: 0 | L44: 0 | M44: 0 | N44: 0 | O44: =SUM(C44:N44) -> 40 | Q44: =SUM(C44:E44) -> 0
A45: 4 | B45: PURWAKARTA | C45: 1 | D45: 2 | E45: 16 | F45: 182 | G45: 0 | H45: 1 | I45: 0 | J45: 21 | K45: 11 | L45: 0 | M45: 1 | N45: 5 | O45: =SUM(C45:N45) -> 240 | Q45: =SUM(C45:E45) -> 19
A46: 5 | B46: GROGOL | C46: 0 | D46: 0 | E46: 0 | F46: 45 | G46: 119 | H46: 0 | I46: 0 | J46: 20 | K46: 0 | L46: 0 | M46: 0 | N46: 10 | O46: =SUM(C46:N46) -> 194 | Q46: =SUM(C46:E46) -> 0
A47: 6 | B47: CILEGON | C47: 5 | D47: 0 | E47: 0 | F47: 36 | G47: 18 | H47: 0 | I47: 0 | J47: 14 | K47: 21 | L47: 6 | M47: 0 | N47: 0 | O47: =SUM(C47:N47) -> 100 | Q47: =SUM(C47:E47) -> 5
A48: 7 | B48: JOMBANG | C48: 1 | D48: 4 | E48: 245 | F48: 99 | G48: 1 | H48: 1 | I48: 0 | J48: 237 | K48: 27 | L48: 3 | M48: 0 | N48: 4 | O48: =SUM(C48:N48) -> 622 | Q48: =SUM(C48:E48) -> 250
A49: 8 | B49: CIBEBER | C49: 25 | D49: 1 | E49: 42 | F49: 64 | G49: 145 | H49: 6 | I49: 26 | J49: 66 | K49: 101 | L49: 0 | M49: 48 | N49: 27 | O49: =SUM(C49:N49) -> 551 | Q49: =SUM(C49:E49) -> 68
A50: JUMLAH | C50: =SUM(C42:C49) -> 32 | D50: =SUM(D42:D49) -> 11 | E50: =SUM(E42:E49) -> 317 | F50: =SUM(F42:F49) -> 535 | G50: =SUM(G42:G49) -> 647 | H50: =SUM(H42:H49) -> 12 | I50: =SUM(I42:I49) -> 45 | J50: =SUM(J42:J49) -> 392 | ... O50: =SUM(O42:O49) -> 2418
J52: =SUM(C50:J50) -> 1991
L56: =J50*5.8 -> 2273.6
A68: DATA PRODUKSI PADI (SAWAH) PER BULAN
A69: KOTA CILEGON TAHUN 2016
O71: (Ton)
A72: No | B72: Kecamatan | C72: Bulan | O72: Jumlah
C73: Jan | D73: Feb | E73: Maret | F73: Apr | G73: Mei | H73: Juni | I73: Juli | J73: Agst | K73: Sept | L73: Okt | M73: Nov | N73: Des
A74: 1 | B74: 2 | C74: 3 | D74: 4 | E74: 5 | F74: 6 | G74: 7 | H74: 8 | I74: 9 | J74: 10 | K74: 11 | L74: 12 | M74: 13 | N74: 14 | O74: 15
...

Sheet puso
A1: DATA LUAS PUSO PADI (SAWAH) PER BULAN
A2: KOTA CILEGON TAHUN 2016
O3: (Ha)
A4: No | B4: Kecamatan | C4: Bulan | O4: Jumlah
C5: Jan | D5: Feb | E5: Maret | F5: Apr | G5: Mei | H5: Juni | I5: Juli | J5: Agst | K5: Sept | L5: Okt | M5: Nov | N5: Des
A6: 1 | B6: 2 | C6: 3 | D6: 4 | E6: 5 | F6: 6 | G6: 7 | H6: 8 | I6: 9 | J6: 10 | K6: 11 | L6: 12 | M6: 13 | N6: 14 | O6: 15
A7: 1 | B7: CIWANDAN | C7: 0 | D7: 0 | E7: 0 | F7: 0 | G7: 0 | H7: 0 | I7: 0 | J7: 0 | K7: 0 | L7: 0 | M7: 0 | N7: 0 | O7: =SUM(C7:N7) -> 0
A8: 2 | B8: CITANGKIL | C8: 0 | D8: 0 | E8: 0 | F8: 0 | G8: 0 | H8: 0 | I8: 0 | J8: 0 | K8: 0 | L8: 0 | M8: 0 | N8: 0 | O8: =SUM(C8:N8) -> 0
A9: 3 | B9: PULOMERAK | C9: 0 | D9: 0 | E9: 0 | F9: 0 | G9: 0 | H9: 0 | I9: 0 | J9: 0 | K9: 0 | L9: 0 | M9: 0 | N9: 0 | O9: =SUM(C9:N9) -> 0
A10: 4 | B10: PURWAKARTA | C10: 0 | D10: 2 | E10: 0 | F10: 0 | G10: 0 | H10: 0 | I10: 0 | J10: 0 | K10: 0 | L10: 0 | M10: 0 | N10: 0 | O10: =SUM(C10:N10) -> 2
A11: 5 | B11: GROGOL | C11: 0 | D11: 0 | E11: 0 | F11: 0 | G11: 0 | H11: 0 | I11: 0 | J11: 0 | K11: 0 | L11: 0 | M11: 0 | N11: 0 | O11: =SUM(C11:N11) -> 0
A12: 6 | B12: CILEGON | C12: 0 | D12: 0 | E12: 0 | F12: 0 | G12: 0 | H12: 0 | I12: 0 | J12: 0 | K12: 0 | L12: 0 | M12: 0 | N12: 0 | O12: =SUM(C12:N12) -> 0
A13: 7 | B13: JOMBANG | C13: 0 | D13: 0 | E13: 0 | F13: 0 | G13: 0 | H13: 0 | I13: 0 | J13: 0 | K13: 0 | L13: 0 | M13: 0 | N13: 0 | O13: =SUM(C13:N13) -> 0
A14: 8 | B14: CIBEBER | C14: 0 | D14: 0 | E14: 0 | F14: 0 | G14: 0 | H14: 0 | I14: 0 | J14: 0 | K14: 0 | L14: 0 | M14: 0 | N14: 0 | O14: =SUM(C14:N14) -> 0
A15: JUMLAH | C15: =SUM(C7:C14) -> 0 | D15: =SUM(D7:D14) -> 2 | E15: =SUM(E7:E14) -> 0 | F15: =SUM(F7:F14) -> 0 | G15: =SUM(G7:G14) -> 0 | H15: =SUM(H7:H14) -> 0 | I15: =SUM(I7:I14) -> 0 | J15: =SUM(J7:J14) -> 0 | ... O15: =SUM(O7:O14) -> 2
A17: DATA LUAS PUSO KEDELAI PER BULAN
A18: KOTA CILEGON TAHUN 2016
O19: (Ha)
A20: No | B20: Kecamatan | C20: Bulan | O20: Jumlah
C21: Jan | D21: Feb | E21: Maret | F21: Apr | G21: Mei | H21: Juni | I21: Juli | J21: Agst | K21: Sept | L21: Okt | M21: Nov | N21: Des
A22: 1 | B22: 2 | C22: 3 | D22: 4 | E22: 5 | F22: 6 | G22: 7 | H22: 8 | I22: 9 | J22: 10 | K22: 11 | L22: 12 | M22: 13 | N22: 14 | O22: 15
A23: 1 | B23: CIWANDAN | C23: 0 | D23: 0 | E23: 0 | F23: 0 | G23: 0 | H23: 0 | I23: 0 | J23: 0 | K23: 0 | L23: 0 | M23: 0 | N23: 0 | O23: =SUM(C23:N23) -> 0
A24: 2 | B24: CITANGKIL | C24: 0 | D24: 0 | E24: 0 | F24: 0 | G24: 0 | H24: 0 | I24: 0 | J24: 0 | K24: 0 | L24: 0 | M24: 0 | N24: 0 | O24: =SUM(C24:N24) -> 0
A25: 3 | B25: PULOMERAK | C25: 0 | D25: 0 | E25: 0 | F25: 0 | G25: 0 | H25: 0 | I25: 0 | J25: 0 | K25: 0 | L25: 0 | M25: 0 | N25: 0 | O25: =SUM(C25:N25) -> 0
A26: 4 | B26: PURWAKARTA | C26: 0 | D26: 0 | E26: 0 | F26: 0 | G26: 0 | H26: 0 | I26: 0 | J26: 0 | K26: 0 | L26: 0 | M26: 0 | N26: 0 | O26: =SUM(C26:N26) -> 0
A27: 5 | B27: GROGOL | C27: 0 | D27: 0 | E27: 0 | F27: 0 | G27: 0 | H27: 0 | I27: 0 | J27: 0 | K27: 0 | L27: 0 | M27: 0 | N27: 0 | O27: =SUM(C27:N27) -> 0
A28: 6 | B28: CILEGON | C28: 0 | D28: 0 | E28: 0 | F28: 0 | G28: 0 | H28: 0 | I28: 0 | J28: 0 | K28: 0 | L28: 0 | M28: 0 | N28: 0 | O28: =SUM(C28:N28) -> 0
A29: 7 | B29: JOMBANG | C29: 0 | D29: 0 | E29: 0 | F29: 0 | G29: 0 | H29: 0 | I29: 0 | J29: 0 | K29: 0 | L29: 0 | M29: 0 | N29: 0 | O29: =SUM(C29:N29) -> 0
A30: 8 | B30: CIBEBER | C30: 0 | D30: 2 | E30: 0 | F30: 0 | G30: 0 | H30: 0 | I30: 0 | J30: 0 | K30: 0 | L30: 0 | M30: 0 | N30: 0 | O30: =SUM(C30:N30) -> 2
A31: JUMLAH | C31: =SUM(C23:C30) -> 0 | D31: =SUM(D23:D30) -> 2 | E31: =SUM(E23:E30) -> 0 | F31: =SUM(F23:F30) -> 0 | G31: =SUM(G23:G30) -> 0 | H31: =SUM(H23:H30) -> 0 | I31: =SUM(I23:I30) -> 0 | J31: =SUM(J23:J30) -> 0 | ... O31: =SUM(O23:O30) -> 2

Sheet padi ladang
A2: DATA LUAS TANAM PADI (DARAT) PER BULAN
A3: KOTA CILEGON TAHUN 2016
O5: (Ha)
A6: No | B6: Kecamatan | C6: Bulan | O6: Jumlah
C7: Jan | D7: Feb | E7: Maret | F7: Apr | G7: Mei | H7: Juni | I7: Juli | J7: Agst | K7: Sept | L7: Okt | M7: Nov | N7: Des
A8: 1 | B8: 2 | C8: 3 | D8: 4 | E8: 5 | F8: 6 | G8: 7 | H8: 8 | I8: 9 | J8: 10 | K8: 11 | L8: 12 | M8: 13 | N8: 14 | O8: 15
A9: 1 | B9: CIWANDAN | C9: 0 | D9: 0 | E9: 0 | F9: 0 | G9: 0 | H9: 0 | I9: 0 | J9: 0 | K9: 0 | L9: 0 | M9: 0 | N9: 0 | O9: =SUM(C9:N9) -> 0
A10: 2 | B10: CITANGKIL | C10: 0 | D10: 0 | E10: 0 | F10: 0 | G10: 0 | H10: 0 | I10: 0 | J10: 0 | K10: 0 | L10: 0 | M10: 0 | N10: 0 | O10: =SUM(C10:N10) -> 0
A11: 3 | B11: PULOMERAK | C11: 10 | D11: 0 | E11: 0 | F11: 0 | G11: 0 | H11: 0 | I11: 0 | J11: 0 | K11: 35 | L11: 0 | M11: 4 | N11: 25 | O11: =SUM(C11:N11) -> 74
A12: 4 | B12: PURWAKARTA | C12: 0 | D12: 0 | E12: 0 | F12: 0 | G12: 0 | H12: 0 | I12: 0 | J12: 0 | K12: 0 | L12: 0 | M12: 0 | N12: 0 | O12: =SUM(C12:N12) -> 0
A13: 5 | B13: GROGOL | C13: 0 | D13: 0 | E13: 0 | F13: 0 | G13: 0 | H13: 0 | I13: 0 | J13: 0 | K13: 0 | L13: 0 | M13: 0 | N13: 0 | O13: =SUM(C13:N13) -> 0
A14: 6 | B14: CILEGON | C14: 0 | D14: 0 | E14: 0 | F14: 0 | G14: 0 | H14: 0 | I14: 0 | J14: 0 | K14: 0 | L14: 0 | M14: 0 | N14: 0 | O14: =SUM(C14:N14) -> 0
A15: 7 | B15: JOMBANG | C15: 0 | D15: 0 | E15: 0 | F15: 0 | G15: 0 | H15: 0 | I15: 0 | J15: 0 | K15: 0 | L15: 0 | M15: 0 | N15: 0 | O15: =SUM(C15:N15) -> 0
A16: 8 | B16: CIBEBER | C16: 0 | D16: 0 | E16: 0 | F16: 0 | G16: 0 | H16: 0 | I16: 0 | J16: 0 | K16: 0 | L16: 0 | M16: 0 | N16: 0 | O16: =SUM(C16:N16) -> 0
A17: JUMLAH | C17: =SUM(C9:C16) -> 10 | D17: =SUM(D9:D16) -> 0 | E17: =SUM(E9:E16) -> 0 | F17: =SUM(F9:F16) -> 0 | G17: =SUM(G9:G16) -> 0 | H17: =SUM(H9:H16) -> 0 | I17: =SUM(I9:I16) -> 0 | J17: =SUM(J9:J16) -> 0 | ... O17: =SUM(O9:O16) -> 74
A35: DATA LUAS PANEN PADI (DARAT) PER BULAN
A36: KOTA CILEGON TAHUN 2016
O38: (Ha)
A39: No | B39: Kecamatan | C39: Bulan | O39: Jumlah
C40: Jan | D40: Feb | E40: Maret | F40: Apr | G40: Mei | H40: Juni | I40: Juli | J40: Agst | K40: Sept | L40: Okt | M40: Nov | N40: Des
A41: 1 | B41: 2 | C41: 3 | D41: 4 | E41: 5 | F41: 6 | G41: 7 | H41: 8 | I41: 9 | J41: 10 | K41: 11 | L41: 12 | M41: 13 | N41: 14 | O41: 15
A42: 1 | B42: CIWANDAN | C42: 0 | D42: 0 | E42: 0 | F42: 0 | G42: 0 | H42: 0 | I42: 0 | J42: 0 | K42: 0 | L42: 0 | M42: 0 | N42: 0 | O42: =SUM(C42:N42) -> 0
A43: 2 | B43: CITANGKIL | C43: 0 | D43: 0 | E43: 0 | F43: 0 | G43: 0 | H43: 0 | I43: 0 | J43: 0 | K43: 0 | L43: 0 | M43: 0 | N43: 0 | O43: =SUM(C43:N43) -> 0
A44: 3 | B44: PULOMERAK | C44: 0 | D44: 0 | E44: 0 | F44: 15 | G44: 0 | H44: 0 | I44: 0 | J44: 0 | K44: 0 | L44: 0 | M44: 0 | N44: 0 | O44: =SUM(C44:N44) -> 15
A45: 4 | B45: PURWAKARTA | C45: 0 | D45: 0 | E45: 0 | F45: 0 | G45: 0 | H45: 0 | I45: 0 | J45: 0 | K45: 0 | L45: 0 | M45: 0 | N45: 0 | O45: =SUM(C45:N45) -> 0
A46: 5 | B46: GROGOL | C46: 0 | D46: 0 | E46: 0 | F46: 0 | G46: 0 | H46: 0 | I46: 0 | J46: 0 | K46: 0 | L46: 0 | M46: 0 | N46: 0 | O46: =SUM(C46:N46) -> 0
A47: 6 | B47: CILEGON | C47: 0 | D47: 0 | E47: 0 | F47: 0 | G47: 0 | H47: 0 | I47: 0 | J47: 0 | K47: 0 | L47: 0 | M47: 0 | N47: 0 | O47: =SUM(C47:N47) -> 0
A48: 7 | B48: JOMBANG | C48: 0 | D48: 0 | E48: 0 | F48: 0 | G48: 0 | H48: 0 | I48: 0 | J48: 0 | K48: 0 | L48: 0 | M48: 0 | N48: 0 | O48: =SUM(C48:N48) -> 0
A49: 8 | B49: CIBEBER | C49: 0 | D49: 0 | E49: 0 | F49: 0 | G49: 0 | H49: 0 | I49: 0 | J49: 0 | K49: 0 | L49: 0 | M49: 0 | N49: 0 | O49: =SUM(C49:N49) -> 0
A50: JUMLAH | C50: =SUM(C42:C49) -> 0 | D50: =SUM(D42:D49) -> 0 | E50: =SUM(E42:E49) -> 0 | F50: =SUM(F42:F49) -> 15 | G50: =SUM(G42:G49) -> 0 | H50: =SUM(H42:H49) -> 0 | I50: =SUM(I42:I49) -> 0 | J50: =SUM(J42:J49) -> 0 | ... O50: =SUM(O42:O49) -> 15
A68: DATA PRODUKSI PADI (DARAT) PER BULAN
A69: KOTA CILEGON TAHUN 2016
O71: (Ton)
A72: No | B72: Kecamatan | C72: Bulan | O72: Jumlah
C73: Jan | D73: Feb | E73: Maret | F73: Apr | G73: Mei | H73: Juni | I73: Juli | J73: Agst | K73: Sept | L73: Okt | M73: Nov | N73: Des
A74: 1 | B74: 2 | C74: 3 | D74: 4 | E74: 5 | F74: 6 | G74: 7 | H74: 8 | I74: 9 | J74: 10 | K74: 11 | L74: 12 | M74: 13 | N74: 14 | O74: 15
A75: 1 | B75: CIWANDAN | C75: 0 | D75: 0 | E75: 0 | F75: 0 | G75: 0 | H75: 0 | I75: 0 | J75: 0 | K75: 0 | L75: 0 | M75: 0 | N75: 0 | O75: =SUM(C75:N75) -> 0
A76: 2 | B76: CITANGKIL | C76: 0 | D76: 0 | E76: 0 | F76: 0 | G76: 0 | H76: 0 | I76: 0 | J76: 0 | K76: 0 | L76: 0 | M76: 0 | N76: 0 | O76: =SUM(C76:N76) -> 0
A77: 3 | B77: PULOMERAK | C77: 0 | D77: 0 | E77: 0 | F77: 59 | G77: 0 | H77: 0 | I77: 0 | J77: 0 | K77: 0 | L77: 0 | M77: 0 | N77: 0 | O77: =SUM(C77:N77) -> 59
A78: 4 | B78: PURWAKARTA | C78: 0 | D78: 0 | E78: 0 | F78: 0 | G78: 0 | H78: 0 | I78: 0 | J78: 0 | K78: 0 | L78: 0 | M78: 0 | N78: 0 | O78: =SUM(C78:N78) -> 0
...

Sheet jagung
A2: DATA LUAS TANAM JAGUNG PER BULAN
A3: KOTA CILEGON TAHUN 2016
O5: (Ha)
A6: No | B6: Kecamatan | C6: Bulan | O6: Jumlah
C7: Jan | D7: Feb | E7: Maret | F7: Apr | G7: Mei | H7: Juni | I7: Juli | J7: Agst | K7: Sept | L7: Okt | M7: Nov | N7: Des
A8: 1 | B8: 2 | C8: 3 | D8: 4 | E8: 5 | F8: 6 | G8: 7 | H8: 8 | I8: 9 | J8: 10 | K8: 11 | L8: 12 | M8: 13 | N8: 14 | O8: 15 | Q8: ok-nop
A9: 1 | B9: CIWANDAN | C9: 2 | D9: 5 | E9: 0 | F9: 1 | G9: 0 | H9: 0 | I9: 0 | J9: 0 | K9: 1 | L9: 1 | M9: 0 | N9: 0 | O9: =SUM(C9:N9) -> 10 | Q9: =SUM(L9:M9) -> 1
A10: 2 | B10: CITANGKIL | C10: 0 | D10: 0 | E10: 0 | F10: 0 | G10: 1 | H10: 0 | I10: 1 | J10: 0 | K10: 0 | L10: 1 | M10: 0 | N10: 0 | O10: =SUM(C10:N10) -> 3 | Q10: =SUM(L10:M10) -> 1
A11: 3 | B11: PULOMERAK | C11: 1 | D11: 0 | E11: 0 | F11: 0 | G11: 3 | H11: 4 | I11: 0 | J11: 0 | K11: 1 | L11: 0 | M11: 35 | N11: 15 | O11: =SUM(C11:N11) -> 59 | Q11: =SUM(L11:M11) -> 35
A12: 4 | B12: PURWAKARTA | C12: 1 | D12: 0 | E12: 0 | F12: 1 | G12: 1 | H12: 0 | I12: 1 | J12: 0 | K12: 1 | L12: 0 | M12: 0 | N12: 1 | O12: =SUM(C12:N12) -> 6 | Q12: =SUM(L12:M12) -> 0
A13: 5 | B13: GROGOL | C13: 0 | D13: 0 | E13: 1 | F13: 0 | G13: 0 | H13: 0 | I13: 3 | J13: 0 | K13: 1 | L13: 0 | M13: 0 | N13: 0 | O13: =SUM(C13:N13) -> 5 | Q13: =SUM(L13:M13) -> 0
A14: 6 | B14: CILEGON | C14: 0 | D14: 0 | E14: 0 | F14: 1 | G14: 0 | H14: 0 | I14: 0 | J14: 0 | K14: 2 | L14: 0 | M14: 0 | N14: 0 | O14: =SUM(C14:N14) -> 3 | Q14: =SUM(L14:M14) -> 0
A15: 7 | B15: JOMBANG | C15: 0 | D15: 0 | E15: 0 | F15: 0.2 | G15: 0 | H15: 0 | I15: 0 | J15: 0.5 | K15: 0 | L15: 0 | M15: 0 | N15: 0 | O15: =SUM(C15:N15) -> 0.7 | Q15: =SUM(L15:M15) -> 0
A16: 8 | B16: CIBEBER | C16: 0 | D16: 1 | E16: 0 | F16: 0 | G16: 1 | I16: 0 | J16: 1 | K16: 0 | L16: 1 | M16: 1 | N16: 0 | O16: =SUM(C16:N16) -> 5 | Q16: =SUM(L16:M16) -> 2
A17: JUMLAH | C17: =SUM(C9:C16) -> 4 | D17: =SUM(D9:D16) -> 6 | E17: =SUM(E9:E16) -> 1 | F17: =SUM(F9:F16) -> 3.2 | G17: =SUM(G9:G16) -> 6 | H17: =SUM(H9:H16) -> 4 | I17: =SUM(I9:I16) -> 5 | J17: =SUM(J9:J16) -> 1.5 | ... O17: =SUM(O9:O16) -> 91.7
N19: =SUM(L17:N17) -> 55
A35: DATA LUAS PANEN JAGUNG PER BULAN
A36: KOTA CILEGON TAHUN 2016
O38: (Ha)
A39: No | B39: Kecamatan | C39: Bulan | O39: Jumlah
C40: Jan | D40: Feb | E40: Maret | F40: Apr | G40: Mei | H40: Juni | I40: Juli | J40: Agst | K40: Sept | L40: Okt | M40: Nov | N40: Des
A41: 1 | B41: 2 | C41: 3 | D41: 4 | E41: 5 | F41: 6 | G41: 7 | H41: 8 | I41: 9 | J41: 10 | K41: 11 | L41: 12 | M41: 13 | N41: 14 | O41: 15
A42: 1 | B42: CIWANDAN | C42: 0 | D42: 2* | E42: 5* | F42: 0 | G42: 0 | H42: 1* | I42: 0 | J42: 0 | K42: 0 | L42: 0 | M42: 1* | N42: 0 | O42: 9* | Q42: 8
A43: 2 | B43: CITANGKIL | C43: 0 | D43: 0 | E43: 0 | F43: 0 | G43: 1 | H43: 0 | I43: 1* | J43: 0 | K43: 0 | L43: 1 | M43: 0 | N43: 0 | O43: =SUM(C43:N43) -> 2 | Q43: 1
A44: 3 | B44: PULOMERAK | C44: 0 | D44: 0 | E44: 0 | F44: 1 | G44: 0 | H44: 0 | I44: 0 | J44: 5 | K44: 6 | L44: 0 | M44: 0 | N44: 0 | O44: =SUM(C44:N44) -> 12 | Q44: =SUM(C44:N44) -> 12
A45: 4 | B45: PURWAKARTA | C45: 0 | D45: 0 | E45: 0 | F45: 1 | G45: 0 | H45: 1* | I45: 1* | J45: 0 | K45: 0 | L45: 1* | M45: 1 | N45: 0 | O45: 5 | Q45: 2
A46: 5 | B46: GROGOL | C46: 0 | D46: 0 | E46: 0 | F46: 0 | G46: 1 | H46: 0 | I46: 0 | J46: 0 | K46: 3 | L46: 0 | M46: 1 | N46: 0 | O46: =SUM(C46:N46) -> 5 | Q46: =SUM(C46:N46) -> 5
A47: 6 | B47: CILEGON | C47: 0 | D47: 0 | E47: 0 | F47: 0 | G47: 0 | H47: 0 | I47: 1* | J47: 0 | K47: 0 | L47: 0 | M47: 2 | N47: 0 | O47: 3 | Q47: =SUM(C47:N47) -> 2
A48: 7 | B48: JOMBANG | C48: 0 | D48: 0 | E48: 0 | F48: 0 | G48: 0 | H48: 0 | I48: 0.2 | J48: 0 | K48: 0 | L48: 0 | M48: 0.5 | N48: 0 | O48: =SUM(C48:N48) -> 0.7 | Q48: =SUM(C48:N48) -> 0.7
A49: 8 | B49: CIBEBER | C49: 0 | D49: 0 | E49: 3* | F49: 0 | G49: 1* | I49: 0 | J49: 1 | K49: 0 | L49: 0 | M49: 1 | N49: 1 | O49: 7 | Q49: 4
A50: JUMLAH | C50: =SUM(C42:C49) -> 0 | D50: 2 | E50: 8 | F50: =SUM(F42:F49) -> 2 | G50: 3 | H50: =SUM(H42:H49) -> 0 | I50: 3.2 | J50: =SUM(J42:J49) -> 6 | K50: =SUM(K42:K49) -> 9 | L50: 2 | M50: 6.5 | N50: =SUM(N42:N49) -> 1 | O50: 43.7 | Q50: =SUM(Q42:Q49) -> 34.7
A52: Ket : * : Panen Muda
A68: DATA PRODUKSI JAGUNG PER BULAN
A69: KOTA CILEGON TAHUN 2016
O71: (Ton)
A72: No | B72: Kecamatan | C72: Bulan | O72: Jumlah
C73: Jan | D73: Feb | E73: Maret | F73: Apr | G73: Mei | H73: Juni | I73: Juli | J73: Agst | K73: Sept | L73: Okt | M73: Nov | N73: Des
A74: 1 | B74: 2 | C74: 3 | D74: 4 | E74: 5 | F74: 6 | G74: 7 | H74: 8 | I74: 9 | J74: 10 | K74: 11 | L74: 12 | M74: 13 | N74: 14 | O74: 15
A75: 1 | B75: CIWANDAN | C75: 0 | D75: 0 | E75: 0 | F75: 0 | G75: 0 | H75: 0 | I75: 0 | J75: 0 | K75: 0 | L75: 0 | M75: 0 | N75: 0 | O75: =SUM(C75:N75) -> 0
A76: 2 | B76: CITANGKIL | C76: 0 | D76: 0 | E76: 0 | F76: 0 | G76: 2 | H76: 0 | I76: 0 | J76: 0 | K76: 0 | L76: 3 | M76: 0 | N76: 0 | O76: =SUM(C76:N76) -> 5
...

Sheet kedelai
A2: DATA LUAS TANAM KEDELAI PER BULAN
A3: KOTA CILEGON TAHUN 2016
O5: (Ha)
A6: No | B6: Kecamatan | C6: Bulan | O6: Jumlah
C7: Jan | D7: Feb | E7: Maret | F7: Apr | G7: Mei | H7: Juni | I7: Juli | J7: Agst | K7: Sept | L7: Okt | M7: Nov | N7: Des
A8: 1 | B8: 2 | C8: 3 | D8: 4 | E8: 5 | F8: 6 | G8: 7 | H8: 8 | I8: 9 | J8: 10 | K8: 11 | L8: 12 | M8: 13 | N8: 14 | O8: 15 | Q8: ok-nop
A9: 1 | B9: CIWANDAN | C9: 0 | D9: 0 | E9: 0 | F9: 0 | G9: 0 | H9: 0 | I9: 0 | J9: 0 | K9: 0 | L9: 0 | M9: 0 | N9: 0 | O9: =SUM(C9:N9) -> 0 | Q9: =SUM(L9:M9) -> 0
A10: 2 | B10: CITANGKIL | C10: 5 | D10: 9 | E10: 6 | F10: 0 | G10: 0 | H10: 0 | I10: 0 | J10: 0 | K10: 0 | L10: 0 | M10: 0 | N10: 0 | O10: =SUM(C10:N10) -> 20 | Q10: =SUM(L10:M10) -> 0
A11: 3 | B11: PULOMERAK | C11: 15 | D11: 0 | E11: 0 | F11: 0 | G11: 0 | H11: 0 | I11: 0 | J11: 0 | K11: 0 | L11: 0 | M11: 0 | N11: 0 | O11: =SUM(C11:N11) -> 15 | Q11: =SUM(L11:M11) -> 0
A12: 4 | B12: PURWAKARTA | C12: 0 | D12: 0 | E12: 0 | F12: 0 | G12: 0 | H12: 0 | I12: 0 | J12: 0 | K12: 0 | L12: 0 | M12: 0 | N12: 0 | O12: =SUM(C12:N12) -> 0 | Q12: =SUM(L12:M12) -> 0
A13: 5 | B13: GROGOL | C13: 0 | D13: 10 | E13: 25 | F13: 0 | G13: 0 | H13: 0 | I13: 0 | J13: 0 | K13: 0 | L13: 0 | M13: 0 | N13: 0 | O13: =SUM(C13:N13) -> 35 | Q13: =SUM(L13:M13) -> 0
A14: 6 | B14: CILEGON | C14: 0 | D14: 0 | E14: 0 | F14: 0 | G14: 0 | H14: 0 | I14: 0 | J14: 0 | K14: 0 | L14: 0 | M14: 0 | N14: 0 | O14: =SUM(C14:N14) -> 0 | Q14: =SUM(L14:M14) -> 0
A15: 7 | B15: JOMBANG | C15: 0 | D15: 0 | E15: 0 | F15: 0 | G15: 0 | H15: 0 | I15: 0 | J15: 0 | K15: 0 | L15: 0 | M15: 0 | N15: 0 | O15: =SUM(C15:N15) -> 0 | Q15: =SUM(L15:M15) -> 0
A16: 8 | B16: CIBEBER | C16: 0 | D16: 0 | E16: 28 | F16: 0 | G16: 0 | H16: 0 | I16: 0 | J16: 0 | K16: 0 | L16: 0 | M16: 0 | N16: 0 | O16: =SUM(C16:N16) -> 28 | Q16: =SUM(L16:M16) -> 0
A17: JUMLAH | C17: =SUM(C9:C16) -> 20 | D17: =SUM(D9:D16) -> 19 | E17: =SUM(E9:E16) -> 59 | F17: =SUM(F9:F16) -> 0 | G17: =SUM(G9:G16) -> 0 | H17: =SUM(H9:H16) -> 0 | I17: =SUM(I9:I16) -> 0 | J17: =SUM(J9:J16) -> 0 | ... O17: =SUM(O9:O16) -> 98
A35: DATA LUAS PANEN KEDELAI PER BULAN
A36: KOTA CILEGON TAHUN 2016
O38: (Ha)
A39: No | B39: Kecamatan | C39: Bulan | O39: Jumlah
C40: Jan | D40: Feb | E40: Maret | F40: Apr | G40: Mei | H40: Juni | I40: Juli | J40: Agst | K40: Sept | L40: Okt | M40: Nov | N40: Des
A41: 1 | B41: 2 | C41: 3 | D41: 4 | E41: 5 | F41: 6 | G41: 7 | H41: 8 | I41: 9 | J41: 10 | K41: 11 | L41: 12 | M41: 13 | N41: 14 | O41: 15
A42: 1 | B42: CIWANDAN | C42: 0 | D42: 0 | E42: 0 | F42: 0 | G42: 0 | H42: 0 | I42: 0 | J42: 0 | K42: 0 | L42: 0 | M42: 0 | N42: 0 | O42: =SUM(C42:N42) -> 0 | Q42: =SUM(C42:E42) -> 0
A43: 2 | B43: CITANGKIL | C43: 1 | D43: 2 | E43: 19 | F43: 3 | G43: 6 | H43: 0 | I43: 0 | J43: 0 | K43: 0 | L43: 0 | M43: 0 | N43: 0 | O43: =SUM(C43:N43) -> 31 | Q43: =SUM(C43:E43) -> 22
A44: 3 | B44: PULOMERAK | C44: 0 | D44: 0 | E44: 40* | F44: 0 | G44: 0 | H44: 0 | I44: 0 | J44: 0 | K44: 0 | L44: 0 | M44: 0 | N44: 0 | O44: =SUM(C44:N44) -> 0 | Q44: =SUM(C44:E44) -> 0
A45: 4 | B45: PURWAKARTA | C45: 0 | D45: 0 | E45: 0 | F45: 0 | G45: 0 | H45: 0 | I45: 0 | J45: 0 | K45: 0 | L45: 0 | M45: 0 | N45: 0 | O45: =SUM(C45:N45) -> 0 | Q45: =SUM(C45:E45) -> 0
A46: 5 | B46: GROGOL | C46: 0 | D46: 4 | E46: 0 | F46: 0 | G46: 10 | H46: 25 | I46: 0 | J46: 0 | K46: 0 | L46: 0 | M46: 0 | N46: 0 | O46: =SUM(C46:N46) -> 39 | Q46: =SUM(C46:E46) -> 4
A47: 6 | B47: CILEGON | C47: 0 | D47: 0 | E47: 0 | F47: 0 | G47: 0 | H47: 0 | I47: 0 | J47: 0 | K47: 0 | L47: 0 | M47: 0 | N47: 0 | O47: =SUM(C47:N47) -> 0 | Q47: =SUM(C47:E47) -> 0
A48: 7 | B48: JOMBANG | C48: 0 | D48: 0 | E48: 0 | F48: 0 | G48: 0 | H48: 0 | I48: 0 | J48: 0 | K48: 0 | L48: 0 | M48: 0 | N48: 0 | O48: =SUM(C48:N48) -> 0 | Q48: =SUM(C48:E48) -> 0
A49: 8 | B49: CIBEBER | C49: 0 | D49: 0 | E49: 0 | F49: 0 | G49: 0 | H49: 28 | I49: 0 | J49: 0 | K49: 0 | L49: 0 | M49: 0 | N49: 0 | O49: =SUM(C49:N49) -> 28 | P49: 15 | Q49: =SUM(C49:E49) -> 0
A50: JUMLAH | C50: =SUM(C42:C49) -> 1 | D50: =SUM(D42:D49) -> 6 | E50: 59 | F50: =SUM(F42:F49) -> 3 | G50: =SUM(G42:G49) -> 16 | H50: =SUM(H42:H49) -> 53 | I50: =SUM(I42:I49) -> 0 | J50: =SUM(J42:J49) -> 0 | K50: =SUM(K42:K49) -> 0 | L50: =SUM(L42:L49) -> 0 | M50: =SUM(M42:M49) -> 0 | ... P50: =SUM(P42:P49) -> 15
A51: Catatan : Cibeber panen muda 5 Ha
A68: DATA PRODUKSI KEDELAI PER BULAN
A69: KOTA CILEGON TAHUN 2016
O71: (Ton)
A72: No | B72: Kecamatan | C72: Bulan | O72: Jumlah
C73: Jan | D73: Feb | E73: Maret | F73: Apr | G73: Mei | H73: Juni | I73: Juli | J73: Agst | K73: Sept | L73: Okt | M73: Nov | N73: Des
A74: 1 | B74: 2 | C74: 3 | D74: 4 | E74: 5 | F74: 6 | G74: 7 | H74: 8 | I74: 9 | J74: 10 | K74: 11 | L74: 12 | M74: 13 | N74: 14 | O74: 15
A75: 1 | B75: CIWANDAN | C75: 0 | D75: 0 | E75: 0 | F75: 0 | G75: 0 | H75: 0 | I75: 0 | J75: 0 | K75: 0 | L75: 0 | M75: 0 | N75: 0 | O75: =SUM(C75:N75) -> 0 | Q75: =SUM(C75:E75) -> 0
A76: 2 | B76: CITANGKIL | C76: 1 | D76: 2 | E76: 15 | F76: 3 | G76: 5 | H76: 0 | I76: 0 | J76: 0 | K76: 0 | L76: 0 | M76: 0 | N76: 0 | O76: =SUM(C76:N76) -> 26 | Q76: =SUM(C76:E76) -> 18
A77: 3 | B77: PULOMERAK | C77: 0 | D77: 0 | E77: 0 | F77: 0 | G77: 9 | H77: 0 | I77: 0 | J77: 0 | K77: 0 | L77: 0 | M77: 0 | N77: 0 | O77: =SUM(C77:N77) -> 9 | Q77: =SUM(C77:E77) -> 0
...

Sheet kc tanah
A2: DATA LUAS TANAM KACANG TANAH PER BULAN
A3: KOTA CILEGON TAHUN 2016
O5: (Ha)
A6: No | B6: Kecamatan | C6: Bulan | O6: Jumlah
C7: Jan | D7: Feb | E7: Maret | F7: Apr | G7: Mei | H7: Juni | I7: Juli | J7: Agst | K7: Sept | L7: Okt | M7: Nov | N7: Des
A8: 1 | B8: 2 | C8: 3 | D8: 4 | E8: 5 | F8: 6 | G8: 7 | H8: 8 | I8: 9 | J8: 10 | K8: 11 | L8: 12 | M8: 13 | N8: 14 | O8: 15
A9: 1 | B9: CIWANDAN | C9: 31 | D9: 0 | E9: 0 | F9: 25 | G9: 105 | H9: 0 | I9: 0 | J9: 0 | K9: 0 | L9: 77 | M9: 49 | N9: 35 | O9: =SUM(C9:N9) -> 322 | Q9: =SUM(F9:K9) -> 130
A10: 2 | B10: CITANGKIL | C10: 125 | D10: 0 | E10: 0 | F10: 0 | G10: 0 | H10: 0 | I10: 0 | J10: 0 | K10: 0 | L10: 122 | M10: 64 | N10: 0 | O10: =SUM(C10:N10) -> 311 | Q10: =SUM(F10:K10) -> 0
A11: 3 | B11: PULOMERAK | C11: 20 | D11: 0 | E11: 0 | F11: 280 | G11: 0 | H11: 0 | I11: 0 | J11: 0 | K11: 0 | L11: 125 | M11: 180 | N11: 0 | O11: =SUM(C11:N11) -> 605 | Q11: =SUM(F11:K11) -> 280
A12: 4 | B12: PURWAKARTA | C12: 22 | D12: 0 | E12: 18 | F12: 0 | G12: 15 | H12: 3 | I12: 17 | J12: 0 | K12: 0 | L12: 11 | M12: 8 | N12: 2 | O12: =SUM(C12:N12) -> 96 | Q12: =SUM(F12:K12) -> 35
A13: 5 | B13: GROGOL | C13: 96 | D13: 0 | E13: 0 | F13: 115 | G13: 0 | H13: 0 | I13: 0 | J13: 0 | K13: 0 | L13: 0 | M13: 230 | N13: 48 | O13: =SUM(C13:N13) -> 489 | Q13: =SUM(F13:K13) -> 115
A14: 6 | B14: CILEGON | C14: 15 | D14: 0 | E14: 20 | F14: 30 | G14: 0 | H14: 0 | I14: 15 | J14: 5 | K14: 0 | L14: 0 | M14: 15 | N14: 0 | O14: =SUM(C14:N14) -> 100 | Q14: =SUM(F14:K14) -> 50
A15: 7 | B15: JOMBANG | C15: 1 | D15: 0 | E15: 1 | F15: 0 | G15: 0 | H15: 0 | I15: 0 | J15: 0 | K15: 0 | L15: 0 | M15: 0 | N15: 0 | O15: =SUM(C15:N15) -> 2 | Q15: =SUM(F15:K15) -> 0
A16: 8 | B16: CIBEBER | C16: 0 | D16: 2 | E16: 75 | F16: 248 | G16: 0 | I16: 225 | J16: 25 | K16: 35 | L16: 175 | M16: 0 | N16: 50 | O16: =SUM(C16:N16) -> 835 | Q16: =SUM(F16:K16) -> 533
A17: JUMLAH | C17: =SUM(C9:C16) -> 310 | D17: =SUM(D9:D16) -> 2 | E17: =SUM(E9:E16) -> 114 | F17: =SUM(F9:F16) -> 698 | G17: =SUM(G9:G16) -> 120 | H17: =SUM(H9:H16) -> 3 | I17: =SUM(I9:I16) -> 257 | J17: =SUM(J9:J16) -> 30 | ... O17: =SUM(O9:O16) -> 2760 | Q17: =SUM(F17:K17) -> 1143
J19: =SUM(C17:J17) -> 1534
A35: DATA LUAS PANEN KACANG TANAH PER BULAN
A36: KOTA CILEGON TAHUN 2016
O38: (Ha)
A39: No | B39: Kecamatan | C39: Bulan | O39: Jumlah
C40: Jan | D40: Feb | E40: Maret | F40: Apr | G40: Mei | H40: Juni | I40: Juli | J40: Agst | K40: Sept | L40: Okt | M40: Nov | N40: Des
A41: 1 | B41: 2 | C41: 3 | D41: 4 | E41: 5 | F41: 6 | G41: 7 | H41: 8 | I41: 9 | J41: 10 | K41: 11 | L41: 12 | M41: 13 | N41: 14 | O41: 15
A42: 1 | B42: CIWANDAN | C42: 0 | D42: 0 | E42: 185 | F42: 31 | G42: 0 | H42: 25 | I42: 105 | J42: 0 | K42: 0 | L42: 0 | M42: 0 | N42: 0 | O42: =SUM(C42:N42) -> 346 | Q42: =SUM(F42:K42) -> 161
A43: 2 | B43: CITANGKIL | C43: 0 | D43: 0 | E43: 0 | F43: 0 | G43: 123 | H43: 63 | I43: 0 | J43: 0 | K43: 0 | L43: 0 | M43: 0 | N43: 0 | O43: =SUM(C43:N43) -> 186 | Q43: =SUM(F43:K43) -> 186
A44: 3 | B44: PULOMERAK | C44: 0 | D44: 0 | E44: 275 | F44: 20 | G44: 0 | H44: 0 | I44: 280 | J44: 0 | K44: 0 | L44: 0 | M44: 0 | N44: 0 | O44: =SUM(C44:N44) -> 575 | Q44: =SUM(F44:K44) -> 300
A45: 4 | B45: PURWAKARTA | C45: 0 | D45: 5 | E45: 141 | F45: 5 | G45: 0 | H45: 18 | I45: 0 | J45: 15 | K45: 20 | L45: 17 | M45: 0 | N45: 0 | O45: =SUM(C45:N45) -> 221 | Q45: =SUM(F45:K45) -> 58
A46: 5 | B46: GROGOL | C46: 0 | D46: 0 | E46: 102 | F46: 96 | G46: 0 | H46: 0 | I46: 115 | J46: 0 | K46: 0 | L46: 0 | M46: 0 | N46: 0 | O46: =SUM(C46:N46) -> 313 | Q46: =SUM(F46:K46) -> 211
A47: 6 | B47: CILEGON | C47: 0 | D47: 15 | E47: 65 | F47: 0 | G47: 0 | H47: 50 | I47: 0 | J47: 0 | K47: 0 | L47: 15 | M47: 5 | N47: 0 | O47: =SUM(C47:N47) -> 150 | Q47: =SUM(F47:K47) -> 50
A48: 7 | B48: JOMBANG | C48: 0 | D48: 0 | E48: 1 | F48: 0 | G48: 0 | H48: 1 | I48: 0 | J48: 0 | K48: 0 | L48: 0 | M48: 0 | N48: 0 | O48: =SUM(C48:N48) -> 2 | Q48: =SUM(F48:K48) -> 1
A49: 8 | B49: CIBEBER | C49: 0 | D49: 0 | E49: 332 | F49: 0 | G49: 2 | I49: 248 | J49: 0 | K49: 30 | L49: 225 | M49: 25 | N49: 175 | O49: =SUM(C49:N49) -> 1037 | Q49: =SUM(F49:K49) -> 280
A50: JUMLAH | C50: =SUM(C42:C49) -> 0 | D50: =SUM(D42:D49) -> 20 | E50: =SUM(E42:E49) -> 1101 | F50: =SUM(F42:F49) -> 152 | G50: =SUM(G42:G49) -> 125 | H50: =SUM(H42:H49) -> 157 | I50: =SUM(I42:I49) -> 748 | J50: =SUM(J42:J49) -> 15 | ... O50: =SUM(O42:O49) -> 2830 | Q50: =SUM(F50:K50) -> 1247
A68: DATA PRODUKSI KACANG TANAH PER BULAN
A69: KOTA CILEGON TAHUN 2016
O71: (Ton)
A72: No | B72: Kecamatan | C72: Bulan | O72: Jumlah
C73: Jan | D73: Feb | E73: Maret | F73: Apr | G73: Mei | H73: Juni | I73: Juli | J73: Agst | K73: Sept | L73: Okt | M73: Nov | N73: Des
A74: 1 | B74: 2 | C74: 3 | D74: 4 | E74: 5 | F74: 6 | G74: 7 | H74: 8 | I74: 9 | J74: 10 | K74: 11 | L74: 12 | M74: 13 | N74: 14 | O74: 15
A75: 1 | B75: CIWANDAN | C75: 0 | D75: 0 | E75: 155 | F75: 24 | G75: 0 | H75: 18 | I75: 69 | J75: 0 | K75: 0 | L75: 0 | M75: 0 | N75: 0 | O75: =SUM(C75:N75) -> 266 | Q75: =SUM(F75:K75) -> 111
A76: 2 | B76: CITANGKIL | C76: 0 | D76: 0 | E76: 0 | F76: 0 | G76: 123 | H76: 47 | I76: 0 | J76: 0 | K76: 0 | L76: 0 | M76: 0 | N76: 0 | O76: =SUM(C76:N76) -> 170 | Q76: =SUM(F76:K76) -> 170
A77: 3 | B77: PULOMERAK | C77: 0 | D77: 0 | E77: 247 | F77: 18 | G77: 0 | H77: 0 | I77: 206 | J77: 0 | K77: 0 | L77: 0 | M77: 0 | N77: 0 | O77: =SUM(C77:N77) -> 471 | Q77: =SUM(F77:K77) -> 224
...

Sheet ubi kayu
A2: DATA LUAS TANAM UBI KAYU PER BULAN
A3: KOTA CILEGON TAHUN 2016
O5: (Ha)
A6: No | B6: Kecamatan | C6: Bulan | O6: Jumlah
C7: Jan | D7: Feb | E7: Maret | F7: Apr | G7: Mei | H7: Juni | I7: Juli | J7: Agst | K7: Sept | L7: Okt | M7: Nov | N7: Des
A8: 1 | B8: 2 | C8: 3 | D8: 4 | E8: 5 | F8: 6 | G8: 7 | H8: 8 | I8: 9 | J8: 10 | K8: 11 | L8: 12 | M8: 13 | N8: 14 | O8: 15 | Q8: APR-SEP
A9: 1 | B9: CIWANDAN | C9: 2 | D9: 10 | E9: 0 | F9: 0 | G9: 0 | H9: 0 | I9: 0 | J9: 0 | K9: 0 | L9: 1 | M9: 5 | N9: 0 | O9: =SUM(C9:N9) -> 18 | Q9: =SUM(F9:K9) -> 0
A10: 2 | B10: CITANGKIL | C10: 1 | D10: 0 | E10: 0 | F10: 0 | G10: 1 | H10: 1 | I10: 1 | J10: 0 | K10: 0 | L10: 0 | M10: 0 | N10: 1 | O10: =SUM(C10:N10) -> 5 | Q10: =SUM(F10:K10) -> 3
A11: 3 | B11: PULOMERAK | C11: 0 | D11: 0 | E11: 0 | F11: 0 | G11: 0 | H11: 0 | I11: 0 | J11: 0 | K11: 0 | L11: 4 | M11: 3 | N11: 2 | O11: =SUM(C11:N11) -> 9 | Q11: =SUM(F11:K11) -> 0
A12: 4 | B12: PURWAKARTA | C12: 0 | D12: 0 | E12: 0 | F12: 0 | G12: 2 | H12: 0 | I12: 0 | J12: 0 | K12: 2 | L12: 0 | M12: 2 | N12: 1 | O12: =SUM(C12:N12) -> 7 | Q12: =SUM(F12:K12) -> 4
A13: 5 | B13: GROGOL | C13: 0 | D13: 0 | E13: 0 | F13: 0 | G13: 0 | H13: 0 | I13: 0 | J13: 0 | K13: 0 | L13: 0 | M13: 1 | N13: 0 | O13: =SUM(C13:N13) -> 1 | Q13: =SUM(F13:K13) -> 0
A14: 6 | B14: CILEGON | C14: 0 | D14: 0 | E14: 5 | F14: 0 | G14: 0 | H14: 0 | I14: 3 | J14: 0 | K14: 0 | L14: 0 | M14: 0 | N14: 3 | O14: =SUM(C14:N14) -> 11 | Q14: =SUM(F14:K14) -> 3
A15: 7 | B15: JOMBANG | C15: 0 | D15: 0 | E15: 0 | F15: 0 | G15: 0 | H15: 0 | I15: 0 | J15: 0 | K15: 0 | L15: 0 | M15: 0 | N15: 0 | O15: =SUM(C15:N15) -> 0 | Q15: =SUM(F15:K15) -> 0
A16: 8 | B16: CIBEBER | C16: 0 | D16: 2 | E16: 2 | F16: 2 | G16: 0 | I16: 2 | J16: 0 | K16: 3 | L16: 5 | M16: 0 | N16: 0 | O16: =SUM(C16:N16) -> 16 | Q16: =SUM(F16:K16) -> 7
A17: JUMLAH | C17: =SUM(C9:C16) -> 3 | D17: =SUM(D9:D16) -> 12 | E17: =SUM(E9:E16) -> 7 | F17: =SUM(F9:F16) -> 2 | G17: =SUM(G9:G16) -> 3 | H17: =SUM(H9:H16) -> 1 | I17: =SUM(I9:I16) -> 6 | J17: =SUM(J9:J16) -> 0 | ... O17: =SUM(O9:O16) -> 67 | Q17: =SUM(F17:K17) -> 17
A34: DATA LUAS PANEN UBI KAYU PER BULAN
A35: KOTA CILEGON TAHUN 2016
O37: (Ha)
A38: No | B38: Kecamatan | C38: Bulan | O38: Jumlah
C39: Jan | D39: Feb | E39: Maret | F39: Apr | G39: Mei | H39: Juni | I39: Juli | J39: Agst | K39: Sept | L39: Okt | M39: Nov | N39: Des
A40: 1 | B40: 2 | C40: 3 | D40: 4 | E40: 5 | F40: 6 | G40: 7 | H40: 8 | I40: 9 | J40: 10 | K40: 11 | L40: 12 | M40: 13 | N40: 14 | O40: 15
A41: 1 | B41: CIWANDAN | C41: 0 | D41: 0 | E41: 0 | F41: 0 | G41: 0 | H41: 0 | I41: 9 | J41: 2 | K41: 0 | L41: 2 | M41: 0 | N41: 0 | O41: =SUM(C41:N41) -> 13 | Q41: =SUM(F41:K41) -> 11
A42: 2 | B42: CITANGKIL | C42: 0 | D42: 0 | E42: 0 | F42: 0 | G42: 1 | H42: 0 | I42: 0 | J42: 0 | K42: 1 | L42: 0 | M42: 0 | N42: 0 | O42: =SUM(C42:N42) -> 2 | Q42: =SUM(F42:K42) -> 2
A43: 3 | B43: PULOMERAK | C43: 0 | D43: 0 | E43: 0 | F43: 4 | G43: 0 | H43: 0 | I43: 0 | J43: 2 | K43: 0 | L43: 2 | M43: 0 | N43: 0 | O43: =SUM(C43:N43) -> 8 | Q43: =SUM(F43:K43) -> 6
A44: 4 | B44: PURWAKARTA | C44: 0 | D44: 0 | E44: 0 | F44: 1 | G44: 0 | H44: 2 | I44: 0 | J44: 0 | K44: 0 | L44: 0 | M44: 1 | N44: 2 | O44: =SUM(C44:N44) -> 6 | Q44: =SUM(F44:K44) -> 3
A45: 5 | B45: GROGOL | C45: 0 | D45: 0 | E45: 0 | F45: 0 | G45: 0 | H45: 1 | I45: 0 | J45: 0 | K45: 0 | L45: 0 | M45: 0 | N45: 0 | O45: =SUM(C45:N45) -> 1 | Q45: =SUM(F45:K45) -> 1
A46: 6 | B46: CILEGON | C46: 0 | D46: 0 | E46: 0 | F46: 0 | G46: 0 | H46: 0 | I46: 2 | J46: 2 | K46: 0 | L46: 0 | M46: 4 | N46: 0 | O46: =SUM(C46:N46) -> 8 | Q46: =SUM(F46:K46) -> 4
A47: 7 | B47: JOMBANG | C47: 0 | D47: 0 | E47: 0 | F47: 0 | G47: 0 | H47: 0 | I47: 0 | J47: 0 | K47: 0 | L47: 0 | M47: 0 | N47: 0 | O47: =SUM(C47:N47) -> 0 | Q47: =SUM(F47:K47) -> 0
A48: 8 | B48: CIBEBER | C48: 4 | D48: 0 | E48: 4 | F48: 0 | G48: 0 | I48: 0 | J48: 0 | K48: 8 | L48: 0 | M48: 0 | N48: 2 | O48: =SUM(C48:N48) -> 18 | Q48: =SUM(F48:K48) -> 8
A49: JUMLAH | C49: =SUM(C41:C48) -> 4 | D49: =SUM(D41:D48) -> 0 | E49: =SUM(E41:E48) -> 4 | F49: =SUM(F41:F48) -> 5 | G49: =SUM(G41:G48) -> 1 | H49: =SUM(H41:H48) -> 3 | I49: =SUM(I41:I48) -> 11 | J49: =SUM(J41:J48) -> 6 | ... O49: =SUM(O41:O48) -> 56 | Q49: =SUM(F49:K49) -> 35
A68: DATA PRODUKSI UBI KAYU PER BULAN
A69: KOTA CILEGON TAHUN 2016
O71: (Ton)
A72: No | B72: Kecamatan | C72: Bulan | O72: Jumlah
C73: Jan | D73: Feb | E73: Maret | F73: Apr | G73: Mei | H73: Juni | I73: Juli | J73: Agst | K73: Sept | L73: Okt | M73: Nov | N73: Des
A74: 1 | B74: 2 | C74: 3 | D74: 4 | E74: 5 | F74: 6 | G74: 7 | H74: 8 | I74: 9 | J74: 10 | K74: 11 | L74: 12 | M74: 13 | N74: 14 | O74: 15
A75: 1 | B75: CIWANDAN | C75: 0 | D75: 0 | E75: 0 | F75: 0 | G75: 0 | H75: 0 | I75: 89 | J75: 18 | K75: 0 | L75: 19 | M75: 0 | N75: 0 | O75: =SUM(C75:N75) -> 126 | Q75: =SUM(F75:K75) -> 107
A76: 2 | B76: CITANGKIL | C76: 0 | D76: 0 | E76: 0 | F76: 0 | G76: 12 | H76: 0 | I76: 0 | J76: 0 | K76: 10 | L76: 0 | M76: 0 | N76: 0 | O76: =SUM(C76:N76) -> 22 | Q76: =SUM(F76:K76) -> 22
A77: 3 | B77: PULOMERAK | C77: 0 | D77: 0 | E77: 0 | F77: 68 | G77: 0 | H77: 0 | I77: 0 | J77: 34 | K77: 0 | L77: 26 | M77: 0 | N77: 0 | O77: =SUM(C77:N77) -> 128 | Q77: =SUM(F77:K77) -> 102
A78: 4 | B78: PURWAKARTA | C78: 0 | D78: 0 | E78: 0 | F78: 12 | G78: 0 | H78: 30 | I78: 0 | J78: 0 | K78: 0 | L78: 0 | M78: 15 | N78: 37 | O78: =SUM(C78:N78) -> 94 | Q78: =SUM(F78:K78) -> 42
...

Sheet ubi jalar
A2: DATA LUAS TANAM UBI JALAR PER BULAN
A3: KOTA CILEGON TAHUN 2016
O5: (Ha)
A6: No | B6: Kecamatan | C6: Bulan | O6: Jumlah
C7: Jan | D7: Feb | E7: Maret | F7: Apr | G7: Mei | H7: Juni | I7: Juli | J7: Agst | K7: Sept | L7: Okt | M7: Nov | N7: Des
A8: 1 | B8: 2 | C8: 3 | D8: 4 | E8: 5 | F8: 6 | G8: 7 | H8: 8 | I8: 9 | J8: 10 | K8: 11 | L8: 12 | M8: 13 | N8: 14 | O8: 15 | Q8: APR-SEP
A9: 1 | B9: CIWANDAN | C9: 1 | D9: 4 | E9: 0 | F9: 2 | G9: 0 | H9: 0 | I9: 0 | J9: 0 | K9: 0 | L9: 1 | M9: 2 | N9: 2 | O9: =SUM(C9:N9) -> 12 | Q9: =SUM(F9:K9) -> 2
A10: 2 | B10: CITANGKIL | C10: 2 | D10: 0 | E10: 0 | F10: 0 | G10: 0 | H10: 1 | I10: 1 | J10: 0 | K10: 1 | L10: 1 | M10: 0 | N10: 0 | O10: =SUM(C10:N10) -> 6 | Q10: =SUM(F10:K10) -> 3
A11: 3 | B11: PULOMERAK | C11: 0 | D11: 0 | E11: 0 | F11: 0 | G11: 0 | H11: 0 | I11: 0 | J11: 0 | K11: 0 | L11: 0 | M11: 0 | N11: 0 | O11: =SUM(C11:N11) -> 0 | Q11: =SUM(F11:K11) -> 0
A12: 4 | B12: PURWAKARTA | C12: 0 | D12: 0 | E12: 0 | F12: 1 | G12: 1 | H12: 0 | I12: 0 | J12: 0 | K12: 1 | L12: 1 | M12: 1 | N12: 2 | O12: =SUM(C12:N12) -> 7 | Q12: =SUM(F12:K12) -> 3
A13: 5 | B13: GROGOL | C13: 0 | D13: 0 | E13: 2 | F13: 0 | G13: 1 | H13: 0 | I13: 0 | J13: 0 | K13: 0 | L13: 0 | M13: 0 | N13: 0 | O13: =SUM(C13:N13) -> 3 | Q13: =SUM(F13:K13) -> 1
A14: 6 | B14: CILEGON | C14: 0 | D14: 0 | E14: 0 | F14: 0 | G14: 0 | H14: 0 | I14: 0 | J14: 0 | K14: 0 | L14: 0 | M14: 0 | N14: 0 | O14: =SUM(C14:N14) -> 0 | Q14: =SUM(F14:K14) -> 0
A15: 7 | B15: JOMBANG | C15: 0 | D15: 0 | E15: 0 | F15: 0 | G15: 0 | H15: 0 | I15: 0 | J15: 0 | K15: 0 | L15: 0 | M15: 0 | N15: 0 | O15: =SUM(C15:N15) -> 0 | Q15: =SUM(F15:K15) -> 0
A16: 8 | B16: CIBEBER | C16: 0 | D16: 0 | E16: 1 | F16: 0 | G16: 0 | I16: 0 | J16: 1 | K16: 1 | L16: 1 | M16: 0 | N16: 0 | O16: =SUM(C16:N16) -> 4 | Q16: =SUM(F16:K16) -> 2
A17: JUMLAH | C17: =SUM(C9:C16) -> 3 | D17: =SUM(D9:D16) -> 4 | E17: =SUM(E9:E16) -> 3 | F17: =SUM(F9:F16) -> 3 | G17: =SUM(G9:G16) -> 2 | H17: =SUM(H9:H16) -> 1 | I17: =SUM(I9:I16) -> 1 | J17: =SUM(J9:J16) -> 1 | ... O17: =SUM(O9:O16) -> 32 | Q17: =SUM(F17:K17) -> 11
A35: DATA LUAS PANEN UBI JALAR PER BULAN
A36: KOTA CILEGON TAHUN 2016
O38: (Ha)
A39: No | B39: Kecamatan | C39: Bulan | O39: Jumlah
C40: Jan | D40: Feb | E40: Maret | F40: Apr | G40: Mei | H40: Juni | I40: Juli | J40: Agst | K40: Sept | L40: Okt | M40: Nov | N40: Des
A41: 1 | B41: 2 | C41: 3 | D41: 4 | E41: 5 | F41: 6 | G41: 7 | H41: 8 | I41: 9 | J41: 10 | K41: 11 | L41: 12 | M41: 13 | N41: 14 | O41: 15
A42: 1 | B42: CIWANDAN | C42: 0 | D42: 0 | E42: 3 | F42: 4 | G42: 0 | H42: 0 | I42: 0 | J42: 2 | K42: 0 | L42: 0 | M42: 0 | N42: 0 | O42: =SUM(C42:N42) -> 9 | Q42: =SUM(F42:K42) -> 6
A43: 2 | B43: CITANGKIL | C43: 0 | D43: 0 | E43: 0 | F43: 0 | G43: 3 | H43: 0 | I43: 0 | J43: 0 | K43: 0 | L43: 1 | M43: 0 | N43: 0 | O43: =SUM(C43:N43) -> 4 | Q43: =SUM(F43:K43) -> 3
A44: 3 | B44: PULOMERAK | C44: 0 | D44: 0 | E44: 0 | F44: 0 | G44: 0 | H44: 0 | I44: 0 | J44: 0 | K44: 0 | L44: 0 | M44: 0 | N44: 0 | O44: =SUM(C44:N44) -> 0 | Q44: =SUM(F44:K44) -> 0
A45: 4 | B45: PURWAKARTA | C45: 0 | D45: 0 | E45: 1 | F45: 1 | G45: 0 | H45: 0 | I45: 0 | J45: 0 | K45: 0 | L45: 2 | M45: 0 | N45: 2 | O45: =SUM(C45:N45) -> 6 | Q45: =SUM(F45:K45) -> 1
A46: 5 | B46: GROGOL | C46: 0 | D46: 0 | E46: 1 | F46: 0 | G46: 0 | H46: 0 | I46: 1 | J46: 0 | K46: 0 | L46: 1 | M46: 0 | N46: 0 | O46: =SUM(C46:N46) -> 3 | Q46: =SUM(F46:K46) -> 1
A47: 6 | B47: CILEGON | C47: 0 | D47: 0 | E47: 0 | F47: 0 | G47: 0 | H47: 0 | I47: 0 | J47: 0 | K47: 0 | L47: 0 | M47: 0 | N47: 0 | O47: =SUM(C47:N47) -> 0 | Q47: =SUM(F47:K47) -> 0
A48: 7 | B48: JOMBANG | C48: 0 | D48: 0 | E48: 0 | F48: 0 | G48: 0 | H48: 0 | I48: 0 | J48: 0 | K48: 0 | L48: 0 | M48: 0 | N48: 0 | O48: =SUM(C48:N48) -> 0 | Q48: =SUM(F48:K48) -> 0
A49: 8 | B49: CIBEBER | C49: 1 | D49: 0 | E49: 1 | F49: 0 | G49: 0 | H49: 0 | I49: 0 | J49: 0 | K49: 2 | L49: 1 | M49: 0 | N49: 0 | O49: =SUM(C49:N49) -> 5 | Q49: =SUM(F49:K49) -> 2
A50: JUMLAH | C50: =SUM(C42:C49) -> 1 | D50: =SUM(D42:D49) -> 0 | E50: =SUM(E42:E49) -> 6 | F50: =SUM(F42:F49) -> 5 | G50: =SUM(G42:G49) -> 3 | H50: =SUM(H42:H49) -> 0 | I50: =SUM(I42:I49) -> 1 | J50: =SUM(J42:J49) -> 2 | ... O50: =SUM(O42:O49) -> 27 | Q50: =SUM(F50:K50) -> 13
A68: DATA PRODUKSI UBI JALAR PER BULAN
A69: KOTA CILEGON TAHUN 2016
O71: (Ton)
A72: No | B72: Kecamatan | C72: Bulan | O72: Jumlah
C73: Jan | D73: Feb | E73: Maret | F73: Apr | G73: Mei | H73: Juni | I73: Juli | J73: Agst | K73: Sept | L73: Okt | M73: Nov | N73: Des
A74: 1 | B74: 2 | C74: 3 | D74: 4 | E74: 5 | F74: 6 | G74: 7 | H74: 8 | I74: 9 | J74: 10 | K74: 11 | L74: 12 | M74: 13 | N74: 14 | O74: 15
A75: 1 | B75: CIWANDAN | C75: 0 | D75: 0 | E75: 33 | F75: 38 | G75: 0 | H75: 0 | I75: 0 | J75: 17 | K75: 0 | L75: 0 | M75: 0 | N75: 0 | O75: =SUM(C75:N75) -> 88 | Q75: =SUM(F75:K75) -> 55
A76: 2 | B76: CITANGKIL | C76: 0 | D76: 0 | E76: 0 | F76: 0 | G76: 30 | H76: 0 | I76: 0 | J76: 0 | K76: 0 | L76: 9 | M76: 0 | N76: 0 | O76: =SUM(C76:N76) -> 39 | Q76: =SUM(F76:K76) -> 30
A77: 3 | B77: PULOMERAK | C77: 0 | D77: 0 | E77: 0 | F77: 0 | G77: 0 | H77: 0 | I77: 0 | J77: 0 | K77: 0 | L77: 0 | M77: 0 | N77: 0 | O77: =SUM(C77:N77) -> 0 | Q77: =SUM(F77:K77) -> 0
A78: 4 | B78: PURWAKARTA | C78: 0 | D78: 0 | E78: 11 | F78: 11 | G78: 0 | H78: 0 | I78: 0 | J78: 0 | K78: 0 | L78: 30 | M78: 0 | N78: 25 | O78: =SUM(C78:N78) -> 77 | Q78: =SUM(F78:K78) -> 11
...

Sheet kc ijo
A2: DATA LUAS TANAM KACANG HIJAU PER BULAN
A3: KOTA CILEGON TAHUN 2016
O5: (Ha)
A6: No | B6: Kecamatan | C6: Bulan | O6: Jumlah
C7: Jan | D7: Feb | E7: Maret | F7: Apr | G7: Mei | H7: Juni | I7: Juli | J7: Agst | K7: Sept | L7: Okt | M7: Nov | N7: Des
A8: 1 | B8: 2 | C8: 3 | D8: 4 | E8: 5 | F8: 6 | G8: 7 | H8: 8 | I8: 9 | J8: 10 | K8: 11 | L8: 12 | M8: 13 | N8: 14 | O8: 15 | Q8: APR-SEP
A9: 1 | B9: CIWANDAN | C9: 1 | D9: 2 | E9: 0 | F9: 0 | G9: 0 | H9: 0 | I9: 0 | J9: 0 | K9: 0 | L9: 0 | M9: 0 | N9: 2 | O9: =SUM(C9:N9) -> 5 | Q9: =SUM(F9:K9) -> 0
A10: 2 | B10: CITANGKIL | C10: 1 | D10: 0 | E10: 0 | F10: 0 | G10: 0 | H10: 1 | I10: 0 | J10: 0 | K10: 0 | L10: 0 | M10: 0 | N10: 0 | O10: =SUM(C10:N10) -> 2 | Q10: =SUM(F10:K10) -> 1
A11: 3 | B11: PULOMERAK | C11: 0 | D11: 0 | E11: 0 | F11: 0 | G11: 1 | H11: 2 | I11: 0 | J11: 0 | K11: 0 | L11: 0 | M11: 0 | N11: 0 | O11: =SUM(C11:N11) -> 3 | Q11: =SUM(F11:K11) -> 3
A12: 4 | B12: PURWAKARTA | C12: 0 | D12: 0 | E12: 0 | F12: 0 | G12: 0 | H12: 11 | I12: 1 | J12: 0 | K12: 0 | L12: 1 | M12: 0 | N12: 2 | O12: =SUM(C12:N12) -> 15 | Q12: =SUM(F12:K12) -> 12
A13: 5 | B13: GROGOL | C13: 0 | D13: 0 | E13: 0 | F13: 0 | G13: 1 | H13: 0 | I13: 0 | J13: 0 | K13: 0 | L13: 0 | M13: 0 | N13: 0 | O13: =SUM(C13:N13) -> 1 | Q13: =SUM(F13:K13) -> 1
A14: 6 | B14: CILEGON | C14: 0 | D14: 0 | E14: 0 | F14: 0 | G14: 0 | H14: 0 | I14: 0 | J14: 0 | K14: 0 | L14: 0 | M14: 0 | N14: 0 | O14: =SUM(C14:N14) -> 0 | Q14: =SUM(F14:K14) -> 0
A15: 7 | B15: JOMBANG | C15: 0 | D15: 0 | E15: 0 | F15: 0 | G15: 0 | H15: 0 | I15: 0 | J15: 0 | K15: 0 | L15: 0 | M15: 0 | N15: 0 | O15: =SUM(C15:N15) -> 0 | Q15: =SUM(F15:K15) -> 0
A16: 8 | B16: CIBEBER | C16: 0 | D16: 0 | E16: 0 | F16: 0 | G16: 0 | I16: 0 | J16: 1 | K16: 0 | L16: 0 | M16: 0 | N16: 0 | O16: =SUM(C16:N16) -> 1 | Q16: =SUM(F16:K16) -> 1
A17: JUMLAH | C17: =SUM(C9:C16) -> 2 | D17: =SUM(D9:D16) -> 2 | E17: =SUM(E9:E16) -> 0 | F17: =SUM(F9:F16) -> 0 | G17: =SUM(G9:G16) -> 2 | H17: =SUM(H9:H16) -> 14 | I17: =SUM(I9:I16) -> 1 | J17: =SUM(J9:J16) -> 1 | ... O17: =SUM(O9:O16) -> 27 | Q17: =SUM(F17:K17) -> 18
A35: DATA LUAS PANEN KACANG HIJAU PER BULAN
A36: KOTA CILEGON TAHUN 2016
O38: (Ha)
A39: No | B39: Kecamatan | C39: Bulan | O39: Jumlah
C40: Jan | D40: Feb | E40: Maret | F40: Apr | G40: Mei | H40: Juni | I40: Juli | J40: Agst | K40: Sept | L40: Okt | M40: Nov | N40: Des
A41: 1 | B41: 2 | C41: 3 | D41: 4 | E41: 5 | F41: 6 | G41: 7 | H41: 8 | I41: 9 | J41: 10 | K41: 11 | L41: 12 | M41: 13 | N41: 14 | O41: 15
A42: 1 | B42: CIWANDAN | C42: 0 | D42: 0 | E42: 3 | F42: 0 | G42: 0 | H42: 0 | I42: 0 | J42: 0 | K42: 0 | L42: 0 | M42: 0 | O42: =SUM(C42:N42) -> 3 | Q42: =SUM(F42:K42) -> 0
A43: 2 | B43: CITANGKIL | C43: 0 | D43: 0 | E43: 0 | F43: 0 | G43: 1 | H43: 0 | I43: 0 | J43: 0 | K43: 0 | L43: 0 | M43: 0 | N43: 0 | O43: =SUM(C43:N43) -> 1 | Q43: =SUM(F43:K43) -> 1
A44: 3 | B44: PULOMERAK | C44: 0 | D44: 0 | E44: 0 | F44: 0 | G44: 0 | H44: 0 | I44: 0 | J44: 3 | K44: 0 | L44: 0 | M44: 0 | N44: 0 | O44: =SUM(C44:N44) -> 3 | Q44: =SUM(F44:K44) -> 3
A45: 4 | B45: PURWAKARTA | C45: 0 | D45: 0 | E45: 0 | F45: 0 | G45: 0 | H45: 0 | I45: 0 | J45: 11 | K45: 1 | L45: 0 | M45: 0 | N45: 1 | O45: =SUM(C45:N45) -> 13 | Q45: =SUM(F45:K45) -> 12
A46: 5 | B46: GROGOL | C46: 0 | D46: 0 | E46: 0 | F46: 0 | G46: 0 | H46: 0 | I46: 1 | J46: 0 | K46: 0 | L46: 0 | M46: 0 | N46: 0 | O46: =SUM(C46:N46) -> 1 | Q46: =SUM(F46:K46) -> 1
A47: 6 | B47: CILEGON | C47: 0 | D47: 0 | E47: 0 | F47: 0 | G47: 0 | H47: 0 | I47: 0 | J47: 0 | K47: 0 | L47: 0 | M47: 0 | N47: 0 | O47: =SUM(C47:N47) -> 0 | Q47: =SUM(F47:K47) -> 0
A48: 7 | B48: JOMBANG | C48: 0 | D48: 0 | E48: 0 | F48: 0 | G48: 0 | H48: 0 | I48: 0 | J48: 0 | K48: 0 | L48: 0 | M48: 0 | N48: 0 | O48: =SUM(C48:N48) -> 0 | Q48: =SUM(F48:K48) -> 0
A49: 8 | B49: CIBEBER | C49: 0 | D49: 0 | E49: 0 | F49: 0 | G49: 0 | H49: 0 | I49: 0 | J49: 0 | K49: 0 | L49: 1 | M49: 0 | N49: 0 | O49: =SUM(C49:N49) -> 1 | Q49: =SUM(F49:K49) -> 0
A50: JUMLAH | C50: =SUM(C42:C49) -> 0 | D50: =SUM(D42:D49) -> 0 | E50: =SUM(E42:E49) -> 3 | F50: =SUM(F42:F49) -> 0 | G50: =SUM(G42:G49) -> 1 | H50: =SUM(H42:H49) -> 0 | I50: =SUM(I42:I49) -> 1 | J50: =SUM(J42:J49) -> 14 | ... O50: =SUM(O42:O49) -> 22 | Q50: =SUM(F50:K50) -> 17
A68: DATA PRODUKSI KACANG HIJAU PER BULAN
A69: KOTA CILEGON TAHUN 2016
O71: (Ton)
A72: No | B72: Kecamatan | C72: Bulan | O72: Jumlah
C73: Jan | D73: Feb | E73: Maret | F73: Apr | G73: Mei | H73: Juni | I73: Juli | J73: Agst | K73: Sept | L73: Okt | M73: Nov | N73: Des
A74: 1 | B74: 2 | C74: 3 | D74: 4 | E74: 5 | F74: 6 | G74: 7 | H74: 8 | I74: 9 | J74: 10 | K74: 11 | L74: 12 | M74: 13 | N74: 14 | O74: 15
A75: 1 | B75: CIWANDAN | C75: 0 | D75: 0 | E75: 2 | F75: 0 | G75: 0 | H75: 0 | I75: 0 | J75: 0 | K75: 0 | L75: 0 | M75: 0 | O75: =SUM(C75:N75) -> 2 | Q75: =SUM(F75:K75) -> 0
A76: 2 | B76: CITANGKIL | C76: 0 | D76: 0 | E76: 0 | F76: 0 | G76: 1 | H76: 0 | I76: 0 | J76: 0 | K76: 0 | L76: 0 | M76: 0 | N76: 0 | O76: =SUM(C76:N76) -> 1 | Q76: =SUM(F76:K76) -> 1
A77: 3 | B77: PULOMERAK | C77: 0 | D77: 0 | E77: 0 | F77: 0 | G77: 0 | H77: 0 | I77: 0 | J77: 2.4 | K77: 0 | L77: 0 | M77: 0 | N77: 0 | O77: =SUM(C77:N77) -> 2.4 | Q77: =SUM(F77:K77) -> 2.4
A78: 4 | B78: PURWAKARTA | C78: 0 | D78: 0 | E78: 0 | F78: 0 | G78: 0 | H78: 0 | I78: 0 | J78: 8.8 | K78: 0.6 | L78: 0 | M78: 0 | N78: 0.6 | O78: =SUM(C78:N78) -> 10 | Q78: =SUM(F78:K78) -> 9.4
...

Sheet rekap
A1: REALISASI TANAM, PANEN, PRODUKSI DAN PRODUKTIVITAS PADI DAN PALAWIJA
A2: KOTA CILEGON 2016
A4: 1. PADI SAWAH
A5: No | B5: Kecamatan | C5: TANAM | D5: PANEN | E5: PRODUKSI | F5: PRODUKTIVITAS
C6: (Ha) | D6: (Ha) | E6: (Ton) | F6: (Ku/Ha)
A7: 1 | B7: 2 | C7: 3 | D7: 4 | E7: 5 | F7: 6
A8: 1 | B8: CIWANDAN | C8: ='padi sawah'!O9 -> 377 | D8: ='padi sawah'!O42 -> 330 | E8: ='padi sawah'!O75 -> 1694 | F8: ='padi sawah'!O108 -> 51.333333
A9: 2 | B9: CITANGKIL | C9: ='padi sawah'!O10 -> 491 | D9: ='padi sawah'!O43 -> 341 | E9: ='padi sawah'!O76 -> 2451 | F9: ='padi sawah'!O109 -> 71.876833
A10: 3 | B10: PULOMERAK | C10: ='padi sawah'!O11 -> 55 | D10: ='padi sawah'!O44 -> 40 | E10: ='padi sawah'!O77 -> 221 | F10: ='padi sawah'!O110 -> 55.25
A11: 4 | B11: PURWAKARTA | C11: ='padi sawah'!O12 -> 270 | D11: ='padi sawah'!O45 -> 240 | E11: ='padi sawah'!O78 -> 1407 | F11: ='padi sawah'!O111 -> 58.625
A12: 5 | B12: GROGOL | C12: ='padi sawah'!O13 -> 209 | D12: ='padi sawah'!O46 -> 194 | E12: ='padi sawah'!O79 -> 1147 | F12: ='padi sawah'!O112 -> 59.123711
A13: 6 | B13: CILEGON | C13: ='padi sawah'!O14 -> 138 | D13: ='padi sawah'!O47 -> 100 | E13: ='padi sawah'!O80 -> 673 | F13: ='padi sawah'!O113 -> 67.3
A14: 7 | B14: JOMBANG | C14: ='padi sawah'!O15 -> 598 | D14: ='padi sawah'!O48 -> 622 | E14: ='padi sawah'!O81 -> 3660 | F14: ='padi sawah'!O114 -> 58.842444
A15: 8 | B15: CIBEBER | C15: ='padi sawah'!O16 -> 756 | D15: ='padi sawah'!O49 -> 551 | E15: ='padi sawah'!O82 -> 3841 | F15: ='padi sawah'!O115 -> 69.709619
A16: JUMLAH | C16: =SUM(C8:C15) -> 2894 | D16: =SUM(D8:D15) -> 2418 | E16: =SUM(E8:E15) -> 15094 | F16: =E16/D16*10 -> 62.42349
A18: 2. PADI LADANG
A19: No | B19: Kecamatan | C19: TANAM | D19: PANEN | E19: PRODUKSI | F19: PRODUKTIVITAS
C20: (Ha) | D20: (Ha) | E20: (Ton) | F20: (Ku/Ha)
A21: 1 | B21: 2 | C21: 3 | D21: 4 | E21: 5 | F21: 6
A22: 1 | B22: CIWANDAN | C22: ='padi ladang'!O9 -> 0 | D22: ='padi ladang'!O42 -> 0 | E22: ='padi ladang'!O75 -> 0 | F22: ='padi ladang'!O108 -> 0
A23: 2 | B23: CITANGKIL | C23: ='padi ladang'!O10 -> 0 | D23: ='padi ladang'!O43 -> 0 | E23: ='padi ladang'!O76 -> 0 | F23: ='padi ladang'!O109 -> 0
A24: 3 | B24: PULOMERAK | C24: ='padi ladang'!O11 -> 74 | D24: ='padi ladang'!O44 -> 15 | E24: ='padi ladang'!O77 -> 59 | F24: ='padi ladang'!O110 -> 39.333333
A25: 4 | B25: PURWAKARTA | C25: ='padi ladang'!O12 -> 0 | D25: ='padi ladang'!O45 -> 0 | E25: ='padi ladang'!O78 -> 0 | F25: ='padi ladang'!O111 -> 0
A26: 5 | B26: GROGOL | C26: ='padi ladang'!O13 -> 0 | D26: ='padi ladang'!O46 -> 0 | E26: ='padi ladang'!O79 -> 0 | F26: ='padi ladang'!O112 -> 0
A27: 6 | B27: CILEGON | C27: ='padi ladang'!O14 -> 0 | D27: ='padi ladang'!O47 -> 0 | E27: ='padi ladang'!O80 -> 0 | F27: ='padi ladang'!O113 -> 0
A28: 7 | B28: JOMBANG | C28: ='padi ladang'!O15 -> 0 | D28: ='padi ladang'!O48 -> 0 | E28: ='padi ladang'!O81 -> 0 | F28: ='padi ladang'!O114 -> 0
A29: 8 | B29: CIBEBER | C29: ='padi ladang'!O16 -> 0 | D29: ='padi ladang'!O49 -> 0 | E29: ='padi ladang'!O82 -> 0 | F29: ='padi ladang'!O115 -> 0
A30: JUMLAH | C30: =SUM(C22:C29) -> 74 | D30: =SUM(D22:D29) -> 15 | E30: =SUM(E22:E29) -> 59 | F30: =E30/D30*10 -> 39.333333
A32: 3. JAGUNG
A33: No | B33: Kecamatan | C33: TANAM | D33: PANEN | E33: PRODUKSI | F33: PRODUKTIVITAS
C34: (Ha) | D34: (Ha) | E34: (Ton) | F34: (Ku/Ha)
A35: 1 | B35: 2 | C35: 3 | D35: 4 | E35: 5 | F35: 6
A36: 1 | B36: CIWANDAN | C36: =jagung!O9 -> 10 | D36: =jagung!Q42 -> 8 | E36: =jagung!O75 -> 0 | F36: =jagung!O108 -> 0
A37: 2 | B37: CITANGKIL | C37: =jagung!O10 -> 3 | D37: =jagung!Q43 -> 1 | E37: =jagung!O76 -> 5 | F37: =jagung!O109 -> 29.13
A38: 3 | B38: PULOMERAK | C38: =jagung!O11 -> 59 | D38: =jagung!Q44 -> 12 | E38: =jagung!O77 -> 31 | F38: =jagung!O110 -> 26.1175
A39: 4 | B39: PURWAKARTA | C39: =jagung!O12 -> 6 | D39: =jagung!Q45 -> 2 | E39: =jagung!O78 -> 6 | F39: =jagung!O111 -> 35.555
A40: 5 | B40: GROGOL | C40: =jagung!O13 -> 5 | D40: =jagung!Q46 -> 5 | E40: =jagung!O79 -> 14 | F40: =jagung!O112 -> 30.775
A41: 6 | B41: CILEGON | C41: =jagung!O14 -> 3 | D41: =jagung!Q47 -> 2 | E41: =jagung!O80 -> 8 | F41: =jagung!O113 -> 40
A42: 7 | B42: JOMBANG | C42: =jagung!O15 -> 0.7 | D42: =jagung!Q48 -> 0.7 | E42: =jagung!O81 -> 2.4 | F42: =jagung!O114 -> 27.5
A43: 8 | B43: CIBEBER | C43: =jagung!O16 -> 5 | D43: =jagung!Q49 -> 4 | E43: =jagung!O82 -> 8 | F43: =jagung!O115 -> 39.575
...

Sheet okt-mar
A2: REALISASI TANAM PADI SAWAH OKTOBER 2015 S/D MARET 2016 DAN APRIL S/D SEPTEMBER 2016
A3: KOTA CILEGON
Q4: (Ha)
A5: No | B5: Kecamatan | C5: 2015 S/D 2016 | I5: Okt-Mar | J5: 2016 | P5: Apr-Sep | Q5: Jumlah
C6: Okt | D6: Nov | E6: Des | F6: Jan | G6: Peb | H6: Mar | J6: April | K6: Mei | L6: Juni | M6: Juli | N6: Agust | O6: Sep
A7: 1 | B7: 2 | C7: 3 | D7: 4 | E7: 5 | F7: 6 | G7: 7 | H7: 8 | I7: 9 | J7: 10 | K7: 11 | L7: 12 | M7: 13 | N7: 14 | O7: 15 | P7: 16 | Q7: 17
A8: 1 | B8: CIWANDAN | C8: 0 | D8: 0 | E8: 0 | F8: ='padi sawah'!C9 -> 7 | G8: ='padi sawah'!D9 -> 248 | H8: ='padi sawah'!E9 -> 0 | I8: =SUM(C8:H8) -> 255 | J8: ='padi sawah'!F9 -> 0 | K8: ='padi sawah'!G9 -> 3 | L8: ='padi sawah'!H9 -> 37 | M8: ='padi sawah'!I9 -> 27 | N8: ='padi sawah'!J9 -> 8 | O8: ='padi sawah'!K9 -> 0 | P8: =SUM(J8:O8) -> 75 | Q8: =SUM(I8,P8) -> 330 | S8: 0 | T8: =I8+S8 -> 255
A9: 2 | B9: CITANGKIL | C9: 4 | D9: 2 | E9: 29 | F9: ='padi sawah'!C10 -> 49 | G9: ='padi sawah'!D10 -> 128 | H9: ='padi sawah'!E10 -> 4 | I9: =SUM(C9:H9) -> 216 | J9: ='padi sawah'!F10 -> 5 | K9: ='padi sawah'!G10 -> 13 | L9: ='padi sawah'!H10 -> 38 | M9: ='padi sawah'!I10 -> 37 | N9: ='padi sawah'!J10 -> 31 | O9: ='padi sawah'!K10 -> 11 | P9: =SUM(J9:O9) -> 135 | Q9: =SUM(I9,P9) -> 351 | S9: 4 | T9: =I9+S9 -> 220
A10: 3 | B10: PULOMERAK | C10: 0 | D10: 0 | E10: 0 | F10: ='padi sawah'!C11 -> 10 | G10: ='padi sawah'!D11 -> 15 | H10: ='padi sawah'!E11 -> 0 | I10: =SUM(C10:H10) -> 25 | J10: ='padi sawah'!F11 -> 0 | K10: ='padi sawah'!G11 -> 10 | L10: ='padi sawah'!H11 -> 5 | M10: ='padi sawah'!I11 -> 0 | N10: ='padi sawah'!J11 -> 0 | O10: ='padi sawah'!K11 -> 5 | P10: =SUM(J10:O10) -> 20 | Q10: =SUM(I10,P10) -> 45 | S10: 0 | T10: =I10+S10 -> 25
A11: 4 | B11: PURWAKARTA | C11: 1 | D11: 2 | E11: 16 | F11: ='padi sawah'!C12 -> 182 | G11: ='padi sawah'!D12 -> 1 | H11: ='padi sawah'!E12 -> 1 | I11: =SUM(C11:H11) -> 203 | J11: ='padi sawah'!F12 -> 0 | K11: ='padi sawah'!G12 -> 21 | L11: ='padi sawah'!H12 -> 11 | M11: ='padi sawah'!I12 -> 2 | N11: ='padi sawah'!J12 -> 1 | O11: ='padi sawah'!K12 -> 5 | P11: =SUM(J11:O11) -> 40 | Q11: =SUM(I11,P11) -> 243 | S11: 1 | T11: =I11+S11 -> 204
A12: 5 | B12: GROGOL | C12: 0 | D12: 0 | E12: 0 | F12: ='padi sawah'!C13 -> 45 | G12: ='padi sawah'!D13 -> 119 | H12: ='padi sawah'!E13 -> 0 | I12: =SUM(C12:H12) -> 164 | J12: ='padi sawah'!F13 -> 0 | K12: ='padi sawah'!G13 -> 20 | L12: ='padi sawah'!H13 -> 0 | M12: ='padi sawah'!I13 -> 0 | N12: ='padi sawah'!J13 -> 0 | O12: ='padi sawah'!K13 -> 10 | P12: =SUM(J12:O12) -> 30 | Q12: =SUM(I12,P12) -> 194 | S12: 0 | T12: =I12+S12 -> 164
A13: 6 | B13: CILEGON | C13: 0 | D13: 5 | E13: 7 | F13: ='padi sawah'!C14 -> 29 | G13: ='padi sawah'!D14 -> 18 | H13: ='padi sawah'!E14 -> 0 | I13: =SUM(C13:H13) -> 59 | J13: ='padi sawah'!F14 -> 0 | K13: ='padi sawah'!G14 -> 10 | L13: ='padi sawah'!H14 -> 25 | M13: ='padi sawah'!I14 -> 6 | N13: ='padi sawah'!J14 -> 0 | O13: ='padi sawah'!K14 -> 0 | P13: =SUM(J13:O13) -> 41 | Q13: =SUM(I13,P13) -> 100 | S13: 0 | T13: =I13+S13 -> 59
A14: 7 | B14: JOMBANG | C14: 0 | D14: 5 | E14: 179 | F14: ='padi sawah'!C15 -> 104 | G14: ='padi sawah'!D15 -> 59 | H14: ='padi sawah'!E15 -> 1 | I14: =SUM(C14:H14) -> 348 | J14: ='padi sawah'!F15 -> 1 | K14: ='padi sawah'!G15 -> 48 | L14: ='padi sawah'!H15 -> 189 | M14: ='padi sawah'!I15 -> 27 | N14: ='padi sawah'!J15 -> 3 | O14: ='padi sawah'!K15 -> 1 | P14: =SUM(J14:O14) -> 269 | Q14: =SUM(I14,P14) -> 617 | S14: 1.3 | T14: =I14+S14 -> 349.3
A15: 8 | B15: CIBEBER | C15: 1 | D15: 1 | E15: 42 | F15: ='padi sawah'!C16 -> 64 | G15: ='padi sawah'!D16 -> 145 | H15: ='padi sawah'!E16 -> 6 | I15: =SUM(C15:H15) -> 259 | J15: ='padi sawah'!F16 -> 26 | K15: ='padi sawah'!G16 -> 66 | L15: ='padi sawah'!H16 -> 101 | M15: ='padi sawah'!I16 -> 0 | N15: ='padi sawah'!J16 -> 48 | O15: ='padi sawah'!K16 -> 27 | P15: =SUM(J15:O15) -> 268 | Q15: =SUM(I15,P15) -> 527 | S15: 6 | T15: =I15+S15 -> 265 | V15: 737.7
A16: JUMLAH | C16: =SUM(C8:C15) -> 6 | D16: =SUM(D8:D15) -> 15 | E16: =SUM(E8:E15) -> 273 | F16: =SUM(F8:F15) -> 490 | G16: =SUM(G8:G15) -> 733 | H16: =SUM(H8:H15) -> 12 | I16: =SUM(I8:I15) -> 1529 | J16: =SUM(J8:J15) -> 32 | ... Q16: =SUM(Q8:Q15) -> 2407 | S16: =SUM(S8:S15) -> 12.3 | T16: =SUM(T8:T15) -> 1541.3 | U16: 1695 | V16: =U16-T16 -> 153.7 | W16: =SUM(F16:H16,J16:O16) -> 2113
V17: =V15+V16 -> 891.4
A18: REALISASI TANAM PADI LADANG OKTOBER 2015 S/D MARET 2016 DAN APRIL S/D SEPTEMBER 2016
A19: KOTA CILEGON
Q20: (Ha)
A21: No | B21: Kecamatan | C21: 2015 S/D 2016 | I21: Okt-Mar | J21: 2016 | P21: Apr-Sep | Q21: Jumlah
C22: Okt | D22: Nov | E22: Des | F22: Jan | G22: Peb | H22: Mar | J22: April | K22: Mei | L22: Juni | M22: Juli | N22: Agust | O22: Sep
A23: 1 | B23: 2 | C23: 3 | D23: 4 | E23: 5 | F23: 6 | G23: 7 | H23: 8 | I23: 9 | J23: 10 | K23: 11 | L23: 12 | M23: 13 | N23: 14 | O23: 15 | P23: 16 | Q23: 17
A24: 1 | B24: CIWANDAN | C24: 0 | D24: 0 | E24: 0 | F24: ='padi ladang'!C9 -> 0 | G24: ='padi ladang'!D9 -> 0 | H24: ='padi ladang'!E9 -> 0 | I24: =SUM(C24:H24) -> 0 | J24: ='padi ladang'!F9 -> 0 | K24: ='padi ladang'!G9 -> 0 | L24: ='padi ladang'!H9 -> 0 | M24: ='padi ladang'!I9 -> 0 | N24: ='padi ladang'!J9 -> 0 | O24: ='padi ladang'!K9 -> 0 | P24: =SUM(J24:O24) -> 0 | Q24: =SUM(I24,P24) -> 0
A25: 2 | B25: CITANGKIL | C25: 0 | D25: 0 | E25: 0 | F25: ='padi ladang'!C10 -> 0 | G25: ='padi ladang'!D10 -> 0 | H25: ='padi ladang'!E10 -> 0 | I25: =SUM(C25:H25) -> 0 | J25: ='padi ladang'!F10 -> 0 | K25: ='padi ladang'!G10 -> 0 | L25: ='padi ladang'!H10 -> 0 | M25: ='padi ladang'!I10 -> 0 | N25: ='padi ladang'!J10 -> 0 | O25: ='padi ladang'!K10 -> 0 | P25: =SUM(J25:O25) -> 0 | Q25: =SUM(I25,P25) -> 0
A26: 3 | B26: PULOMERAK | C26: 0 | D26: 0 | E26: 5 | F26: ='padi ladang'!C11 -> 10 | G26: ='padi ladang'!D11 -> 0 | H26: ='padi ladang'!E11 -> 0 | I26: =SUM(C26:H26) -> 15 | J26: ='padi ladang'!F11 -> 0 | K26: ='padi ladang'!G11 -> 0 | L26: ='padi ladang'!H11 -> 0 | M26: ='padi ladang'!I11 -> 0 | N26: ='padi ladang'!J11 -> 0 | O26: ='padi ladang'!K11 -> 35 | P26: =SUM(J26:O26) -> 35 | Q26: =SUM(I26,P26) -> 50
A27: 4 | B27: PURWAKARTA | C27: 0 | D27: 0 | E27: 0 | F27: ='padi ladang'!C12 -> 0 | G27: ='padi ladang'!D12 -> 0 | H27: ='padi ladang'!E12 -> 0 | I27: =SUM(C27:H27) -> 0 | J27: ='padi ladang'!F12 -> 0 | K27: ='padi ladang'!G12 -> 0 | L27: ='padi ladang'!H12 -> 0 | M27: ='padi ladang'!I12 -> 0 | N27: ='padi ladang'!J12 -> 0 | O27: ='padi ladang'!K12 -> 0 | P27: =SUM(J27:O27) -> 0 | Q27: =SUM(I27,P27) -> 0
A28: 5 | B28: GROGOL | C28: 0 | D28: 0 | E28: 0 | F28: ='padi ladang'!C13 -> 0 | G28: ='padi ladang'!D13 -> 0 | H28: ='padi ladang'!E13 -> 0 | I28: =SUM(C28:H28) -> 0 | J28: ='padi ladang'!F13 -> 0 | K28: ='padi ladang'!G13 -> 0 | L28: ='padi ladang'!H13 -> 0 | M28: ='padi ladang'!I13 -> 0 | N28: ='padi ladang'!J13 -> 0 | O28: ='padi ladang'!K13 -> 0 | P28: =SUM(J28:O28) -> 0 | Q28: =SUM(I28,P28) -> 0
A29: 6 | B29: CILEGON | C29: 0 | D29: 0 | E29: 0 | F29: ='padi ladang'!C14 -> 0 | G29: ='padi ladang'!D14 -> 0 | H29: ='padi ladang'!E14 -> 0 | I29: =SUM(C29:H29) -> 0 | J29: ='padi ladang'!F14 -> 0 | K29: ='padi ladang'!G14 -> 0 | L29: ='padi ladang'!H14 -> 0 | M29: ='padi ladang'!I14 -> 0 | N29: ='padi ladang'!J14 -> 0 | O29: ='padi ladang'!K14 -> 0 | P29: =SUM(J29:O29) -> 0 | Q29: =SUM(I29,P29) -> 0
A30: 7 | B30: JOMBANG | C30: 0 | D30: 0 | E30: 0 | F30: ='padi ladang'!C15 -> 0 | G30: ='padi ladang'!D15 -> 0 | H30: ='padi ladang'!E15 -> 0 | I30: =SUM(C30:H30) -> 0 | J30: ='padi ladang'!F15 -> 0 | K30: ='padi ladang'!G15 -> 0 | L30: ='padi ladang'!H15 -> 0 | M30: ='padi ladang'!I15 -> 0 | N30: ='padi ladang'!J15 -> 0 | O30: ='padi ladang'!K15 -> 0 | P30: =SUM(J30:O30) -> 0 | Q30: =SUM(I30,P30) -> 0
A31: 8 | B31: CIBEBER | C31: 0 | D31: 0 | E31: 0 | F31: ='padi ladang'!C16 -> 0 | G31: ='padi ladang'!D16 -> 0 | H31: ='padi ladang'!E16 -> 0 | I31: =SUM(C31:H31) -> 0 | J31: ='padi ladang'!F16 -> 0 | K31: ='padi ladang'!G16 -> 0 | L31: ='padi ladang'!H16 -> 0 | M31: ='padi ladang'!I16 -> 0 | N31: ='padi ladang'!J16 -> 0 | O31: ='padi ladang'!K16 -> 0 | P31: =SUM(J31:O31) -> 0 | Q31: =SUM(I31,P31) -> 0
A32: JUMLAH | C32: =SUM(C24:C31) -> 0 | D32: =SUM(D24:D31) -> 0 | E32: =SUM(E24:E31) -> 5 | F32: =SUM(F24:F31) -> 10 | G32: =SUM(G24:G31) -> 0 | H32: =SUM(H24:H31) -> 0 | I32: =SUM(I24:I31) -> 15 | J32: =SUM(J24:J31) -> 0 | ... Q32: =SUM(Q24:Q31) -> 50
A34: REALISASI TANAM JAGUNG OKTOBER 2015 S/D MARET 2016 DAN APRIL S/D SEPTEMBER 2016
A35: KOTA CILEGON
Q36: (Ha)
A37: No | B37: Kecamatan | C37: 2015 S/D 2016 | I37: Okt-Mar | J37: 2016 | P37: Apr-Sep | Q37: Jumlah
C38: Okt | D38: Nov | E38: Des | F38: Jan | G38: Peb | H38: Mar | J38: April | K38: Mei | L38: Juni | M38: Juli | N38: Agust | O38: Sep
A39: 1 | B39: 2 | C39: 3 | D39: 4 | E39: 5 | F39: 6 | G39: 7 | H39: 8 | I39: 9 | J39: 10 | K39: 11 | L39: 12 | M39: 13 | N39: 14 | O39: 15 | P39: 16 | Q39: 17
