Workbook

Sheet padi sawah
A2: DATA LUAS TANAM PADI (SAWAH) PER BULAN
A3: KOTA CILEGON TAHUN 2020
O5: (Ha)
A6: No | B6: Kecamatan | C6: Bulan | O6: Jumlah
C7: Jan | D7: Feb | E7: Maret | F7: Apr | G7: Mei | H7: Juni | I7: Juli | J7: Agst | K7: Sept | L7: Okt | M7: Nov | N7: Des | Q7: apr - juni
A8: 1 | B8: 2 | C8: 3 | D8: 4 | E8: 5 | F8: 6 | G8: 7 | H8: 8 | I8: 9 | J8: 10 | K8: 11 | L8: 12 | M8: 13 | N8: 14 | O8: 15
A9: 1 | B9: CIWANDAN | C9: 70 | D9: 75 | E9: 65 | F9: 15 | G9: 0 | H9: 45 | I9: 5 | J9: 0 | K9: 7 | L9: 3 | M9: 2 | N9: 0 | O9: =SUM(C9:N9) -> 287 | Q9: =SUM(F9:H9) -> 60
A10: 2 | B10: CITANGKIL | C10: 108 | D10: 83 | E10: 0 | F10: 5 | G10: 11 | H10: 85 | I10: 23 | J10: 0 | K10: 13 | L10: 3 | M10: 23 | N10: 63 | O10: =SUM(C10:N10) -> 417 | Q10: =SUM(F10:H10) -> 101
A11: 3 | B11: PULOMERAK | C11: 25 | D11: 0 | E11: 0 | F11: 0 | G11: 10 | H11: 0 | I11: 0 | J11: 0 | K11: 0 | L11: 0 | M11: 0 | N11: 10 | O11: =SUM(C11:N11) -> 45 | Q11: =SUM(F11:H11) -> 10
A12: 4 | B12: PURWAKARTA | C12: 182 | D12: 0 | E12: 0 | F12: 3 | G12: 10 | H12: 0 | I12: 5 | J12: 0 | K12: 1 | L12: 2 | M12: 2 | N12: 115 | O12: =SUM(C12:N12) -> 320 | Q12: =SUM(F12:H12) -> 13
A13: 5 | B13: GROGOL | C13: 162 | D13: 0 | E13: 0 | F13: 0 | G13: 0 | H13: 15 | I13: 0 | J13: 0 | K13: 0 | L13: 2 | M13: 0 | N13: 155 | O13: =SUM(C13:N13) -> 334 | Q13: =SUM(F13:H13) -> 15
A14: 6 | B14: CILEGON | C14: 14 | D14: 36 | E14: 0 | F14: 0 | G14: 4 | H14: 7 | I14: 20 | J14: 12 | K14: 0 | L14: 0 | M14: 11 | N14: 9 | O14: =SUM(C14:N14) -> 113 | Q14: =SUM(F14:H14) -> 11
A15: 7 | B15: JOMBANG | C15: 180 | D15: 120 | E15: 0 | F15: 0 | G15: 0 | H15: 185 | I15: 90 | J15: 0 | K15: 0 | L15: 0 | M15: 3 | N15: 93 | O15: =SUM(C15:N15) -> 671 | Q15: =SUM(F15:H15) -> 185
A16: 8 | B16: CIBEBER | C16: 44 | D16: 20 | E16: 25 | F16: 5 | G16: 42 | H16: 167 | I16: 0 | J16: 18 | K16: 5 | L16: 6 | M16: 11 | N16: 142 | O16: =SUM(C16:N16) -> 485 | Q16: =SUM(F16:H16) -> 214
A17: JUMLAH | C17: =SUM(C9:C16) -> 785 | D17: =SUM(D9:D16) -> 334 | E17: =SUM(E9:E16) -> 90 | F17: =SUM(F9:F16) -> 28 | G17: =SUM(G9:G16) -> 77 | H17: =SUM(H9:H16) -> 504 | I17: =SUM(I9:I16) -> 143 | J17: =SUM(J9:J16) -> 30 | ... O17: =SUM(O9:O16) -> 2672 | Q17: =SUM(Q9:Q16) -> 609
H19: =SUM(G17:H17) -> 581
C20: =C17*96% -> 753.6 | D20: =D17*96% -> 320.64 | E20: =E17*96% -> 86.4 | F20: =F17*96% -> 26.88 | G20: =G17*96% -> 73.92 | H20: =H17*96% -> 483.84 | I20: =I17*96% -> 137.28 | J20: =J17*96% -> 28.8 | ... O20: =O17*96% -> 2565.12
A35: DATA LUAS PANEN PADI (SAWAH) PER BULAN
A36: KOTA CILEGON TAHUN 2020
O38: (Ha)
A39: No | B39: Kecamatan | C39: Bulan | O39: Jumlah
C40: Jan | D40: Feb | E40: Maret | F40: Apr | G40: Mei | H40: Juni | I40: Juli | J40: Agst | K40: Sept | L40: Okt | M40: Nov | N40: Des
A41: 1 | B41: 2 | C41: 3 | D41: 4 | E41: 5 | F41: 6 | G41: 7 | H41: 8 | I41: 9 | J41: 10 | K41: 11 | L41: 12 | M41: 13 | N41: 14 | O41: 15
A42: 1 | B42: CIWANDAN | C42: 0 | D42: 0 | E42: 0 | F42: 145 | G42: 65 | H42: 0 | I42: 0 | J42: 20 | K42: 45 | L42: 0 | M42: 0 | N42: 0 | O42: =SUM(C42:N42) -> 275
A43: 2 | B43: CITANGKIL | C43: 2 | D43: 0 | E43: 14 | F43: 102 | G43: 81 | H43: 0 | I43: 5 | J43: 19 | K43: 78 | L43: 22 | M43: 0 | N43: 7 | O43: =SUM(C43:N43) -> 330
A44: 3 | B44: PULOMERAK | C44: 0 | D44: 0 | E44: 0 | F44: 25 | G44: 0 | H44: 0 | I44: 0 | J44: 10 | K44: 0 | L44: 0 | M44: 0 | N44: 0 | O44: =SUM(C44:N44) -> 35
A45: 4 | B45: PURWAKARTA | C45: 0 | D45: 0 | E45: 0 | F45: 184 | G45: 0 | H45: 0 | I45: 3 | J45: 10 | K45: 5 | L45: 0 | M45: 0 | N45: 1 | O45: =SUM(C45:N45) -> 203
A46: 5 | B46: GROGOL | C46: 0 | D46: 0 | E46: 0 | F46: 162 | G46: 0 | H46: 0 | I46: 0 | J46: 0 | K46: 15 | L46: 0 | M46: 0 | N46: 0 | O46: =SUM(C46:N46) -> 177
A47: 6 | B47: CILEGON | C47: 5 | D47: 0 | E47: 0 | F47: 14 | G47: 36 | H47: 0 | I47: 0 | J47: 4 | K47: 7 | L47: 20 | M47: 12 | N47: 0 | O47: =SUM(C47:N47) -> 98
A48: 7 | B48: JOMBANG | C48: 0 | D48: 0 | E48: 20 | F48: 180 | G48: 120 | H48: 0 | I48: 0 | J48: 1 | K48: 184 | L48: 90 | M48: 0 | N48: 0 | O48: =SUM(C48:N48) -> 595
A49: 8 | B49: CIBEBER | C49: 19 | D49: 10 | E49: 0 | F49: 64 | G49: 25 | H49: 0 | I49: 47 | J49: 67 | K49: 100 | L49: 18 | M49: 5 | N49: 0 | O49: =SUM(C49:N49) -> 355
A50: JUMLAH | C50: =SUM(C42:C49) -> 26 | D50: =SUM(D42:D49) -> 10 | E50: =SUM(E42:E49) -> 34 | F50: =SUM(F42:F49) -> 876 | G50: =SUM(G42:G49) -> 327 | H50: =SUM(H42:H49) -> 0 | I50: =SUM(I42:I49) -> 55 | J50: =SUM(J42:J49) -> 131 | ... O50: =SUM(O42:O49) -> 2068 | Q50: =O50*5% -> 103.4 | R50: =O50-Q50 -> 1964.6 | S50: =O50*95% -> 1964.6
J52: =SUM(C50:J50) -> 1459
L56: =J50*5.8 -> 759.8
A68: DATA PRODUKSI PADI (SAWAH) PER BULAN
A69: KOTA CILEGON TAHUN 2020
O71: (Ton GKG)
A72: No | B72: Kecamatan | C72: Bulan | O72: Jumlah
C73: Jan | D73: Feb | E73: Maret | F73: Apr | G73: Mei | H73: Juni | I73: Juli | J73: Agst | K73: Sept | L73: Okt | M73: Nov | N73: Des
A74: 1 | B74: 2 | C74: 3 | D74: 4 | E74: 5 | F74: 6 | G74: 7 | H74: 8 | I74: 9 | J74: 10 | K74: 11 | L74: 12 | M74: 13 | N74: 14 | O74: 15
...

Sheet puso
A1: DATA LUAS PUSO PADI (SAWAH) PER BULAN
A2: KOTA CILEGON TAHUN 2020
O3: (Ha)
A4: No | B4: Kecamatan | C4: Bulan | O4: Jumlah
C5: Jan | D5: Feb | E5: Maret | F5: Apr | G5: Mei | H5: Juni | I5: Juli | J5: Agst | K5: Sept | L5: Okt | M5: Nov | N5: Des
A6: 1 | B6: 2 | C6: 3 | D6: 4 | E6: 5 | F6: 6 | G6: 7 | H6: 8 | I6: 9 | J6: 10 | K6: 11 | L6: 12 | M6: 13 | N6: 14 | O6: 15
A7: 1 | B7: CIWANDAN | C7: 0 | D7: 0 | E7: 0 | F7: 0 | G7: 0 | H7: 0 | I7: 0 | J7: 0 | K7: 0 | L7: 0 | M7: 0 | N7: 0 | O7: =SUM(C7:N7) -> 0
A8: 2 | B8: CITANGKIL | C8: 0 | D8: 0 | E8: 0 | F8: 0 | G8: 0 | H8: 0 | I8: 0 | J8: 0 | K8: 0 | L8: 0 | M8: 0 | N8: 0 | O8: =SUM(C8:N8) -> 0
A9: 3 | B9: PULOMERAK | C9: 0 | D9: 0 | E9: 0 | F9: 0 | G9: 0 | H9: 0 | I9: 0 | J9: 0 | K9: 0 | L9: 0 | M9: 0 | N9: 0 | O9: =SUM(C9:N9) -> 0
A10: 4 | B10: PURWAKARTA | C10: 0 | D10: 0 | E10: 0 | F10: 0 | G10: 0 | H10: 0 | I10: 0 | J10: 0 | K10: 0 | L10: 0 | M10: 0 | N10: 0 | O10: =SUM(C10:N10) -> 0
A11: 5 | B11: GROGOL | C11: 0 | D11: 0 | E11: 0 | F11: 0 | G11: 0 | H11: 0 | I11: 0 | J11: 0 | K11: 0 | L11: 0 | M11: 0 | N11: 0 | O11: =SUM(C11:N11) -> 0
A12: 6 | B12: CILEGON | C12: 0 | D12: 0 | E12: 0 | F12: 0 | G12: 0 | H12: 0 | I12: 0 | J12: 0 | K12: 0 | L12: 0 | M12: 0 | N12: 0 | O12: =SUM(C12:N12) -> 0
A13: 7 | B13: JOMBANG | C13: 0 | D13: 0 | E13: 0 | F13: 0 | G13: 0 | H13: 0 | I13: 0 | J13: 0 | K13: 0 | L13: 0 | M13: 0 | N13: 0 | O13: =SUM(C13:N13) -> 0
A14: 8 | B14: CIBEBER | C14: 0 | D14: 0 | E14: 0 | F14: 0 | G14: 0 | H14: 0 | I14: 0 | J14: 0 | K14: 0 | L14: 0 | M14: 0 | N14: 0 | O14: =SUM(C14:N14) -> 0
A15: JUMLAH | C15: =SUM(C7:C14) -> 0 | D15: =SUM(D7:D14) -> 0 | E15: =SUM(E7:E14) -> 0 | F15: =SUM(F7:F14) -> 0 | G15: =SUM(G7:G14) -> 0 | H15: =SUM(H7:H14) -> 0 | I15: =SUM(I7:I14) -> 0 | J15: =SUM(J7:J14) -> 0 | ... O15: =SUM(O7:O14) -> 0
A18: DATA LUAS PUSO KEDELAI PER BULAN
A19: KOTA CILEGON TAHUN 2020
O20: (Ha)
A21: No | B21: Kecamatan | C21: Bulan | O21: Jumlah
C22: Jan | D22: Feb | E22: Maret | F22: Apr | G22: Mei | H22: Juni | I22: Juli | J22: Agst | K22: Sept | L22: Okt | M22: Nov | N22: Des
A23: 1 | B23: 2 | C23: 3 | D23: 4 | E23: 5 | F23: 6 | G23: 7 | H23: 8 | I23: 9 | J23: 10 | K23: 11 | L23: 12 | M23: 13 | N23: 14 | O23: 15
A24: 1 | B24: CIWANDAN | C24: 0 | D24: 0 | E24: 0 | F24: 0 | G24: 0 | H24: 0 | I24: 0 | J24: 0 | K24: 0 | L24: 0 | M24: 0 | N24: 0 | O24: =SUM(C24:N24) -> 0
A25: 2 | B25: CITANGKIL | C25: 0 | D25: 0 | E25: 0 | F25: 0 | G25: 0 | H25: 0 | I25: 0 | J25: 0 | K25: 0 | L25: 0 | M25: 0 | N25: 0 | O25: =SUM(C25:N25) -> 0
A26: 3 | B26: PULOMERAK | C26: 0 | D26: 0 | E26: 0 | F26: 0 | G26: 0 | H26: 0 | I26: 0 | J26: 0 | K26: 0 | L26: 0 | M26: 0 | N26: 0 | O26: =SUM(C26:N26) -> 0
A27: 4 | B27: PURWAKARTA | C27: 0 | D27: 0 | E27: 0 | F27: 0 | G27: 0 | H27: 0 | I27: 0 | J27: 0 | K27: 0 | L27: 0 | M27: 0 | N27: 0 | O27: =SUM(C27:N27) -> 0
A28: 5 | B28: GROGOL | C28: 0 | D28: 0 | E28: 0 | F28: 0 | G28: 0 | H28: 0 | I28: 0 | J28: 0 | K28: 0 | L28: 0 | M28: 0 | N28: 0 | O28: =SUM(C28:N28) -> 0
A29: 6 | B29: CILEGON | C29: 0 | D29: 0 | E29: 0 | F29: 0 | G29: 0 | H29: 0 | I29: 0 | J29: 0 | K29: 0 | L29: 0 | M29: 0 | N29: 0 | O29: =SUM(C29:N29) -> 0
A30: 7 | B30: JOMBANG | C30: 0 | D30: 0 | E30: 0 | F30: 0 | G30: 0 | H30: 0 | I30: 0 | J30: 0 | K30: 0 | L30: 0 | M30: 0 | N30: 0 | O30: =SUM(C30:N30) -> 0
A31: 8 | B31: CIBEBER | C31: 0 | D31: 0 | E31: 0 | F31: 0 | G31: 0 | H31: 0 | I31: 0 | J31: 0 | K31: 0 | L31: 0 | M31: 0 | N31: 0 | O31: =SUM(C31:N31) -> 0
A32: JUMLAH | C32: =SUM(C24:C31) -> 0 | D32: =SUM(D24:D31) -> 0 | E32: =SUM(E24:E31) -> 0 | F32: =SUM(F24:F31) -> 0 | G32: =SUM(G24:G31) -> 0 | H32: =SUM(H24:H31) -> 0 | I32: =SUM(I24:I31) -> 0 | J32: =SUM(J24:J31) -> 0 | ... O32: =SUM(O24:O31) -> 0
L35: Mengetahui,
L36: Kepala Dinas Ketahanan Pangan dan Pertanian
L37: Kota Cilegon
L41: Ir. Wawan Hermawan
L42: NIP. 19600110 198603 1 012

Sheet padi ladang
A2: DATA LUAS TANAM PADI (DARAT) PER BULAN
A3: KOTA CILEGON TAHUN 2020
O5: (Ha)
A6: No | B6: Kecamatan | C6: Bulan | O6: Jumlah
C7: Jan | D7: Feb | E7: Maret | F7: Apr | G7: Mei | H7: Juni | I7: Juli | J7: Agst | K7: Sept | L7: Okt | M7: Nov | N7: Des
A8: 1 | B8: 2 | C8: 3 | D8: 4 | E8: 5 | F8: 6 | G8: 7 | H8: 8 | I8: 9 | J8: 10 | K8: 11 | L8: 12 | M8: 13 | N8: 14 | O8: 15
A9: 1 | B9: CIWANDAN | C9: 0 | D9: 0 | E9: 0 | F9: 0 | G9: 0 | H9: 0 | I9: 0 | J9: 0 | K9: 0 | L9: 0 | M9: 0 | N9: 0 | O9: =SUM(C9:N9) -> 0
A10: 2 | B10: CITANGKIL | C10: 0 | D10: 0 | E10: 0 | F10: 0 | G10: 0 | H10: 0 | I10: 0 | J10: 0 | K10: 0 | L10: 0 | M10: 0 | N10: 0 | O10: =SUM(C10:N10) -> 0
A11: 3 | B11: PULOMERAK | C11: 0 | D11: 0 | E11: 0 | F11: 0 | G11: 0 | H11: 0 | I11: 0 | J11: 0 | K11: 0 | L11: 0 | M11: 0 | N11: 0 | O11: =SUM(C11:N11) -> 0
A12: 4 | B12: PURWAKARTA | C12: 0 | D12: 0 | E12: 0 | F12: 0 | G12: 0 | H12: 0 | I12: 0 | J12: 0 | K12: 0 | L12: 0 | M12: 0 | N12: 0 | O12: =SUM(C12:N12) -> 0
A13: 5 | B13: GROGOL | C13: 0 | D13: 0 | E13: 0 | F13: 0 | G13: 0 | H13: 0 | I13: 0 | J13: 0 | K13: 0 | L13: 0 | M13: 0 | N13: 0 | O13: =SUM(C13:N13) -> 0
A14: 6 | B14: CILEGON | C14: 0 | D14: 0 | E14: 0 | F14: 0 | G14: 0 | H14: 0 | I14: 0 | J14: 0 | K14: 0 | L14: 0 | M14: 0 | N14: 0 | O14: =SUM(C14:N14) -> 0
A15: 7 | B15: JOMBANG | C15: 0 | D15: 0 | E15: 0 | F15: 0 | G15: 0 | H15: 0 | I15: 0 | J15: 0 | K15: 0 | L15: 0 | M15: 0 | N15: 0 | O15: =SUM(C15:N15) -> 0
A16: 8 | B16: CIBEBER | C16: 0 | D16: 0 | E16: 0 | F16: 0 | G16: 0 | H16: 2 | I16: 0 | J16: 0 | K16: 0 | L16: 0 | M16: 0 | N16: 0 | O16: =SUM(C16:N16) -> 2
A17: JUMLAH | C17: =SUM(C9:C16) -> 0 | D17: =SUM(D9:D16) -> 0 | E17: =SUM(E9:E16) -> 0 | F17: =SUM(F9:F16) -> 0 | G17: =SUM(G9:G16) -> 0 | H17: =SUM(H9:H16) -> 2 | I17: =SUM(I9:I16) -> 0 | J17: =SUM(J9:J16) -> 0 | ... O17: =SUM(O9:O16) -> 2
A35: DATA LUAS PANEN PADI (DARAT) PER BULAN
A36: KOTA CILEGON TAHUN 2020
O38: (Ha)
A39: No | B39: Kecamatan | C39: Bulan | O39: Jumlah
C40: Jan | D40: Feb | E40: Maret | F40: Apr | G40: Mei | H40: Juni | I40: Juli | J40: Agst | K40: Sept | L40: Okt | M40: Nov | N40: Des
A41: 1 | B41: 2 | C41: 3 | D41: 4 | E41: 5 | F41: 6 | G41: 7 | H41: 8 | I41: 9 | J41: 10 | K41: 11 | L41: 12 | M41: 13 | N41: 14 | O41: 15
A42: 1 | B42: CIWANDAN | C42: 0 | D42: 0 | E42: 0 | F42: 0 | G42: 0 | H42: 0 | I42: 0 | J42: 0 | K42: 0 | L42: 0 | M42: 0 | N42: 0 | O42: =SUM(C42:N42) -> 0
A43: 2 | B43: CITANGKIL | C43: 0 | D43: 0 | E43: 0 | F43: 0 | G43: 0 | H43: 0 | I43: 0 | J43: 0 | K43: 0 | L43: 0 | M43: 0 | N43: 0 | O43: =SUM(C43:N43) -> 0
A44: 3 | B44: PULOMERAK | C44: 0 | D44: 0 | E44: 0 | F44: 0 | G44: 0 | H44: 0 | I44: 0 | J44: 0 | K44: 0 | L44: 0 | M44: 0 | N44: 0 | O44: =SUM(C44:N44) -> 0
A45: 4 | B45: PURWAKARTA | C45: 0 | D45: 0 | E45: 0 | F45: 0 | G45: 0 | H45: 0 | I45: 0 | J45: 0 | K45: 0 | L45: 0 | M45: 0 | N45: 0 | O45: =SUM(C45:N45) -> 0
A46: 5 | B46: GROGOL | C46: 0 | D46: 0 | E46: 0 | F46: 0 | G46: 0 | H46: 0 | I46: 0 | J46: 0 | K46: 0 | L46: 0 | M46: 0 | N46: 0 | O46: =SUM(C46:N46) -> 0
A47: 6 | B47: CILEGON | C47: 0 | D47: 0 | E47: 0 | F47: 0 | G47: 0 | H47: 0 | I47: 0 | J47: 0 | K47: 0 | L47: 0 | M47: 0 | N47: 0 | O47: =SUM(C47:N47) -> 0
A48: 7 | B48: JOMBANG | C48: 0 | D48: 0 | E48: 0 | F48: 0 | G48: 0 | H48: 0 | I48: 0 | J48: 0 | K48: 0 | L48: 0 | M48: 0 | N48: 0 | O48: =SUM(C48:N48) -> 0
A49: 8 | B49: CIBEBER | C49: 0 | D49: 0 | E49: 0 | F49: 0 | G49: 0 | H49: 0 | I49: 0 | J49: 0 | K49: 2 | L49: 0 | M49: 0 | N49: 0 | O49: =SUM(C49:N49) -> 2
A50: JUMLAH | C50: =SUM(C42:C49) -> 0 | D50: =SUM(D42:D49) -> 0 | E50: =SUM(E42:E49) -> 0 | F50: =SUM(F42:F49) -> 0 | G50: =SUM(G42:G49) -> 0 | H50: =SUM(H42:H49) -> 0 | I50: =SUM(I42:I49) -> 0 | J50: =SUM(J42:J49) -> 0 | ... O50: =SUM(O42:O49) -> 2
A68: DATA PRODUKSI PADI (DARAT) PER BULAN
A69: KOTA CILEGON TAHUN 2020
O71: (Ton)
A72: No | B72: Kecamatan | C72: Bulan | O72: Jumlah
C73: Jan | D73: Feb | E73: Maret | F73: Apr | G73: Mei | H73: Juni | I73: Juli | J73: Agst | K73: Sept | L73: Okt | M73: Nov | N73: Des
A74: 1 | B74: 2 | C74: 3 | D74: 4 | E74: 5 | F74: 6 | G74: 7 | H74: 8 | I74: 9 | J74: 10 | K74: 11 | L74: 12 | M74: 13 | N74: 14 | O74: 15
A75: 1 | B75: CIWANDAN | C75: 0 | D75: 0 | E75: 0 | F75: 0 | G75: 0 | H75: 0 | I75: 0 | J75: 0 | K75: 0 | L75: 0 | M75: 0 | N75: 0 | O75: =SUM(C75:N75) -> 0
A76: 2 | B76: CITANGKIL | C76: 0 | D76: 0 | E76: 0 | F76: 0 | G76: 0 | H76: 0 | I76: 0 | J76: 0 | K76: 0 | L76: 0 | M76: 0 | N76: 0 | O76: =SUM(C76:N76) -> 0
A77: 3 | B77: PULOMERAK | C77: 0 | D77: 0 | E77: 0 | F77: 0 | G77: 0 | H77: 0 | I77: 0 | J77: 0 | K77: 0 | L77: 0 | M77: 0 | N77: 0 | O77: =SUM(C77:N77) -> 0
A78: 4 | B78: PURWAKARTA | C78: 0 | D78: 0 | E78: 0 | F78: 0 | G78: 0 | H78: 0 | I78: 0 | J78: 0 | K78: 0 | L78: 0 | M78: 0 | N78: 0 | O78: =SUM(C78:N78) -> 0
...

Sheet jagung
A2: DATA LUAS TANAM JAGUNG PER BULAN
A3: KOTA CILEGON TAHUN 2020
O5: (Ha)
A6: No | B6: Kecamatan | C6: Bulan | O6: Jumlah
C7: Jan | D7: Feb | E7: Maret | F7: Apr | G7: Mei | H7: Juni | I7: Juli | J7: Agst | K7: Sept | L7: Okt | M7: Nov | N7: Des
A8: 1 | B8: 2 | C8: 3 | D8: 4 | E8: 5 | F8: 6 | G8: 7 | H8: 8 | I8: 9 | J8: 10 | K8: 11 | L8: 12 | M8: 13 | N8: 14 | O8: 15
A9: 1 | B9: CIWANDAN | C9: 6 | D9: 3 | E9: 0 | F9: 0 | G9: 0 | H9: 1 | I9: 0 | J9: 1 | K9: 0 | L9: 1 | M9: 0 | N9: 0 | O9: =SUM(C9:N9) -> 12
A10: 2 | B10: CITANGKIL | C10: 0 | D10: 1 | E10: 0 | F10: 0 | G10: 1 | H10: 0 | I10: 0 | J10: 1 | K10: 0 | L10: 1 | M10: 0 | N10: 1 | O10: =SUM(C10:N10) -> 5
A11: 3 | B11: PULOMERAK | C11: 0 | D11: 0 | E11: 0 | F11: 0 | G11: 0 | H11: 0 | I11: 0 | J11: 0 | K11: 0 | L11: 0 | M11: 0 | N11: 0 | O11: =SUM(C11:N11) -> 0
A12: 4 | B12: PURWAKARTA | C12: 2 | D12: 1 | E12: 0 | F12: 2 | G12: 0 | H12: 0 | I12: 0 | J12: 2 | K12: 0 | L12: 0 | M12: 0 | N12: 0 | O12: =SUM(C12:N12) -> 7
A13: 5 | B13: GROGOL | C13: 0 | D13: 0 | E13: 0 | F13: 0 | G13: 0 | H13: 0 | I13: 0 | J13: 0 | K13: 0 | L13: 0 | M13: 0 | N13: 0 | O13: =SUM(C13:N13) -> 0
A14: 6 | B14: CILEGON | C14: 0 | D14: 0 | E14: 0 | F14: 0 | G14: 0 | H14: 0 | I14: 0 | J14: 0 | K14: 0 | L14: 0 | M14: 0 | N14: 0.5 | O14: =SUM(C14:N14) -> 0.5
A15: 7 | B15: JOMBANG | C15: 0 | D15: 0 | E15: 0 | F15: 0 | G15: 0 | H15: 0 | I15: 0 | J15: 0 | K15: 1 | L15: 0 | M15: 1 | N15: 0 | O15: =SUM(C15:N15) -> 2
A16: 8 | B16: CIBEBER | C16: 0 | D16: 0 | E16: 1 | F16: 1 | G16: 0 | H16: 0 | I16: 0 | J16: 0 | K16: 0 | L16: 0 | M16: 2 | N16: 0 | O16: =SUM(C16:N16) -> 4
A17: JUMLAH | C17: =SUM(C9:C16) -> 8 | D17: =SUM(D9:D16) -> 5 | E17: =SUM(E9:E16) -> 1 | F17: =SUM(F9:F16) -> 3 | G17: =SUM(G9:G16) -> 1 | H17: =SUM(H9:H16) -> 1 | I17: =SUM(I9:I16) -> 0 | J17: =SUM(J9:J16) -> 4 | ... O17: =SUM(O9:O16) -> 30.5
N19: =SUM(L17:N17) -> 6.5
A35: DATA LUAS PANEN JAGUNG PER BULAN
A36: KOTA CILEGON TAHUN 2020
O38: (Ha)
A39: No | B39: Kecamatan | C39: Bulan | O39: Jumlah
C40: Jan | D40: Feb | E40: Maret | F40: Apr | G40: Mei | H40: Juni | I40: Juli | J40: Agst | K40: Sept | L40: Okt | M40: Nov | N40: Des
A41: 1 | B41: 2 | C41: 3 | D41: 4 | E41: 5 | F41: 6 | G41: 7 | H41: 8 | I41: 9 | J41: 10 | K41: 11 | L41: 12 | M41: 13 | N41: 14 | O41: 15
A42: 1 | B42: CIWANDAN | C42: 0 | D42: 0 | E42: 0 | F42: 6 | G42: 3 | H42: 0 | I42: 0 | J42: 0 | K42: 0 | L42: 0 | M42: 0 | N42: 0 | O42: =SUM(C42:N42) -> 9
A43: 2 | B43: CITANGKIL | C43: 0 | D43: 0 | E43: 0 | F43: 1* | G43: 0 | H43: 0 | I43: 1* | J43: 0 | K43: 0 | L43: 1* | M43: 0 | N43: 1* | O43: 4
A44: 3 | B44: PULOMERAK | C44: 0 | D44: 0 | E44: 0 | F44: 0 | G44: 0 | H44: 0 | I44: 0 | J44: 0 | K44: 0 | L44: 0 | M44: 0 | N44: 0 | O44: =SUM(C44:N44) -> 0
A45: 4 | B45: PURWAKARTA | C45: 0 | D45: 0 | E45: 2* | F45: 0 | G45: 1* | H45: 1 | I45: 0 | J45: 1 | K45: 0 | L45: 0 | M45: 1 | N45: 0 | O45: 6
A46: 5 | B46: GROGOL | C46: 0 | D46: 0 | E46: 0 | F46: 0 | G46: 0 | H46: 0 | I46: 0 | J46: 0 | K46: 0 | L46: 0 | M46: 0 | N46: 0 | O46: =SUM(C46:N46) -> 0
A47: 6 | B47: CILEGON | C47: 0 | D47: 0 | E47: 0 | F47: 0 | G47: 0 | H47: 0 | I47: 0 | J47: 0 | K47: 0 | L47: 0 | M47: 0 | N47: 0 | O47: =SUM(C47:N47) -> 0
A48: 7 | B48: JOMBANG | C48: 0 | D48: 0 | E48: 0 | F48: 0 | G48: 0 | H48: 0 | I48: 0 | J48: 0 | K48: 0 | L48: 0 | M48: 1* | N48: 0 | O48: 1
A49: 8 | B49: CIBEBER | C49: 1 | D49: 0 | E49: 0 | F49: 1* | G49: 0 | H49: 1 | I49: 0 | J49: 0 | K49: 0 | L49: 0 | M49: 0 | N49: 0 | O49: 3
A50: JUMLAH | C50: =SUM(C42:C49) -> 1 | D50: =SUM(D42:D49) -> 0 | E50: 2 | F50: 8 | G50: 4 | H50: =SUM(H42:H49) -> 2 | I50: 1 | J50: =SUM(J42:J49) -> 1 | K50: =SUM(K42:K49) -> 0 | L50: 1 | M50: 2 | N50: 1 | O50: =SUM(O42:O49) -> 23 | Q50: =SUM(C50:N50) -> 23
A52: Ket : * : Panen Muda
A68: DATA PRODUKSI JAGUNG PER BULAN
A69: KOTA CILEGON TAHUN 2020
N71: (Ton Pipilan Kering)
A72: No | B72: Kecamatan | C72: Bulan | O72: Jumlah
C73: Jan | D73: Feb | E73: Maret | F73: Apr | G73: Mei | H73: Juni | I73: Juli | J73: Agst | K73: Sept | L73: Okt | M73: Nov | N73: Des
A74: 1 | B74: 2 | C74: 3 | D74: 4 | E74: 5 | F74: 6 | G74: 7 | H74: 8 | I74: 9 | J74: 10 | K74: 11 | L74: 12 | M74: 13 | N74: 14 | O74: 15
A75: 1 | B75: CIWANDAN | C75: 0 | D75: 0 | E75: 0 | F75: 17.1 | G75: 9 | H75: 0 | I75: 0 | J75: 0 | K75: 0 | L75: 0 | M75: 0 | N75: 0 | O75: =SUM(C75:N75) -> 26.1
A76: 2 | B76: CITANGKIL | C76: 0 | D76: 0 | E76: 0 | F76: 0 | G76: 0 | H76: 0 | I76: 0 | J76: 0 | K76: 0 | L76: 0 | M76: 0 | N76: 0 | O76: =SUM(C76:N76) -> 0
...

Sheet kedelai
A2: DATA LUAS TANAM KEDELAI PER BULAN
A3: KOTA CILEGON TAHUN 2020
O5: (Ha)
A6: No | B6: Kecamatan | C6: Bulan | O6: Jumlah
C7: Jan | D7: Feb | E7: Maret | F7: Apr | G7: Mei | H7: Juni | I7: Juli | J7: Agst | K7: Sept | L7: Okt | M7: Nov | N7: Des
A8: 1 | B8: 2 | C8: 3 | D8: 4 | E8: 5 | F8: 6 | G8: 7 | H8: 8 | I8: 9 | J8: 10 | K8: 11 | L8: 12 | M8: 13 | N8: 14 | O8: 15 | Q8: ok-nop
A9: 1 | B9: CIWANDAN | C9: 0 | D9: 0 | E9: 0 | F9: 0 | G9: 0 | H9: 0 | I9: 0 | J9: 0 | K9: 0 | L9: 0 | M9: 0 | N9: 0 | O9: =SUM(C9:N9) -> 0 | Q9: =SUM(L9:M9) -> 0
A10: 2 | B10: CITANGKIL | C10: 0 | D10: 0 | E10: 0 | F10: 0 | G10: 0 | H10: 0 | I10: 0 | J10: 0 | K10: 0 | L10: 0 | M10: 0 | N10: 0 | O10: =SUM(C10:N10) -> 0 | Q10: =SUM(L10:M10) -> 0
A11: 3 | B11: PULOMERAK | C11: 0 | D11: 0 | E11: 0 | F11: 0 | G11: 0 | H11: 0 | I11: 0 | J11: 0 | K11: 0 | L11: 0 | M11: 0 | N11: 0 | O11: =SUM(C11:N11) -> 0 | Q11: =SUM(L11:M11) -> 0
A12: 4 | B12: PURWAKARTA | C12: 0 | D12: 0 | E12: 0 | F12: 0 | G12: 0 | H12: 0 | I12: 0 | J12: 0 | K12: 0 | L12: 0 | M12: 0 | N12: 0 | O12: =SUM(C12:N12) -> 0 | Q12: =SUM(L12:M12) -> 0
A13: 5 | B13: GROGOL | C13: 0 | D13: 0 | E13: 0 | F13: 0 | G13: 0 | H13: 0 | I13: 0 | J13: 0 | K13: 0 | L13: 0 | M13: 0 | N13: 0 | O13: =SUM(C13:N13) -> 0 | Q13: =SUM(L13:M13) -> 0
A14: 6 | B14: CILEGON | C14: 0 | D14: 0 | E14: 0 | F14: 0 | G14: 0 | H14: 0 | I14: 0 | J14: 0 | K14: 0 | L14: 0 | M14: 0 | N14: 0 | O14: =SUM(C14:N14) -> 0 | Q14: =SUM(L14:M14) -> 0
A15: 7 | B15: JOMBANG | C15: 0 | D15: 0 | E15: 0 | F15: 0 | G15: 0 | H15: 0 | I15: 0 | J15: 0 | K15: 0 | L15: 0 | M15: 0 | N15: 0 | O15: =SUM(C15:N15) -> 0 | Q15: =SUM(L15:M15) -> 0
A16: 8 | B16: CIBEBER | C16: 0 | D16: 0 | E16: 0 | F16: 0 | G16: 0 | H16: 0 | I16: 0 | J16: 0 | K16: 0 | L16: 0 | M16: 0 | N16: 0 | O16: =SUM(C16:N16) -> 0 | Q16: =SUM(L16:M16) -> 0
A17: JUMLAH | C17: =SUM(C9:C16) -> 0 | D17: =SUM(D9:D16) -> 0 | E17: =SUM(E9:E16) -> 0 | F17: =SUM(F9:F16) -> 0 | G17: =SUM(G9:G16) -> 0 | H17: =SUM(H9:H16) -> 0 | I17: =SUM(I9:I16) -> 0 | J17: =SUM(J9:J16) -> 0 | ... O17: =SUM(O9:O16) -> 0
A35: DATA LUAS PANEN KEDELAI PER BULAN
A36: KOTA CILEGON TAHUN 2020
O38: (Ha)
A39: No | B39: Kecamatan | C39: Bulan | O39: Jumlah
C40: Jan | D40: Feb | E40: Maret | F40: Apr | G40: Mei | H40: Juni | I40: Juli | J40: Agst | K40: Sept | L40: Okt | M40: Nov | N40: Des
A41: 1 | B41: 2 | C41: 3 | D41: 4 | E41: 5 | F41: 6 | G41: 7 | H41: 8 | I41: 9 | J41: 10 | K41: 11 | L41: 12 | M41: 13 | N41: 14 | O41: 15
A42: 1 | B42: CIWANDAN | C42: 0 | D42: 0 | E42: 0 | F42: 0 | G42: 0 | H42: 0 | I42: 0 | J42: 0 | K42: 0 | L42: 0 | M42: 0 | N42: 0 | O42: =SUM(C42:N42) -> 0 | Q42: =SUM(C42:E42) -> 0
A43: 2 | B43: CITANGKIL | C43: 0 | D43: 0 | E43: 0 | F43: 0 | G43: 0 | H43: 0 | I43: 0 | J43: 0 | K43: 0 | L43: 0 | M43: 0 | N43: 0 | O43: =SUM(C43:N43) -> 0 | Q43: =SUM(C43:E43) -> 0
A44: 3 | B44: PULOMERAK | C44: 0 | D44: 0 | E44: 0 | F44: 0 | G44: 0 | H44: 0 | I44: 0 | J44: 0 | K44: 0 | L44: 0 | M44: 0 | N44: 0 | O44: =SUM(C44:N44) -> 0 | Q44: =SUM(C44:E44) -> 0
A45: 4 | B45: PURWAKARTA | C45: 0 | D45: 0 | E45: 0 | F45: 0 | G45: 0 | H45: 0 | I45: 0 | J45: 0 | K45: 0 | L45: 0 | M45: 0 | N45: 0 | O45: =SUM(C45:N45) -> 0 | Q45: =SUM(C45:E45) -> 0
A46: 5 | B46: GROGOL | C46: 0 | D46: 0 | E46: 0 | F46: 0 | G46: 0 | H46: 0 | I46: 0 | J46: 0 | K46: 0 | L46: 0 | M46: 0 | N46: 0 | O46: =SUM(C46:N46) -> 0 | Q46: =SUM(C46:E46) -> 0
A47: 6 | B47: CILEGON | C47: 0 | D47: 0 | E47: 0 | F47: 0 | G47: 0 | H47: 0 | I47: 0 | J47: 0 | K47: 0 | L47: 0 | M47: 0 | N47: 0 | O47: =SUM(C47:N47) -> 0 | Q47: =SUM(C47:E47) -> 0
A48: 7 | B48: JOMBANG | C48: 0 | D48: 0 | E48: 0 | F48: 0 | G48: 0 | H48: 0 | I48: 0 | J48: 0 | K48: 0 | L48: 0 | M48: 0 | N48: 0 | O48: =SUM(C48:N48) -> 0 | Q48: =SUM(C48:E48) -> 0
A49: 8 | B49: CIBEBER | C49: 0 | D49: 0 | E49: 0 | F49: 0 | G49: 0 | H49: 0 | I49: 0 | J49: 0 | K49: 0 | L49: 0 | M49: 0 | N49: 0 | O49: =SUM(C49:N49) -> 0 | P49: 15 | Q49: =SUM(C49:E49) -> 0
A50: JUMLAH | C50: =SUM(C42:C49) -> 0 | D50: =SUM(D42:D49) -> 0 | E50: =SUM(E42:E49) -> 0 | F50: =SUM(F42:F49) -> 0 | G50: =SUM(G42:G49) -> 0 | H50: =SUM(H42:H49) -> 0 | I50: =SUM(I42:I49) -> 0 | J50: =SUM(J42:J49) -> 0 | ... P50: =SUM(P42:P49) -> 15
A68: DATA PRODUKSI KEDELAI PER BULAN
A69: KOTA CILEGON TAHUN 2020
O71: (Ton)
A72: No | B72: Kecamatan | C72: Bulan | O72: Jumlah
C73: Jan | D73: Feb | E73: Maret | F73: Apr | G73: Mei | H73: Juni | I73: Juli | J73: Agst | K73: Sept | L73: Okt | M73: Nov | N73: Des
A74: 1 | B74: 2 | C74: 3 | D74: 4 | E74: 5 | F74: 6 | G74: 7 | H74: 8 | I74: 9 | J74: 10 | K74: 11 | L74: 12 | M74: 13 | N74: 14 | O74: 15
A75: 1 | B75: CIWANDAN | C75: 0 | D75: 0 | E75: 0 | F75: 0 | G75: 0 | H75: 0 | I75: 0 | J75: 0 | K75: 0 | L75: 0 | M75: 0 | N75: 0 | O75: =SUM(C75:N75) -> 0 | Q75: =SUM(C75:E75) -> 0
A76: 2 | B76: CITANGKIL | C76: 0 | D76: 0 | E76: 0 | F76: 0 | G76: 0 | H76: 0 | I76: 0 | J76: 0 | K76: 0 | L76: 0 | M76: 0 | N76: 0 | O76: =SUM(C76:N76) -> 0 | Q76: =SUM(C76:E76) -> 0
A77: 3 | B77: PULOMERAK | C77: 0 | D77: 0 | E77: 0 | F77: 0 | G77: 0 | H77: 0 | I77: 0 | J77: 0 | K77: 0 | L77: 0 | M77: 0 | N77: 0 | O77: =SUM(C77:N77) -> 0 | Q77: =SUM(C77:E77) -> 0
A78: 4 | B78: PURWAKARTA | C78: 0 | D78: 0 | E78: 0 | F78: 0 | G78: 0 | H78: 0 | I78: 0 | J78: 0 | K78: 0 | L78: 0 | M78: 0 | N78: 0 | O78: =SUM(C78:N78) -> 0 | Q78: =SUM(C78:E78) -> 0
...

Sheet kc tanah
A2: DATA LUAS TANAM KACANG TANAH PER BULAN
A3: KOTA CILEGON TAHUN 2020
O5: (Ha)
A6: No | B6: Kecamatan | C6: Bulan | O6: Jumlah
C7: Jan | D7: Feb | E7: Maret | F7: Apr | G7: Mei | H7: Juni | I7: Juli | J7: Agst | K7: Sept | L7: Okt | M7: Nov | N7: Des
A8: 1 | B8: 2 | C8: 3 | D8: 4 | E8: 5 | F8: 6 | G8: 7 | H8: 8 | I8: 9 | J8: 10 | K8: 11 | L8: 12 | M8: 13 | N8: 14 | O8: 15
A9: 1 | B9: CIWANDAN | C9: 60 | D9: 40 | E9: 0 | F9: 0 | G9: 0 | H9: 0 | I9: 0 | J9: 0 | K9: 0 | L9: 0 | M9: 0 | N9: 0 | O9: =SUM(C9:N9) -> 100 | P9: =SUM(I9:K9) -> 0 | Q9: =SUM(F9:K9) -> 0
A10: 2 | B10: CITANGKIL | C10: 45 | D10: 0 | E10: 110 | F10: 35 | G10: 0 | H10: 0 | I10: 0 | J10: 0 | K10: 0 | L10: 2 | M10: 106 | N10: 45 | O10: =SUM(C10:N10) -> 343 | P10: =SUM(I10:K10) -> 0 | Q10: =SUM(F10:K10) -> 35
A11: 3 | B11: PULOMERAK | C11: 80 | D11: 0 | E11: 0 | F11: 120 | G11: 0 | H11: 0 | I11: 80 | J11: 0 | K11: 0 | L11: 110 | M11: 0 | N11: 50 | O11: =SUM(C11:N11) -> 440 | P11: =SUM(I11:K11) -> 80 | Q11: =SUM(F11:K11) -> 200
A12: 4 | B12: PURWAKARTA | C12: 15 | D12: 0 | E12: 18 | F12: 10 | G12: 0 | H12: 25 | I12: 15 | J12: 5 | K12: 11 | L12: 0 | M12: 0 | N12: 0 | O12: =SUM(C12:N12) -> 99 | P12: =SUM(I12:K12) -> 31 | Q12: =SUM(F12:K12) -> 66
A13: 5 | B13: GROGOL | C13: 0 | D13: 0 | E13: 0 | F13: 62 | G13: 0 | H13: 0 | I13: 0 | J13: 0 | K13: 0 | L13: 0 | M13: 0 | N13: 25 | O13: =SUM(C13:N13) -> 87 | P13: =SUM(I13:K13) -> 0 | Q13: =SUM(F13:K13) -> 62
A14: 6 | B14: CILEGON | C14: 25 | D14: 0 | E14: 40 | F14: 25 | G14: 0 | H14: 0 | I14: 2 | J14: 0 | K14: 0 | L14: 0 | M14: 30 | N14: 271 | O14: =SUM(C14:N14) -> 393 | P14: =SUM(I14:K14) -> 2 | Q14: =SUM(F14:K14) -> 27
A15: 7 | B15: JOMBANG | C15: 0 | D15: 0 | E15: 0 | F15: 1 | G15: 0 | H15: 0 | I15: 0 | J15: 0 | K15: 0 | L15: 0 | M15: 0 | N15: 0 | O15: =SUM(C15:N15) -> 1 | P15: =SUM(I15:K15) -> 0 | Q15: =SUM(F15:K15) -> 1
A16: 8 | B16: CIBEBER | C16: 10 | D16: 0 | E16: 25 | F16: 120 | G16: 0 | H16: 0 | I16: 0 | J16: 0 | K16: 0 | L16: 8 | M16: 137 | N16: 0 | O16: =SUM(C16:N16) -> 300 | P16: =SUM(I16:K16) -> 0 | Q16: =SUM(F16:K16) -> 120
A17: JUMLAH | C17: =SUM(C9:C16) -> 235 | D17: =SUM(D9:D16) -> 40 | E17: =SUM(E9:E16) -> 193 | F17: =SUM(F9:F16) -> 373 | G17: =SUM(G9:G16) -> 0 | H17: =SUM(H9:H16) -> 25 | I17: =SUM(I9:I16) -> 97 | J17: =SUM(J9:J16) -> 5 | ... P17: =SUM(P9:P16) -> 113 | Q17: =SUM(I9:K9) -> 0
J19: =SUM(C17:J17) -> 968
A35: DATA LUAS PANEN KACANG TANAH PER BULAN
A36: KOTA CILEGON TAHUN 2020
O38: (Ha)
A39: No | B39: Kecamatan | C39: Bulan | O39: Jumlah
C40: Jan | D40: Feb | E40: Maret | F40: Apr | G40: Mei | H40: Juni | I40: Juli | J40: Agst | K40: Sept | L40: Okt | M40: Nov | N40: Des
A41: 1 | B41: 2 | C41: 3 | D41: 4 | E41: 5 | F41: 6 | G41: 7 | H41: 8 | I41: 9 | J41: 10 | K41: 11 | L41: 12 | M41: 13 | N41: 14 | O41: 15
A42: 1 | B42: CIWANDAN | C42: 0 | D42: 0 | E42: 0 | F42: 60 | G42: 40 | H42: 0 | I42: 0 | J42: 0 | K42: 0 | L42: 0 | M42: 0 | N42: 0 | O42: =SUM(C42:N42) -> 100 | Q42: =SUM(F42:K42) -> 100
A43: 2 | B43: CITANGKIL | C43: 0 | D43: 0 | E43: 135 | F43: 45 | G43: 0 | H43: 110 | I43: 35 | J43: 0 | K43: 0 | L43: 0 | M43: 0 | N43: 0 | O43: =SUM(C43:N43) -> 325 | Q43: =SUM(F43:K43) -> 190
A44: 3 | B44: PULOMERAK | C44: 50 | D44: 0 | E44: 0 | F44: 80 | G44: 0 | H44: 0 | I44: 120 | J44: 0 | K44: 0 | L44: 80 | M44: 0 | N44: 110 | O44: =SUM(C44:N44) -> 440 | Q44: =SUM(F44:K44) -> 200
A45: 4 | B45: PURWAKARTA | C45: 0 | D45: 0 | E45: 40 | F45: 0 | G45: 5 | H45: 23 | I45: 0 | J45: 0 | K45: 20 | L45: 0 | M45: 0 | N45: 0 | O45: =SUM(C45:N45) -> 88 | Q45: =SUM(F45:K45) -> 48
A46: 5 | B46: GROGOL | C46: 0 | D46: 0 | E46: 271 | F46: 0 | G46: 0 | H46: 12 | I46: 50 | J46: 0 | K46: 0 | L46: 0 | M46: 0 | N46: 0 | O46: =SUM(C46:N46) -> 333 | Q46: =SUM(F46:K46) -> 62
A47: 6 | B47: CILEGON | C47: 0 | D47: 45 | E47: 25 | F47: 0 | G47: 0 | H47: 40 | I47: 25 | J47: 0 | K47: 2 | L47: 0 | M47: 0 | N47: 0 | O47: =SUM(C47:N47) -> 137 | Q47: =SUM(F47:K47) -> 67
A48: 7 | B48: JOMBANG | C48: 0 | D48: 0 | E48: 1 | F48: 0 | G48: 0 | H48: 0 | I48: 1 | J48: 0 | K48: 0 | L48: 0 | M48: 0 | N48: 0 | O48: =SUM(C48:N48) -> 2 | Q48: =SUM(F48:K48) -> 1
A49: 8 | B49: CIBEBER | C49: 0 | D49: 135 | E49: 10 | F49: 0 | G49: 0 | H49: 25 | I49: 120 | J49: 0 | K49: 0 | L49: 0 | M49: 0 | N49: 8 | O49: =SUM(C49:N49) -> 298 | Q49: =SUM(F49:K49) -> 145
A50: JUMLAH | C50: =SUM(C42:C49) -> 50 | D50: =SUM(D42:D49) -> 180 | E50: =SUM(E42:E49) -> 482 | F50: =SUM(F42:F49) -> 185 | G50: =SUM(G42:G49) -> 45 | H50: =SUM(H42:H49) -> 210 | I50: =SUM(I42:I49) -> 351 | J50: =SUM(J42:J49) -> 0 | ... O50: =SUM(O42:O49) -> 1723 | Q50: =SUM(F50:K50) -> 813
A68: DATA PRODUKSI KACANG TANAH PER BULAN
A69: KOTA CILEGON TAHUN 2020
O71: (Ton)
A72: No | B72: Kecamatan | C72: Bulan | O72: Jumlah
C73: Jan | D73: Feb | E73: Maret | F73: Apr | G73: Mei | H73: Juni | I73: Juli | J73: Agst | K73: Sept | L73: Okt | M73: Nov | N73: Des
A74: 1 | B74: 2 | C74: 3 | D74: 4 | E74: 5 | F74: 6 | G74: 7 | H74: 8 | I74: 9 | J74: 10 | K74: 11 | L74: 12 | M74: 13 | N74: 14 | O74: 15
A75: 1 | B75: CIWANDAN | C75: 0 | D75: 0 | E75: 0 | F75: 69 | G75: 37.3 | H75: 0 | I75: 0 | J75: 0 | K75: 0 | L75: 0 | M75: 0 | N75: 0 | O75: =SUM(C75:N75) -> 106.3 | Q75: =SUM(F75:K75) -> 106.3
A76: 2 | B76: CITANGKIL | C76: 0 | D76: 0 | E76: 178.9 | F76: 51.7 | G76: 0 | H76: 128.3 | I76: 38.9 | J76: 0 | K76: 0 | L76: 0 | M76: 0 | N76: 0 | O76: =SUM(C76:N76) -> 397.8 | Q76: =SUM(F76:K76) -> 218.9
A77: 3 | B77: PULOMERAK | C77: 60.1 | D77: 0 | E77: 0 | F77: 94.1 | G77: 0 | H77: 0 | I77: 138 | J77: 0 | K77: 0 | L77: 89.7 | M77: 0 | N77: 126.7 | O77: =SUM(C77:N77) -> 508.6 | Q77: =SUM(F77:K77) -> 232.1
...

Sheet ubi kayu
A2: DATA LUAS TANAM UBI KAYU PER BULAN
A3: KOTA CILEGON TAHUN 2020
O5: (Ha)
A6: No | B6: Kecamatan | C6: Bulan | O6: Jumlah
C7: Jan | D7: Feb | E7: Maret | F7: Apr | G7: Mei | H7: Juni | I7: Juli | J7: Agst | K7: Sept | L7: Okt | M7: Nov | N7: Des
A8: 1 | B8: 2 | C8: 3 | D8: 4 | E8: 5 | F8: 6 | G8: 7 | H8: 8 | I8: 9 | J8: 10 | K8: 11 | L8: 12 | M8: 13 | N8: 14 | O8: 15
A9: 1 | B9: CIWANDAN | C9: 6 | D9: 3 | E9: 0 | F9: 0 | G9: 0 | H9: 2 | I9: 0 | J9: 0 | K9: 0 | L9: 15 | M9: 5 | N9: 0 | O9: =SUM(C9:N9) -> 31
A10: 2 | B10: CITANGKIL | C10: 1 | D10: 1 | E10: 0 | F10: 1 | G10: 0 | H10: 0 | I10: 0 | J10: 0 | K10: 0 | L10: 1 | M10: 0 | N10: 1 | O10: =SUM(C10:N10) -> 5
A11: 3 | B11: PULOMERAK | C11: 15 | D11: 20 | E11: 0 | F11: 10 | G11: 0 | H11: 10 | I11: 0 | J11: 0 | K11: 0 | L11: 10 | M11: 0 | N11: 0 | O11: =SUM(C11:N11) -> 65
A12: 4 | B12: PURWAKARTA | C12: 1 | D12: 0 | E12: 0 | F12: 0 | G12: 0 | H12: 0 | I12: 0 | J12: 0 | K12: 0 | L12: 0 | M12: 0 | N12: 0 | O12: =SUM(C12:N12) -> 1
A13: 5 | B13: GROGOL | C13: 0 | D13: 0 | E13: 0 | F13: 0 | G13: 0 | H13: 0 | I13: 0 | J13: 0 | K13: 0 | L13: 0 | M13: 0 | N13: 0 | O13: =SUM(C13:N13) -> 0
A14: 6 | B14: CILEGON | C14: 0 | D14: 0 | E14: 0 | F14: 0 | G14: 0 | H14: 0 | I14: 0 | J14: 0 | K14: 0 | L14: 0 | M14: 0 | N14: 0 | O14: =SUM(C14:N14) -> 0
A15: 7 | B15: JOMBANG | C15: 0 | D15: 1 | E15: 1 | F15: 0 | G15: 0 | H15: 0 | I15: 0 | J15: 0 | K15: 0 | L15: 0 | M15: 0 | N15: 0 | O15: =SUM(C15:N15) -> 2
A16: 8 | B16: CIBEBER | C16: 3 | D16: 1 | E16: 0 | F16: 1 | G16: 0 | H16: 0 | I16: 1 | J16: 1 | K16: 1 | L16: 0 | M16: 0 | N16: 0 | O16: =SUM(C16:N16) -> 8
A17: JUMLAH | C17: =SUM(C9:C16) -> 26 | D17: =SUM(D9:D16) -> 26 | E17: =SUM(E9:E16) -> 1 | F17: =SUM(F9:F16) -> 12 | G17: =SUM(G9:G16) -> 0 | H17: =SUM(H9:H16) -> 12 | I17: =SUM(I9:I16) -> 1 | J17: =SUM(J9:J16) -> 1 | ... O17: =SUM(O9:O16) -> 112
A34: DATA LUAS PANEN UBI KAYU PER BULAN
A35: KOTA CILEGON TAHUN 2020
O37: (Ha)
A38: No | B38: Kecamatan | C38: Bulan | O38: Jumlah
C39: Jan | D39: Feb | E39: Maret | F39: Apr | G39: Mei | H39: Juni | I39: Juli | J39: Agst | K39: Sept | L39: Okt | M39: Nov | N39: Des
A40: 1 | B40: 2 | C40: 3 | D40: 4 | E40: 5 | F40: 6 | G40: 7 | H40: 8 | I40: 9 | J40: 10 | K40: 11 | L40: 12 | M40: 13 | N40: 14 | O40: 15
A41: 1 | B41: CIWANDAN | C41: 0 | D41: 0 | E41: 0 | F41: 0 | G41: 2 | H41: 0 | I41: 0 | J41: 2 | K41: 1 | L41: 0 | M41: 0 | N41: 0 | O41: =SUM(C41:N41) -> 5
A42: 2 | B42: CITANGKIL | C42: 2 | D42: 0 | E42: 0 | F42: 0 | G42: 0 | H42: 0 | I42: 0 | J42: 0 | K42: 0 | L42: 1 | M42: 0 | N42: 1 | O42: =SUM(C42:N42) -> 4
A43: 3 | B43: PULOMERAK | C43: 0 | D43: 0 | E43: 0 | F43: 0 | G43: 0 | H43: 0 | I43: 0 | J43: 0 | K43: 0 | L43: 0 | M43: 0 | N43: 0 | O43: =SUM(C43:N43) -> 0
A44: 4 | B44: PURWAKARTA | C44: 0 | D44: 0 | E44: 0 | F44: 0 | G44: 0 | H44: 0 | I44: 0 | J44: 0 | K44: 0 | L44: 0 | M44: 0 | N44: 0 | O44: =SUM(C44:N44) -> 0
A45: 5 | B45: GROGOL | C45: 0 | D45: 0 | E45: 0 | F45: 0 | G45: 0 | H45: 2 | I45: 1 | J45: 0 | K45: 0 | L45: 0 | M45: 0 | N45: 0 | O45: =SUM(C45:N45) -> 3
A46: 6 | B46: CILEGON | C46: 0 | D46: 0 | E46: 0 | F46: 0 | G46: 1 | H46: 0 | I46: 0 | J46: 0 | K46: 0 | L46: 0 | M46: 0 | N46: 0 | O46: =SUM(C46:N46) -> 1
A47: 7 | B47: JOMBANG | C47: 0 | D47: 0 | E47: 0 | F47: 0 | G47: 0 | H47: 0 | I47: 0 | J47: 0 | K47: 0 | L47: 0 | M47: 1 | N47: 0 | O47: =SUM(C47:N47) -> 1
A48: 8 | B48: CIBEBER | C48: 0 | D48: 0 | E48: 0 | F48: 2 | G48: 0 | H48: 1 | I48: 1 | J48: 2 | K48: 0 | L48: 0 | M48: 0 | N48: 0 | O48: =SUM(C48:N48) -> 6
A49: JUMLAH | C49: =SUM(C41:C48) -> 2 | D49: =SUM(D41:D48) -> 0 | E49: =SUM(E41:E48) -> 0 | F49: =SUM(F41:F48) -> 2 | G49: =SUM(G41:G48) -> 3 | H49: =SUM(H41:H48) -> 3 | I49: =SUM(I41:I48) -> 2 | J49: =SUM(J41:J48) -> 4 | ... O49: =SUM(O41:O48) -> 20
A68: DATA PRODUKSI UBI KAYU PER BULAN
A69: KOTA CILEGON TAHUN 2020
O71: (Ton)
A72: No | B72: Kecamatan | C72: Bulan | O72: Jumlah
C73: Jan | D73: Feb | E73: Maret | F73: Apr | G73: Mei | H73: Juni | I73: Juli | J73: Agst | K73: Sept | L73: Okt | M73: Nov | N73: Des
A74: 1 | B74: 2 | C74: 3 | D74: 4 | E74: 5 | F74: 6 | G74: 7 | H74: 8 | I74: 9 | J74: 10 | K74: 11 | L74: 12 | M74: 13 | N74: 14 | O74: 15
A75: 1 | B75: CIWANDAN | C75: 0 | D75: 0 | E75: 0 | F75: 0 | G75: 20.4 | H75: 0 | I75: 0 | J75: 28 | K75: 12 | L75: 0 | M75: 0 | N75: 0 | O75: =SUM(C75:N75) -> 60.4
A76: 2 | B76: CITANGKIL | C76: 25.6 | D76: 0 | E76: 0 | F76: 0 | G76: 0 | H76: 0 | I76: 0 | J76: 0 | K76: 0 | L76: 12.6 | M76: 0 | N76: 13.2 | O76: =SUM(C76:N76) -> 51.4
A77: 3 | B77: PULOMERAK | C77: 0 | D77: 0 | E77: 0 | F77: 0 | G77: 0 | H77: 0 | I77: 0 | J77: 0 | K77: 0 | L77: 0 | M77: 0 | N77: 0 | O77: =SUM(C77:N77) -> 0
A78: 4 | B78: PURWAKARTA | C78: 0 | D78: 0 | E78: 0 | F78: 0 | G78: 0 | H78: 0 | I78: 0 | J78: 0 | K78: 0 | L78: 0 | M78: 0 | N78: 0 | O78: =SUM(C78:N78) -> 0
...

Sheet ubi jalar
A2: DATA LUAS TANAM UBI JALAR PER BULAN
A3: KOTA CILEGON TAHUN 2020
O5: (Ha)
A6: No | B6: Kecamatan | C6: Bulan | O6: Jumlah
C7: Jan | D7: Feb | E7: Maret | F7: Apr | G7: Mei | H7: Juni | I7: Juli | J7: Agst | K7: Sept | L7: Okt | M7: Nov | N7: Des
A8: 1 | B8: 2 | C8: 3 | D8: 4 | E8: 5 | F8: 6 | G8: 7 | H8: 8 | I8: 9 | J8: 10 | K8: 11 | L8: 12 | M8: 13 | N8: 14 | O8: 15
A9: 1 | B9: CIWANDAN | C9: 3 | D9: 3 | E9: 3 | F9: 0 | G9: 0 | H9: 1 | I9: 1 | J9: 0 | K9: 0 | L9: 5 | M9: 6 | N9: 0 | O9: =SUM(C9:N9) -> 22
A10: 2 | B10: CITANGKIL | C10: 0 | D10: 0 | E10: 1 | F10: 1 | G10: 0 | H10: 1 | I10: 1 | J10: 0 | K10: 0 | L10: 1 | M10: 1 | N10: 1 | O10: =SUM(C10:N10) -> 7
A11: 3 | B11: PULOMERAK | C11: 0 | D11: 0 | E11: 0 | F11: 0 | G11: 0 | H11: 0 | I11: 0 | J11: 0 | K11: 0 | L11: 0 | M11: 0 | N11: 0 | O11: =SUM(C11:N11) -> 0
A12: 4 | B12: PURWAKARTA | C12: 0 | D12: 0 | E12: 0 | F12: 0 | G12: 0 | H12: 0 | I12: 2 | J12: 0 | K12: 0 | L12: 0 | M12: 0 | N12: 0 | O12: =SUM(C12:N12) -> 2
A13: 5 | B13: GROGOL | C13: 0 | D13: 0 | E13: 0 | F13: 0 | G13: 0 | H13: 0 | I13: 0 | J13: 0 | K13: 0 | L13: 0 | M13: 0 | N13: 0 | O13: =SUM(C13:N13) -> 0
A14: 6 | B14: CILEGON | C14: 1 | D14: 1 | E14: 0 | F14: 0 | G14: 0 | H14: 0 | I14: 0 | J14: 0 | K14: 0 | L14: 0 | M14: 0 | N14: 0 | O14: =SUM(C14:N14) -> 2
A15: 7 | B15: JOMBANG | C15: 0 | D15: 0 | E15: 0 | F15: 0 | G15: 0 | H15: 0 | I15: 0 | J15: 0 | K15: 0 | L15: 0 | M15: 0 | N15: 0 | O15: =SUM(C15:N15) -> 0
A16: 8 | B16: CIBEBER | C16: 0 | D16: 0 | E16: 0 | F16: 1 | G16: 0 | H16: 0 | I16: 0 | J16: 0 | K16: 0 | L16: 0 | M16: 0 | N16: 0 | O16: =SUM(C16:N16) -> 1
A17: JUMLAH | C17: =SUM(C9:C16) -> 4 | D17: =SUM(D9:D16) -> 4 | E17: =SUM(E9:E16) -> 4 | F17: =SUM(F9:F16) -> 2 | G17: =SUM(G9:G16) -> 0 | H17: =SUM(H9:H16) -> 2 | I17: =SUM(I9:I16) -> 4 | J17: =SUM(J9:J16) -> 0 | ... O17: =SUM(O9:O16) -> 34
A35: DATA LUAS PANEN UBI JALAR PER BULAN
A36: KOTA CILEGON TAHUN 2020
O38: (Ha)
A39: No | B39: Kecamatan | C39: Bulan | O39: Jumlah
C40: Jan | D40: Feb | E40: Maret | F40: Apr | G40: Mei | H40: Juni | I40: Juli | J40: Agst | K40: Sept | L40: Okt | M40: Nov | N40: Des
A41: 1 | B41: 2 | C41: 3 | D41: 4 | E41: 5 | F41: 6 | G41: 7 | H41: 8 | I41: 9 | J41: 10 | K41: 11 | L41: 12 | M41: 13 | N41: 14 | O41: 15
A42: 1 | B42: CIWANDAN | C42: 0 | D42: 0 | E42: 0 | F42: 0 | G42: 9 | H42: 0 | I42: 0 | J42: 1 | K42: 0 | L42: 0 | M42: 0 | N42: 0 | O42: =SUM(C42:N42) -> 10
A43: 2 | B43: CITANGKIL | C43: 0 | D43: 0 | E43: 1 | F43: 1 | G43: 0 | H43: 0 | I43: 0 | J43: 1 | K43: 1 | L43: 0 | M43: 1 | N43: 0 | O43: =SUM(C43:N43) -> 5
A44: 3 | B44: PULOMERAK | C44: 0 | D44: 0 | E44: 0 | F44: 0 | G44: 0 | H44: 0 | I44: 0 | J44: 0 | K44: 0 | L44: 0 | M44: 0 | N44: 0 | O44: =SUM(C44:N44) -> 0
A45: 4 | B45: PURWAKARTA | C45: 0 | D45: 0 | E45: 0 | F45: 0 | G45: 0 | H45: 0 | I45: 0 | J45: 0 | K45: 0 | L45: 0 | M45: 0 | N45: 1 | O45: =SUM(C45:N45) -> 1
A46: 5 | B46: GROGOL | C46: 0 | D46: 0 | E46: 0 | F46: 0 | G46: 0 | H46: 0 | I46: 0 | J46: 0 | K46: 0 | L46: 0 | M46: 0 | N46: 0 | O46: =SUM(C46:N46) -> 0
A47: 6 | B47: CILEGON | C47: 0 | D47: 1 | E47: 0 | F47: 0 | G47: 1 | H47: 0 | I47: 0 | J47: 0 | K47: 0 | L47: 0 | M47: 0 | N47: 0 | O47: =SUM(C47:N47) -> 2
A48: 7 | B48: JOMBANG | C48: 0 | D48: 0 | E48: 0 | F48: 0 | G48: 0 | H48: 0 | I48: 0 | J48: 0 | K48: 0 | L48: 0 | M48: 0 | N48: 0 | O48: =SUM(C48:N48) -> 0
A49: 8 | B49: CIBEBER | C49: 0 | D49: 0 | E49: 1 | F49: 0 | G49: 0 | H49: 0 | I49: 1 | J49: 0 | K49: 0 | L49: 0 | M49: 0 | N49: 0 | O49: =SUM(C49:N49) -> 2
A50: JUMLAH | C50: =SUM(C42:C49) -> 0 | D50: =SUM(D42:D49) -> 1 | E50: =SUM(E42:E49) -> 2 | F50: =SUM(F42:F49) -> 1 | G50: =SUM(G42:G49) -> 10 | H50: =SUM(H42:H49) -> 0 | I50: =SUM(I42:I49) -> 1 | J50: =SUM(J42:J49) -> 2 | ... O50: =SUM(O42:O49) -> 20
A68: DATA PRODUKSI UBI JALAR PER BULAN
A69: KOTA CILEGON TAHUN 2020
O71: (Ton)
A72: No | B72: Kecamatan | C72: Bulan | O72: Jumlah
C73: Jan | D73: Feb | E73: Maret | F73: Apr | G73: Mei | H73: Juni | I73: Juli | J73: Agst | K73: Sept | L73: Okt | M73: Nov | N73: Des
A74: 1 | B74: 2 | C74: 3 | D74: 4 | E74: 5 | F74: 6 | G74: 7 | H74: 8 | I74: 9 | J74: 10 | K74: 11 | L74: 12 | M74: 13 | N74: 14 | O74: 15
A75: 1 | B75: CIWANDAN | C75: 0 | D75: 0 | E75: 0 | F75: 0 | G75: 86.7 | H75: 0 | I75: 0 | J75: 10 | K75: 0 | L75: 0 | M75: 0 | N75: 0 | O75: =SUM(C75:N75) -> 96.7
A76: 2 | B76: CITANGKIL | C76: 0 | D76: 0 | E76: 10.2 | F76: 10.4 | G76: 0 | H76: 0 | I76: 0 | J76: 10.1 | K76: 10.2 | L76: 0 | M76: 10.6 | N76: 0 | O76: =SUM(C76:N76) -> 51.5
A77: 3 | B77: PULOMERAK | C77: 0 | D77: 0 | E77: 0 | F77: 0 | G77: 0 | H77: 0 | I77: 0 | J77: 0 | K77: 0 | L77: 0 | M77: 0 | N77: 0 | O77: =SUM(C77:N77) -> 0
A78: 4 | B78: PURWAKARTA | C78: 0 | D78: 0 | E78: 0 | F78: 0 | G78: 0 | H78: 0 | I78: 0 | J78: 0 | K78: 0 | L78: 0 | M78: 0 | N78: 10.8 | O78: =SUM(C78:N78) -> 10.8
...

Sheet kc ijo
A2: DATA LUAS TANAM KACANG HIJAU PER BULAN
A3: KOTA CILEGON TAHUN 2020
O5: (Ha)
A6: No | B6: Kecamatan | C6: Bulan | O6: Jumlah
C7: Jan | D7: Feb | E7: Maret | F7: Apr | G7: Mei | H7: Juni | I7: Juli | J7: Agst | K7: Sept | L7: Okt | M7: Nov | N7: Des
A8: 1 | B8: 2 | C8: 3 | D8: 4 | E8: 5 | F8: 6 | G8: 7 | H8: 8 | I8: 9 | J8: 10 | K8: 11 | L8: 12 | M8: 13 | N8: 14 | O8: 15
A9: 1 | B9: CIWANDAN | C9: 1 | D9: 2 | E9: 3 | F9: 0 | G9: 0 | H9: 1 | I9: 0 | J9: 0 | K9: 0 | L9: 0 | M9: 0 | N9: 0 | O9: =SUM(C9:N9) -> 7
A10: 2 | B10: CITANGKIL | C10: 0 | D10: 0 | E10: 0 | F10: 0 | G10: 0 | H10: 0 | I10: 0 | J10: 0 | K10: 0 | L10: 0 | M10: 0 | N10: 0 | O10: =SUM(C10:N10) -> 0
A11: 3 | B11: PULOMERAK | C11: 0 | D11: 0 | E11: 0 | F11: 0 | G11: 0 | H11: 0 | I11: 0 | J11: 0 | K11: 0 | L11: 0 | M11: 0 | N11: 0 | O11: =SUM(C11:N11) -> 0
A12: 4 | B12: PURWAKARTA | C12: 0 | D12: 15 | E12: 0 | F12: 0 | G12: 0 | H12: 5 | I12: 0 | J12: 15 | K12: 0 | L12: 0 | M12: 0 | N12: 0 | O12: =SUM(C12:N12) -> 35
A13: 5 | B13: GROGOL | C13: 0 | D13: 0 | E13: 0 | F13: 0 | G13: 0 | H13: 0 | I13: 0 | J13: 0 | K13: 0 | L13: 0 | M13: 0 | N13: 0 | O13: =SUM(C13:N13) -> 0
A14: 6 | B14: CILEGON | C14: 0 | D14: 0 | E14: 0 | F14: 0 | G14: 0 | H14: 0 | I14: 0 | J14: 0 | K14: 0 | L14: 0 | M14: 0 | N14: 0 | O14: =SUM(C14:N14) -> 0
A15: 7 | B15: JOMBANG | C15: 0 | D15: 0 | E15: 0 | F15: 0 | G15: 0 | H15: 0 | I15: 0 | J15: 0 | K15: 0 | L15: 0 | M15: 0 | N15: 0 | O15: =SUM(C15:N15) -> 0
A16: 8 | B16: CIBEBER | C16: 0 | D16: 0 | E16: 0 | F16: 1 | G16: 0 | H16: 0 | I16: 0 | J16: 0 | K16: 0 | L16: 0 | M16: 0 | N16: 0 | O16: =SUM(C16:N16) -> 1
A17: JUMLAH | C17: =SUM(C9:C16) -> 1 | D17: =SUM(D9:D16) -> 17 | E17: =SUM(E9:E16) -> 3 | F17: =SUM(F9:F16) -> 1 | G17: =SUM(G9:G16) -> 0 | H17: =SUM(H9:H16) -> 6 | I17: =SUM(I9:I16) -> 0 | J17: =SUM(J9:J16) -> 15 | ... O17: =SUM(O9:O16) -> 43
A35: DATA LUAS PANEN KACANG HIJAU PER BULAN
A36: KOTA CILEGON TAHUN 2020
O38: (Ha)
A39: No | B39: Kecamatan | C39: Bulan | O39: Jumlah
C40: Jan | D40: Feb | E40: Maret | F40: Apr | G40: Mei | H40: Juni | I40: Juli | J40: Agst | K40: Sept | L40: Okt | M40: Nov | N40: Des
A41: 1 | B41: 2 | C41: 3 | D41: 4 | E41: 5 | F41: 6 | G41: 7 | H41: 8 | I41: 9 | J41: 10 | K41: 11 | L41: 12 | M41: 13 | N41: 14 | O41: 15
A42: 1 | B42: CIWANDAN | C42: 0 | D42: 0 | E42: 0 | F42: 1 | G42: 5 | H42: 0 | I42: 0 | J42: 0 | K42: 0 | L42: 0 | M42: 0 | N42: 0 | O42: =SUM(C42:N42) -> 6
A43: 2 | B43: CITANGKIL | C43: 0 | D43: 0 | E43: 1 | F43: 0 | G43: 0 | H43: 0 | I43: 0 | J43: 0 | K43: 0 | L43: 0 | M43: 0 | N43: 0 | O43: =SUM(C43:N43) -> 1
A44: 3 | B44: PULOMERAK | C44: 0 | D44: 0 | E44: 0 | F44: 0 | G44: 0 | H44: 0 | I44: 0 | J44: 0 | K44: 0 | L44: 0 | M44: 0 | N44: 0 | O44: =SUM(C44:N44) -> 0
A45: 4 | B45: PURWAKARTA | C45: 0 | D45: 0 | E45: 10 | F45: 0 | G45: 0 | H45: 10 | I45: 10 | J45: 0 | K45: 0 | L45: 0 | M45: 0 | N45: 5 | O45: =SUM(C45:N45) -> 35
A46: 5 | B46: GROGOL | C46: 0 | D46: 0 | E46: 0 | F46: 0 | G46: 0 | H46: 0 | I46: 0 | J46: 0 | K46: 0 | L46: 0 | M46: 0 | N46: 0 | O46: =SUM(C46:N46) -> 0
A47: 6 | B47: CILEGON | C47: 0 | D47: 0 | E47: 0 | F47: 0 | G47: 0 | H47: 0 | I47: 0 | J47: 0 | K47: 0 | L47: 0 | M47: 0 | N47: 0 | O47: =SUM(C47:N47) -> 0
A48: 7 | B48: JOMBANG | C48: 0 | D48: 0 | E48: 0 | F48: 0 | G48: 0 | H48: 0 | I48: 0 | J48: 0 | K48: 0 | L48: 0 | M48: 0 | N48: 0 | O48: =SUM(C48:N48) -> 0
A49: 8 | B49: CIBEBER | C49: 0 | D49: 1 | E49: 0 | F49: 0 | G49: 0 | H49: 1 | I49: 0 | J49: 0 | K49: 0 | L49: 0 | M49: 0 | N49: 0 | O49: =SUM(C49:N49) -> 2
A50: JUMLAH | C50: =SUM(C42:C49) -> 0 | D50: =SUM(D42:D49) -> 1 | E50: =SUM(E42:E49) -> 11 | F50: =SUM(F42:F49) -> 1 | G50: =SUM(G42:G49) -> 5 | H50: =SUM(H42:H49) -> 11 | I50: =SUM(I42:I49) -> 10 | J50: =SUM(J42:J49) -> 0 | ... O50: =SUM(O42:O49) -> 44
A68: DATA PRODUKSI KACANG HIJAU PER BULAN
A69: KOTA CILEGON TAHUN 2020
O71: (Ton)
A72: No | B72: Kecamatan | C72: Bulan | O72: Jumlah
C73: Jan | D73: Feb | E73: Maret | F73: Apr | G73: Mei | H73: Juni | I73: Juli | J73: Agst | K73: Sept | L73: Okt | M73: Nov | N73: Des
A74: 1 | B74: 2 | C74: 3 | D74: 4 | E74: 5 | F74: 6 | G74: 7 | H74: 8 | I74: 9 | J74: 10 | K74: 11 | L74: 12 | M74: 13 | N74: 14 | O74: 15
A75: 1 | B75: CIWANDAN | C75: 0 | D75: 0 | E75: 0 | F75: 0.8 | G75: 4 | H75: 0 | I75: 0 | J75: 0 | K75: 0 | L75: 0 | M75: 0 | N75: 0 | O75: =SUM(C75:N75) -> 4.8
A76: 2 | B76: CITANGKIL | C76: 0 | D76: 0 | E76: 0.9 | F76: 0 | G76: 0 | H76: 0 | I76: 0 | J76: 0 | K76: 0 | L76: 0 | M76: 0 | N76: 0 | O76: =SUM(C76:N76) -> 0.9
A77: 3 | B77: PULOMERAK | C77: 0 | D77: 0 | E77: 0 | F77: 0 | G77: 0 | H77: 0 | I77: 0 | J77: 0 | K77: 0 | L77: 0 | M77: 0 | N77: 0 | O77: =SUM(C77:N77) -> 0
A78: 4 | B78: PURWAKARTA | C78: 0 | D78: 0 | E78: 9 | F78: 0 | G78: 0 | H78: 8.2 | I78: 8.2 | J78: 0 | K78: 0 | L78: 0 | M78: 0 | N78: 4.5 | O78: =SUM(C78:N78) -> 29.9
...

Sheet talas
A2: DATA LUAS TANAM TALAS PER BULAN
A3: KOTA CILEGON TAHUN 2020
O5: (Ha)
A6: No | B6: Kecamatan | C6: Bulan | O6: Jumlah
C7: Jan | D7: Feb | E7: Maret | F7: Apr | G7: Mei | H7: Juni | I7: Juli | J7: Agst | K7: Sept | L7: Okt | M7: Nov | N7: Des
A8: 1 | B8: 2 | C8: 3 | D8: 4 | E8: 5 | F8: 6 | G8: 7 | H8: 8 | I8: 9 | J8: 10 | K8: 11 | L8: 12 | M8: 13 | N8: 14 | O8: 15 | Q8: ok-nop
A9: 1 | B9: CIWANDAN | C9: 0 | D9: 0 | E9: 0 | F9: 0 | G9: 0 | H9: 0 | I9: 0 | J9: 0 | K9: 0 | L9: 0 | M9: 0 | N9: 0 | O9: =SUM(C9:N9) -> 0 | Q9: =SUM(L9:M9) -> 0
A10: 2 | B10: CITANGKIL | C10: 0 | D10: 0 | E10: 0 | F10: 1 | G10: 0 | H10: 0 | I10: 0 | J10: 0 | K10: 0 | L10: 0 | M10: 0 | N10: 0 | O10: =SUM(C10:N10) -> 1 | Q10: =SUM(L10:M10) -> 0
A11: 3 | B11: PULOMERAK | C11: 0 | D11: 0 | E11: 0 | F11: 0 | G11: 0 | H11: 0 | I11: 0 | J11: 0 | K11: 0 | L11: 0 | M11: 0 | N11: 0 | O11: =SUM(C11:N11) -> 0 | Q11: =SUM(L11:M11) -> 0
A12: 4 | B12: PURWAKARTA | C12: 0 | D12: 0 | E12: 0 | F12: 0 | G12: 0 | H12: 0 | I12: 0 | J12: 0 | K12: 0 | L12: 0 | M12: 0 | N12: 0 | O12: =SUM(C12:N12) -> 0 | Q12: =SUM(L12:M12) -> 0
A13: 5 | B13: GROGOL | C13: 0 | D13: 0 | E13: 0 | F13: 0 | G13: 0 | H13: 0 | I13: 0 | J13: 0 | K13: 0 | L13: 0 | M13: 1 | N13: 0 | O13: =SUM(C13:N13) -> 1 | Q13: =SUM(L13:M13) -> 1
A14: 6 | B14: CILEGON | C14: 0 | D14: 0 | E14: 0 | F14: 0 | G14: 0 | H14: 0 | I14: 0 | J14: 0 | K14: 0 | L14: 0 | M14: 0 | N14: 0 | O14: =SUM(C14:N14) -> 0 | Q14: =SUM(L14:M14) -> 0
A15: 7 | B15: JOMBANG | C15: 0 | D15: 0 | E15: 0 | F15: 0 | G15: 0 | H15: 0 | I15: 0 | J15: 0 | K15: 0 | L15: 0 | M15: 0 | N15: 0 | O15: =SUM(C15:N15) -> 0 | Q15: =SUM(L15:M15) -> 0
A16: 8 | B16: CIBEBER | C16: 0 | D16: 0 | E16: 0 | F16: 0 | G16: 0 | H16: 0 | I16: 0 | J16: 0 | K16: 0 | L16: 0 | M16: 0 | N16: 0 | O16: =SUM(C16:N16) -> 0 | Q16: =SUM(L16:M16) -> 0
A17: JUMLAH | C17: =SUM(C9:C16) -> 0 | D17: =SUM(D9:D16) -> 0 | E17: =SUM(E9:E16) -> 0 | F17: =SUM(F9:F16) -> 1 | G17: =SUM(G9:G16) -> 0 | H17: =SUM(H9:H16) -> 0 | I17: =SUM(I9:I16) -> 0 | J17: =SUM(J9:J16) -> 0 | ... O17: =SUM(O9:O16) -> 2
A35: DATA LUAS PANEN TALAS PER BULAN
A36: KOTA CILEGON TAHUN 2020
O38: (Ha)
A39: No | B39: Kecamatan | C39: Bulan | O39: Jumlah
C40: Jan | D40: Feb | E40: Maret | F40: Apr | G40: Mei | H40: Juni | I40: Juli | J40: Agst | K40: Sept | L40: Okt | M40: Nov | N40: Des
A41: 1 | B41: 2 | C41: 3 | D41: 4 | E41: 5 | F41: 6 | G41: 7 | H41: 8 | I41: 9 | J41: 10 | K41: 11 | L41: 12 | M41: 13 | N41: 14 | O41: 15
A42: 1 | B42: CIWANDAN | C42: 0 | D42: 0 | E42: 0 | F42: 0 | G42: 0 | H42: 0 | I42: 0 | J42: 0 | K42: 0 | L42: 0 | M42: 0 | N42: 0 | O42: =SUM(C42:N42) -> 0 | Q42: =SUM(C42:E42) -> 0
A43: 2 | B43: CITANGKIL | C43: 0 | D43: 1 | E43: 0 | F43: 0 | G43: 0 | H43: 0 | I43: 0 | J43: 0 | K43: 0 | L43: 0 | M43: 0 | N43: 0 | O43: =SUM(C43:N43) -> 1 | Q43: =SUM(C43:E43) -> 1
A44: 3 | B44: PULOMERAK | C44: 0 | D44: 0 | E44: 0 | F44: 0 | G44: 0 | H44: 0 | I44: 0 | J44: 0 | K44: 0 | L44: 0 | M44: 0 | N44: 0 | O44: =SUM(C44:N44) -> 0 | Q44: =SUM(C44:E44) -> 0
A45: 4 | B45: PURWAKARTA | C45: 0 | D45: 0 | E45: 0 | F45: 0 | G45: 0 | H45: 0 | I45: 0 | J45: 0 | K45: 0 | L45: 0 | M45: 0 | N45: 0 | O45: =SUM(C45:N45) -> 0 | Q45: =SUM(C45:E45) -> 0
A46: 5 | B46: GROGOL | C46: 0 | D46: 0 | E46: 0 | F46: 0 | G46: 0 | H46: 0 | I46: 0 | J46: 0 | K46: 0 | L46: 0 | M46: 0 | N46: 0 | O46: =SUM(C46:N46) -> 0 | Q46: =SUM(C46:E46) -> 0
A47: 6 | B47: CILEGON | C47: 0 | D47: 0 | E47: 0 | F47: 0 | G47: 0 | H47: 0 | I47: 0 | J47: 0 | K47: 0 | L47: 0 | M47: 0 | N47: 0 | O47: =SUM(C47:N47) -> 0 | Q47: =SUM(C47:E47) -> 0
A48: 7 | B48: JOMBANG | C48: 0 | D48: 0 | E48: 0 | F48: 0 | G48: 0 | H48: 0 | I48: 0 | J48: 0 | K48: 0 | L48: 0 | M48: 0 | N48: 0 | O48: =SUM(C48:N48) -> 0 | Q48: =SUM(C48:E48) -> 0
A49: 8 | B49: CIBEBER | C49: 0 | D49: 0 | E49: 0 | F49: 0 | G49: 0 | H49: 0 | I49: 0 | J49: 0 | K49: 0 | L49: 0 | M49: 0 | N49: 0 | O49: =SUM(C49:N49) -> 0 | P49: 15 | Q49: =SUM(C49:E49) -> 0
A50: JUMLAH | C50: =SUM(C42:C49) -> 0 | D50: =SUM(D42:D49) -> 1 | E50: =SUM(E42:E49) -> 0 | F50: =SUM(F42:F49) -> 0 | G50: =SUM(G42:G49) -> 0 | H50: =SUM(H42:H49) -> 0 | I50: =SUM(I42:I49) -> 0 | J50: =SUM(J42:J49) -> 0 | ... P50: =SUM(P42:P49) -> 15
A68: DATA PRODUKSI TALAS PER BULAN
A69: KOTA CILEGON TAHUN 2020
O71: (Ton)
A72: No | B72: Kecamatan | C72: Bulan | O72: Jumlah
C73: Jan | D73: Feb | E73: Maret | F73: Apr | G73: Mei | H73: Juni | I73: Juli | J73: Agst | K73: Sept | L73: Okt | M73: Nov | N73: Des
A74: 1 | B74: 2 | C74: 3 | D74: 4 | E74: 5 | F74: 6 | G74: 7 | H74: 8 | I74: 9 | J74: 10 | K74: 11 | L74: 12 | M74: 13 | N74: 14 | O74: 15
A75: 1 | B75: CIWANDAN | C75: 0 | D75: 0 | E75: 0 | F75: 0 | G75: 0 | H75: 0 | I75: 0 | J75: 0 | K75: 0 | L75: 0 | M75: 0 | N75: 0 | O75: =SUM(C75:N75) -> 0 | Q75: =SUM(C75:E75) -> 0
A76: 2 | B76: CITANGKIL | C76: 0 | D76: 9.8 | E76: 0 | F76: 0 | G76: 0 | H76: 0 | I76: 0 | J76: 0 | K76: 0 | L76: 0 | M76: 0 | N76: 0 | O76: =SUM(C76:N76) -> 9.8 | Q76: =SUM(C76:E76) -> 9.8
A77: 3 | B77: PULOMERAK | C77: 0 | D77: 0 | E77: 0 | F77: 0 | G77: 0 | H77: 0 | I77: 0 | J77: 0 | K77: 0 | L77: 0 | M77: 0 | N77: 0 | O77: =SUM(C77:N77) -> 0 | Q77: =SUM(C77:E77) -> 0
A78: 4 | B78: PURWAKARTA | C78: 0 | D78: 0 | E78: 0 | F78: 0 | G78: 0 | H78: 0 | I78: 0 | J78: 0 | K78: 0 | L78: 0 | M78: 0 | N78: 0 | O78: =SUM(C78:N78) -> 0 | Q78: =SUM(C78:E78) -> 0
...

Sheet sorgum
A2: DATA LUAS TANAM SORGUM PER BULAN
A3: KOTA CILEGON TAHUN 2020
O5: (Ha)
A6: No | B6: Kecamatan | C6: Bulan | O6: Jumlah
C7: Jan | D7: Feb | E7: Maret | F7: Apr | G7: Mei | H7: Juni | I7: Juli | J7: Agst | K7: Sept | L7: Okt | M7: Nov | N7: Des
A8: 1 | B8: 2 | C8: 3 | D8: 4 | E8: 5 | F8: 6 | G8: 7 | H8: 8 | I8: 9 | J8: 10 | K8: 11 | L8: 12 | M8: 13 | N8: 14 | O8: 15 | Q8: ok-nop
A9: 1 | B9: CIWANDAN | C9: 0 | D9: 0 | E9: 0 | F9: 0 | G9: 0 | H9: 0 | I9: 0 | J9: 0 | K9: 0 | L9: 0 | M9: 0 | N9: 0 | O9: =SUM(C9:N9) -> 0 | Q9: =SUM(L9:M9) -> 0
A10: 2 | B10: CITANGKIL | C10: 0 | D10: 0 | E10: 0 | F10: 0 | G10: 0 | H10: 0 | I10: 0 | J10: 0 | K10: 0 | L10: 0 | M10: 0 | N10: 0 | O10: =SUM(C10:N10) -> 0 | Q10: =SUM(L10:M10) -> 0
A11: 3 | B11: PULOMERAK | C11: 0 | D11: 0 | E11: 0 | F11: 0 | G11: 0 | H11: 0 | I11: 0 | J11: 0 | K11: 0 | L11: 0 | M11: 0 | N11: 0 | O11: =SUM(C11:N11) -> 0 | Q11: =SUM(L11:M11) -> 0
A12: 4 | B12: PURWAKARTA | C12: 0 | D12: 0 | E12: 0 | F12: 0 | G12: 0 | H12: 0 | I12: 0 | J12: 0 | K12: 0 | L12: 0 | M12: 0 | N12: 0 | O12: =SUM(C12:N12) -> 0 | Q12: =SUM(L12:M12) -> 0
A13: 5 | B13: GROGOL | C13: 0 | D13: 0 | E13: 0 | F13: 0 | G13: 0 | H13: 0 | I13: 0 | J13: 0 | K13: 0 | L13: 0 | M13: 0 | N13: 0 | O13: =SUM(C13:N13) -> 0 | Q13: =SUM(L13:M13) -> 0
A14: 6 | B14: CILEGON | C14: 0 | D14: 0 | E14: 0 | F14: 0 | G14: 0 | H14: 0 | I14: 0 | J14: 0 | K14: 0 | L14: 0 | M14: 0 | N14: 0 | O14: =SUM(C14:N14) -> 0 | Q14: =SUM(L14:M14) -> 0
A15: 7 | B15: JOMBANG | C15: 0 | D15: 0 | E15: 0 | F15: 0 | G15: 0 | H15: 0 | I15: 0 | J15: 0 | K15: 0 | L15: 0 | M15: 0 | N15: 0 | O15: =SUM(C15:N15) -> 0 | Q15: =SUM(L15:M15) -> 0
A16: 8 | B16: CIBEBER | C16: 0 | D16: 0 | E16: 0 | F16: 0 | G16: 0 | H16: 0 | I16: 0 | J16: 0 | K16: 0 | L16: 0 | M16: 0 | N16: 0 | O16: =SUM(C16:N16) -> 0 | Q16: =SUM(L16:M16) -> 0
A17: JUMLAH | C17: =SUM(C9:C16) -> 0 | D17: =SUM(D9:D16) -> 0 | E17: =SUM(E9:E16) -> 0 | F17: =SUM(F9:F16) -> 0 | G17: =SUM(G9:G16) -> 0 | H17: =SUM(H9:H16) -> 0 | I17: =SUM(I9:I16) -> 0 | J17: =SUM(J9:J16) -> 0 | ... O17: =SUM(O9:O16) -> 0
A35: DATA LUAS PANEN SORGUM PER BULAN
A36: KOTA CILEGON TAHUN 2020
O38: (Ha)
A39: No | B39: Kecamatan | C39: Bulan | O39: Jumlah
C40: Jan | D40: Feb | E40: Maret | F40: Apr | G40: Mei | H40: Juni | I40: Juli | J40: Agst | K40: Sept | L40: Okt | M40: Nov | N40: Des
A41: 1 | B41: 2 | C41: 3 | D41: 4 | E41: 5 | F41: 6 | G41: 7 | H41: 8 | I41: 9 | J41: 10 | K41: 11 | L41: 12 | M41: 13 | N41: 14 | O41: 15
A42: 1 | B42: CIWANDAN | C42: 0 | D42: 0 | E42: 0 | F42: 0 | G42: 0 | H42: 0 | I42: 0 | J42: 0 | K42: 0 | L42: 0 | M42: 0 | N42: 0 | O42: =SUM(C42:N42) -> 0 | Q42: =SUM(C42:E42) -> 0
A43: 2 | B43: CITANGKIL | C43: 0 | D43: 0 | E43: 0 | F43: 0 | G43: 0 | H43: 0 | I43: 0 | J43: 0 | K43: 0 | L43: 0 | M43: 0 | N43: 0 | O43: =SUM(C43:N43) -> 0 | Q43: =SUM(C43:E43) -> 0
A44: 3 | B44: PULOMERAK | C44: 0 | D44: 0 | E44: 0 | F44: 0 | G44: 0 | H44: 0 | I44: 0 | J44: 0 | K44: 0 | L44: 0 | M44: 0 | N44: 0 | O44: =SUM(C44:N44) -> 0 | Q44: =SUM(C44:E44) -> 0
A45: 4 | B45: PURWAKARTA | C45: 0 | D45: 0 | E45: 0 | F45: 0 | G45: 0 | H45: 0 | I45: 0 | J45: 0 | K45: 0 | L45: 0 | M45: 0 | N45: 0 | O45: =SUM(C45:N45) -> 0 | Q45: =SUM(C45:E45) -> 0
A46: 5 | B46: GROGOL | C46: 0 | D46: 0 | E46: 0 | F46: 0 | G46: 0 | H46: 0 | I46: 0 | J46: 0 | K46: 0 | L46: 0 | M46: 0 | N46: 0 | O46: =SUM(C46:N46) -> 0 | Q46: =SUM(C46:E46) -> 0
A47: 6 | B47: CILEGON | C47: 0 | D47: 0 | E47: 0 | F47: 0 | G47: 0 | H47: 0 | I47: 0 | J47: 0 | K47: 0 | L47: 0 | M47: 0 | N47: 0 | O47: =SUM(C47:N47) -> 0 | Q47: =SUM(C47:E47) -> 0
A48: 7 | B48: JOMBANG | C48: 0 | D48: 0 | E48: 0 | F48: 0 | G48: 0 | H48: 0 | I48: 0 | J48: 0 | K48: 0 | L48: 0 | M48: 0 | N48: 0 | O48: =SUM(C48:N48) -> 0 | Q48: =SUM(C48:E48) -> 0
A49: 8 | B49: CIBEBER | C49: 0.5 | D49: 0 | E49: 0 | F49: 0 | G49: 0 | H49: 0 | I49: 0 | J49: 0 | K49: 0 | L49: 0 | M49: 0 | N49: 0 | O49: =SUM(C49:N49) -> 0.5 | P49: 15 | Q49: =SUM(C49:E49) -> 0.5
A50: JUMLAH | C50: =SUM(C42:C49) -> 0.5 | D50: =SUM(D42:D49) -> 0 | E50: =SUM(E42:E49) -> 0 | F50: =SUM(F42:F49) -> 0 | G50: =SUM(G42:G49) -> 0 | H50: =SUM(H42:H49) -> 0 | I50: =SUM(I42:I49) -> 0 | J50: =SUM(J42:J49) -> 0 | ... P50: =SUM(P42:P49) -> 15
A68: DATA PRODUKSI SORGUM PER BULAN
A69: KOTA CILEGON TAHUN 2020
O71: (Ton)
A72: No | B72: Kecamatan | C72: Bulan | O72: Jumlah
C73: Jan | D73: Feb | E73: Maret | F73: Apr | G73: Mei | H73: Juni | I73: Juli | J73: Agst | K73: Sept | L73: Okt | M73: Nov | N73: Des
A74: 1 | B74: 2 | C74: 3 | D74: 4 | E74: 5 | F74: 6 | G74: 7 | H74: 8 | I74: 9 | J74: 10 | K74: 11 | L74: 12 | M74: 13 | N74: 14 | O74: 15
A75: 1 | B75: CIWANDAN | C75: 0 | D75: 0 | E75: 0 | F75: 0 | G75: 0 | H75: 0 | I75: 0 | J75: 0 | K75: 0 | L75: 0 | M75: 0 | N75: 0 | O75: =SUM(C75:N75) -> 0 | Q75: =SUM(C75:E75) -> 0
A76: 2 | B76: CITANGKIL | C76: 0 | D76: 0 | E76: 0 | F76: 0 | G76: 0 | H76: 0 | I76: 0 | J76: 0 | K76: 0 | L76: 0 | M76: 0 | N76: 0 | O76: =SUM(C76:N76) -> 0 | Q76: =SUM(C76:E76) -> 0
A77: 3 | B77: PULOMERAK | C77: 0 | D77: 0 | E77: 0 | F77: 0 | G77: 0 | H77: 0 | I77: 0 | J77: 0 | K77: 0 | L77: 0 | M77: 0 | N77: 0 | O77: =SUM(C77:N77) -> 0 | Q77: =SUM(C77:E77) -> 0
A78: 4 | B78: PURWAKARTA | C78: 0 | D78: 0 | E78: 0 | F78: 0 | G78: 0 | H78: 0 | I78: 0 | J78: 0 | K78: 0 | L78: 0 | M78: 0 | N78: 0 | O78: =SUM(C78:N78) -> 0 | Q78: =SUM(C78:E78) -> 0
...

Sheet rekap
A1: REALISASI TANAM, PANEN, PRODUKSI DAN PRODUKTIVITAS PADI DAN PALAWIJA
A2: KOTA CILEGON 2020
A4: 1. PADI SAWAH
A5: No | B5: Kecamatan | C5: TANAM | D5: PANEN | E5: PRODUKSI | F5: PRODUKTIVITAS
C6: (Ha) | D6: (Ha) | E6: (Ton) | F6: (Ku/Ha)
A7: 1 | B7: 2 | C7: 3 | D7: 4 | E7: 5 | F7: 6
A8: 1 | B8: CIWANDAN | C8: ='padi sawah'!O9 -> 287 | D8: ='padi sawah'!O42 -> 275 | E8: ='padi sawah'!O75 -> 1544.3 | F8: ='padi sawah'!O108 -> 56.156364
A9: 2 | B9: CITANGKIL | C9: ='padi sawah'!O10 -> 417 | D9: ='padi sawah'!O43 -> 330 | E9: ='padi sawah'!O76 -> 2144.1 | F9: ='padi sawah'!O109 -> 64.972727
A10: 3 | B10: PULOMERAK | C10: ='padi sawah'!O11 -> 45 | D10: ='padi sawah'!O44 -> 35 | E10: ='padi sawah'!O77 -> 204.3 | F10: ='padi sawah'!O110 -> 58.371429
A11: 4 | B11: PURWAKARTA | C11: ='padi sawah'!O12 -> 320 | D11: ='padi sawah'!O45 -> 203 | E11: ='padi sawah'!O78 -> 1164.1 | F11: ='padi sawah'!O111 -> 57.344828
A12: 5 | B12: GROGOL | C12: ='padi sawah'!O13 -> 334 | D12: ='padi sawah'!O46 -> 177 | E12: ='padi sawah'!O79 -> 994.2 | F12: ='padi sawah'!O112 -> 56.169492
A13: 6 | B13: CILEGON | C13: ='padi sawah'!O14 -> 113 | D13: ='padi sawah'!O47 -> 98 | E13: ='padi sawah'!O80 -> 563.9 | F13: ='padi sawah'!O113 -> 57.540816
A14: 7 | B14: JOMBANG | C14: ='padi sawah'!O15 -> 671 | D14: ='padi sawah'!O48 -> 595 | E14: ='padi sawah'!O81 -> 3628.1 | F14: ='padi sawah'!O114 -> 60.976471
A15: 8 | B15: CIBEBER | C15: ='padi sawah'!O16 -> 485 | D15: ='padi sawah'!O49 -> 355 | E15: ='padi sawah'!O82 -> 2173.7 | F15: ='padi sawah'!O115 -> 61.230986
A16: JUMLAH | C16: =SUM(C8:C15) -> 2672 | D16: =SUM(D8:D15) -> 2068 | E16: =SUM(E8:E15) -> 12416.7 | F16: =E16/D16*10 -> 60.04207
A18: 2. PADI LADANG
A19: No | B19: Kecamatan | C19: TANAM | D19: PANEN | E19: PRODUKSI | F19: PRODUKTIVITAS
C20: (Ha) | D20: (Ha) | E20: (Ton) | F20: (Ku/Ha)
A21: 1 | B21: 2 | C21: 3 | D21: 4 | E21: 5 | F21: 6
A22: 1 | B22: CIWANDAN | C22: ='padi ladang'!O9 -> 0 | D22: ='padi ladang'!O42 -> 0 | E22: ='padi ladang'!O75 -> 0 | F22: ='padi ladang'!O108 -> 0
A23: 2 | B23: CITANGKIL | C23: ='padi ladang'!O10 -> 0 | D23: ='padi ladang'!O43 -> 0 | E23: ='padi ladang'!O76 -> 0 | F23: ='padi ladang'!O109 -> 0
A24: 3 | B24: PULOMERAK | C24: ='padi ladang'!O11 -> 0 | D24: ='padi ladang'!O44 -> 0 | E24: ='padi ladang'!O77 -> 0 | F24: ='padi ladang'!O110 -> 0
A25: 4 | B25: PURWAKARTA | C25: ='padi ladang'!O12 -> 0 | D25: ='padi ladang'!O45 -> 0 | E25: ='padi ladang'!O78 -> 0 | F25: ='padi ladang'!O111 -> 0
A26: 5 | B26: GROGOL | C26: ='padi ladang'!O13 -> 0 | D26: ='padi ladang'!O46 -> 0 | E26: ='padi ladang'!O79 -> 0 | F26: ='padi ladang'!O112 -> 0
A27: 6 | B27: CILEGON | C27: ='padi ladang'!O14 -> 0 | D27: ='padi ladang'!O47 -> 0 | E27: ='padi ladang'!O80 -> 0 | F27: ='padi ladang'!O113 -> 0
A28: 7 | B28: JOMBANG | C28: ='padi ladang'!O15 -> 0 | D28: ='padi ladang'!O48 -> 0 | E28: ='padi ladang'!O81 -> 0 | F28: ='padi ladang'!O114 -> 0
A29: 8 | B29: CIBEBER | C29: ='padi ladang'!O16 -> 2 | D29: ='padi ladang'!O49 -> 2 | E29: ='padi ladang'!O82 -> 11.2 | F29: ='padi ladang'!O115 -> 56.11
A30: JUMLAH | C30: =SUM(C22:C29) -> 2 | D30: =SUM(D22:D29) -> 2 | E30: =SUM(E22:E29) -> 11.2 | F30: 0
A32: 3. JAGUNG
A33: No | B33: Kecamatan | C33: TANAM | D33: PANEN | E33: PRODUKSI | F33: PRODUKTIVITAS
C34: (Ha) | D34: (Ha) | E34: (Ton) | F34: (Ku/Ha)
A35: 1 | B35: 2 | C35: 3 | D35: 4 | E35: 5 | F35: 6
A36: 1 | B36: CIWANDAN | C36: =jagung!O9 -> 12 | D36: =jagung!O42 -> 9 | E36: =jagung!O75 -> 26.1 | F36: =jagung!O108 -> 29
A37: 2 | B37: CITANGKIL | C37: =jagung!O10 -> 5 | D37: =jagung!O43 -> 4 | E37: =jagung!O76 -> 0 | F37: =jagung!O109 -> 0
A38: 3 | B38: PULOMERAK | C38: =jagung!O11 -> 0 | D38: =jagung!O44 -> 0 | E38: =jagung!O77 -> 0 | F38: =jagung!O110 -> 0
A39: 4 | B39: PURWAKARTA | C39: =jagung!O12 -> 7 | D39: =jagung!O45 -> 6 | E39: =jagung!O78 -> 7.9 | F39: =jagung!O111 -> 26.533333
A40: 5 | B40: GROGOL | C40: =jagung!O13 -> 0 | D40: =jagung!O46 -> 0 | E40: =jagung!O79 -> 0 | F40: =jagung!O112 -> 0
A41: 6 | B41: CILEGON | C41: =jagung!O14 -> 0.5 | D41: =jagung!O47 -> 0 | E41: =jagung!O80 -> 0 | F41: =jagung!O113 -> 0
A42: 7 | B42: JOMBANG | C42: =jagung!O15 -> 2 | D42: =jagung!O48 -> 1 | E42: =jagung!O81 -> 0 | F42: =jagung!O114 -> 0
A43: 8 | B43: CIBEBER | C43: =jagung!O16 -> 4 | D43: =jagung!O49 -> 3 | E43: =jagung!O82 -> 5.1 | F43: =jagung!O115 -> 25.635
...

Sheet jag&kc
A1: REALISASI TANAM, PANEN, PRODUKSI DAN PRODUKTIVITAS PADI DAN PALAWIJA
A2: KOTA CILEGON 2019
A4: 1. JAGUNG
A5: No | B5: Kecamatan | C5: TANAM | D5: PANEN | E5: PRODUKSI | F5: PRODUKTIVITAS
C6: (Ha) | D6: (Ha) | E6: (Ton) | F6: (Ku/Ha)
A7: 1 | B7: 2 | C7: 3 | D7: 4 | E7: 5 | F7: 6
A8: 1 | B8: CIWANDAN | C8: 14 | D8: 20 | E8: 63.8 | F8: 31.9
A9: 2 | B9: CITANGKIL | C9: 7 | D9: 7 | E9: 18.8 | F9: 26.857143
A10: 3 | B10: PULOMERAK | C10: 5 | D10: 95 | E10: 324.5 | F10: 34.157895
A11: 4 | B11: PURWAKARTA | C11: 5 | D11: 10 | E11: 26.8 | F11: 26.8
A12: 5 | B12: GROGOL | C12: 15 | D12: 27 | E12: 79.1 | F12: 29.296296
A13: 6 | B13: CILEGON | C13: 5 | D13: 5 | E13: 12 | F13: 24
A14: 7 | B14: JOMBANG | C14: 0 | D14: 3 | E14: 7.7 | F14: 25.666667
A15: 8 | B15: CIBEBER | C15: 7 | D15: 21 | E15: 62 | F15: 29.52381
A16: JUMLAH | C16: 58 | D16: 188 | E16: 594.7 | F16: 31.632979
A18: 2. KACANG TANAH
A19: No | B19: Kecamatan | C19: TANAM | D19: PANEN | E19: PRODUKSI | F19: PRODUKTIVITAS
C20: (Ha) | D20: (Ha) | E20: (Ton) | F20: (Ku/Ha)
