Workbook

Sheet padi sawah
A2: DATA LUAS TANAM PADI (SAWAH) PER BULAN
A3: KOTA CILEGON TAHUN 2015
O5: (Ha)
A6: No | B6: Kecamatan | C6: Bulan | O6: Jumlah
C7: Jan | D7: Feb | E7: Maret | F7: Apr | G7: Mei | H7: Juni | I7: Juli | J7: Agst | K7: Sept | L7: Okt | M7: Nov | N7: Des | S7: JAN-APR | T7: MEI-AGST
A8: 1 | B8: 2 | C8: 3 | D8: 4 | E8: 5 | F8: 6 | G8: 7 | H8: 8 | I8: 9 | J8: 10 | K8: 11 | L8: 12 | M8: 13 | N8: 14 | O8: 15 | Q8: ok-nop
A9: 1 | B9: CIWANDAN | C9: 204 | D9: 0 | E9: 0 | F9: 2 | G9: 18 | H9: 8 | I9: 0 | J9: 1 | K9: 0 | L9: 0 | M9: 0 | N9: 0 | O9: =SUM(C9:N9) -> 233 | Q9: =SUM(L9:M9) -> 0 | S9: =SUM(C9:F9) -> 206 | T9: =SUM(G9:J9) -> 27
A10: 2 | B10: CITANGKIL | C10: 114 | D10: 0 | E10: 15 | F10: 29 | G10: 7 | H10: 65 | I10: 1 | J10: 4 | K10: 4 | L10: 4 | M10: 2 | N10: 29 | O10: =SUM(C10:N10) -> 274 | Q10: =SUM(L10:M10) -> 6 | S10: =SUM(C10:F10) -> 158 | T10: =SUM(G10:J10) -> 77
A11: 3 | B11: PULOMERAK | C11: 38 | D11: 0 | E11: 0 | F11: 5 | G11: 10 | H11: 0 | I11: 0 | J11: 0 | K11: 0 | L11: 0 | M11: 0 | N11: 0 | O11: =SUM(C11:N11) -> 53 | Q11: =SUM(L11:M11) -> 0 | S11: =SUM(C11:F11) -> 43 | T11: =SUM(G11:J11) -> 10
A12: 4 | B12: PURWAKARTA | C12: 16 | D12: 0 | E12: 0 | F12: 0 | G12: 7 | H12: 7 | I12: 0 | J12: 2 | K12: 0 | L12: 1 | M12: 2 | N12: 16 | O12: =SUM(C12:N12) -> 51 | Q12: =SUM(L12:M12) -> 3 | S12: =SUM(C12:F12) -> 16 | T12: =SUM(G12:J12) -> 16
A13: 5 | B13: GROGOL | C13: 225 | D13: 0 | E13: 0 | F13: 0 | G13: 10 | H13: 10 | I13: 0 | J13: 0 | K13: 0 | L13: 0 | M13: 0 | N13: 0 | O13: =SUM(C13:N13) -> 245 | Q13: =SUM(L13:M13) -> 0 | S13: =SUM(C13:F13) -> 225 | T13: =SUM(G13:J13) -> 20
A14: 6 | B14: CILEGON | C14: 0 | D14: 0 | E14: 0 | F14: 6 | G14: 15 | H14: 10 | I14: 0 | J14: 7 | K14: 0 | L14: 0 | M14: 5 | N14: 7 | O14: =SUM(C14:N14) -> 50 | Q14: =SUM(L14:M14) -> 5 | S14: =SUM(C14:F14) -> 6 | T14: =SUM(G14:J14) -> 32
A15: 7 | B15: JOMBANG | C15: 133 | D15: 0 | E15: 0 | F15: 0 | G15: 8 | H15: 183 | I15: 110 | J15: 6 | K15: 0 | L15: 0 | M15: 5 | N15: 179 | O15: =SUM(C15:N15) -> 624 | Q15: =SUM(L15:M15) -> 5 | S15: =SUM(C15:F15) -> 133 | T15: =SUM(G15:J15) -> 307
A16: 8 | B16: CIBEBER | C16: 201 | D16: 0 | E16: 0 | F16: 36 | G16: 116 | H16: 11 | I16: 1 | J16: 0 | K16: 24 | L16: 1 | M16: 1 | N16: 42 | O16: =SUM(C16:N16) -> 433 | Q16: =SUM(L16:M16) -> 2 | S16: =SUM(C16:F16) -> 237 | T16: =SUM(G16:J16) -> 128
A17: JUMLAH | C17: =SUM(C9:C16) -> 931 | D17: =SUM(D9:D16) -> 0 | E17: =SUM(E9:E16) -> 15 | F17: =SUM(F9:F16) -> 78 | G17: =SUM(G9:G16) -> 191 | H17: =SUM(H9:H16) -> 294 | I17: =SUM(I9:I16) -> 112 | J17: =SUM(J9:J16) -> 20 | ... O17: =SUM(O9:O16) -> 1963 | Q17: =SUM(L17:M17) -> 21
J19: =SUM(C17:J17) -> 1641 | K19: =SUM(F17:K17) -> 723 | N19: =SUM(L17:N17) -> 294
K20: =SUM(K17:M17) -> 49
A35: DATA LUAS PANEN PADI (SAWAH) PER BULAN
A36: KOTA CILEGON TAHUN 2015
O38: (Ha)
A39: No | B39: Kecamatan | C39: Bulan | O39: Jumlah
C40: Jan | D40: Feb | E40: Maret | F40: Apr | G40: Mei | H40: Juni | I40: Juli | J40: Agst | K40: Sept | L40: Okt | M40: Nov | N40: Des
A41: 1 | B41: 2 | C41: 3 | D41: 4 | E41: 5 | F41: 6 | G41: 7 | H41: 8 | I41: 9 | J41: 10 | K41: 11 | L41: 12 | M41: 13 | N41: 14 | O41: 15
A42: 1 | B42: CIWANDAN | C42: 0 | D42: 0 | E42: 0 | F42: 204 | G42: 0 | H42: 2 | I42: 0 | J42: 20 | K42: 6 | L42: 0 | M42: 1 | N42: 0 | O42: =SUM(C42:N42) -> 233 | Q42: =SUM(C42:E42) -> 0
A43: 2 | B43: CITANGKIL | C43: 0 | D43: 25 | E43: 64 | F43: 75 | G43: 90 | H43: 0 | I43: 32 | J43: 81 | K43: 12 | L43: 0 | M43: 0 | N43: 8 | O43: =SUM(C43:N43) -> 387 | Q43: =SUM(C43:E43) -> 89
A44: 3 | B44: PULOMERAK | C44: 0 | D44: 0 | E44: 10 | F44: 38 | G44: 0 | H44: 0 | I44: 5 | J44: 10 | K44: 0 | L44: 0 | M44: 0 | N44: 0 | O44: =SUM(C44:N44) -> 63 | Q44: =SUM(C44:E44) -> 10
A45: 4 | B45: PURWAKARTA | C45: 0 | D45: 3 | E45: 165 | F45: 16 | G45: 0 | H45: 0 | I45: 0 | J45: 7 | K45: 7 | L45: 0 | M45: 2 | N45: 0 | O45: =SUM(C45:N45) -> 200 | Q45: =SUM(C45:E45) -> 168
A46: 5 | B46: GROGOL | C46: 0 | D46: 0 | E46: 25 | F46: 225 | G46: 0 | H46: 0 | I46: 0 | J46: 10 | K46: 10 | L46: 0 | M46: 0 | N46: 0 | O46: =SUM(C46:N46) -> 270 | Q46: =SUM(C46:E46) -> 25
A47: 6 | B47: CILEGON | C47: 0 | D47: 0 | E47: 44 | F47: 0 | G47: 0 | H47: 6 | I47: 0 | J47: 10 | K47: 14 | L47: 0 | M47: 7 | N47: 0 | O47: =SUM(C47:N47) -> 81 | Q47: =SUM(C47:E47) -> 44
A48: 7 | B48: JOMBANG | C48: 1 | D48: 1 | E48: 92 | F48: 162 | G48: 23 | H48: 0 | I48: 2 | J48: 30 | K48: 183 | L48: 92 | M48: 0 | N48: 0 | O48: =SUM(C48:N48) -> 586 | Q48: =SUM(C48:E48) -> 94
A49: 8 | B49: CIBEBER | C49: 0 | D49: 30 | E49: 206 | F49: 68 | G49: 0 | H49: 4 | I49: 40 | J49: 107 | K49: 11 | L49: 0 | M49: 0 | N49: 0 | O49: =SUM(C49:N49) -> 466 | Q49: =SUM(C49:E49) -> 236
A50: JUMLAH | C50: =SUM(C42:C49) -> 1 | D50: =SUM(D42:D49) -> 59 | E50: =SUM(E42:E49) -> 606 | F50: =SUM(F42:F49) -> 788 | G50: =SUM(G42:G49) -> 113 | H50: =SUM(H42:H49) -> 12 | I50: =SUM(I42:I49) -> 79 | J50: =SUM(J42:J49) -> 275 | ... O50: =SUM(O42:O49) -> 2286
A68: DATA PRODUKSI PADI (SAWAH) PER BULAN
A69: KOTA CILEGON TAHUN 2015
O71: (Ton)
A72: No | B72: Kecamatan | C72: Bulan | O72: Jumlah
C73: Jan | D73: Feb | E73: Maret | F73: Apr | G73: Mei | H73: Juni | I73: Juli | J73: Agst | K73: Sept | L73: Okt | M73: Nov | N73: Des
A74: 1 | B74: 2 | C74: 3 | D74: 4 | E74: 5 | F74: 6 | G74: 7 | H74: 8 | I74: 9 | J74: 10 | K74: 11 | L74: 12 | M74: 13 | N74: 14 | O74: 15
A75: 1 | B75: CIWANDAN | C75: 0 | D75: 0 | E75: 0 | F75: 1327 | G75: 0 | H75: 10 | I75: 0 | J75: 90 | K75: 35 | L75: 0 | M75: 4 | N75: 0 | O75: =SUM(C75:N75) -> 1466 | Q75: =SUM(C75:E75) -> 0
A76: 2 | B76: CITANGKIL | C76: 0 | D76: 173 | E76: 523 | F76: 455 | G76: 805 | H76: 0 | I76: 245 | J76: 639 | K76: 102 | L76: 0 | M76: 0 | N76: 71 | O76: =SUM(C76:N76) -> 3013 | Q76: =SUM(C76:E76) -> 696
...

Sheet puso
A1: DATA LUAS PUSO PADI (SAWAH) PER BULAN
A2: KOTA CILEGON TAHUN 2015
O3: (Ha)
A4: No | B4: Kecamatan | C4: Bulan | O4: Jumlah
C5: Jan | D5: Feb | E5: Maret | F5: Apr | G5: Mei | H5: Juni | I5: Juli | J5: Agst | K5: Sept | L5: Okt | M5: Nov | N5: Des
A6: 1 | B6: 2 | C6: 3 | D6: 4 | E6: 5 | F6: 6 | G6: 7 | H6: 8 | I6: 9 | J6: 10 | K6: 11 | L6: 12 | M6: 13 | N6: 14 | O6: 15
A7: 1 | B7: CIWANDAN | C7: 0 | D7: 0 | E7: 0 | F7: 0 | G7: 0 | H7: 0 | I7: 0 | J7: 0 | K7: 0 | L7: 0 | M7: 0 | N7: 0 | O7: =SUM(C7:N7) -> 0
A8: 2 | B8: CITANGKIL | C8: 0 | D8: 0 | E8: 0 | F8: 0 | G8: 0 | H8: 0 | I8: 0 | J8: 2 | K8: 0 | L8: 0 | M8: 0 | N8: 0 | O8: =SUM(C8:N8) -> 2
A9: 3 | B9: PULOMERAK | C9: 0 | D9: 0 | E9: 0 | F9: 0 | G9: 0 | H9: 0 | I9: 0 | J9: 0 | K9: 0 | L9: 0 | M9: 0 | N9: 0 | O9: =SUM(C9:N9) -> 0
A10: 4 | B10: PURWAKARTA | C10: 0 | D10: 0 | E10: 0 | F10: 0 | G10: 0 | H10: 0 | I10: 0 | J10: 0 | K10: 0 | L10: 0 | M10: 0 | N10: 0 | O10: =SUM(C10:N10) -> 0
A11: 5 | B11: GROGOL | C11: 0 | D11: 0 | E11: 0 | F11: 0 | G11: 0 | H11: 0 | I11: 0 | J11: 0 | K11: 0 | L11: 0 | M11: 0 | N11: 0 | O11: =SUM(C11:N11) -> 0
A12: 6 | B12: CILEGON | C12: 0 | D12: 0 | E12: 0 | F12: 0 | G12: 0 | H12: 0 | I12: 0 | J12: 1 | K12: 0 | L12: 0 | M12: 0 | N12: 0 | O12: =SUM(C12:N12) -> 1
A13: 7 | B13: JOMBANG | C13: 0 | D13: 0 | E13: 0 | F13: 0 | G13: 0 | H13: 0 | I13: 0 | J13: 0 | K13: 0 | L13: 0 | M13: 0 | N13: 0 | O13: =SUM(C13:N13) -> 0
A14: 8 | B14: CIBEBER | C14: 0 | D14: 0 | E14: 0 | F14: 0 | G14: 0 | H14: 0 | I14: 0 | J14: 2 | K14: 0 | L14: 0 | M14: 0 | N14: 0 | O14: =SUM(C14:N14) -> 2
A15: JUMLAH | C15: =SUM(C7:C14) -> 0 | D15: =SUM(D7:D14) -> 0 | E15: =SUM(E7:E14) -> 0 | F15: =SUM(F7:F14) -> 0 | G15: =SUM(G7:G14) -> 0 | H15: =SUM(H7:H14) -> 0 | I15: =SUM(I7:I14) -> 0 | J15: =SUM(J7:J14) -> 5 | ... O15: =SUM(O7:O14) -> 5
A17: DATA LUAS PUSO KEDELAI PER BULAN
A18: KOTA CILEGON TAHUN 2015
O19: (Ha)
A20: No | B20: Kecamatan | C20: Bulan | O20: Jumlah
C21: Jan | D21: Feb | E21: Maret | F21: Apr | G21: Mei | H21: Juni | I21: Juli | J21: Agst | K21: Sept | L21: Okt | M21: Nov | N21: Des
A22: 1 | B22: 2 | C22: 3 | D22: 4 | E22: 5 | F22: 6 | G22: 7 | H22: 8 | I22: 9 | J22: 10 | K22: 11 | L22: 12 | M22: 13 | N22: 14 | O22: 15
A23: 1 | B23: CIWANDAN | C23: 2 | D23: 0 | E23: 0 | F23: 0 | G23: 0 | H23: 0 | I23: 0 | J23: 0 | K23: 0 | L23: 0 | M23: 0 | N23: 0 | O23: =SUM(C23:N23) -> 2
A24: 2 | B24: CITANGKIL | C24: 0 | D24: 0 | E24: 0 | F24: 0 | G24: 0 | H24: 0 | I24: 0 | J24: 0 | K24: 0 | L24: 0 | M24: 0 | N24: 0 | O24: =SUM(C24:N24) -> 0
A25: 3 | B25: PULOMERAK | C25: 0 | D25: 0 | E25: 0 | F25: 0 | G25: 0 | H25: 0 | I25: 0 | J25: 0 | K25: 0 | L25: 0 | M25: 0 | N25: 0 | O25: =SUM(C25:N25) -> 0
A26: 4 | B26: PURWAKARTA | C26: 0 | D26: 0 | E26: 0 | F26: 0 | G26: 0 | H26: 0 | I26: 0 | J26: 0 | K26: 0 | L26: 0 | M26: 0 | N26: 0 | O26: =SUM(C26:N26) -> 0
A27: 5 | B27: GROGOL | C27: 0 | D27: 0 | E27: 0 | F27: 0 | G27: 0 | H27: 0 | I27: 0 | J27: 0 | K27: 0 | L27: 0 | M27: 0 | N27: 0 | O27: =SUM(C27:N27) -> 0
A28: 6 | B28: CILEGON | C28: 0 | D28: 0 | E28: 0 | F28: 0 | G28: 0 | H28: 0 | I28: 0 | J28: 0 | K28: 0 | L28: 0 | M28: 0 | N28: 0 | O28: =SUM(C28:N28) -> 0
A29: 7 | B29: JOMBANG | C29: 0 | D29: 0 | E29: 0 | F29: 0 | G29: 0 | H29: 0 | I29: 0 | J29: 0 | K29: 0 | L29: 0 | M29: 0 | N29: 0 | O29: =SUM(C29:N29) -> 0
A30: 8 | B30: CIBEBER | C30: 0 | D30: 0 | E30: 0 | F30: 0 | G30: 0 | H30: 0 | I30: 0 | J30: 0 | K30: 0 | L30: 0 | M30: 0 | N30: 0 | O30: =SUM(C30:N30) -> 0
A31: JUMLAH | C31: =SUM(C23:C30) -> 2 | D31: =SUM(D23:D30) -> 0 | E31: =SUM(E23:E30) -> 0 | F31: =SUM(F23:F30) -> 0 | G31: =SUM(G23:G30) -> 0 | H31: =SUM(H23:H30) -> 0 | I31: =SUM(I23:I30) -> 0 | J31: =SUM(J23:J30) -> 0 | ... O31: =SUM(O23:O30) -> 2

Sheet padi ladang
A2: DATA LUAS TANAM PADI (DARAT) PER BULAN
A3: KOTA CILEGON TAHUN 2015
O5: (Ha)
A6: No | B6: Kecamatan | C6: Bulan | O6: Jumlah
C7: Jan | D7: Feb | E7: Maret | F7: Apr | G7: Mei | H7: Juni | I7: Juli | J7: Agst | K7: Sept | L7: Okt | M7: Nov | N7: Des
A8: 1 | B8: 2 | C8: 3 | D8: 4 | E8: 5 | F8: 6 | G8: 7 | H8: 8 | I8: 9 | J8: 10 | K8: 11 | L8: 12 | M8: 13 | N8: 14 | O8: 15
A9: 1 | B9: CIWANDAN | C9: 0 | D9: 0 | E9: 0 | F9: 0 | G9: 0 | H9: 0 | I9: 0 | J9: 0 | K9: 0 | L9: 0 | M9: 0 | N9: 0 | O9: =SUM(C9:N9) -> 0
A10: 2 | B10: CITANGKIL | C10: 0 | D10: 0 | E10: 0 | F10: 0 | G10: 0 | H10: 0 | I10: 0 | J10: 0 | K10: 0 | L10: 0 | M10: 0 | N10: 0 | O10: =SUM(C10:N10) -> 0
A11: 3 | B11: PULOMERAK | C11: 10 | D11: 0 | E11: 0 | F11: 0 | G11: 0 | H11: 0 | I11: 0 | J11: 0 | K11: 0 | L11: 0 | M11: 0 | N11: 5 | O11: =SUM(C11:N11) -> 15
A12: 4 | B12: PURWAKARTA | C12: 0 | D12: 0 | E12: 0 | F12: 0 | G12: 0 | H12: 0 | I12: 0 | J12: 0 | K12: 0 | L12: 0 | M12: 0 | N12: 0 | O12: =SUM(C12:N12) -> 0
A13: 5 | B13: GROGOL | C13: 0 | D13: 0 | E13: 0 | F13: 0 | G13: 0 | H13: 0 | I13: 0 | J13: 0 | K13: 0 | L13: 0 | M13: 0 | N13: 0 | O13: =SUM(C13:N13) -> 0
A14: 6 | B14: CILEGON | C14: 0 | D14: 0 | E14: 0 | F14: 0 | G14: 0 | H14: 0 | I14: 0 | J14: 0 | K14: 0 | L14: 0 | M14: 0 | N14: 0 | O14: =SUM(C14:N14) -> 0
A15: 7 | B15: JOMBANG | C15: 0 | D15: 0 | E15: 0 | F15: 0 | G15: 0 | H15: 0 | I15: 0 | J15: 0 | K15: 0 | L15: 0 | M15: 0 | N15: 0 | O15: =SUM(C15:N15) -> 0
A16: 8 | B16: CIBEBER | C16: 0 | D16: 0 | E16: 0 | F16: 0 | G16: 0 | H16: 0 | I16: 0 | J16: 0 | K16: 0 | L16: 0 | M16: 0 | N16: 0 | O16: =SUM(C16:N16) -> 0
A17: JUMLAH | C17: =SUM(C9:C16) -> 10 | D17: =SUM(D9:D16) -> 0 | E17: =SUM(E9:E16) -> 0 | F17: =SUM(F9:F16) -> 0 | G17: =SUM(G9:G16) -> 0 | H17: =SUM(H9:H16) -> 0 | I17: =SUM(I9:I16) -> 0 | J17: =SUM(J9:J16) -> 0 | ... O17: =SUM(O9:O16) -> 15
A35: DATA LUAS PANEN PADI (DARAT) PER BULAN
A36: KOTA CILEGON TAHUN 2015
O38: (Ha)
A39: No | B39: Kecamatan | C39: Bulan | O39: Jumlah
C40: Jan | D40: Feb | E40: Maret | F40: Apr | G40: Mei | H40: Juni | I40: Juli | J40: Agst | K40: Sept | L40: Okt | M40: Nov | N40: Des
A41: 1 | B41: 2 | C41: 3 | D41: 4 | E41: 5 | F41: 6 | G41: 7 | H41: 8 | I41: 9 | J41: 10 | K41: 11 | L41: 12 | M41: 13 | N41: 14 | O41: 15
A42: 1 | B42: CIWANDAN | C42: 0 | D42: 0 | E42: 0 | F42: 0 | G42: 0 | H42: 0 | I42: 0 | J42: 0 | K42: 0 | L42: 0 | M42: 0 | N42: 0 | O42: =SUM(C42:N42) -> 0
A43: 2 | B43: CITANGKIL | C43: 0 | D43: 0 | E43: 0 | F43: 0 | G43: 0 | H43: 0 | I43: 0 | J43: 0 | K43: 0 | L43: 0 | M43: 0 | N43: 0 | O43: =SUM(C43:N43) -> 0
A44: 3 | B44: PULOMERAK | C44: 0 | D44: 0 | E44: 15 | F44: 10 | G44: 0 | H44: 0 | I44: 0 | J44: 0 | K44: 0 | L44: 0 | M44: 0 | N44: 0 | O44: =SUM(C44:N44) -> 25
A45: 4 | B45: PURWAKARTA | C45: 0 | D45: 0 | E45: 0 | F45: 0 | G45: 0 | H45: 0 | I45: 0 | J45: 0 | K45: 0 | L45: 0 | M45: 0 | N45: 0 | O45: =SUM(C45:N45) -> 0
A46: 5 | B46: GROGOL | C46: 0 | D46: 0 | E46: 0 | F46: 0 | G46: 0 | H46: 0 | I46: 0 | J46: 0 | K46: 0 | L46: 0 | M46: 0 | N46: 0 | O46: =SUM(C46:N46) -> 0
A47: 6 | B47: CILEGON | C47: 0 | D47: 0 | E47: 0 | F47: 0 | G47: 0 | H47: 0 | I47: 0 | J47: 0 | K47: 0 | L47: 0 | M47: 0 | N47: 0 | O47: =SUM(C47:N47) -> 0
A48: 7 | B48: JOMBANG | C48: 0 | D48: 0 | E48: 0 | F48: 0 | G48: 0 | H48: 0 | I48: 0 | J48: 0 | K48: 0 | L48: 0 | M48: 0 | N48: 0 | O48: =SUM(C48:N48) -> 0
A49: 8 | B49: CIBEBER | C49: 0 | D49: 0 | E49: 0 | F49: 0 | G49: 0 | H49: 0 | I49: 0 | J49: 0 | K49: 0 | L49: 0 | M49: 0 | N49: 0 | O49: =SUM(C49:N49) -> 0
A50: JUMLAH | C50: =SUM(C42:C49) -> 0 | D50: =SUM(D42:D49) -> 0 | E50: =SUM(E42:E49) -> 15 | F50: =SUM(F42:F49) -> 10 | G50: =SUM(G42:G49) -> 0 | H50: =SUM(H42:H49) -> 0 | I50: =SUM(I42:I49) -> 0 | J50: =SUM(J42:J49) -> 0 | ... O50: =SUM(O42:O49) -> 25
A68: DATA PRODUKSI PADI (DARAT) PER BULAN
A69: KOTA CILEGON TAHUN 2015
O71: (Ton)
A72: No | B72: Kecamatan | C72: Bulan | O72: Jumlah
C73: Jan | D73: Feb | E73: Maret | F73: Apr | G73: Mei | H73: Juni | I73: Juli | J73: Agst | K73: Sept | L73: Okt | M73: Nov | N73: Des
A74: 1 | B74: 2 | C74: 3 | D74: 4 | E74: 5 | F74: 6 | G74: 7 | H74: 8 | I74: 9 | J74: 10 | K74: 11 | L74: 12 | M74: 13 | N74: 14 | O74: 15
A75: 1 | B75: CIWANDAN | C75: 0 | D75: 0 | E75: 0 | F75: 0 | G75: 0 | H75: 0 | I75: 0 | J75: 0 | K75: 0 | L75: 0 | M75: 0 | N75: 0 | O75: =SUM(C75:N75) -> 0
A76: 2 | B76: CITANGKIL | C76: 0 | D76: 0 | E76: 0 | F76: 0 | G76: 0 | H76: 0 | I76: 0 | J76: 0 | K76: 0 | L76: 0 | M76: 0 | N76: 0 | O76: =SUM(C76:N76) -> 0
A77: 3 | B77: PULOMERAK | C77: 0 | D77: 0 | E77: 46 | F77: 30 | G77: 0 | H77: 0 | I77: 0 | J77: 0 | K77: 0 | L77: 0 | M77: 0 | N77: 0 | O77: =SUM(C77:N77) -> 76
A78: 4 | B78: PURWAKARTA | C78: 0 | D78: 0 | E78: 0 | F78: 0 | G78: 0 | H78: 0 | I78: 0 | J78: 0 | K78: 0 | L78: 0 | M78: 0 | N78: 0 | O78: =SUM(C78:N78) -> 0
...

Sheet jagung
A2: DATA LUAS TANAM JAGUNG PER BULAN
A3: KOTA CILEGON TAHUN 2015
O5: (Ha)
A6: No | B6: Kecamatan | C6: Bulan | O6: Jumlah
C7: Jan | D7: Feb | E7: Maret | F7: Apr | G7: Mei | H7: Juni | I7: Juli | J7: Agst | K7: Sept | L7: Okt | M7: Nov | N7: Des
A8: 1 | B8: 2 | C8: 3 | D8: 4 | E8: 5 | F8: 6 | G8: 7 | H8: 8 | I8: 9 | J8: 10 | K8: 11 | L8: 12 | M8: 13 | N8: 14 | O8: 15 | Q8: ok-nop
A9: 1 | B9: CIWANDAN | C9: 0 | D9: 0 | E9: 0 | F9: 0 | G9: 0 | H9: 0 | I9: 0 | J9: 0 | K9: 0 | L9: 0 | M9: 0 | N9: 0 | O9: =SUM(C9:N9) -> 0 | Q9: =SUM(L9:M9) -> 0
A10: 2 | B10: CITANGKIL | C10: 0 | D10: 0 | E10: 1 | F10: 0 | G10: 0 | H10: 1 | I10: 0 | J10: 0 | K10: 0 | L10: 0 | M10: 0 | N10: 1 | O10: =SUM(C10:N10) -> 3 | Q10: =SUM(L10:M10) -> 0
A11: 3 | B11: PULOMERAK | C11: 2 | D11: 3 | E11: 0 | F11: 0 | G11: 2 | H11: 0 | I11: 0 | J11: 0 | K11: 0 | L11: 0 | M11: 2 | N11: 2 | O11: =SUM(C11:N11) -> 11 | Q11: =SUM(L11:M11) -> 2
A12: 4 | B12: PURWAKARTA | C12: 0 | D12: 0 | E12: 1 | F12: 1 | G12: 1 | H12: 2 | I12: 0 | J12: 0 | K12: 0 | L12: 0 | M12: 0 | N12: 0 | O12: =SUM(C12:N12) -> 5 | Q12: =SUM(L12:M12) -> 0
A13: 5 | B13: GROGOL | C13: 0 | D13: 0 | E13: 0 | F13: 0 | G13: 2 | H13: 0 | I13: 0 | J13: 0 | K13: 0 | L13: 1 | M13: 0 | N13: 0 | O13: =SUM(C13:N13) -> 3 | Q13: =SUM(L13:M13) -> 1
A14: 6 | B14: CILEGON | C14: 0 | D14: 0 | E14: 0 | F14: 0 | G14: 0 | H14: 0 | I14: 0 | J14: 0 | K14: 0 | L14: 0 | M14: 0 | N14: 0 | O14: =SUM(C14:N14) -> 0 | Q14: =SUM(L14:M14) -> 0
A15: 7 | B15: JOMBANG | C15: 0 | D15: 0 | E15: 0 | F15: 0 | G15: 0 | H15: 0 | I15: 0 | J15: 0 | K15: 0 | L15: 0 | M15: 0 | N15: 0 | O15: =SUM(C15:N15) -> 0 | Q15: =SUM(L15:M15) -> 0
A16: 8 | B16: CIBEBER | C16: 0 | D16: 1 | E16: 0 | F16: 1 | G16: 0 | H16: 0 | I16: 0 | J16: 0 | K16: 0 | L16: 0 | M16: 0 | N16: 3 | O16: =SUM(C16:N16) -> 5 | Q16: =SUM(L16:M16) -> 0
A17: JUMLAH | C17: =SUM(C9:C16) -> 2 | D17: =SUM(D9:D16) -> 4 | E17: =SUM(E9:E16) -> 2 | F17: =SUM(F9:F16) -> 2 | G17: =SUM(G9:G16) -> 5 | H17: =SUM(H9:H16) -> 3 | I17: =SUM(I9:I16) -> 0 | J17: =SUM(J9:J16) -> 0 | ... O17: =SUM(O9:O16) -> 27
A35: DATA LUAS PANEN JAGUNG PER BULAN
A36: KOTA CILEGON TAHUN 2015
O38: (Ha)
A39: No | B39: Kecamatan | C39: Bulan | O39: Jumlah
C40: Jan | D40: Feb | E40: Maret | F40: Apr | G40: Mei | H40: Juni | I40: Juli | J40: Agst | K40: Sept | L40: Okt | M40: Nov | N40: Des
A41: 1 | B41: 2 | C41: 3 | D41: 4 | E41: 5 | F41: 6 | G41: 7 | H41: 8 | I41: 9 | J41: 10 | K41: 11 | L41: 12 | M41: 13 | N41: 14 | O41: 15
A42: 1 | B42: CIWANDAN | C42: 0 | D42: 5* | E42: 0 | F42: 0 | G42: 0 | H42: 0 | I42: 0 | J42: 0 | K42: 0 | L42: 0 | M42: 0 | N42: 0 | O42: =SUM(C42:N42) -> 0 | Q42: 5 | R42: *
A43: 2 | B43: CITANGKIL | C43: 0 | D43: 0 | E43: 0 | F43: 0 | G43: 0 | H43: 1* | I43: 0 | J43: 1* | K43: 0 | L43: 0 | M43: 0 | N43: 0 | O43: =SUM(C43:N43) -> 0 | Q43: 2 | R43: *
A44: 3 | B44: PULOMERAK | C44: 0 | D44: 0 | E44: 4 | F44: 3 | G44: 0 | H44: 0 | I44: 0 | J44: 2 | K44: 0 | L44: 0 | M44: 0 | N44: 0 | O44: =SUM(C44:N44) -> 9 | Q44: =SUM(C44:N44) -> 9
A45: 4 | B45: PURWAKARTA | C45: 0 | D45: 0 | E45: 0 | F45: 0 | G45: 1 | H45: 0 | I45: 0 | J45: 1 | K45: 2 | L45: 0 | M45: 0 | N45: 0 | O45: =SUM(C45:N45) -> 4 | Q45: =SUM(C45:N45) -> 4
A46: 5 | B46: GROGOL | C46: 0 | D46: 0 | E46: 0 | F46: 0 | G46: 0 | H46: 0 | I46: 0 | J46: 2 | K46: 0 | L46: 0 | M46: 0 | N46: 1 | O46: =SUM(C46:N46) -> 3 | Q46: =SUM(C46:N46) -> 3
A47: 6 | B47: CILEGON | C47: 0 | D47: 0 | E47: 0 | F47: 0 | G47: 0 | H47: 0 | I47: 0 | J47: 0 | K47: 0 | L47: 0 | M47: 0 | N47: 0 | O47: =SUM(C47:N47) -> 0 | Q47: =SUM(C47:N47) -> 0
A48: 7 | B48: JOMBANG | C48: 0 | D48: 0 | E48: 0 | F48: 0 | G48: 0 | H48: 0 | I48: 0 | J48: 0 | K48: 0 | L48: 0 | M48: 0 | N48: 0 | O48: =SUM(C48:N48) -> 0 | Q48: =SUM(C48:N48) -> 0
A49: 8 | B49: CIBEBER | C49: 1* | D49: 0 | E49: 0 | F49: 1 | G49: 0 | H49: 0 | I49: 1 | J49: 0 | K49: 0 | L49: 0 | M49: 0 | N49: 0 | O49: =SUM(C49:N49) -> 2 | Q49: 3 | R49: *
A50: JUMLAH | C50: 1 | D50: 5 | E50: =SUM(E42:E49) -> 4 | F50: =SUM(F42:F49) -> 4 | G50: =SUM(G42:G49) -> 1 | H50: 1 | I50: =SUM(I42:I49) -> 1 | J50: 6 | K50: =SUM(K42:K49) -> 2 | L50: =SUM(L42:L49) -> 0 | M50: =SUM(M42:M49) -> 0 | N50: =SUM(N42:N49) -> 1 | O50: =SUM(O42:O49) -> 18 | Q50: =SUM(Q42:Q49) -> 26
A52: Ket : * : Panen Muda
A68: DATA PRODUKSI JAGUNG PER BULAN
A69: KOTA CILEGON TAHUN 2015
O71: (Ton)
A72: No | B72: Kecamatan | C72: Bulan | O72: Jumlah
C73: Jan | D73: Feb | E73: Maret | F73: Apr | G73: Mei | H73: Juni | I73: Juli | J73: Agst | K73: Sept | L73: Okt | M73: Nov | N73: Des
A74: 1 | B74: 2 | C74: 3 | D74: 4 | E74: 5 | F74: 6 | G74: 7 | H74: 8 | I74: 9 | J74: 10 | K74: 11 | L74: 12 | M74: 13 | N74: 14 | O74: 15
A75: 1 | B75: CIWANDAN | C75: 0 | D75: 0 | E75: 0 | F75: 0 | G75: 0 | H75: 0 | I75: 0 | J75: 0 | K75: 0 | L75: 0 | M75: 0 | N75: 0 | O75: =SUM(C75:N75) -> 0
A76: 2 | B76: CITANGKIL | C76: 0 | D76: 0 | E76: 0 | F76: 0 | G76: 0 | H76: 0 | I76: 0 | J76: 0 | K76: 0 | L76: 0 | M76: 0 | N76: 0 | O76: =SUM(C76:N76) -> 0
A77: 3 | B77: PULOMERAK | C77: 0 | D77: 0 | E77: 11 | F77: 9 | G77: 0 | H77: 0 | I77: 0 | J77: 5 | K77: 0 | L77: 0 | M77: 0 | N77: 0 | O77: =SUM(C77:N77) -> 25
...

Sheet kedelai
A2: DATA LUAS TANAM KEDELAI PER BULAN
A3: KOTA CILEGON TAHUN 2015
O5: (Ha)
A6: No | B6: Kecamatan | C6: Bulan | O6: Jumlah
C7: Jan | D7: Feb | E7: Maret | F7: Apr | G7: Mei | H7: Juni | I7: Juli | J7: Agst | K7: Sept | L7: Okt | M7: Nov | N7: Des
A8: 1 | B8: 2 | C8: 3 | D8: 4 | E8: 5 | F8: 6 | G8: 7 | H8: 8 | I8: 9 | J8: 10 | K8: 11 | L8: 12 | M8: 13 | N8: 14 | O8: 15 | Q8: ok-nop
A9: 1 | B9: CIWANDAN | C9: 0 | D9: 0 | E9: 0 | F9: 0 | G9: 0 | H9: 0 | I9: 0 | J9: 0 | K9: 0 | L9: 0 | M9: 0 | N9: 0 | O9: =SUM(C9:N9) -> 0 | Q9: =SUM(L9:M9) -> 0
A10: 2 | B10: CITANGKIL | C10: 0 | D10: 0 | E10: 0 | F10: 0 | G10: 0 | H10: 0 | I10: 0 | J10: 0 | K10: 0 | L10: 1 | M10: 5 | N10: 5 | O10: =SUM(C10:N10) -> 11 | Q10: =SUM(L10:M10) -> 6
A11: 3 | B11: PULOMERAK | C11: 0 | D11: 0 | E11: 0 | F11: 0 | G11: 0 | H11: 0 | I11: 0 | J11: 0 | K11: 0 | L11: 0 | M11: 0 | N11: 25 | O11: =SUM(C11:N11) -> 25 | Q11: =SUM(L11:M11) -> 0
A12: 4 | B12: PURWAKARTA | C12: 0 | D12: 0 | E12: 0 | F12: 0 | G12: 0 | H12: 0 | I12: 0 | J12: 0 | K12: 0 | L12: 0 | M12: 0 | N12: 0 | O12: =SUM(C12:N12) -> 0 | Q12: =SUM(L12:M12) -> 0
A13: 5 | B13: GROGOL | C13: 0 | D13: 5 | E13: 5 | F13: 0 | G13: 0 | H13: 0 | I13: 0 | J13: 0 | K13: 2 | L13: 2 | M13: 2 | N13: 4 | O13: =SUM(C13:N13) -> 20 | Q13: =SUM(L13:M13) -> 4
A14: 6 | B14: CILEGON | C14: 0 | D14: 0 | E14: 0 | F14: 0 | G14: 0 | H14: 0 | I14: 0 | J14: 0 | K14: 0 | L14: 0 | M14: 0 | N14: 0 | O14: =SUM(C14:N14) -> 0 | Q14: =SUM(L14:M14) -> 0
A15: 7 | B15: JOMBANG | C15: 0 | D15: 0 | E15: 0 | F15: 0 | G15: 0 | H15: 0 | I15: 0 | J15: 0 | K15: 0 | L15: 0 | M15: 0 | N15: 0 | O15: =SUM(C15:N15) -> 0 | Q15: =SUM(L15:M15) -> 0
A16: 8 | B16: CIBEBER | C16: 0 | D16: 0 | E16: 0 | F16: 0 | G16: 0 | H16: 0 | I16: 0 | J16: 0 | K16: 0 | L16: 0 | M16: 0 | N16: 2 | O16: =SUM(C16:N16) -> 2 | Q16: =SUM(L16:M16) -> 0
A17: JUMLAH | C17: =SUM(C9:C16) -> 0 | D17: =SUM(D9:D16) -> 5 | E17: =SUM(E9:E16) -> 5 | F17: =SUM(F9:F16) -> 0 | G17: =SUM(G9:G16) -> 0 | H17: =SUM(H9:H16) -> 0 | I17: =SUM(I9:I16) -> 0 | J17: =SUM(J9:J16) -> 0 | ... O17: =SUM(O9:O16) -> 58
A35: DATA LUAS PANEN KEDELAI PER BULAN
A36: KOTA CILEGON TAHUN 2015
O38: (Ha)
A39: No | B39: Kecamatan | C39: Bulan | O39: Jumlah
C40: Jan | D40: Feb | E40: Maret | F40: Apr | G40: Mei | H40: Juni | I40: Juli | J40: Agst | K40: Sept | L40: Okt | M40: Nov | N40: Des
A41: 1 | B41: 2 | C41: 3 | D41: 4 | E41: 5 | F41: 6 | G41: 7 | H41: 8 | I41: 9 | J41: 10 | K41: 11 | L41: 12 | M41: 13 | N41: 14 | O41: 15
A42: 1 | B42: CIWANDAN | C42: 0 | D42: 0 | E42: 0 | F42: 0 | G42: 0 | H42: 0 | I42: 0 | J42: 0 | K42: 0 | L42: 0 | M42: 0 | N42: 0 | O42: =SUM(C42:N42) -> 0 | Q42: =SUM(C42:E42) -> 0
A43: 2 | B43: CITANGKIL | C43: 0 | D43: 0 | E43: 0 | F43: 0 | G43: 0 | H43: 0 | I43: 0 | J43: 0 | K43: 0 | L43: 0 | M43: 0 | N43: 0 | O43: =SUM(C43:N43) -> 0 | Q43: =SUM(C43:E43) -> 0
A44: 3 | B44: PULOMERAK | C44: 10 | D44: 0 | E44: 0 | F44: 0 | G44: 0 | H44: 0 | I44: 0 | J44: 0 | K44: 0 | L44: 0 | M44: 0 | N44: 0 | O44: =SUM(C44:N44) -> 10 | Q44: =SUM(C44:E44) -> 10
A45: 4 | B45: PURWAKARTA | C45: 0 | D45: 0 | E45: 0 | F45: 0 | G45: 0 | H45: 0 | I45: 0 | J45: 0 | K45: 0 | L45: 0 | M45: 0 | N45: 0 | O45: =SUM(C45:N45) -> 0 | Q45: =SUM(C45:E45) -> 0
A46: 5 | B46: GROGOL | C46: 0 | D46: 0 | E46: 0 | F46: 0 | G46: 10 | H46: 0 | I46: 0 | J46: 0 | K46: 0 | L46: 0 | M46: 0 | N46: 6 | O46: =SUM(C46:N46) -> 16 | Q46: =SUM(C46:E46) -> 0
A47: 6 | B47: CILEGON | C47: 0 | D47: 0 | E47: 0 | F47: 0 | G47: 0 | H47: 0 | I47: 0 | J47: 0 | K47: 0 | L47: 0 | M47: 0 | N47: 0 | O47: =SUM(C47:N47) -> 0 | Q47: =SUM(C47:E47) -> 0
A48: 7 | B48: JOMBANG | C48: 0 | D48: 0 | E48: 0 | F48: 0 | G48: 0 | H48: 0 | I48: 0 | J48: 0 | K48: 0 | L48: 0 | M48: 0 | N48: 0 | O48: =SUM(C48:N48) -> 0 | Q48: =SUM(C48:E48) -> 0
A49: 8 | B49: CIBEBER | C49: 15 | D49: 0 | E49: 0 | F49: 0 | G49: 0 | H49: 0 | I49: 0 | J49: 0 | K49: 0 | L49: 0 | M49: 0 | N49: 0 | O49: =SUM(C49:N49) -> 15 | P49: 15 | Q49: =SUM(C49:E49) -> 15
A50: JUMLAH | C50: 25 | D50: =SUM(D42:D49) -> 0 | E50: =SUM(E42:E49) -> 0 | F50: =SUM(F42:F49) -> 0 | G50: =SUM(G42:G49) -> 10 | H50: =SUM(H42:H49) -> 0 | I50: =SUM(I42:I49) -> 0 | J50: =SUM(J42:J49) -> 0 | K50: =SUM(K42:K49) -> 0 | ... P50: =SUM(P42:P49) -> 15
A51: Catatan : Cibeber panen muda 5 Ha
A68: DATA PRODUKSI KEDELAI PER BULAN
A69: KOTA CILEGON TAHUN 2015
O71: (Ton)
A72: No | B72: Kecamatan | C72: Bulan | O72: Jumlah
C73: Jan | D73: Feb | E73: Maret | F73: Apr | G73: Mei | H73: Juni | I73: Juli | J73: Agst | K73: Sept | L73: Okt | M73: Nov | N73: Des
A74: 1 | B74: 2 | C74: 3 | D74: 4 | E74: 5 | F74: 6 | G74: 7 | H74: 8 | I74: 9 | J74: 10 | K74: 11 | L74: 12 | M74: 13 | N74: 14 | O74: 15
A75: 1 | B75: CIWANDAN | C75: 0 | D75: 0 | E75: 0 | F75: 0 | G75: 0 | H75: 0 | I75: 0 | J75: 0 | K75: 0 | L75: 0 | M75: 0 | N75: 0 | O75: =SUM(C75:N75) -> 0 | Q75: =SUM(C75:E75) -> 0
A76: 2 | B76: CITANGKIL | C76: 0 | D76: 0 | E76: 0 | F76: 0 | G76: 0 | H76: 0 | I76: 0 | J76: 0 | K76: 0 | L76: 0 | M76: 0 | N76: 0 | O76: =SUM(C76:N76) -> 0 | Q76: =SUM(C76:E76) -> 0
A77: 3 | B77: PULOMERAK | C77: 9 | D77: 0 | E77: 0 | F77: 0 | G77: 0 | H77: 0 | I77: 0 | J77: 0 | K77: 0 | L77: 0 | M77: 0 | N77: 0 | O77: =SUM(C77:N77) -> 9 | Q77: =SUM(C77:E77) -> 9
...

Sheet kc tanah
A2: DATA LUAS TANAM KACANG TANAH PER BULAN
A3: KOTA CILEGON TAHUN 2015
O5: (Ha)
A6: No | B6: Kecamatan | C6: Bulan | O6: Jumlah
C7: Jan | D7: Feb | E7: Maret | F7: Apr | G7: Mei | H7: Juni | I7: Juli | J7: Agst | K7: Sept | L7: Okt | M7: Nov | N7: Des
A8: 1 | B8: 2 | C8: 3 | D8: 4 | E8: 5 | F8: 6 | G8: 7 | H8: 8 | I8: 9 | J8: 10 | K8: 11 | L8: 12 | M8: 13 | N8: 14 | O8: 15
A9: 1 | B9: CIWANDAN | C9: 35 | D9: 0 | E9: 82 | F9: 0 | G9: 0 | H9: 0 | I9: 0 | J9: 0 | K9: 0 | L9: 0 | M9: 0 | N9: 185 | O9: =SUM(C9:N9) -> 302 | Q9: =SUM(F9:K9) -> 0
A10: 2 | B10: CITANGKIL | C10: 131 | D10: 0 | E10: 1 | F10: 15 | G10: 10 | H10: 0 | I10: 0 | J10: 0 | K10: 0 | L10: 1 | M10: 3 | N10: 57 | O10: =SUM(C10:N10) -> 218 | Q10: =SUM(F10:K10) -> 25
A11: 3 | B11: PULOMERAK | C11: 0 | D11: 0 | E11: 257 | F11: 57 | G11: 0 | H11: 0 | I11: 0 | J11: 0 | K11: 0 | L11: 0 | M11: 0 | N11: 275 | O11: =SUM(C11:N11) -> 589 | Q11: =SUM(F11:K11) -> 57
A12: 4 | B12: PURWAKARTA | C12: 0 | D12: 0 | E12: 23 | F12: 16 | G12: 3 | H12: 12 | I12: 0 | J12: 0 | K12: 3 | L12: 0 | M12: 5 | N12: 141 | O12: =SUM(C12:N12) -> 203 | Q12: =SUM(F12:K12) -> 34
A13: 5 | B13: GROGOL | C13: 0 | D13: 0 | E13: 175 | F13: 68 | G13: 0 | H13: 0 | I13: 0 | J13: 0 | K13: 0 | L13: 0 | M13: 0 | N13: 102 | O13: =SUM(C13:N13) -> 345 | Q13: =SUM(F13:K13) -> 68
A14: 6 | B14: CILEGON | C14: 0 | D14: 0 | E14: 38 | F14: 30 | G14: 0 | H14: 0 | I14: 0 | J14: 0 | K14: 0 | L14: 0 | M14: 15 | N14: 50 | O14: =SUM(C14:N14) -> 133 | Q14: =SUM(F14:K14) -> 30
A15: 7 | B15: JOMBANG | C15: 1 | D15: 0 | E15: 0 | F15: 0 | G15: 0 | H15: 1 | I15: 1 | J15: 0 | K15: 0 | L15: 0 | M15: 0 | N15: 0 | O15: =SUM(C15:N15) -> 3 | Q15: =SUM(F15:K15) -> 2
A16: 8 | B16: CIBEBER | C16: 0 | D16: 0 | E16: 112 | F16: 275 | G16: 0 | H16: 0 | I16: 0 | J16: 75 | K16: 0 | L16: 0 | M16: 0 | N16: 332 | O16: =SUM(C16:N16) -> 794 | Q16: =SUM(F16:K16) -> 350
A17: JUMLAH | C17: =SUM(C9:C16) -> 167 | D17: =SUM(D9:D16) -> 0 | E17: =SUM(E9:E16) -> 688 | F17: =SUM(F9:F16) -> 461 | G17: =SUM(G9:G16) -> 13 | H17: =SUM(H9:H16) -> 13 | I17: =SUM(I9:I16) -> 1 | J17: =SUM(J9:J16) -> 75 | ... O17: =SUM(O9:O16) -> 2587 | Q17: =SUM(F17:K17) -> 566
J19: =SUM(C17:J17) -> 1418
A35: DATA LUAS PANEN KACANG TANAH PER BULAN
A36: KOTA CILEGON TAHUN 2015
O38: (Ha)
A39: No | B39: Kecamatan | C39: Bulan | O39: Jumlah
C40: Jan | D40: Feb | E40: Maret | F40: Apr | G40: Mei | H40: Juni | I40: Juli | J40: Agst | K40: Sept | L40: Okt | M40: Nov | N40: Des
A41: 1 | B41: 2 | C41: 3 | D41: 4 | E41: 5 | F41: 6 | G41: 7 | H41: 8 | I41: 9 | J41: 10 | K41: 11 | L41: 12 | M41: 13 | N41: 14 | O41: 15
A42: 1 | B42: CIWANDAN | C42: 0 | D42: 37 | E42: 137 | F42: 0 | G42: 0 | H42: 82 | I42: 0 | J42: 0 | K42: 0 | L42: 0 | M42: 0 | N42: 0 | O42: =SUM(C42:N42) -> 256 | Q42: =SUM(F42:K42) -> 82
A43: 2 | B43: CITANGKIL | C43: 0 | D43: 3 | E43: 133 | F43: 51 | G43: 0 | H43: 1 | I43: 5 | J43: 19 | K43: 0 | L43: 0 | M43: 0 | N43: 0 | O43: =SUM(C43:N43) -> 212 | Q43: =SUM(F43:K43) -> 76
A44: 3 | B44: PULOMERAK | C44: 0 | D44: 85 | E44: 180 | F44: 0 | G44: 0 | H44: 257 | I44: 57 | J44: 0 | K44: 0 | L44: 0 | M44: 0 | N44: 0 | O44: =SUM(C44:N44) -> 579 | Q44: =SUM(F44:K44) -> 314
A45: 4 | B45: PURWAKARTA | C45: 0 | D45: 5 | E45: 234 | F45: 0 | G45: 0 | H45: 23 | I45: 16 | J45: 3 | K45: 12 | L45: 0 | M45: 0 | N45: 3 | O45: =SUM(C45:N45) -> 296 | Q45: =SUM(F45:K45) -> 54
A46: 5 | B46: GROGOL | C46: 0 | D46: 0 | E46: 260 | F46: 0 | G46: 0 | H46: 175 | I46: 0 | J46: 68 | K46: 0 | L46: 0 | M46: 0 | N46: 0 | O46: =SUM(C46:N46) -> 503 | Q46: =SUM(F46:K46) -> 243
A47: 6 | B47: CILEGON | C47: 0 | D47: 35 | E47: 41 | F47: 0 | G47: 0 | H47: 68 | I47: 0 | J47: 0 | K47: 0 | L47: 0 | M47: 0 | N47: 0 | O47: =SUM(C47:N47) -> 144 | Q47: =SUM(F47:K47) -> 68
A48: 7 | B48: JOMBANG | C48: 0 | D48: 1 | E48: 1 | F48: 0 | G48: 0 | H48: 0 | I48: 0 | J48: 0 | K48: 1 | L48: 1 | M48: 0 | N48: 0 | O48: =SUM(C48:N48) -> 4 | Q48: =SUM(F48:K48) -> 1
A49: 8 | B49: CIBEBER | C49: 0 | D49: 47 | E49: 187 | F49: 0 | G49: 0 | H49: 0 | I49: 112 | J49: 275 | K49: 0 | L49: 0 | M49: 75 | N49: 0 | O49: =SUM(C49:N49) -> 696 | Q49: =SUM(F49:K49) -> 387
A50: JUMLAH | C50: =SUM(C42:C49) -> 0 | D50: =SUM(D42:D49) -> 213 | E50: =SUM(E42:E49) -> 1173 | F50: =SUM(F42:F49) -> 51 | G50: =SUM(G42:G49) -> 0 | H50: =SUM(H42:H49) -> 606 | I50: =SUM(I42:I49) -> 190 | J50: =SUM(J42:J49) -> 365 | ... O50: =SUM(O42:O49) -> 2690 | Q50: =SUM(F50:K50) -> 1225
A68: DATA PRODUKSI KACANG TANAH PER BULAN
A69: KOTA CILEGON TAHUN 2015
O71: (Ton)
A72: No | B72: Kecamatan | C72: Bulan | O72: Jumlah
C73: Jan | D73: Feb | E73: Maret | F73: Apr | G73: Mei | H73: Juni | I73: Juli | J73: Agst | K73: Sept | L73: Okt | M73: Nov | N73: Des
A74: 1 | B74: 2 | C74: 3 | D74: 4 | E74: 5 | F74: 6 | G74: 7 | H74: 8 | I74: 9 | J74: 10 | K74: 11 | L74: 12 | M74: 13 | N74: 14 | O74: 15
A75: 1 | B75: CIWANDAN | C75: 0 | D75: 44 | E75: 139 | F75: 0 | G75: 0 | H75: 68 | I75: 0 | J75: 0 | K75: 0 | L75: 0 | M75: 0 | N75: 0 | O75: =SUM(C75:N75) -> 251 | Q75: =SUM(F75:K75) -> 68
A76: 2 | B76: CITANGKIL | C76: 0 | D76: 5 | E76: 202 | F76: 83 | G76: 0 | H76: 1 | I76: 4 | J76: 16 | K76: 0 | L76: 0 | M76: 0 | N76: 0 | O76: =SUM(C76:N76) -> 311 | Q76: =SUM(F76:K76) -> 104
A77: 3 | B77: PULOMERAK | C77: 0 | D77: 142 | E77: 252 | F77: 0 | G77: 0 | H77: 176 | I77: 39 | J77: 0 | K77: 0 | L77: 0 | M77: 0 | N77: 0 | O77: =SUM(C77:N77) -> 609 | Q77: =SUM(F77:K77) -> 215
...

Sheet ubi kayu
A2: DATA LUAS TANAM UBI KAYU PER BULAN
A3: KOTA CILEGON TAHUN 2015
O5: (Ha)
A6: No | B6: Kecamatan | C6: Bulan | O6: Jumlah
C7: Jan | D7: Feb | E7: Maret | F7: Apr | G7: Mei | H7: Juni | I7: Juli | J7: Agst | K7: Sept | L7: Okt | M7: Nov | N7: Des
A8: 1 | B8: 2 | C8: 3 | D8: 4 | E8: 5 | F8: 6 | G8: 7 | H8: 8 | I8: 9 | J8: 10 | K8: 11 | L8: 12 | M8: 13 | N8: 14 | O8: 15 | Q8: APR-SEP
A9: 1 | B9: CIWANDAN | C9: 1 | D9: 0 | E9: 0 | F9: 0 | G9: 0 | H9: 0 | I9: 0 | J9: 0 | K9: 0 | L9: 0 | M9: 0 | N9: 1 | O9: =SUM(C9:N9) -> 2 | Q9: =SUM(F9:K9) -> 0
A10: 2 | B10: CITANGKIL | C10: 0 | D10: 0 | E10: 0 | F10: 0 | G10: 0 | H10: 0 | I10: 0 | J10: 0 | K10: 0 | L10: 0 | M10: 0 | N10: 0 | O10: =SUM(C10:N10) -> 0 | Q10: =SUM(F10:K10) -> 0
A11: 3 | B11: PULOMERAK | C11: 1 | D11: 0 | E11: 0 | F11: 0 | G11: 0 | H11: 0 | I11: 0 | J11: 0 | K11: 0 | L11: 0 | M11: 0 | N11: 3 | O11: =SUM(C11:N11) -> 4 | Q11: =SUM(F11:K11) -> 0
A12: 4 | B12: PURWAKARTA | C12: 0 | D12: 0 | E12: 1 | F12: 1 | G12: 1 | H12: 0 | I12: 0 | J12: 1 | K12: 0 | L12: 0 | M12: 0 | N12: 2 | O12: =SUM(C12:N12) -> 6 | Q12: =SUM(F12:K12) -> 3
A13: 5 | B13: GROGOL | C13: 0 | D13: 0 | E13: 0 | F13: 0 | G13: 0 | H13: 0 | I13: 0 | J13: 0 | K13: 0 | L13: 0 | M13: 0 | N13: 1 | O13: =SUM(C13:N13) -> 1 | Q13: =SUM(F13:K13) -> 0
A14: 6 | B14: CILEGON | C14: 2 | D14: 0 | E14: 0 | F14: 0 | G14: 2 | H14: 0 | I14: 0 | J14: 0 | K14: 0 | L14: 0 | M14: 0 | N14: 0 | O14: =SUM(C14:N14) -> 4 | Q14: =SUM(F14:K14) -> 2
A15: 7 | B15: JOMBANG | C15: 0 | D15: 0 | E15: 0 | F15: 0 | G15: 0 | H15: 0 | I15: 0 | J15: 0 | K15: 0 | L15: 0 | M15: 0 | N15: 0 | O15: =SUM(C15:N15) -> 0 | Q15: =SUM(F15:K15) -> 0
A16: 8 | B16: CIBEBER | C16: 1 | D16: 0 | E16: 1 | F16: 1 | G16: 0 | H16: 0 | I16: 0 | J16: 0 | K16: 0 | L16: 0 | M16: 0 | N16: 2 | O16: =SUM(C16:N16) -> 5 | Q16: =SUM(F16:K16) -> 1
A17: JUMLAH | C17: =SUM(C9:C16) -> 5 | D17: =SUM(D9:D16) -> 0 | E17: =SUM(E9:E16) -> 2 | F17: =SUM(F9:F16) -> 2 | G17: =SUM(G9:G16) -> 3 | H17: =SUM(H9:H16) -> 0 | I17: =SUM(I9:I16) -> 0 | J17: =SUM(J9:J16) -> 1 | ... O17: =SUM(O9:O16) -> 22 | Q17: =SUM(F17:K17) -> 6
A35: DATA LUAS PANEN UBI KAYU PER BULAN
A36: KOTA CILEGON TAHUN 2015
O38: (Ha)
A39: No | B39: Kecamatan | C39: Bulan | O39: Jumlah
C40: Jan | D40: Feb | E40: Maret | F40: Apr | G40: Mei | H40: Juni | I40: Juli | J40: Agst | K40: Sept | L40: Okt | M40: Nov | N40: Des
A41: 1 | B41: 2 | C41: 3 | D41: 4 | E41: 5 | F41: 6 | G41: 7 | H41: 8 | I41: 9 | J41: 10 | K41: 11 | L41: 12 | M41: 13 | N41: 14 | O41: 15
A42: 1 | B42: CIWANDAN | C42: 0 | D42: 0 | E42: 0 | F42: 0 | G42: 0 | H42: 3 | I42: 1 | J42: 0 | K42: 0 | L42: 0 | M42: 0 | N42: 0 | O42: =SUM(C42:N42) -> 4 | Q42: =SUM(F42:K42) -> 4
A43: 2 | B43: CITANGKIL | C43: 0 | D43: 0 | E43: 0 | F43: 0 | G43: 0 | H43: 0 | I43: 0 | J43: 0 | K43: 0 | L43: 0 | M43: 0 | N43: 0 | O43: =SUM(C43:N43) -> 0 | Q43: =SUM(F43:K43) -> 0
A44: 3 | B44: PULOMERAK | C44: 0 | D44: 0 | E44: 0 | F44: 0 | G44: 0 | H44: 0 | I44: 0 | J44: 0 | K44: 0 | L44: 0 | M44: 0 | N44: 0 | O44: =SUM(C44:N44) -> 0 | Q44: =SUM(F44:K44) -> 0
A45: 4 | B45: PURWAKARTA | C45: 0 | D45: 0 | E45: 0 | F45: 0 | G45: 0 | H45: 0 | I45: 0 | J45: 3 | K45: 0 | L45: 0 | M45: 1 | N45: 1 | O45: =SUM(C45:N45) -> 5 | Q45: =SUM(F45:K45) -> 3
A46: 5 | B46: GROGOL | C46: 0 | D46: 0 | E46: 0 | F46: 0 | G46: 0 | H46: 0 | I46: 0 | J46: 0 | K46: 0 | L46: 0 | M46: 0 | N46: 2 | O46: =SUM(C46:N46) -> 2 | Q46: =SUM(F46:K46) -> 0
A47: 6 | B47: CILEGON | C47: 0 | D47: 0 | E47: 0 | F47: 0 | G47: 0 | H47: 0 | I47: 0 | J47: 0 | K47: 2 | L47: 4 | M47: 0 | N47: 0 | O47: =SUM(C47:N47) -> 6 | Q47: =SUM(F47:K47) -> 2
A48: 7 | B48: JOMBANG | C48: 0 | D48: 0 | E48: 0 | F48: 0 | G48: 0 | H48: 0 | I48: 0 | J48: 0 | K48: 0 | L48: 0 | M48: 0 | N48: 0 | O48: =SUM(C48:N48) -> 0 | Q48: =SUM(F48:K48) -> 0
A49: 8 | B49: CIBEBER | C49: 0 | D49: 0 | E49: 0 | F49: 0 | G49: 0 | H49: 0 | I49: 0 | J49: 0 | K49: 0 | L49: 0 | M49: 0 | N49: 0 | O49: =SUM(C49:N49) -> 0 | Q49: =SUM(F49:K49) -> 0
A50: JUMLAH | C50: =SUM(C42:C49) -> 0 | D50: =SUM(D42:D49) -> 0 | E50: =SUM(E42:E49) -> 0 | F50: =SUM(F42:F49) -> 0 | G50: =SUM(G42:G49) -> 0 | H50: =SUM(H42:H49) -> 3 | I50: =SUM(I42:I49) -> 1 | J50: =SUM(J42:J49) -> 3 | ... O50: =SUM(O42:O49) -> 17 | Q50: =SUM(F50:K50) -> 9
A68: DATA PRODUKSI UBI KAYU PER BULAN
A69: KOTA CILEGON TAHUN 2015
O71: (Ton)
A72: No | B72: Kecamatan | C72: Bulan | O72: Jumlah
C73: Jan | D73: Feb | E73: Maret | F73: Apr | G73: Mei | H73: Juni | I73: Juli | J73: Agst | K73: Sept | L73: Okt | M73: Nov | N73: Des
A74: 1 | B74: 2 | C74: 3 | D74: 4 | E74: 5 | F74: 6 | G74: 7 | H74: 8 | I74: 9 | J74: 10 | K74: 11 | L74: 12 | M74: 13 | N74: 14 | O74: 15
A75: 1 | B75: CIWANDAN | C75: 0 | D75: 0 | E75: 0 | F75: 0 | G75: 0 | H75: 28 | I75: 9 | J75: 0 | K75: 0 | L75: 0 | M75: 0 | N75: 0 | O75: =SUM(C75:N75) -> 37 | Q75: =SUM(F75:K75) -> 37
A76: 2 | B76: CITANGKIL | C76: 0 | D76: 0 | E76: 0 | F76: 0 | G76: 0 | H76: 0 | I76: 0 | J76: 0 | K76: 0 | L76: 0 | M76: 0 | N76: 0 | O76: =SUM(C76:N76) -> 0 | Q76: =SUM(F76:K76) -> 0
A77: 3 | B77: PULOMERAK | C77: 0 | D77: 0 | E77: 0 | F77: 0 | G77: 0 | H77: 0 | I77: 0 | J77: 0 | K77: 0 | L77: 0 | M77: 0 | N77: 0 | O77: =SUM(C77:N77) -> 0 | Q77: =SUM(F77:K77) -> 0
A78: 4 | B78: PURWAKARTA | C78: 0 | D78: 0 | E78: 0 | F78: 0 | G78: 0 | H78: 0 | I78: 0 | J78: 37 | K78: 0 | L78: 0 | M78: 13 | N78: 12 | O78: =SUM(C78:N78) -> 62 | Q78: =SUM(F78:K78) -> 37
...

Sheet ubi jalar
A2: DATA LUAS TANAM UBI JALAR PER BULAN
A3: KOTA CILEGON TAHUN 2015
O5: (Ha)
A6: No | B6: Kecamatan | C6: Bulan | O6: Jumlah
C7: Jan | D7: Feb | E7: Maret | F7: Apr | G7: Mei | H7: Juni | I7: Juli | J7: Agst | K7: Sept | L7: Okt | M7: Nov | N7: Des
A8: 1 | B8: 2 | C8: 3 | D8: 4 | E8: 5 | F8: 6 | G8: 7 | H8: 8 | I8: 9 | J8: 10 | K8: 11 | L8: 12 | M8: 13 | N8: 14 | O8: 15 | Q8: APR-SEP
A9: 1 | B9: CIWANDAN | C9: 0 | D9: 0 | E9: 0 | F9: 0 | G9: 0 | H9: 0 | I9: 0 | J9: 0 | K9: 0 | L9: 0 | M9: 0 | N9: 0 | O9: =SUM(C9:N9) -> 0 | Q9: =SUM(F9:K9) -> 0
A10: 2 | B10: CITANGKIL | C10: 0 | D10: 0 | E10: 0 | F10: 0 | G10: 0 | H10: 0 | I10: 0 | J10: 0 | K10: 0 | L10: 1 | M10: 1 | N10: 0 | O10: =SUM(C10:N10) -> 2 | Q10: =SUM(F10:K10) -> 0
A11: 3 | B11: PULOMERAK | C11: 0 | D11: 0 | E11: 0 | F11: 0 | G11: 0 | H11: 0 | I11: 0 | J11: 0 | K11: 0 | L11: 0 | M11: 0 | N11: 0 | O11: =SUM(C11:N11) -> 0 | Q11: =SUM(F11:K11) -> 0
A12: 4 | B12: PURWAKARTA | C12: 0 | D12: 1 | E12: 1 | F12: 0 | G12: 0 | H12: 0 | I12: 0 | J12: 0 | K12: 0 | L12: 1 | M12: 1 | N12: 0 | O12: =SUM(C12:N12) -> 4 | Q12: =SUM(F12:K12) -> 0
A13: 5 | B13: GROGOL | C13: 0 | D13: 1 | E13: 1 | F13: 1 | G13: 0 | H13: 0 | I13: 0 | J13: 0 | K13: 0 | L13: 0 | M13: 0 | N13: 0 | O13: =SUM(C13:N13) -> 3 | Q13: =SUM(F13:K13) -> 1
A14: 6 | B14: CILEGON | C14: 0 | D14: 0 | E14: 0 | F14: 0 | G14: 0 | H14: 0 | I14: 0 | J14: 0 | K14: 0 | L14: 0 | M14: 0 | N14: 0 | O14: =SUM(C14:N14) -> 0 | Q14: =SUM(F14:K14) -> 0
A15: 7 | B15: JOMBANG | C15: 0 | D15: 0 | E15: 0 | F15: 0 | G15: 0 | H15: 1 | I15: 1 | J15: 0 | K15: 0 | L15: 0 | M15: 0 | N15: 0 | O15: =SUM(C15:N15) -> 2 | Q15: =SUM(F15:K15) -> 2
A16: 8 | B16: CIBEBER | C16: 1 | D16: 0 | E16: 0 | F16: 1 | G16: 0 | H16: 0 | I16: 0 | J16: 1 | K16: 0 | L16: 0 | M16: 0 | N16: 1 | O16: =SUM(C16:N16) -> 4 | Q16: =SUM(F16:K16) -> 2
A17: JUMLAH | C17: =SUM(C9:C16) -> 1 | D17: =SUM(D9:D16) -> 2 | E17: =SUM(E9:E16) -> 2 | F17: =SUM(F9:F16) -> 2 | G17: =SUM(G9:G16) -> 0 | H17: =SUM(H9:H16) -> 1 | I17: =SUM(I9:I16) -> 1 | J17: =SUM(J9:J16) -> 1 | ... O17: =SUM(O9:O16) -> 15 | Q17: =SUM(F17:K17) -> 5
A35: DATA LUAS PANEN UBI JALAR PER BULAN
A36: KOTA CILEGON TAHUN 2015
O38: (Ha)
A39: No | B39: Kecamatan | C39: Bulan | O39: Jumlah
C40: Jan | D40: Feb | E40: Maret | F40: Apr | G40: Mei | H40: Juni | I40: Juli | J40: Agst | K40: Sept | L40: Okt | M40: Nov | N40: Des
A41: 1 | B41: 2 | C41: 3 | D41: 4 | E41: 5 | F41: 6 | G41: 7 | H41: 8 | I41: 9 | J41: 10 | K41: 11 | L41: 12 | M41: 13 | N41: 14 | O41: 15
A42: 1 | B42: CIWANDAN | C42: 0 | D42: 0 | E42: 0 | F42: 5 | G42: 0 | H42: 0 | I42: 0 | J42: 0 | K42: 0 | L42: 0 | M42: 0 | N42: 0 | O42: =SUM(C42:N42) -> 5 | Q42: =SUM(F42:K42) -> 5
A43: 2 | B43: CITANGKIL | C43: 0 | D43: 0 | E43: 0 | F43: 0 | G43: 0 | H43: 0 | I43: 0 | J43: 0 | K43: 0 | L43: 0 | M43: 0 | N43: 0 | O43: =SUM(C43:N43) -> 0 | Q43: =SUM(F43:K43) -> 0
A44: 3 | B44: PULOMERAK | C44: 0 | D44: 0 | E44: 0 | F44: 0 | G44: 0 | H44: 0 | I44: 0 | J44: 0 | K44: 0 | L44: 0 | M44: 0 | N44: 0 | O44: =SUM(C44:N44) -> 0 | Q44: =SUM(F44:K44) -> 0
A45: 4 | B45: PURWAKARTA | C45: 0 | D45: 0 | E45: 0 | F45: 0 | G45: 1 | H45: 0 | I45: 1 | J45: 1 | K45: 0 | L45: 0 | M45: 0 | N45: 0 | O45: =SUM(C45:N45) -> 3 | Q45: =SUM(F45:K45) -> 3
A46: 5 | B46: GROGOL | C46: 0 | D46: 0 | E46: 0 | F46: 0 | G46: 0 | H46: 0 | I46: 0 | J46: 0 | K46: 1 | L46: 2 | M46: 0 | N46: 0 | O46: =SUM(C46:N46) -> 3 | Q46: =SUM(F46:K46) -> 1
A47: 6 | B47: CILEGON | C47: 0 | D47: 0 | E47: 0 | F47: 0 | G47: 0 | H47: 0 | I47: 0 | J47: 0 | K47: 0 | L47: 0 | M47: 0 | N47: 0 | O47: =SUM(C47:N47) -> 0 | Q47: =SUM(F47:K47) -> 0
A48: 7 | B48: JOMBANG | C48: 0 | D48: 0 | E48: 0 | F48: 0 | G48: 0 | H48: 0 | I48: 0 | J48: 0 | K48: 0 | L48: 1 | M48: 1 | N48: 0 | O48: =SUM(C48:N48) -> 2 | Q48: =SUM(F48:K48) -> 0
A49: 8 | B49: CIBEBER | C49: 0 | D49: 0 | E49: 0 | F49: 0 | G49: 0 | H49: 1 | I49: 1 | J49: 0 | K49: 0 | L49: 0 | M49: 0 | N49: 0 | O49: =SUM(C49:N49) -> 2 | Q49: =SUM(F49:K49) -> 2
A50: JUMLAH | C50: =SUM(C42:C49) -> 0 | D50: =SUM(D42:D49) -> 0 | E50: =SUM(E42:E49) -> 0 | F50: =SUM(F42:F49) -> 5 | G50: =SUM(G42:G49) -> 1 | H50: =SUM(H42:H49) -> 1 | I50: =SUM(I42:I49) -> 2 | J50: =SUM(J42:J49) -> 1 | ... O50: =SUM(O42:O49) -> 15 | Q50: =SUM(F50:K50) -> 11
A68: DATA PRODUKSI UBI JALAR PER BULAN
A69: KOTA CILEGON TAHUN 2015
O71: (Ton)
A72: No | B72: Kecamatan | C72: Bulan | O72: Jumlah
C73: Jan | D73: Feb | E73: Maret | F73: Apr | G73: Mei | H73: Juni | I73: Juli | J73: Agst | K73: Sept | L73: Okt | M73: Nov | N73: Des
A74: 1 | B74: 2 | C74: 3 | D74: 4 | E74: 5 | F74: 6 | G74: 7 | H74: 8 | I74: 9 | J74: 10 | K74: 11 | L74: 12 | M74: 13 | N74: 14 | O74: 15
A75: 1 | B75: CIWANDAN | C75: 0 | D75: 0 | E75: 0 | F75: 42 | G75: 0 | H75: 0 | I75: 0 | J75: 0 | K75: 0 | L75: 0 | M75: 0 | N75: 0 | O75: =SUM(C75:N75) -> 42 | Q75: =SUM(F75:K75) -> 42
A76: 2 | B76: CITANGKIL | C76: 0 | D76: 0 | E76: 0 | F76: 0 | G76: 0 | H76: 0 | I76: 0 | J76: 0 | K76: 0 | L76: 0 | M76: 0 | N76: 0 | O76: =SUM(C76:N76) -> 0 | Q76: =SUM(F76:K76) -> 0
A77: 3 | B77: PULOMERAK | C77: 0 | D77: 0 | E77: 0 | F77: 0 | G77: 0 | H77: 0 | I77: 0 | J77: 0 | K77: 0 | L77: 0 | M77: 0 | N77: 0 | O77: =SUM(C77:N77) -> 0 | Q77: =SUM(F77:K77) -> 0
A78: 4 | B78: PURWAKARTA | C78: 0 | D78: 0 | E78: 0 | F78: 0 | G78: 11 | H78: 0 | I78: 10 | J78: 11 | K78: 0 | L78: 0 | M78: 0 | N78: 0 | O78: =SUM(C78:N78) -> 32 | Q78: =SUM(F78:K78) -> 32
...

Sheet kc ijo
A2: DATA LUAS TANAM KACANG HIJAU PER BULAN
A3: KOTA CILEGON TAHUN 2015
O5: (Ha)
A6: No | B6: Kecamatan | C6: Bulan | O6: Jumlah
C7: Jan | D7: Feb | E7: Maret | F7: Apr | G7: Mei | H7: Juni | I7: Juli | J7: Agst | K7: Sept | L7: Okt | M7: Nov | N7: Des
A8: 1 | B8: 2 | C8: 3 | D8: 4 | E8: 5 | F8: 6 | G8: 7 | H8: 8 | I8: 9 | J8: 10 | K8: 11 | L8: 12 | M8: 13 | N8: 14 | O8: 15 | Q8: APR-SEP
A9: 1 | B9: CIWANDAN | C9: 2 | D9: 0 | E9: 0 | F9: 0 | G9: 0 | H9: 0 | I9: 0 | J9: 0 | K9: 0 | L9: 0 | M9: 0 | N9: 0 | O9: =SUM(C9:N9) -> 2 | Q9: =SUM(F9:K9) -> 0
A10: 2 | B10: CITANGKIL | C10: 0 | D10: 0 | E10: 0 | F10: 0 | G10: 0 | H10: 0 | I10: 0 | J10: 0 | K10: 0 | L10: 0 | M10: 0 | N10: 0 | O10: =SUM(C10:N10) -> 0 | Q10: =SUM(F10:K10) -> 0
A11: 3 | B11: PULOMERAK | C11: 0 | D11: 0 | E11: 0 | F11: 1 | G11: 2 | H11: 0 | I11: 0 | J11: 0 | K11: 0 | L11: 0 | M11: 0 | N11: 0 | O11: =SUM(C11:N11) -> 3 | Q11: =SUM(F11:K11) -> 3
A12: 4 | B12: PURWAKARTA | C12: 0 | D12: 0 | E12: 0 | F12: 8 | G12: 10 | H12: 0 | I12: 0 | J12: 0 | K12: 0 | L12: 0 | M12: 0 | N12: 0 | O12: =SUM(C12:N12) -> 18 | Q12: =SUM(F12:K12) -> 18
A13: 5 | B13: GROGOL | C13: 0 | D13: 0 | E13: 0 | F13: 0 | G13: 12 | H13: 0 | I13: 0 | J13: 0 | K13: 0 | L13: 0 | M13: 0 | N13: 0 | O13: =SUM(C13:N13) -> 12 | Q13: =SUM(F13:K13) -> 12
A14: 6 | B14: CILEGON | C14: 0 | D14: 0 | E14: 0 | F14: 0 | G14: 0 | H14: 0 | I14: 0 | J14: 0 | K14: 0 | L14: 0 | M14: 0 | N14: 0 | O14: =SUM(C14:N14) -> 0 | Q14: =SUM(F14:K14) -> 0
A15: 7 | B15: JOMBANG | C15: 0 | D15: 0 | E15: 0 | F15: 0 | G15: 0 | H15: 0 | I15: 0 | J15: 0 | K15: 0 | L15: 0 | M15: 0 | N15: 0 | O15: =SUM(C15:N15) -> 0 | Q15: =SUM(F15:K15) -> 0
A16: 8 | B16: CIBEBER | C16: 1 | D16: 0 | E16: 0 | F16: 1 | G16: 0 | H16: 0 | I16: 0 | J16: 0 | K16: 0 | L16: 0 | M16: 0 | N16: 0 | O16: =SUM(C16:N16) -> 2 | Q16: =SUM(F16:K16) -> 1
A17: JUMLAH | C17: =SUM(C9:C16) -> 3 | D17: =SUM(D9:D16) -> 0 | E17: =SUM(E9:E16) -> 0 | F17: =SUM(F9:F16) -> 10 | G17: =SUM(G9:G16) -> 24 | H17: =SUM(H9:H16) -> 0 | I17: =SUM(I9:I16) -> 0 | J17: =SUM(J9:J16) -> 0 | ... O17: =SUM(O9:O16) -> 37 | Q17: =SUM(F17:K17) -> 34
A35: DATA LUAS PANEN KACANG HIJAU PER BULAN
A36: KOTA CILEGON TAHUN 2015
O38: (Ha)
A39: No | B39: Kecamatan | C39: Bulan | O39: Jumlah
C40: Jan | D40: Feb | E40: Maret | F40: Apr | G40: Mei | H40: Juni | I40: Juli | J40: Agst | K40: Sept | L40: Okt | M40: Nov | N40: Des
A41: 1 | B41: 2 | C41: 3 | D41: 4 | E41: 5 | F41: 6 | G41: 7 | H41: 8 | I41: 9 | J41: 10 | K41: 11 | L41: 12 | M41: 13 | N41: 14 | O41: 15
A42: 1 | B42: CIWANDAN | C42: 0 | D42: 2 | E42: 2 | F42: 0 | G42: 0 | H42: 0 | I42: 0 | J42: 0 | K42: 0 | L42: 0 | M42: 0 | N42: 0 | O42: =SUM(C42:N42) -> 4 | Q42: =SUM(F42:K42) -> 0
A43: 2 | B43: CITANGKIL | C43: 0 | D43: 0 | E43: 0 | F43: 0 | G43: 0 | H43: 0 | I43: 0 | J43: 0 | K43: 0 | L43: 0 | M43: 0 | N43: 0 | O43: =SUM(C43:N43) -> 0 | Q43: =SUM(F43:K43) -> 0
A44: 3 | B44: PULOMERAK | C44: 0 | D44: 0 | E44: 0 | F44: 0 | G44: 0 | H44: 0 | I44: 0 | J44: 3 | K44: 0 | L44: 0 | M44: 0 | N44: 0 | O44: =SUM(C44:N44) -> 3 | Q44: =SUM(F44:K44) -> 3
A45: 4 | B45: PURWAKARTA | C45: 0 | D45: 0 | E45: 0 | F45: 0 | G45: 0 | H45: 0 | I45: 18 | J45: 0 | K45: 0 | L45: 0 | M45: 0 | N45: 0 | O45: =SUM(C45:N45) -> 18 | Q45: =SUM(F45:K45) -> 18
A46: 5 | B46: GROGOL | C46: 0 | D46: 0 | E46: 0 | F46: 0 | G46: 0 | H46: 0 | I46: 0 | J46: 12 | K46: 0 | L46: 0 | M46: 0 | N46: 0 | O46: =SUM(C46:N46) -> 12 | Q46: =SUM(F46:K46) -> 12
A47: 6 | B47: CILEGON | C47: 0 | D47: 0 | E47: 0 | F47: 0 | G47: 0 | H47: 0 | I47: 0 | J47: 0 | K47: 0 | L47: 0 | M47: 0 | N47: 0 | O47: =SUM(C47:N47) -> 0 | Q47: =SUM(F47:K47) -> 0
A48: 7 | B48: JOMBANG | C48: 0 | D48: 0 | E48: 0 | F48: 0 | G48: 0 | H48: 0 | I48: 0 | J48: 0 | K48: 0 | L48: 0 | M48: 0 | N48: 0 | O48: =SUM(C48:N48) -> 0 | Q48: =SUM(F48:K48) -> 0
A49: 8 | B49: CIBEBER | C49: 0 | D49: 0 | E49: 0 | F49: 1 | G49: 0 | H49: 0 | I49: 1 | J49: 0 | K49: 0 | L49: 0 | M49: 0 | N49: 0 | O49: =SUM(C49:N49) -> 2 | Q49: =SUM(F49:K49) -> 2
A50: JUMLAH | C50: =SUM(C42:C49) -> 0 | D50: =SUM(D42:D49) -> 2 | E50: =SUM(E42:E49) -> 2 | F50: =SUM(F42:F49) -> 1 | G50: =SUM(G42:G49) -> 0 | H50: =SUM(H42:H49) -> 0 | I50: =SUM(I42:I49) -> 19 | J50: =SUM(J42:J49) -> 15 | ... O50: =SUM(O42:O49) -> 39 | Q50: =SUM(F50:K50) -> 35
A68: DATA PRODUKSI KACANG HIJAU PER BULAN
A69: KOTA CILEGON TAHUN 2015
O71: (Ton)
A72: No | B72: Kecamatan | C72: Bulan | O72: Jumlah
C73: Jan | D73: Feb | E73: Maret | F73: Apr | G73: Mei | H73: Juni | I73: Juli | J73: Agst | K73: Sept | L73: Okt | M73: Nov | N73: Des
A74: 1 | B74: 2 | C74: 3 | D74: 4 | E74: 5 | F74: 6 | G74: 7 | H74: 8 | I74: 9 | J74: 10 | K74: 11 | L74: 12 | M74: 13 | N74: 14 | O74: 15
A75: 1 | B75: CIWANDAN | C75: 0 | D75: 1 | E75: 1 | F75: 0 | G75: 0 | H75: 0 | I75: 0 | J75: 0 | K75: 0 | L75: 0 | M75: 0 | N75: 0 | O75: =SUM(C75:N75) -> 2 | Q75: =SUM(F75:K75) -> 0
A76: 2 | B76: CITANGKIL | C76: 0 | D76: 0 | E76: 0 | F76: 0 | G76: 0 | H76: 0 | I76: 0 | J76: 0 | K76: 0 | L76: 0 | M76: 0 | N76: 0 | O76: =SUM(C76:N76) -> 0 | Q76: =SUM(F76:K76) -> 0
A77: 3 | B77: PULOMERAK | C77: 0 | D77: 0 | E77: 0 | F77: 0 | G77: 0 | H77: 0 | I77: 0 | J77: 3 | K77: 0 | L77: 0 | M77: 0 | N77: 0 | O77: =SUM(C77:N77) -> 3 | Q77: =SUM(F77:K77) -> 3
A78: 4 | B78: PURWAKARTA | C78: 0 | D78: 0 | E78: 0 | F78: 0 | G78: 0 | H78: 0 | I78: 16 | J78: 0 | K78: 0 | L78: 0 | M78: 0 | N78: 0 | O78: =SUM(C78:N78) -> 16 | Q78: =SUM(F78:K78) -> 16
...

Sheet rekap
A1: REALISASI TANAM, PANEN, PRODUKSI DAN PRODUKTIVITAS PADI DAN JAGUNG
A2: KOTA CILEGON 2015
A4: 1. PADI SAWAH
A5: No | B5: Kecamatan | C5: TANAM | D5: PANEN | E5: PRODUKSI | F5: PRODUKTIVITAS
C6: (Ha) | D6: (Ha) | E6: (Ton GKG) | F6: (Ku/Ha)
A7: 1 | B7: 2 | C7: 3 | D7: 4 | E7: 5 | F7: 6
A8: 1 | B8: CIWANDAN | C8: ='okt-mar'!Q7 -> 233 | D8: ='padi sawah'!O42 -> 233 | E8: ='padi sawah'!O75 -> 1466 | F8: ='padi sawah'!O108 -> 62.918455
A9: 2 | B9: CITANGKIL | C9: ='okt-mar'!Q8 -> 389 | D9: ='padi sawah'!O43 -> 387 | E9: ='padi sawah'!O76 -> 3013 | F9: ='padi sawah'!O109 -> 77.855297
A10: 3 | B10: PULOMERAK | C10: ='okt-mar'!Q9 -> 63 | D10: ='padi sawah'!O44 -> 63 | E10: ='padi sawah'!O77 -> 341 | F10: ='padi sawah'!O110 -> 54.126984
A11: 4 | B11: PURWAKARTA | C11: ='okt-mar'!Q10 -> 200 | D11: ='padi sawah'!O45 -> 200 | E11: ='padi sawah'!O78 -> 1145 | F11: ='padi sawah'!O111 -> 57.25
A12: 5 | B12: GROGOL | C12: ='okt-mar'!Q11 -> 270 | D12: ='padi sawah'!O46 -> 270 | E12: ='padi sawah'!O79 -> 1609 | F12: ='padi sawah'!O112 -> 59.592593
A13: 6 | B13: CILEGON | C13: ='okt-mar'!Q12 -> 82 | D13: ='padi sawah'!O47 -> 81 | E13: ='padi sawah'!O80 -> 584 | F13: ='padi sawah'!O113 -> 72.098765
A14: 7 | B14: JOMBANG | C14: ='okt-mar'!Q13 -> 586 | D14: ='padi sawah'!O48 -> 586 | E14: ='padi sawah'!O81 -> 3438 | F14: ='padi sawah'!O114 -> 58.668942
A15: 8 | B15: CIBEBER | C15: ='okt-mar'!Q14 -> 492 | D15: ='padi sawah'!O49 -> 466 | E15: ='padi sawah'!O82 -> 3138 | F15: ='padi sawah'!O115 -> 67.339056
A16: JUMLAH | C16: =SUM(C8:C15) -> 2315 | D16: =SUM(D8:D15) -> 2286 | E16: =SUM(E8:E15) -> 14734 | F16: =E16/D16*10 -> 64.453193
A18: 2. PADI LADANG
A19: No | B19: Kecamatan | C19: TANAM | D19: PANEN | E19: PRODUKSI | F19: PRODUKTIVITAS
C20: (Ha) | D20: (Ha) | E20: (Ton GKG) | F20: (Ku/Ha)
A21: 1 | B21: 2 | C21: 3 | D21: 4 | E21: 5 | F21: 6
A22: 1 | B22: CIWANDAN | C22: 0 | D22: 0 | E22: 0 | F22: 0
A23: 2 | B23: CITANGKIL | C23: 0 | D23: 0 | E23: 0 | F23: 0
A24: 3 | B24: PULOMERAK | C24: ='okt-mar'!Q81 -> 25 | D24: ='padi ladang'!O44 -> 25 | E24: ='padi ladang'!O77 -> 76 | F24: ='padi ladang'!O110 -> 30.4
A25: 4 | B25: PURWAKARTA | C25: 0 | D25: 0 | E25: 0 | F25: 0
A26: 5 | B26: GROGOL | C26: 0 | D26: 0 | E26: 0 | F26: 0
A27: 6 | B27: CILEGON | C27: 0 | D27: 0 | E27: 0 | F27: 0
A28: 7 | B28: JOMBANG | C28: 0 | D28: 0 | E28: 0 | F28: 0
A29: 8 | B29: CIBEBER | C29: 0 | D29: 0 | E29: 0 | F29: 0
A30: JUMLAH | C30: =SUM(C22:C29) -> 25 | D30: =SUM(D22:D29) -> 25 | E30: =SUM(E22:E29) -> 76 | F30: =E30/D30*10 -> 30.4
A32: 3. JAGUNG
A33: No | B33: Kecamatan | C33: TANAM | D33: PANEN | E33: PRODUKSI | F33: PRODUKTIVITAS
C34: (Ha) | D34: (Ha) | E34: (Ton Biji Kering) | F34: (Ku/Ha)
A35: 1 | B35: 2 | C35: 3 | D35: 4 | E35: 5 | F35: 6
A36: 1 | B36: CIWANDAN | C36: ='okt-mar'!Q223 -> 5 | D36: 5* | E36: =jagung!O75 -> 0 | F36: 0 | I36: *
A37: 2 | B37: CITANGKIL | C37: ='okt-mar'!Q224 -> 2 | D37: 2* | E37: =jagung!O76 -> 0 | F37: 0 | I37: *
A38: 3 | B38: PULOMERAK | C38: ='okt-mar'!Q225 -> 9 | D38: =jagung!Q44 -> 9 | E38: =jagung!O77 -> 25 | F38: =jagung!O110 -> 27.777778
A39: 4 | B39: PURWAKARTA | C39: ='okt-mar'!Q226 -> 5 | D39: =jagung!Q45 -> 4 | E39: =jagung!O78 -> 9 | F39: =jagung!O111 -> 22.5
A40: 5 | B40: GROGOL | C40: ='okt-mar'!Q227 -> 2 | D40: =jagung!Q46 -> 3 | E40: =jagung!O79 -> 7 | F40: =jagung!O112 -> 23.333333
A41: 6 | B41: CILEGON | C41: ='okt-mar'!Q228 -> 0 | D41: =jagung!Q47 -> 0 | E41: =jagung!O80 -> 0 | F41: 0
A42: 7 | B42: JOMBANG | C42: ='okt-mar'!Q229 -> 0 | D42: =jagung!Q48 -> 0 | E42: =jagung!O81 -> 0 | F42: 0
A43: 8 | B43: CIBEBER | C43: ='okt-mar'!Q230 -> 3 | D43: =jagung!Q49 -> 3 | E43: =jagung!O82 -> 6 | F43: =jagung!O115 -> 30 | I43: *
...

Sheet okt-mar
A1: REALISASI TANAM PADI SAWAH OKTOBER 2014 S/D MARET 2015 DAN APRIL S/D SEPTEMBER 2015 | T1: REALISASI PRODUKSI PADI SAWAH OKTOBER 2013 S/D MARET 2014
A2: KOTA CILEGON | T2: KOTA CILEGON
Q3: (Ha) | AH3: (Ton)
A4: No | B4: Kecamatan | C4: 2014 S/D 2015 | I4: Okt-Mar | J4: 2015 | P4: Apr-Sep | Q4: Jumlah | T4: No | U4: Kecamatan | V4: 2014 S/D 2015 | AB4: 2015 | AH4: Jumlah
C5: Okt | D5: Nov | E5: Des | F5: Jan | G5: Peb | H5: Mar | J5: April | K5: Mei | L5: Juni | M5: Juli | N5: Agust | O5: Sep | V5: Okt | W5: Nov | X5: Des | Y5: Jan | Z5: Peb | AA5: Mar | AB5: April | AC5: Mei | AD5: Juni | AE5: Juli | AF5: Agust | AG5: Sep
A6: 1 | B6: 2 | C6: 3 | D6: 4 | E6: 5 | F6: 6 | G6: 7 | H6: 8 | I6: 9 | J6: 10 | K6: 11 | L6: 12 | M6: 13 | N6: 14 | O6: 15 | P6: 16 | Q6: 17 | T6: 1 | U6: 2 | V6: 3 | W6: 4 | X6: 5 | Y6: 6 | Z6: 7 | AA6: 8 | AB6: 9 | AC6: 10 | AD6: 11 | AE6: 12 | AF6: 13 | AG6: 14 | AH6: 15
A7: 1 | B7: CIWANDAN | C7: 0 | D7: 0 | E7: 0 | F7: 204 | G7: 0 | H7: 0 | I7: =SUM(C7:H7) -> 204 | J7: 2 | K7: 18 | L7: 8 | M7: 0 | N7: ='padi sawah'!J9 -> 1 | O7: ='padi sawah'!K9 -> 0 | P7: =SUM(J7:O7) -> 29 | Q7: =SUM(I7,P7) -> 233 | T7: 1 | U7: CIWANDAN | V7: 0 | W7: 0 | X7: 9 | Y7: 0 | Z7: 9 | AA7: 22 | AH7: =SUM(V7:AA7) -> 40
A8: 2 | B8: CITANGKIL | C8: 0 | D8: 25 | E8: 125 | F8: 114 | G8: 0 | H8: 15 | I8: =SUM(C8:H8) -> 279 | J8: 29 | K8: 7 | L8: 65 | M8: 1 | N8: ='padi sawah'!J10 -> 4 | O8: ='padi sawah'!K10 -> 4 | P8: =SUM(J8:O8) -> 110 | Q8: =SUM(I8,P8) -> 389 | T8: 2 | U8: CITANGKIL | V8: 0 | W8: 0 | X8: 117 | Y8: 28 | Z8: 0 | AA8: 168 | AH8: =SUM(V8:AA8) -> 313
A9: 3 | B9: PULOMERAK | C9: 0 | D9: 0 | E9: 10 | F9: 38 | G9: 0 | H9: 0 | I9: =SUM(C9:H9) -> 48 | J9: 5 | K9: 10 | L9: 0 | M9: 0 | N9: ='padi sawah'!J11 -> 0 | O9: ='padi sawah'!K11 -> 0 | P9: =SUM(J9:O9) -> 15 | Q9: =SUM(I9,P9) -> 63 | T9: 3 | U9: PULOMERAK | V9: 0 | W9: 0 | X9: 0 | Y9: 0 | Z9: 0 | AA9: 0 | AH9: =SUM(V9:AA9) -> 0
A10: 4 | B10: PURWAKARTA | C10: 0 | D10: 3 | E10: 165 | F10: 16 | G10: 0 | H10: 0 | I10: =SUM(C10:H10) -> 184 | J10: 0 | K10: 7 | L10: 7 | M10: 0 | N10: ='padi sawah'!J12 -> 2 | O10: ='padi sawah'!K12 -> 0 | P10: =SUM(J10:O10) -> 16 | Q10: =SUM(I10,P10) -> 200 | T10: 4 | U10: PURWAKARTA | V10: 0 | W10: 0 | X10: 0 | Y10: 10 | Z10: 0 | AA10: 161 | AH10: =SUM(V10:AA10) -> 171
A11: 5 | B11: GROGOL | C11: 0 | D11: 0 | E11: 25 | F11: 225 | G11: 0 | H11: 0 | I11: =SUM(C11:H11) -> 250 | J11: 0 | K11: 10 | L11: 10 | M11: 0 | N11: ='padi sawah'!J13 -> 0 | O11: ='padi sawah'!K13 -> 0 | P11: =SUM(J11:O11) -> 20 | Q11: =SUM(I11,P11) -> 270 | T11: 5 | U11: GROGOL | V11: 42 | W11: 0 | X11: 0 | Y11: 0 | Z11: 0 | AA11: 0 | AH11: =SUM(V11:AA11) -> 42
A12: 6 | B12: CILEGON | C12: 0 | D12: 8 | E12: 36 | F12: 0 | G12: 0 | H12: 0 | I12: =SUM(C12:H12) -> 44 | J12: 6 | K12: 15 | L12: 10 | M12: 0 | N12: ='padi sawah'!J14 -> 7 | O12: ='padi sawah'!K14 -> 0 | P12: =SUM(J12:O12) -> 38 | Q12: =SUM(I12,P12) -> 82 | T12: 6 | U12: CILEGON | V12: 0 | W12: 0 | X12: 0 | Y12: 85 | Z12: 0 | AA12: 0 | AH12: =SUM(V12:AA12) -> 85
A13: 7 | B13: JOMBANG | C13: 1 | D13: 1 | E13: 144 | F13: 133 | G13: 0 | H13: 0 | I13: =SUM(C13:H13) -> 279 | J13: 0 | K13: 8 | L13: 183 | M13: 110 | N13: ='padi sawah'!J15 -> 6 | O13: ='padi sawah'!K15 -> 0 | P13: =SUM(J13:O13) -> 307 | Q13: =SUM(I13,P13) -> 586 | T13: 7 | U13: JOMBANG | V13: 0 | W13: 56 | X13: 50 | Y13: 0 | Z13: 0 | AA13: 1474 | AH13: =SUM(V13:AA13) -> 1580
A14: 8 | B14: CIBEBER | C14: 0 | D14: 30 | E14: 73 | F14: 201 | G14: 0 | H14: 0 | I14: =SUM(C14:H14) -> 304 | J14: 36 | K14: 116 | L14: 11 | M14: 1 | N14: ='padi sawah'!J16 -> 0 | O14: ='padi sawah'!K16 -> 24 | P14: =SUM(J14:O14) -> 188 | Q14: =SUM(I14,P14) -> 492 | T14: 8 | U14: CIBEBER | V14: 20 | W14: 216 | X14: 35 | Y14: 197 | Z14: 0 | AA14: 157 | AH14: =SUM(V14:AA14) -> 625
A15: JUMLAH | C15: =SUM(C7:C14) -> 1 | D15: =SUM(D7:D14) -> 67 | E15: =SUM(E7:E14) -> 578 | F15: =SUM(F7:F14) -> 931 | G15: =SUM(G7:G14) -> 0 | H15: =SUM(H7:H14) -> 15 | I15: =SUM(I7:I14) -> 1592 | J15: =SUM(J7:J14) -> 78 | ... Q15: =SUM(Q7:Q14) -> 2315 | T15: JUMLAH | V15: =SUM(V7:V14) -> 62 | W15: =SUM(W7:W14) -> 272 | X15: =SUM(X7:X14) -> 211 | Y15: =SUM(Y7:Y14) -> 320 | Z15: =SUM(Z7:Z14) -> 9 | AA15: =SUM(AA7:AA14) -> 1982 | AB15: =SUM(AB7:AB14) -> 0 | AC15: =SUM(AC7:AC14) -> 0 | ... AH15: =SUM(AH7:AH14) -> 2856
A17: REALISASI PANEN PADI SAWAH OKTOBER 2014 S/D MARET 2015 DAN APRIL S/D SEPTEMBER 2015 | T17: REALISASI PRODUKSI PADI LADANG OKTOBER 2013 S/D MARET 2014
A18: KOTA CILEGON | T18: KOTA CILEGON
Q19: (Ha) | AH19: (Ton)
A20: No | B20: Kecamatan | C20: 2014 S/D 2015 | I20: Okt-Mar | J20: 2015 | P20: Apr-Sep | Q20: Jumlah | T20: No | U20: Kecamatan | V20: 2014 S/D 2015 | AB20: 2015 | AH20: Jumlah
C21: Okt | D21: Nov | E21: Des | F21: Jan | G21: Peb | H21: Mar | J21: April | K21: Mei | L21: Juni | M21: Juli | N21: Agust | O21: Sep | V21: Okt | W21: Nov | X21: Des | Y21: Jan | Z21: Peb | AA21: Mar | AB21: April | AC21: Mei | AD21: Juni | AE21: Juli | AF21: Agust | AG21: Sep
A22: 1 | B22: 2 | C22: 3 | D22: 4 | E22: 5 | F22: 6 | G22: 7 | H22: 8 | I22: 9 | J22: 10 | K22: 11 | L22: 12 | M22: 13 | N22: 14 | O22: 15 | P22: 16 | Q22: 17 | T22: 1 | U22: 2 | V22: 3 | W22: 4 | X22: 5 | Y22: 6 | Z22: 7 | AA22: 8 | AB22: 9 | AC22: 10 | AD22: 11 | AE22: 12 | AF22: 13 | AG22: 14 | AH22: 15
A23: 1 | B23: CIWANDAN | C23: 2 | D23: 0 | E23: 0 | F23: 0 | G23: 0 | H23: 0 | I23: =SUM(C23:H23) -> 2 | J23: 204 | K23: 0 | L23: 2 | M23: 0 | N23: ='padi sawah'!J42 -> 20 | O23: ='padi sawah'!K42 -> 6 | P23: =SUM(J23:O23) -> 232 | Q23: =SUM(I23,P23) -> 234 | T23: 1 | U23: CIWANDAN | V23: 0 | W23: 0 | X23: 0 | Y23: 0 | Z23: 0 | AA23: 0 | AH23: =SUM(V23:AG23) -> 0
A24: 2 | B24: CITANGKIL | C24: 3 | D24: 1 | E24: 0 | F24: 0 | G24: 25 | H24: 64 | I24: =SUM(C24:H24) -> 93 | J24: 75 | K24: 90 | L24: 0 | M24: 32 | N24: ='padi sawah'!J43 -> 81 | O24: ='padi sawah'!K43 -> 12 | P24: =SUM(J24:O24) -> 290 | Q24: =SUM(I24,P24) -> 383 | T24: 2 | U24: CITANGKIL | V24: 0 | W24: 0 | X24: 0 | Y24: 0 | Z24: 0 | AA24: 0 | AH24: =SUM(V24:AG24) -> 0
A25: 3 | B25: PULOMERAK | C25: 0 | D25: 0 | E25: 0 | F25: 0 | G25: 0 | H25: 10 | I25: =SUM(C25:H25) -> 10 | J25: 38 | K25: 0 | L25: 0 | M25: 5 | N25: ='padi sawah'!J44 -> 10 | O25: ='padi sawah'!K44 -> 0 | P25: =SUM(J25:O25) -> 53 | Q25: =SUM(I25,P25) -> 63 | T25: 3 | U25: PULOMERAK | V25: 0 | W25: 0 | X25: 0 | Y25: 0 | Z25: 0 | AA25: 93 | AH25: =SUM(V25:AG25) -> 93
A26: 4 | B26: PURWAKARTA | C26: 0 | D26: 0 | E26: 2 | F26: 0 | G26: 3 | H26: 165 | I26: =SUM(C26:H26) -> 170 | J26: 16 | K26: 0 | L26: 0 | M26: 0 | N26: ='padi sawah'!J45 -> 7 | O26: ='padi sawah'!K45 -> 7 | P26: =SUM(J26:O26) -> 30 | Q26: =SUM(I26,P26) -> 200 | T26: 4 | U26: PURWAKARTA | V26: 0 | W26: 0 | X26: 0 | Y26: 0 | Z26: 0 | AA26: 0 | AH26: =SUM(V26:AG26) -> 0
A27: 5 | B27: GROGOL | C27: 22 | D27: 5 | E27: 0 | F27: 0 | G27: 0 | H27: 25 | I27: =SUM(C27:H27) -> 52 | J27: 225 | K27: 0 | L27: 0 | M27: 0 | N27: ='padi sawah'!J46 -> 10 | O27: ='padi sawah'!K46 -> 10 | P27: =SUM(J27:O27) -> 245 | Q27: =SUM(I27,P27) -> 297 | T27: 5 | U27: GROGOL | V27: 0 | W27: 0 | X27: 0 | Y27: 0 | Z27: 0 | AA27: 0 | AH27: =SUM(V27:AG27) -> 0
A28: 6 | B28: CILEGON | C28: 0 | D28: 0 | E28: 0 | F28: 0 | G28: 0 | H28: 44 | I28: =SUM(C28:H28) -> 44 | J28: 0 | K28: 0 | L28: 6 | M28: 0 | N28: ='padi sawah'!J47 -> 10 | O28: ='padi sawah'!K47 -> 14 | P28: =SUM(J28:O28) -> 30 | Q28: =SUM(I28,P28) -> 74 | T28: 6 | U28: CILEGON | V28: 0 | W28: 0 | X28: 0 | Y28: 0 | Z28: 0 | AA28: 0 | AH28: =SUM(V28:AG28) -> 0
A29: 7 | B29: JOMBANG | C29: 49 | D29: 4 | E29: 2 | F29: 1 | G29: 1 | H29: 92 | I29: =SUM(C29:H29) -> 149 | J29: 162 | K29: 23 | L29: 0 | M29: 2 | N29: ='padi sawah'!J48 -> 30 | O29: ='padi sawah'!K48 -> 183 | P29: =SUM(J29:O29) -> 400 | Q29: =SUM(I29,P29) -> 549 | T29: 7 | U29: JOMBANG | V29: 0 | W29: 0 | X29: 0 | Y29: 0 | Z29: 0 | AA29: 0 | AH29: =SUM(V29:AG29) -> 0
A30: 8 | B30: CIBEBER | C30: 34 | D30: 22 | E30: 0 | F30: 0 | G30: 30 | H30: 206 | I30: =SUM(C30:H30) -> 292 | J30: 68 | K30: 0 | L30: 4 | M30: 40 | N30: ='padi sawah'!J49 -> 107 | O30: ='padi sawah'!K49 -> 11 | P30: =SUM(J30:O30) -> 230 | Q30: =SUM(I30,P30) -> 522 | T30: 8 | U30: CIBEBER | V30: 0 | W30: 0 | X30: 0 | Y30: 0 | Z30: 0 | AA30: 0 | AH30: =SUM(V30:AG30) -> 0
A31: JUMLAH | C31: 110 | D31: 32 | E31: 4 | F31: 1 | G31: 59 | H31: 606 | I31: =SUM(I23:I30) -> 812 | J31: =SUM(J23:J30) -> 788 | K31: =SUM(K23:K30) -> 113 | L31: =SUM(L23:L30) -> 12 | M31: =SUM(M23:M30) -> 79 | N31: =SUM(N23:N30) -> 275 | O31: =SUM(O23:O30) -> 243 | P31: =SUM(P23:P30) -> 1510 | Q31: =SUM(Q23:Q30) -> 2322 | T31: JUMLAH | V31: =SUM(V23:V30) -> 0 | W31: =SUM(W23:W30) -> 0 | X31: =SUM(X23:X30) -> 0 | Y31: =SUM(Y23:Y30) -> 0 | Z31: =SUM(Z23:Z30) -> 0 | AA31: =SUM(AA23:AA30) -> 93 | AB31: =SUM(AB23:AB30) -> 0 | AC31: =SUM(AC23:AC30) -> 0 | ... AH31: =SUM(AH23:AH30) -> 93
A37: REALISASI PRODUKSI PADI SAWAH OKTOBER 2014 S/D MARET 2015 DAN APRIL S/D SEPTEMBER 2015
A38: KOTA CILEGON
Q39: (Ha)
A40: No | B40: Kecamatan | C40: 2014 S/D 2015 | I40: Okt-Mar | J40: 2015 | P40: Apr-Sep | Q40: Jumlah
C41: Okt | D41: Nov | E41: Des | F41: Jan | G41: Peb | H41: Mar | J41: April | K41: Mei | L41: Juni | M41: Juli | N41: Agust | O41: Sep
A42: 1 | B42: 2 | C42: 3 | D42: 4 | E42: 5 | F42: 6 | G42: 7 | H42: 8 | I42: 9 | J42: 10 | K42: 11 | L42: 12 | M42: 13 | N42: 14 | O42: 15 | P42: 16 | Q42: 17
A43: 1 | B43: CIWANDAN | C43: 7 | D43: 0 | E43: 0 | F43: 0 | G43: 0 | H43: 0 | I43: =SUM(C43:H43) -> 7 | J43: 1327 | K43: 0 | L43: 10 | M43: 0 | N43: ='padi sawah'!J75 -> 90 | O43: ='padi sawah'!K75 -> 35 | P43: =SUM(J43:O43) -> 1462 | Q43: =SUM(I43,P43) -> 1469
